# Cursed Village Large House
# MC 1.7.10; 8 Nov 2014
# Created by Ruins mod version 14.2 Ingame Parser
# authoring Player: Jordan_Greywolf
# Special Instructions: Place in /templateparser folder.
# Last Updated: 27 Apr 2015
# Updated to MC 1.8: 5 Mar 2016
# Updated to MC 1.9: 20 Apr 2016
# Updated to MC 1.11: 12 Jan 2017
# Updated to MC 1.12: 22 Jun 2017


weight=1
embed_into_distance=2
acceptable_target_blocks=


unacceptable_target_blocks=flowing_lava,lava,cloud,Natura:Cloud,red_mushroom_block,brown_mushroom_block,planks,cobblestone,mossy_cobblestone,iron_bars,glass,redstone_torch,torch,stone_slab,double_stone_slab,oak_stairs,spruce_stairs,birch_stairs,dark_oak_stairs,acacia_stairs,jungle_stairs,slime_congealed,slime_dirt,slime_grass,fence,stone_brick,cobblestone_wall,command_block

dimensions=8,12,9
allowable_overhang=0
max_leveling=6
leveling_buffer=0
preserve_water=0
preserve_lava=0
preserve_plants=1

rule1=0,100,minecraft:cobblestone,minecraft:cobblestone,minecraft:cobblestone,minecraft:mossy_cobblestone,minecraft:gravel,minecraft:monster_egg-1
rule2=0,100,minecraft:dirt-0
rule3=0,100,minecraft:planks-0,minecraft:planks-0,minecraft:gravel,minecraft:grass,minecraft:wooden_slab
rule4=0,100,minecraft:gravel-0
rule5=0,100,minecraft:log-0
rule6=0,50,minecraft:glass_pane-0
rule7=0,100,minecraft:planks-0
rule8=0,90,minecraft:oak_stairs-3
rule9=0,90,minecraft:oak_stairs-0
rule10=0,90,minecraft:oak_stairs-1
rule11=0,90,minecraft:oak_stairs-2

rule12=0,100,CommandBlock:RUINSTRIGGER /summon zombie_villager ~0 ~0 ~0 {CustomName:"Zombie Anklebiter",CanPickUpLoot:1,CanBreakDoors:1,IsBaby:1,PersistenceRequired:1}:@

# Buried Treasure
rule13=0,100,ChestGenHook:pyramidJungleChest:2

rule14=0,100,CommandBlock:RUINSTRIGGER /summon Zombie_Villager ~0 ~0 ~0 {ArmorItems:[{Count:1,id:leather_helmet,{},{},{}}],CanPickUpLoot:1,CanBreakDoors:1,PersistenceRequired:1}:@

#---------------------------

layer
2,2,1,1,1,1,1,1,1
2,2,1,2,2,2,2,2,1
2,2,1,2,2,2,2,2,1
2,2,1,2,2,2,2,2,1
2,2,1,2,2,2,2,2,1
1,1,1,2,2,2,2,2,1
1,2,2,2,2,2,2,2,1
1,2,2,2,13,2,2,2,1
1,2,2,2,12,2,2,2,1
1,2,2,2,2,2,2,2,1
1,1,1,1,1,1,1,1,1
4,4,4,4,4,4,4,4,4
endlayer

layer
2,2,1,1,1,1,1,1,1
2,2,1,3,3,3,3,3,1
2,2,1,3,3,3,3,3,1
2,2,1,3,3,3,3,3,1
2,2,1,3,3,3,3,3,1
1,1,1,3,3,3,3,3,1
1,3,3,3,3,3,3,3,1
1,3,3,3,7,3,3,3,1
1,3,3,3,7,3,3,3,1
1,3,3,3,3,3,3,3,1
1,1,1,1,1,1,1,1,1
4,4,4,4,4,4,4,4,4
endlayer

layer
0,0,1,1,1,1,1,1,1
0,0,1,0,0,0,14,0,1
0,0,1,0,14,0,0,0,1
0,0,1,14,0,0,14,0,1
0,0,1,0,0,0,0,0,1
1,1,1,0,12,0,0,0,1
1,14,0,0,0,0,0,14,1
1,0,0,0,0,0,0,0,1
1,0,14,0,12,0,14,0,1
1,0,0,0,0,0,14,0,1
1,1,0,1,1,1,1,1,1
0,0,0,0,0,0,0,0,0
endlayer

layer
0,0,1,1,1,1,1,1,1
0,0,5,0,0,0,0,0,5
0,0,6,0,0,0,0,0,6
0,0,6,0,0,0,0,0,6
0,0,5,0,0,0,0,0,5
1,7,7,0,0,0,0,0,7
5,0,0,0,0,0,0,0,5
6,0,0,0,0,0,0,0,6
6,0,0,0,0,0,0,0,6
5,0,0,0,0,0,0,0,5
1,7,0,7,5,6,5,7,1
0,0,0,0,0,0,0,0,0
endlayer

layer
0,8,1,1,1,1,1,1,1
0,8,1,0,0,0,0,0,1
0,8,1,0,0,0,0,0,1
0,8,1,0,0,0,0,0,1
9,7,1,0,0,0,0,0,1
1,7,7,0,0,0,0,0,1
1,0,0,0,0,0,0,0,1
1,0,0,0,0,0,0,0,1
1,0,0,0,0,0,0,0,1
1,0,0,0,0,0,0,0,1
1,7,7,7,7,7,7,7,1
10,10,10,10,10,10,10,10,10
endlayer

layer
0,0,8,7,5,6,5,7,11
0,0,8,7,0,0,0,7,11
0,0,8,7,0,0,0,7,11
0,0,8,7,0,0,0,7,11
0,0,8,7,0,0,0,7,11
9,9,7,7,0,0,0,7,11
7,7,7,7,0,0,0,7,7
7,0,0,0,0,0,0,7,7
7,0,0,0,0,0,0,7,7
7,7,7,7,7,7,7,7,7
10,10,10,10,10,10,10,10,10
0,0,0,0,0,0,0,0,0
endlayer

layer
0,0,0,8,7,7,7,11,0
0,0,0,8,7,0,7,11,0
0,0,0,8,7,0,7,11,0
0,0,0,8,7,0,7,11,0
0,0,0,8,7,0,7,11,0
0,0,0,8,7,0,7,11,0
9,9,9,7,7,0,7,7,9
7,7,7,7,7,7,7,7,7
7,7,7,7,7,7,7,7,7
10,10,10,10,10,10,10,10,10
0,0,0,0,0,0,0,0,0
0,0,0,0,0,0,0,0,0
endlayer

layer
0,0,0,0,8,7,11,0,0
0,0,0,0,8,7,11,0,0
0,0,0,0,8,7,11,0,0
0,0,0,0,8,7,11,0,0
0,0,0,0,8,7,11,0,0
0,0,0,0,8,7,11,0,0
0,0,0,0,8,7,11,0,0
9,9,9,9,7,7,7,9,9
10,10,10,10,10,10,10,10,10
0,0,0,0,0,0,0,0,0
0,0,0,0,0,0,0,0,0
0,0,0,0,0,0,0,0,0
endlayer

