
# Created by Ruins mod version 17.0 Ingame Parser
# authoring Player: ST753M

weight=1
embed_into_distance=4
acceptable_target_blocks=
unacceptable_target_blocks=flowing_water,water,flowing_lava,lava
dimensions=21,25,25
allowable_overhang=4
max_leveling=2
leveling_buffer=-1
preserve_water=1
preserve_lava=0
uniqueMinDistance=800

=0,100,preserveBlock
rule1=0,100,minecraft:prismarine-0
^0,100,minecraft:prismarine-1
^0,100,minecraft:prismarine-2
rule2=0,100,minecraft:prismarine-0
^0,100,minecraft:prismarine-1
^0,100,minecraft:prismarine-2
rule3=0,100,minecraft:sea_lantern-0,minecraft:prismarine-0
rule4=0,100,minecraft:water-0
rule5=0,100,ChestGenHook:chests/jungle_temple:2-5,ChestGenHook:chests/simple_dungeon:2-5
rule6=0,100,ChestGenHook:chests/jungle_temple:3-3,ChestGenHook:chests/simple_dungeon:3-3
rule7=0,100,ChestGenHook:chests/jungle_temple:2-2,ChestGenHook:chests/simple_dungeon:2-2
rule8=0,100,ChestGenHook:chests/jungle_temple:3-4,ChestGenHook:chests/simple_dungeon:3-4
rule9=0,100,CommandBlock:RUINSTRIGGER /summon elder_guardian ~ ~1 ~ {PersistenceRequired:1}:@-1,CommandBlock:RUINSTRIGGER /summon guardian ~ ~1 ~ {PersistenceRequired:1}:@-1
rule10=0,100,MobSpawner:guardian,minecraft:prismarine-0

rule11=0,100,minecraft:stained_glass-9
^0,100,preserveBlock
rule12^0,100,air
^0,100,preserveBlock

layer
0,0,0,0,0,0,0,0,0,0,0,0,0,0,0,0,0,0,0,0,0,0,0,0,0
0,1,2,2,0,0,0,0,0,0,0,0,0,0,0,0,0,0,0,0,0,2,2,1,0
0,2,2,2,0,0,0,0,0,0,0,0,0,0,0,0,0,0,0,0,0,2,2,2,0
0,2,2,2,2,0,0,0,0,0,0,0,0,0,0,0,0,0,0,0,2,2,2,2,0
0,0,0,2,2,2,2,2,2,2,2,2,2,2,2,2,2,2,2,2,2,2,0,0,0
0,0,0,0,2,1,1,2,1,1,1,2,2,2,1,1,1,2,1,1,2,0,0,0,0
0,0,0,0,2,1,2,2,1,2,2,1,1,1,2,2,1,2,2,1,2,0,0,0,0
0,0,0,0,2,2,2,1,2,2,1,1,2,1,1,2,2,1,2,2,2,0,0,0,0
0,0,0,0,2,1,1,2,1,1,1,2,1,2,1,1,1,2,1,1,2,0,0,0,0
0,0,0,0,2,1,2,2,1,2,1,2,1,2,1,2,1,2,2,1,2,0,0,0,0
0,0,0,0,2,1,2,1,1,1,2,2,1,2,2,1,1,1,2,1,2,0,0,0,0
0,0,0,0,2,2,1,1,2,2,2,1,1,1,2,2,2,1,1,2,2,0,0,0,0
0,0,0,0,2,2,1,2,1,1,1,1,3,1,1,1,1,2,1,2,2,0,0,0,0
0,0,0,0,2,2,1,1,2,2,2,1,1,1,2,2,2,1,1,2,2,0,0,0,0
0,0,0,0,2,1,2,1,1,1,2,2,1,2,2,1,1,1,2,1,2,0,0,0,0
0,0,0,0,2,1,2,2,1,2,1,2,1,2,1,2,1,2,2,1,2,0,0,0,0
0,0,0,0,2,1,1,2,1,1,1,2,1,2,1,1,1,2,1,1,2,0,0,0,0
0,0,0,0,2,2,2,1,2,2,1,1,2,1,1,2,2,1,2,2,2,0,0,0,0
0,0,0,0,2,1,2,2,1,2,2,1,1,1,2,2,1,2,2,1,2,0,0,0,0
0,0,0,0,2,1,1,2,1,1,1,2,2,2,1,1,1,2,1,1,2,0,0,0,0
0,0,0,2,2,2,2,2,2,2,2,2,2,2,2,2,2,2,2,2,2,2,0,0,0
0,2,2,2,2,0,0,0,0,0,0,0,0,0,0,0,0,0,0,0,2,2,2,2,0
0,2,2,2,0,0,0,0,0,0,0,0,0,0,0,0,0,0,0,0,0,2,2,2,0
0,1,2,2,0,0,0,0,0,0,0,0,0,0,0,0,0,0,0,0,0,2,2,1,0
0,0,0,0,0,0,0,0,0,0,0,0,0,0,0,0,0,0,0,0,0,0,0,0,0
endlayer

layer
0,0,2,2,2,0,0,0,0,0,0,0,0,0,0,0,0,0,0,0,2,2,2,0,0
0,1,1,1,2,0,0,0,0,0,0,0,0,0,0,0,0,0,0,0,2,1,1,1,0
2,1,1,1,2,0,0,0,0,0,0,0,0,0,0,0,0,0,0,0,2,1,1,1,2
2,1,1,1,2,2,2,2,2,2,2,2,2,2,2,2,2,2,2,2,2,1,1,1,2
2,2,2,2,4,4,4,4,4,4,4,4,1,4,4,4,4,4,4,4,4,2,2,2,2
0,0,0,2,4,4,4,4,4,4,4,4,4,4,4,4,4,4,4,4,4,2,0,0,0
0,0,0,2,4,4,4,4,4,4,4,4,4,4,4,4,4,4,4,4,4,2,0,0,0
0,0,0,2,4,4,4,4,4,4,4,4,4,4,4,4,4,4,4,4,4,2,0,0,0
0,0,0,2,4,4,4,4,4,4,4,4,4,4,4,4,4,4,4,4,4,2,0,0,0
0,0,0,2,4,4,4,4,4,4,4,4,4,4,4,4,4,4,4,4,4,2,0,0,0
0,0,0,2,4,4,4,4,4,4,4,4,4,4,4,4,4,4,4,4,4,2,0,0,0
0,0,0,2,4,4,4,4,4,4,4,4,4,4,4,4,4,4,4,4,4,2,0,0,0
0,0,0,2,1,4,4,4,4,4,4,4,4,4,4,4,4,4,4,4,1,2,0,0,0
0,0,0,2,4,4,4,4,4,4,4,4,4,4,4,4,4,4,4,4,4,2,0,0,0
0,0,0,2,4,4,4,4,4,4,4,4,4,4,4,4,4,4,4,4,4,2,0,0,0
0,0,0,2,4,4,4,4,4,4,4,4,4,4,4,4,4,4,4,4,4,2,0,0,0
0,0,0,2,4,4,4,4,4,4,4,4,4,4,4,4,4,4,4,4,4,2,0,0,0
0,0,0,2,4,4,4,4,4,4,4,4,4,4,4,4,4,4,4,4,4,2,0,0,0
0,0,0,2,4,4,4,4,4,4,4,4,4,4,4,4,4,4,4,4,4,2,0,0,0
0,0,0,2,4,4,4,4,4,4,4,4,4,4,4,4,4,4,4,4,4,2,0,0,0
2,2,2,2,4,4,4,4,4,4,4,4,1,4,4,4,4,4,4,4,4,2,2,2,2
2,1,1,1,2,2,2,2,2,2,2,2,2,2,2,2,2,2,2,2,2,1,1,1,2
2,1,1,1,2,0,0,0,0,0,0,0,0,0,0,0,0,0,0,0,2,1,1,1,2
0,1,1,1,2,0,0,0,0,0,0,0,0,0,0,0,0,0,0,0,2,1,1,1,0
0,0,2,2,2,0,0,0,0,0,0,0,0,0,0,0,0,0,0,0,2,2,2,0,0
endlayer

layer
0,0,2,0,2,0,0,0,0,0,0,0,0,0,0,0,0,0,0,0,2,0,2,0,0
0,1,1,1,0,0,0,0,0,0,0,0,0,0,0,0,0,0,0,0,0,1,1,1,0
2,1,1,1,0,0,0,0,0,0,0,0,0,0,0,0,0,0,0,0,0,1,1,1,2
0,1,1,1,2,1,1,1,1,1,1,1,1,1,1,1,1,1,1,1,2,1,1,1,0
2,0,0,2,4,4,4,4,4,4,4,4,5,4,4,4,4,4,4,4,4,2,0,0,2
0,0,0,1,4,4,4,4,4,4,4,4,4,4,4,4,4,4,4,4,4,1,0,0,0
0,0,0,1,4,4,4,4,4,4,4,4,4,4,4,4,4,4,4,4,4,1,0,0,0
0,0,0,1,4,4,4,4,4,4,4,4,4,4,4,4,4,4,4,4,4,1,0,0,0
0,0,0,1,4,4,4,4,4,4,4,4,4,4,4,4,4,4,4,4,4,1,0,0,0
0,0,0,1,4,4,4,4,4,4,4,4,4,4,4,4,4,4,4,4,4,1,0,0,0
0,0,0,1,4,4,4,4,4,4,4,4,4,4,4,4,4,4,4,4,4,1,0,0,0
0,0,0,1,4,4,4,4,4,4,4,4,4,4,4,4,4,4,4,4,4,1,0,0,0
0,0,0,1,7,4,4,4,4,4,4,4,4,4,4,4,4,4,4,4,6,1,0,0,0
0,0,0,1,4,4,4,4,4,4,4,4,4,4,4,4,4,4,4,4,4,1,0,0,0
0,0,0,1,4,4,4,4,4,4,4,4,4,4,4,4,4,4,4,4,4,1,0,0,0
0,0,0,1,4,4,4,4,4,4,4,4,4,4,4,4,4,4,4,4,4,1,0,0,0
0,0,0,1,4,4,4,4,4,4,4,4,4,4,4,4,4,4,4,4,4,1,0,0,0
0,0,0,1,4,4,4,4,4,4,4,4,4,4,4,4,4,4,4,4,4,1,0,0,0
0,0,0,1,4,4,4,4,4,4,4,4,4,4,4,4,4,4,4,4,4,1,0,0,0
0,0,0,1,4,4,4,4,4,4,4,4,4,4,4,4,4,4,4,4,4,1,0,0,0
2,0,0,2,4,4,4,4,4,4,4,4,8,4,4,4,4,4,4,4,4,2,0,0,2
0,1,1,1,2,1,1,1,1,1,1,1,1,1,1,1,1,1,1,1,2,1,1,1,0
2,1,1,1,0,0,0,0,0,0,0,0,0,0,0,0,0,0,0,0,0,1,1,1,2
0,1,1,1,0,0,0,0,0,0,0,0,0,0,0,0,0,0,0,0,0,1,1,1,0
0,0,2,0,2,0,0,0,0,0,0,0,0,0,0,0,0,0,0,0,2,0,2,0,0
endlayer

layer
0,0,2,0,2,0,0,0,0,0,0,0,0,0,0,0,0,0,0,0,2,0,2,0,0
0,1,1,1,0,0,0,0,0,0,0,0,0,0,0,0,0,0,0,0,0,1,1,1,0
2,1,1,1,0,0,0,0,0,0,0,0,0,0,0,0,0,0,0,0,0,1,1,1,2
0,1,1,1,2,2,2,2,2,2,2,2,2,2,2,2,2,2,2,2,2,1,1,1,0
2,0,0,2,4,4,4,4,4,4,4,4,4,4,4,4,4,4,4,4,4,2,0,0,2
0,0,0,2,4,4,4,4,4,4,4,4,4,4,4,4,4,4,4,4,4,2,0,0,0
0,0,0,2,4,4,4,4,4,4,4,4,4,4,4,4,4,4,4,4,4,2,0,0,0
0,0,0,2,4,4,4,4,4,4,4,4,4,4,4,4,4,4,4,4,4,2,0,0,0
0,0,0,2,4,4,4,4,4,4,4,4,4,4,4,4,4,4,4,4,4,2,0,0,0
0,0,0,2,4,4,4,4,4,4,4,4,4,4,4,4,4,4,4,4,4,2,0,0,0
0,0,0,2,4,4,4,4,4,4,4,4,4,4,4,4,4,4,4,4,4,2,0,0,0
0,0,0,2,4,4,4,4,4,4,4,4,4,4,4,4,4,4,4,4,4,2,0,0,0
0,0,0,2,4,4,4,4,4,4,4,4,9,4,4,4,4,4,4,4,4,2,0,0,0
0,0,0,2,4,4,4,4,4,4,4,4,4,4,4,4,4,4,4,4,4,2,0,0,0
0,0,0,2,4,4,4,4,4,4,4,4,4,4,4,4,4,4,4,4,4,2,0,0,0
0,0,0,2,4,4,4,4,4,4,4,4,4,4,4,4,4,4,4,4,4,2,0,0,0
0,0,0,2,4,4,4,4,4,4,4,4,4,4,4,4,4,4,4,4,4,2,0,0,0
0,0,0,2,4,4,4,4,4,4,4,4,4,4,4,4,4,4,4,4,4,2,0,0,0
0,0,0,2,4,4,4,4,4,4,4,4,4,4,4,4,4,4,4,4,4,2,0,0,0
0,0,0,2,4,4,4,4,4,4,4,4,4,4,4,4,4,4,4,4,4,2,0,0,0
2,0,0,2,4,4,4,4,4,4,4,4,4,4,4,4,4,4,4,4,4,2,0,0,2
0,1,1,1,2,2,2,2,2,2,2,2,2,2,2,2,2,2,2,2,2,1,1,1,0
2,1,1,1,0,0,0,0,0,0,0,0,0,0,0,0,0,0,0,0,0,1,1,1,2
0,1,1,1,0,0,0,0,0,0,0,0,0,0,0,0,0,0,0,0,0,1,1,1,0
0,0,2,0,2,0,0,0,0,0,0,0,0,0,0,0,0,0,0,0,2,0,2,0,0
endlayer

layer
0,0,2,2,2,0,0,0,0,0,0,0,0,0,0,0,0,0,0,0,2,2,2,0,0
0,1,1,1,2,0,0,0,0,0,0,0,0,0,0,0,0,0,0,0,2,1,1,1,0
2,1,1,1,2,0,0,0,0,0,0,0,0,0,0,0,0,0,0,0,2,1,1,1,2
2,1,1,1,2,0,0,0,0,0,0,0,0,0,0,0,0,0,0,0,2,1,1,1,2
2,2,2,2,2,2,2,2,2,2,2,2,2,2,2,2,2,2,2,2,2,2,2,2,2
0,0,0,0,2,1,1,1,1,1,1,1,1,1,1,1,1,1,1,1,2,0,0,0,0
0,0,0,0,2,1,2,2,2,2,2,2,2,2,2,2,2,2,2,1,2,0,0,0,0
0,0,0,0,2,1,2,4,4,4,4,4,4,4,4,4,4,4,2,1,2,0,0,0,0
0,0,0,0,2,1,2,4,4,4,4,4,4,4,4,4,4,4,2,1,2,0,0,0,0
0,0,0,0,2,1,2,4,4,4,4,4,4,4,4,4,4,4,2,1,2,0,0,0,0
0,0,0,0,2,1,2,4,4,4,4,4,4,4,4,4,4,4,2,1,2,0,0,0,0
0,0,0,0,2,1,2,4,4,4,4,4,4,4,4,4,4,4,2,1,2,0,0,0,0
0,0,0,0,2,1,2,4,4,4,4,4,4,4,4,4,4,4,2,1,2,0,0,0,0
0,0,0,0,2,1,2,4,4,4,4,4,4,4,4,4,4,4,2,1,2,0,0,0,0
0,0,0,0,2,1,2,4,4,4,4,4,4,4,4,4,4,4,2,1,2,0,0,0,0
0,0,0,0,2,1,2,4,4,4,4,4,4,4,4,4,4,4,2,1,2,0,0,0,0
0,0,0,0,2,1,2,4,4,4,4,4,4,4,4,4,4,4,2,1,2,0,0,0,0
0,0,0,0,2,1,2,4,4,4,4,4,4,4,4,4,4,4,2,1,2,0,0,0,0
0,0,0,0,2,1,2,2,2,2,2,2,2,2,2,2,2,2,2,1,2,0,0,0,0
0,0,0,0,2,1,1,1,1,1,1,1,1,1,1,1,1,1,1,1,2,0,0,0,0
2,2,2,2,2,2,2,2,2,2,2,2,2,2,2,2,2,2,2,2,2,2,2,2,2
2,1,1,1,2,0,0,0,0,0,0,0,0,0,0,0,0,0,0,0,2,1,1,1,2
2,1,1,1,2,0,0,0,0,0,0,0,0,0,0,0,0,0,0,0,2,1,1,1,2
0,1,1,1,2,0,0,0,0,0,0,0,0,0,0,0,0,0,0,0,2,1,1,1,0
0,0,2,2,2,0,0,0,0,0,0,0,0,0,0,0,0,0,0,0,2,2,2,0,0
endlayer

layer
0,0,2,2,0,0,0,0,0,0,0,0,0,0,0,0,0,0,0,0,0,2,2,0,0
0,1,1,1,0,0,0,0,0,0,0,0,0,0,0,0,0,0,0,0,0,1,1,1,0
2,1,10,1,0,0,0,0,0,0,0,0,0,0,0,0,0,0,0,0,0,1,1,1,2
2,1,1,1,0,0,0,0,0,0,0,0,0,0,0,0,0,0,0,0,0,1,1,1,2
0,0,0,0,0,0,0,0,0,0,0,0,0,0,0,0,0,0,0,0,0,0,0,0,0
0,0,0,0,0,0,0,0,0,0,0,0,0,0,0,0,0,0,0,0,0,0,0,0,0
0,0,0,0,0,0,0,0,0,0,0,0,0,0,0,0,0,0,0,0,0,0,0,0,0
0,0,0,0,0,0,0,0,0,0,0,0,0,0,0,0,0,0,0,0,0,0,0,0,0
0,0,0,0,0,0,0,0,0,0,0,0,0,0,0,0,0,0,0,0,0,0,0,0,0
0,0,0,0,0,0,0,0,0,0,0,0,0,0,0,0,0,0,0,0,0,0,0,0,0
0,0,0,0,0,0,0,0,0,0,0,0,0,0,0,0,0,0,0,0,0,0,0,0,0
0,0,0,0,0,0,0,0,0,0,0,0,0,0,0,0,0,0,0,0,0,0,0,0,0
0,0,0,0,0,0,0,0,0,0,0,0,0,0,0,0,0,0,0,0,0,0,0,0,0
0,0,0,0,0,0,0,0,0,0,0,0,0,0,0,0,0,0,0,0,0,0,0,0,0
0,0,0,0,0,0,0,0,0,0,0,0,0,0,0,0,0,0,0,0,0,0,0,0,0
0,0,0,0,0,0,0,0,0,0,0,0,0,0,0,0,0,0,0,0,0,0,0,0,0
0,0,0,0,0,0,0,0,0,0,0,0,0,0,0,0,0,0,0,0,0,0,0,0,0
0,0,0,0,0,0,0,0,0,0,0,0,0,0,0,0,0,0,0,0,0,0,0,0,0
0,0,0,0,0,0,0,0,0,0,0,0,0,0,0,0,0,0,0,0,0,0,0,0,0
0,0,0,0,0,0,0,0,0,0,0,0,0,0,0,0,0,0,0,0,0,0,0,0,0
0,0,0,0,0,0,0,0,0,0,0,0,0,0,0,0,0,0,0,0,0,0,0,0,0
2,1,1,1,0,0,0,0,0,0,0,0,0,0,0,0,0,0,0,0,0,1,1,1,2
2,1,1,1,0,0,0,0,0,0,0,0,0,0,0,0,0,0,0,0,0,1,10,1,2
0,1,1,1,0,0,0,0,0,0,0,0,0,0,0,0,0,0,0,0,0,1,1,1,0
0,0,2,2,0,0,0,0,0,0,0,0,0,0,0,0,0,0,0,0,0,2,2,0,0
endlayer

layer
0,0,2,2,0,0,0,0,0,0,0,0,0,0,0,0,0,0,0,0,0,2,2,0,0
0,1,1,0,0,0,0,0,0,0,0,0,0,0,0,0,0,0,0,0,0,0,1,1,0
2,1,1,0,0,0,0,0,0,0,0,0,0,0,0,0,0,0,0,0,0,0,1,1,2
2,0,0,0,0,0,0,0,0,0,0,0,0,0,0,0,0,0,0,0,0,0,0,0,2
0,0,0,0,0,0,0,0,0,0,0,0,0,0,0,0,0,0,0,0,0,0,0,0,0
0,0,0,0,0,0,0,0,0,0,0,0,0,0,0,0,0,0,0,0,0,0,0,0,0
0,0,0,0,0,0,0,0,0,0,0,0,0,0,0,0,0,0,0,0,0,0,0,0,0
0,0,0,0,0,0,0,0,0,0,0,0,0,0,0,0,0,0,0,0,0,0,0,0,0
0,0,0,0,0,0,0,0,0,0,0,0,0,0,0,0,0,0,0,0,0,0,0,0,0
0,0,0,0,0,0,0,0,0,0,0,0,0,0,0,0,0,0,0,0,0,0,0,0,0
0,0,0,0,0,0,0,0,0,0,0,0,0,0,0,0,0,0,0,0,0,0,0,0,0
0,0,0,0,0,0,0,0,0,0,0,0,0,0,0,0,0,0,0,0,0,0,0,0,0
0,0,0,0,0,0,0,0,0,0,0,0,0,0,0,0,0,0,0,0,0,0,0,0,0
0,0,0,0,0,0,0,0,0,0,0,0,0,0,0,0,0,0,0,0,0,0,0,0,0
0,0,0,0,0,0,0,0,0,0,0,0,0,0,0,0,0,0,0,0,0,0,0,0,0
0,0,0,0,0,0,0,0,0,0,0,0,0,0,0,0,0,0,0,0,0,0,0,0,0
0,0,0,0,0,0,0,0,0,0,0,0,0,0,0,0,0,0,0,0,0,0,0,0,0
0,0,0,0,0,0,0,0,0,0,0,0,0,0,0,0,0,0,0,0,0,0,0,0,0
0,0,0,0,0,0,0,0,0,0,0,0,0,0,0,0,0,0,0,0,0,0,0,0,0
0,0,0,0,0,0,0,0,0,0,0,0,0,0,0,0,0,0,0,0,0,0,0,0,0
0,0,0,0,0,0,0,0,0,0,0,0,0,0,0,0,0,0,0,0,0,0,0,0,0
2,0,0,0,0,0,0,0,0,0,0,0,0,0,0,0,0,0,0,0,0,0,0,0,2
2,1,1,0,0,0,0,0,0,0,0,0,0,0,0,0,0,0,0,0,0,0,1,1,2
0,1,1,0,0,0,0,0,0,0,0,0,0,0,0,0,0,0,0,0,0,0,1,1,0
0,0,2,2,0,0,0,0,0,0,0,0,0,0,0,0,0,0,0,0,0,2,2,0,0
endlayer

layer
0,0,2,2,0,0,0,0,0,0,0,0,0,0,0,0,0,0,0,0,0,2,2,0,0
0,1,1,0,0,0,0,0,0,0,0,0,0,0,0,0,0,0,0,0,0,0,1,1,0
2,1,0,0,0,0,0,0,0,0,0,0,0,0,0,0,0,0,0,0,0,0,0,1,2
2,0,0,0,0,0,0,0,0,0,0,0,0,0,0,0,0,0,0,0,0,0,0,0,2
0,0,0,0,0,0,0,0,0,0,0,0,0,0,0,0,0,0,0,0,0,0,0,0,0
0,0,0,0,0,0,0,0,0,0,0,0,0,0,0,0,0,0,0,0,0,0,0,0,0
0,0,0,0,0,0,0,0,0,0,0,0,0,0,0,0,0,0,0,0,0,0,0,0,0
0,0,0,0,0,0,0,0,0,0,0,0,0,0,0,0,0,0,0,0,0,0,0,0,0
0,0,0,0,0,0,0,0,0,0,0,0,0,0,0,0,0,0,0,0,0,0,0,0,0
0,0,0,0,0,0,0,0,0,0,0,0,0,0,0,0,0,0,0,0,0,0,0,0,0
0,0,0,0,0,0,0,0,0,0,0,0,0,0,0,0,0,0,0,0,0,0,0,0,0
0,0,0,0,0,0,0,0,0,0,0,0,0,0,0,0,0,0,0,0,0,0,0,0,0
0,0,0,0,0,0,0,0,0,0,0,0,0,0,0,0,0,0,0,0,0,0,0,0,0
0,0,0,0,0,0,0,0,0,0,0,0,0,0,0,0,0,0,0,0,0,0,0,0,0
0,0,0,0,0,0,0,0,0,0,0,0,0,0,0,0,0,0,0,0,0,0,0,0,0
0,0,0,0,0,0,0,0,0,0,0,0,0,0,0,0,0,0,0,0,0,0,0,0,0
0,0,0,0,0,0,0,0,0,0,0,0,0,0,0,0,0,0,0,0,0,0,0,0,0
0,0,0,0,0,0,0,0,0,0,0,0,0,0,0,0,0,0,0,0,0,0,0,0,0
0,0,0,0,0,0,0,0,0,0,0,0,0,0,0,0,0,0,0,0,0,0,0,0,0
0,0,0,0,0,0,0,0,0,0,0,0,0,0,0,0,0,0,0,0,0,0,0,0,0
0,0,0,0,0,0,0,0,0,0,0,0,0,0,0,0,0,0,0,0,0,0,0,0,0
2,0,0,0,0,0,0,0,0,0,0,0,0,0,0,0,0,0,0,0,0,0,0,0,2
2,1,0,0,0,0,0,0,0,0,0,0,0,0,0,0,0,0,0,0,0,0,0,1,2
0,1,1,0,0,0,0,0,0,0,0,0,0,0,0,0,0,0,0,0,0,0,1,1,0
0,0,2,2,0,0,0,0,0,0,0,0,0,0,0,0,0,0,0,0,0,2,2,0,0
endlayer

layer
0,0,2,2,2,0,0,0,0,0,0,0,0,0,0,0,0,0,0,0,2,2,2,0,0
0,0,1,0,0,0,0,0,0,0,0,0,0,0,0,0,0,0,0,0,0,0,1,0,0
2,1,0,0,0,0,0,0,0,0,0,0,0,0,0,0,0,0,0,0,0,0,0,1,2
2,0,0,0,0,0,0,0,0,0,0,0,0,0,0,0,0,0,0,0,0,0,0,0,2
2,0,0,0,0,0,0,0,0,0,0,0,0,0,0,0,0,0,0,0,0,0,0,0,2
0,0,0,0,0,0,0,0,0,0,0,0,0,0,0,0,0,0,0,0,0,0,0,0,0
0,0,0,0,0,0,0,0,0,0,0,0,0,0,0,0,0,0,0,0,0,0,0,0,0
0,0,0,0,0,0,0,0,0,0,0,0,0,0,0,0,0,0,0,0,0,0,0,0,0
0,0,0,0,0,0,0,0,0,0,0,0,0,0,0,0,0,0,0,0,0,0,0,0,0
0,0,0,0,0,0,0,0,0,0,0,0,0,0,0,0,0,0,0,0,0,0,0,0,0
0,0,0,0,0,0,0,0,0,0,0,0,0,0,0,0,0,0,0,0,0,0,0,0,0
0,0,0,0,0,0,0,0,0,0,0,0,0,0,0,0,0,0,0,0,0,0,0,0,0
0,0,0,0,0,0,0,0,0,0,0,0,0,0,0,0,0,0,0,0,0,0,0,0,0
0,0,0,0,0,0,0,0,0,0,0,0,0,0,0,0,0,0,0,0,0,0,0,0,0
0,0,0,0,0,0,0,0,0,0,0,0,0,0,0,0,0,0,0,0,0,0,0,0,0
0,0,0,0,0,0,0,0,0,0,0,0,0,0,0,0,0,0,0,0,0,0,0,0,0
0,0,0,0,0,0,0,0,0,0,0,0,0,0,0,0,0,0,0,0,0,0,0,0,0
0,0,0,0,0,0,0,0,0,0,0,0,0,0,0,0,0,0,0,0,0,0,0,0,0
0,0,0,0,0,0,0,0,0,0,0,0,0,0,0,0,0,0,0,0,0,0,0,0,0
0,0,0,0,0,0,0,0,0,0,0,0,0,0,0,0,0,0,0,0,0,0,0,0,0
2,0,0,0,0,0,0,0,0,0,0,0,0,0,0,0,0,0,0,0,0,0,0,0,2
2,0,0,0,0,0,0,0,0,0,0,0,0,0,0,0,0,0,0,0,0,0,0,0,2
2,1,0,0,0,0,0,0,0,0,0,0,0,0,0,0,0,0,0,0,0,0,0,1,2
0,0,1,0,0,0,0,0,0,0,0,0,0,0,0,0,0,0,0,0,0,0,1,0,0
0,0,2,2,2,0,0,0,0,0,0,0,0,0,0,0,0,0,0,0,2,2,2,0,0
endlayer

layer
0,0,0,2,2,0,0,0,0,0,0,0,0,0,0,0,0,0,0,0,2,2,0,0,0
0,0,1,1,0,0,0,0,0,0,0,0,0,0,0,0,0,0,0,0,0,1,1,0,0
0,1,0,0,0,0,0,0,0,0,0,0,0,0,0,0,0,0,0,0,0,0,0,1,0
2,1,0,0,0,0,0,0,0,0,0,0,0,0,0,0,0,0,0,0,0,0,0,1,2
2,0,0,0,0,0,0,0,0,0,0,0,0,0,0,0,0,0,0,0,0,0,0,0,2
0,0,0,0,0,0,0,0,0,0,0,0,0,0,0,0,0,0,0,0,0,0,0,0,0
0,0,0,0,0,0,0,0,0,0,0,0,0,0,0,0,0,0,0,0,0,0,0,0,0
0,0,0,0,0,0,0,0,0,0,0,0,0,0,0,0,0,0,0,0,0,0,0,0,0
0,0,0,0,0,0,0,0,0,0,0,0,0,0,0,0,0,0,0,0,0,0,0,0,0
0,0,0,0,0,0,0,0,0,0,0,0,0,0,0,0,0,0,0,0,0,0,0,0,0
0,0,0,0,0,0,0,0,0,0,0,0,0,0,0,0,0,0,0,0,0,0,0,0,0
0,0,0,0,0,0,0,0,0,0,0,0,0,0,0,0,0,0,0,0,0,0,0,0,0
0,0,0,0,0,0,0,0,0,0,0,0,0,0,0,0,0,0,0,0,0,0,0,0,0
0,0,0,0,0,0,0,0,0,0,0,0,0,0,0,0,0,0,0,0,0,0,0,0,0
0,0,0,0,0,0,0,0,0,0,0,0,0,0,0,0,0,0,0,0,0,0,0,0,0
0,0,0,0,0,0,0,0,0,0,0,0,0,0,0,0,0,0,0,0,0,0,0,0,0
0,0,0,0,0,0,0,0,0,0,0,0,0,0,0,0,0,0,0,0,0,0,0,0,0
0,0,0,0,0,0,0,0,0,0,0,0,0,0,0,0,0,0,0,0,0,0,0,0,0
0,0,0,0,0,0,0,0,0,0,0,0,0,0,0,0,0,0,0,0,0,0,0,0,0
0,0,0,0,0,0,0,0,0,0,0,0,0,0,0,0,0,0,0,0,0,0,0,0,0
2,0,0,0,0,0,0,0,0,0,0,0,0,0,0,0,0,0,0,0,0,0,0,0,2
2,1,0,0,0,0,0,0,0,0,0,0,0,0,0,0,0,0,0,0,0,0,0,1,2
0,1,0,0,0,0,0,0,0,0,0,0,0,0,0,0,0,0,0,0,0,0,0,1,0
0,0,1,1,0,0,0,0,0,0,0,0,0,0,0,0,0,0,0,0,0,1,1,0,0
0,0,0,2,2,0,0,0,0,0,0,0,0,0,0,0,0,0,0,0,2,2,0,0,0
endlayer

layer
0,0,0,2,2,2,0,0,0,0,0,0,0,0,0,0,0,0,0,2,2,2,0,0,0
0,0,0,1,0,0,0,0,0,0,0,0,0,0,0,0,0,0,0,0,0,1,0,0,0
0,0,2,0,0,0,0,0,0,0,0,0,0,0,0,0,0,0,0,0,0,0,2,0,0
2,1,0,0,0,0,0,0,0,0,0,0,0,0,0,0,0,0,0,0,0,0,0,1,2
2,0,0,0,0,0,0,0,0,0,0,0,0,0,0,0,0,0,0,0,0,0,0,0,2
2,0,0,0,0,0,0,0,0,0,0,0,0,0,0,0,0,0,0,0,0,0,0,0,2
0,0,0,0,0,0,0,0,0,0,0,0,0,0,0,0,0,0,0,0,0,0,0,0,0
0,0,0,0,0,0,0,0,0,0,0,0,0,0,0,0,0,0,0,0,0,0,0,0,0
0,0,0,0,0,0,0,0,0,0,0,0,0,0,0,0,0,0,0,0,0,0,0,0,0
0,0,0,0,0,0,0,0,0,0,0,0,0,0,0,0,0,0,0,0,0,0,0,0,0
0,0,0,0,0,0,0,0,0,0,0,0,0,0,0,0,0,0,0,0,0,0,0,0,0
0,0,0,0,0,0,0,0,0,0,0,0,0,0,0,0,0,0,0,0,0,0,0,0,0
0,0,0,0,0,0,0,0,0,0,0,0,0,0,0,0,0,0,0,0,0,0,0,0,0
0,0,0,0,0,0,0,0,0,0,0,0,0,0,0,0,0,0,0,0,0,0,0,0,0
0,0,0,0,0,0,0,0,0,0,0,0,0,0,0,0,0,0,0,0,0,0,0,0,0
0,0,0,0,0,0,0,0,0,0,0,0,0,0,0,0,0,0,0,0,0,0,0,0,0
0,0,0,0,0,0,0,0,0,0,0,0,0,0,0,0,0,0,0,0,0,0,0,0,0
0,0,0,0,0,0,0,0,0,0,0,0,0,0,0,0,0,0,0,0,0,0,0,0,0
0,0,0,0,0,0,0,0,0,0,0,0,0,0,0,0,0,0,0,0,0,0,0,0,0
2,0,0,0,0,0,0,0,0,0,0,0,0,0,0,0,0,0,0,0,0,0,0,0,2
2,0,0,0,0,0,0,0,0,0,0,0,0,0,0,0,0,0,0,0,0,0,0,0,2
2,1,0,0,0,0,0,0,0,0,0,0,0,0,0,0,0,0,0,0,0,0,0,1,2
0,0,2,0,0,0,0,0,0,0,0,0,0,0,0,0,0,0,0,0,0,0,2,0,0
0,0,0,1,0,0,0,0,0,0,0,0,0,0,0,0,0,0,0,0,0,1,0,0,0
0,0,0,2,2,2,0,0,0,0,0,0,0,0,0,0,0,0,0,2,2,2,0,0,0
endlayer

layer
0,0,0,0,2,2,2,0,0,0,0,0,0,0,0,0,0,0,2,2,2,0,0,0,0
0,0,0,1,1,0,0,0,0,0,0,0,0,0,0,0,0,0,0,0,1,1,0,0,0
0,0,2,0,0,0,0,0,0,0,0,0,0,0,0,0,0,0,0,0,0,0,2,0,0
0,1,0,0,0,0,0,0,0,0,0,0,0,0,0,0,0,0,0,0,0,0,0,1,0
2,1,0,0,0,0,0,0,0,0,0,0,0,0,0,0,0,0,0,0,0,0,0,1,2
2,0,0,0,0,0,0,0,0,0,0,0,0,0,0,0,0,0,0,0,0,0,0,0,2
2,0,0,0,0,0,0,0,0,0,0,0,0,0,0,0,0,0,0,0,0,0,0,0,2
0,0,0,0,0,0,0,0,0,0,0,0,0,0,0,0,0,0,0,0,0,0,0,0,0
0,0,0,0,0,0,0,0,0,0,0,0,0,0,0,0,0,0,0,0,0,0,0,0,0
0,0,0,0,0,0,0,0,0,0,0,0,0,0,0,0,0,0,0,0,0,0,0,0,0
0,0,0,0,0,0,0,0,0,0,0,0,0,0,0,0,0,0,0,0,0,0,0,0,0
0,0,0,0,0,0,0,0,0,0,0,0,0,0,0,0,0,0,0,0,0,0,0,0,0
0,0,0,0,0,0,0,0,0,0,0,0,0,0,0,0,0,0,0,0,0,0,0,0,0
0,0,0,0,0,0,0,0,0,0,0,0,0,0,0,0,0,0,0,0,0,0,0,0,0
0,0,0,0,0,0,0,0,0,0,0,0,0,0,0,0,0,0,0,0,0,0,0,0,0
0,0,0,0,0,0,0,0,0,0,0,0,0,0,0,0,0,0,0,0,0,0,0,0,0
0,0,0,0,0,0,0,0,0,0,0,0,0,0,0,0,0,0,0,0,0,0,0,0,0
0,0,0,0,0,0,0,0,0,0,0,0,0,0,0,0,0,0,0,0,0,0,0,0,0
2,0,0,0,0,0,0,0,0,0,0,0,0,0,0,0,0,0,0,0,0,0,0,0,2
2,0,0,0,0,0,0,0,0,0,0,0,0,0,0,0,0,0,0,0,0,0,0,0,2
2,1,0,0,0,0,0,0,0,0,0,0,0,0,0,0,0,0,0,0,0,0,0,1,2
0,1,0,0,0,0,0,0,0,0,0,0,0,0,0,0,0,0,0,0,0,0,0,1,0
0,0,2,0,0,0,0,0,0,0,0,0,0,0,0,0,0,0,0,0,0,0,2,0,0
0,0,0,1,1,0,0,0,0,0,0,0,0,0,0,0,0,0,0,0,1,1,0,0,0
0,0,0,0,2,2,2,0,0,0,0,0,0,0,0,0,0,0,2,2,2,0,0,0,0
endlayer

layer
0,0,0,0,0,2,2,2,0,0,0,0,0,0,0,0,0,2,2,2,0,0,0,0,0
0,0,0,0,1,1,0,0,0,0,0,0,0,0,0,0,0,0,0,1,1,0,0,0,0
0,0,0,2,0,0,0,0,0,0,0,0,0,0,0,0,0,0,0,0,0,2,0,0,0
0,0,2,0,0,0,0,0,0,0,0,0,0,0,0,0,0,0,0,0,0,0,2,0,0
0,1,0,0,0,0,0,0,0,0,0,0,0,0,0,0,0,0,0,0,0,0,0,1,0
2,1,0,0,0,0,0,0,0,0,0,0,0,0,0,0,0,0,0,0,0,0,0,1,2
2,0,0,0,0,0,0,0,0,0,0,0,0,0,0,0,0,0,0,0,0,0,0,0,2
2,0,0,0,0,0,0,0,0,0,0,0,0,0,0,0,0,0,0,0,0,0,0,0,2
0,0,0,0,0,0,0,0,0,0,0,0,0,0,0,0,0,0,0,0,0,0,0,0,0
0,0,0,0,0,0,0,0,0,0,0,0,0,0,0,0,0,0,0,0,0,0,0,0,0
0,0,0,0,0,0,0,0,0,0,0,0,0,0,0,0,0,0,0,0,0,0,0,0,0
0,0,0,0,0,0,0,0,0,0,0,0,0,0,0,0,0,0,0,0,0,0,0,0,0
0,0,0,0,0,0,0,0,0,0,0,0,0,0,0,0,0,0,0,0,0,0,0,0,0
0,0,0,0,0,0,0,0,0,0,0,0,0,0,0,0,0,0,0,0,0,0,0,0,0
0,0,0,0,0,0,0,0,0,0,0,0,0,0,0,0,0,0,0,0,0,0,0,0,0
0,0,0,0,0,0,0,0,0,0,0,0,0,0,0,0,0,0,0,0,0,0,0,0,0
0,0,0,0,0,0,0,0,0,0,0,0,0,0,0,0,0,0,0,0,0,0,0,0,0
2,0,0,0,0,0,0,0,0,0,0,0,0,0,0,0,0,0,0,0,0,0,0,0,2
2,0,0,0,0,0,0,0,0,0,0,0,0,0,0,0,0,0,0,0,0,0,0,0,2
2,1,0,0,0,0,0,0,0,0,0,0,0,0,0,0,0,0,0,0,0,0,0,1,2
0,1,0,0,0,0,0,0,0,0,0,0,0,0,0,0,0,0,0,0,0,0,0,1,0
0,0,2,0,0,0,0,0,0,0,0,0,0,0,0,0,0,0,0,0,0,0,2,0,0
0,0,0,2,0,0,0,0,0,0,0,0,0,0,0,0,0,0,0,0,0,2,0,0,0
0,0,0,0,1,1,0,0,0,0,0,0,0,0,0,0,0,0,0,1,1,0,0,0,0
0,0,0,0,0,2,2,2,0,0,0,0,0,0,0,0,0,2,2,2,0,0,0,0,0
endlayer

layer
0,0,0,0,0,0,2,2,2,2,0,0,0,0,0,2,2,2,2,0,0,0,0,0,0
0,0,0,0,0,1,1,0,0,0,0,0,0,0,0,0,0,0,1,1,0,0,0,0,0
0,0,0,0,2,0,0,0,0,0,0,0,0,0,0,0,0,0,0,0,2,0,0,0,0
0,0,0,11,0,0,0,0,0,0,0,0,0,0,0,0,0,0,0,0,0,11,0,0,0
0,0,2,0,0,0,0,0,0,0,0,0,0,0,0,0,0,0,0,0,0,0,2,0,0
0,1,0,0,0,0,0,0,0,0,0,0,0,0,0,0,0,0,0,0,0,0,0,1,0
2,1,0,0,0,0,0,0,0,0,0,0,0,0,0,0,0,0,0,0,0,0,0,1,2
2,0,0,0,0,0,0,0,0,0,0,0,0,0,0,0,0,0,0,0,0,0,0,0,2
2,0,0,0,0,0,0,0,0,0,0,0,0,0,0,0,0,0,0,0,0,0,0,0,2
2,0,0,0,0,0,0,0,0,0,0,0,0,0,0,0,0,0,0,0,0,0,0,0,2
0,0,0,0,0,0,0,0,0,0,0,0,0,0,0,0,0,0,0,0,0,0,0,0,0
0,0,0,0,0,0,0,0,0,0,0,0,0,0,0,0,0,0,0,0,0,0,0,0,0
0,0,0,0,0,0,0,0,0,0,0,0,0,0,0,0,0,0,0,0,0,0,0,0,0
0,0,0,0,0,0,0,0,0,0,0,0,0,0,0,0,0,0,0,0,0,0,0,0,0
0,0,0,0,0,0,0,0,0,0,0,0,0,0,0,0,0,0,0,0,0,0,0,0,0
2,0,0,0,0,0,0,0,0,0,0,0,0,0,0,0,0,0,0,0,0,0,0,0,2
2,0,0,0,0,0,0,0,0,0,0,0,0,0,0,0,0,0,0,0,0,0,0,0,2
2,0,0,0,0,0,0,0,0,0,0,0,0,0,0,0,0,0,0,0,0,0,0,0,2
2,1,0,0,0,0,0,0,0,0,0,0,0,0,0,0,0,0,0,0,0,0,0,1,2
0,1,0,0,0,0,0,0,0,0,0,0,0,0,0,0,0,0,0,0,0,0,0,1,0
0,0,2,0,0,0,0,0,0,0,0,0,0,0,0,0,0,0,0,0,0,0,2,0,0
0,0,0,11,0,0,0,0,0,0,0,0,0,0,0,0,0,0,0,0,0,11,0,0,0
0,0,0,0,2,0,0,0,0,0,0,0,0,0,0,0,0,0,0,0,2,0,0,0,0
0,0,0,0,0,1,1,0,0,0,0,0,0,0,0,0,0,0,1,1,0,0,0,0,0
0,0,0,0,0,0,2,2,2,2,0,0,0,0,0,2,2,2,2,0,0,0,0,0,0
endlayer

layer
0,0,0,0,0,0,0,2,2,2,2,2,2,2,2,2,2,2,0,0,0,0,0,0,0
0,0,0,0,0,0,1,1,1,0,0,0,0,0,0,0,1,1,1,0,0,0,0,0,0
0,0,0,0,0,2,0,0,0,0,0,0,0,0,0,0,0,0,0,2,0,0,0,0,0
0,0,0,0,11,0,0,0,0,0,0,0,0,0,0,0,0,0,0,0,11,0,0,0,0
0,0,0,11,0,0,0,0,0,0,0,0,0,0,0,0,0,0,0,0,0,11,0,0,0
0,0,2,0,0,0,0,0,0,0,0,0,0,0,0,0,0,0,0,0,0,0,2,0,0
0,1,0,0,0,0,0,0,0,0,0,0,0,0,0,0,0,0,0,0,0,0,0,1,0
2,1,0,0,0,0,0,0,0,0,0,0,0,0,0,0,0,0,0,0,0,0,0,1,2
2,1,0,0,0,0,0,0,0,0,0,0,0,0,0,0,0,0,0,0,0,0,0,1,2
2,0,0,0,0,0,0,0,0,0,0,0,0,0,0,0,0,0,0,0,0,0,0,0,2
2,0,0,0,0,0,0,0,0,0,0,0,0,0,0,0,0,0,0,0,0,0,0,0,2
2,0,0,0,0,0,0,0,0,0,0,0,0,0,0,0,0,0,0,0,0,0,0,0,2
2,0,0,0,0,0,0,0,0,0,0,0,0,0,0,0,0,0,0,0,0,0,0,0,2
2,0,0,0,0,0,0,0,0,0,0,0,0,0,0,0,0,0,0,0,0,0,0,0,2
2,0,0,0,0,0,0,0,0,0,0,0,0,0,0,0,0,0,0,0,0,0,0,0,2
2,0,0,0,0,0,0,0,0,0,0,0,0,0,0,0,0,0,0,0,0,0,0,0,2
2,1,0,0,0,0,0,0,0,0,0,0,0,0,0,0,0,0,0,0,0,0,0,1,2
2,1,0,0,0,0,0,0,0,0,0,0,0,0,0,0,0,0,0,0,0,0,0,1,2
0,1,0,0,0,0,0,0,0,0,0,0,0,0,0,0,0,0,0,0,0,0,0,1,0
0,0,2,0,0,0,0,0,0,0,0,0,0,0,0,0,0,0,0,0,0,0,2,0,0
0,0,0,11,0,0,0,0,0,0,0,0,0,0,0,0,0,0,0,0,0,11,0,0,0
0,0,0,0,11,0,0,0,0,0,0,0,0,0,0,0,0,0,0,0,11,0,0,0,0
0,0,0,0,0,2,0,0,0,0,0,0,0,0,0,0,0,0,0,2,0,0,0,0,0
0,0,0,0,0,0,1,1,1,0,0,0,0,0,0,0,1,1,1,0,0,0,0,0,0
0,0,0,0,0,0,0,2,2,2,2,2,2,2,2,2,2,2,0,0,0,0,0,0,0
endlayer

layer
0,0,0,0,0,0,0,2,0,2,2,2,2,2,2,2,0,2,0,0,0,0,0,0,0
0,0,0,0,0,0,0,2,1,1,1,1,2,1,1,1,1,2,0,0,0,0,0,0,0
0,0,0,0,0,0,1,1,0,0,0,0,0,0,0,0,0,1,1,0,0,0,0,0,0
0,0,0,0,0,2,0,0,0,0,0,0,0,0,0,0,0,0,0,2,0,0,0,0,0
0,0,0,0,11,0,0,0,0,0,0,0,0,0,0,0,0,0,0,0,11,0,0,0,0
0,0,0,2,0,0,0,0,0,0,0,0,0,0,0,0,0,0,0,0,0,2,0,0,0
0,0,1,0,0,0,0,0,0,0,0,0,0,0,0,0,0,0,0,0,0,0,1,0,0
2,2,1,0,0,0,0,0,0,0,0,0,0,0,0,0,0,0,0,0,0,0,1,2,2
0,1,0,0,0,0,0,0,0,0,0,0,0,0,0,0,0,0,0,0,0,0,0,1,0
2,1,0,0,0,0,0,0,0,0,0,0,0,0,0,0,0,0,0,0,0,0,0,1,2
2,1,0,0,0,0,0,0,0,0,0,0,0,0,0,0,0,0,0,0,0,0,0,1,2
2,1,0,0,0,0,0,0,0,0,0,0,0,0,0,0,0,0,0,0,0,0,0,1,2
2,2,0,0,0,0,0,0,0,0,0,0,0,0,0,0,0,0,0,0,0,0,0,2,2
2,1,0,0,0,0,0,0,0,0,0,0,0,0,0,0,0,0,0,0,0,0,0,1,2
2,1,0,0,0,0,0,0,0,0,0,0,0,0,0,0,0,0,0,0,0,0,0,1,2
2,1,0,0,0,0,0,0,0,0,0,0,0,0,0,0,0,0,0,0,0,0,0,1,2
0,1,0,0,0,0,0,0,0,0,0,0,0,0,0,0,0,0,0,0,0,0,0,1,0
2,2,1,0,0,0,0,0,0,0,0,0,0,0,0,0,0,0,0,0,0,0,1,2,2
0,0,1,0,0,0,0,0,0,0,0,0,0,0,0,0,0,0,0,0,0,0,1,0,0
0,0,0,2,0,0,0,0,0,0,0,0,0,0,0,0,0,0,0,0,0,2,0,0,0
0,0,0,0,11,0,0,0,0,0,0,0,0,0,0,0,0,0,0,0,11,0,0,0,0
0,0,0,0,0,2,0,0,0,0,0,0,0,0,0,0,0,0,0,2,0,0,0,0,0
0,0,0,0,0,0,1,1,0,0,0,0,0,0,0,0,0,1,1,0,0,0,0,0,0
0,0,0,0,0,0,0,2,1,1,1,1,2,1,1,1,1,2,0,0,0,0,0,0,0
0,0,0,0,0,0,0,2,0,2,2,2,2,2,2,2,0,2,0,0,0,0,0,0,0
endlayer

layer
0,0,0,0,0,0,0,0,0,2,0,0,0,0,0,2,0,0,0,0,0,0,0,0,0
0,0,0,0,0,0,0,2,0,0,0,0,0,0,0,0,0,2,0,0,0,0,0,0,0
0,0,0,0,0,0,0,2,1,1,1,2,11,2,1,1,1,2,0,0,0,0,0,0,0
0,0,0,0,0,0,1,1,1,0,0,0,0,0,0,0,1,1,1,0,0,0,0,0,0
0,0,0,0,0,2,1,0,0,0,0,0,0,0,0,0,0,0,1,2,0,0,0,0,0
0,0,0,0,2,2,0,0,0,0,0,0,0,0,0,0,0,0,0,2,2,0,0,0,0
0,0,0,1,1,0,0,0,0,0,0,0,0,0,0,0,0,0,0,0,1,1,0,0,0
0,2,2,1,0,0,0,0,0,0,0,0,0,0,0,0,0,0,0,0,0,1,2,2,0
0,0,1,1,0,0,0,0,0,0,0,0,0,0,0,0,0,0,0,0,0,1,1,0,0
2,0,1,0,0,0,0,0,0,0,0,0,0,0,0,0,0,0,0,0,0,0,1,0,2
0,0,1,0,0,0,0,0,0,0,0,0,0,0,0,0,0,0,0,0,0,0,1,0,0
0,0,2,0,0,0,0,0,0,0,0,0,0,0,0,0,0,0,0,0,0,0,2,0,0
0,0,11,0,0,0,0,0,0,0,0,0,0,0,0,0,0,0,0,0,0,0,11,0,0
0,0,2,0,0,0,0,0,0,0,0,0,0,0,0,0,0,0,0,0,0,0,2,0,0
0,0,1,0,0,0,0,0,0,0,0,0,0,0,0,0,0,0,0,0,0,0,1,0,0
2,0,1,0,0,0,0,0,0,0,0,0,0,0,0,0,0,0,0,0,0,0,1,0,2
0,0,1,1,0,0,0,0,0,0,0,0,0,0,0,0,0,0,0,0,0,1,1,0,0
0,2,2,1,0,0,0,0,0,0,0,0,0,0,0,0,0,0,0,0,0,1,2,2,0
0,0,0,1,1,0,0,0,0,0,0,0,0,0,0,0,0,0,0,0,1,1,0,0,0
0,0,0,0,2,2,0,0,0,0,0,0,0,0,0,0,0,0,0,2,2,0,0,0,0
0,0,0,0,0,2,1,0,0,0,0,0,0,0,0,0,0,0,1,2,0,0,0,0,0
0,0,0,0,0,0,1,1,1,0,0,0,0,0,0,0,1,1,1,0,0,0,0,0,0
0,0,0,0,0,0,0,2,1,1,1,2,11,2,1,1,1,2,0,0,0,0,0,0,0
0,0,0,0,0,0,0,2,0,0,0,0,0,0,0,0,0,2,0,0,0,0,0,0,0
0,0,0,0,0,0,0,0,0,2,0,0,0,0,0,2,0,0,0,0,0,0,0,0,0
endlayer

layer
0,0,0,0,0,0,0,0,0,0,0,0,0,0,0,0,0,0,0,0,0,0,0,0,0
0,0,0,0,0,0,0,0,0,0,0,0,0,0,0,0,0,0,0,0,0,0,0,0,0
0,0,0,0,0,0,0,2,0,0,0,0,0,0,0,0,0,2,0,0,0,0,0,0,0
0,0,0,0,0,0,0,0,0,1,2,11,11,11,2,1,0,0,0,0,0,0,0,0,0
0,0,0,0,0,0,0,1,1,2,12,12,12,12,12,2,1,1,0,0,0,0,0,0,0
0,0,0,0,0,2,1,1,12,12,12,12,12,12,12,12,12,1,1,2,0,0,0,0,0
0,0,0,0,0,1,1,12,12,12,12,12,12,12,12,12,12,12,1,1,0,0,0,0,0
0,0,2,0,1,1,12,12,12,12,12,12,12,12,12,12,12,12,12,1,1,0,2,0,0
0,0,0,0,1,12,12,12,12,12,12,12,12,12,12,12,12,12,12,12,1,0,0,0,0
0,0,0,1,2,12,12,12,12,12,12,12,12,12,12,12,12,12,12,12,2,1,0,0,0
0,0,0,2,12,12,12,12,12,12,12,12,12,12,12,12,12,12,12,12,12,2,0,0,0
0,0,0,11,12,12,12,12,12,12,12,12,12,12,12,12,12,12,12,12,12,11,0,0,0
0,0,0,11,12,12,12,12,12,12,12,12,12,12,12,12,12,12,12,12,12,11,0,0,0
0,0,0,11,12,12,12,12,12,12,12,12,12,12,12,12,12,12,12,12,12,11,0,0,0
0,0,0,2,12,12,12,12,12,12,12,12,12,12,12,12,12,12,12,12,12,2,0,0,0
0,0,0,1,2,12,12,12,12,12,12,12,12,12,12,12,12,12,12,12,2,1,0,0,0
0,0,0,0,1,12,12,12,12,12,12,12,12,12,12,12,12,12,12,12,1,0,0,0,0
0,0,2,0,1,1,12,12,12,12,12,12,12,12,12,12,12,12,12,1,1,0,2,0,0
0,0,0,0,0,1,1,12,12,12,12,12,12,12,12,12,12,12,1,1,0,0,0,0,0
0,0,0,0,0,2,1,1,12,12,12,12,12,12,12,12,12,1,1,2,0,0,0,0,0
0,0,0,0,0,0,0,1,1,2,12,12,12,12,12,2,1,1,0,0,0,0,0,0,0
0,0,0,0,0,0,0,0,0,1,2,11,11,11,2,1,0,0,0,0,0,0,0,0,0
0,0,0,0,0,0,0,2,0,0,0,0,0,0,0,0,0,2,0,0,0,0,0,0,0
0,0,0,0,0,0,0,0,0,0,0,0,0,0,0,0,0,0,0,0,0,0,0,0,0
0,0,0,0,0,0,0,0,0,0,0,0,0,0,0,0,0,0,0,0,0,0,0,0,0
endlayer

layer
0,0,0,0,0,0,0,0,0,0,0,0,0,0,0,0,0,0,0,0,0,0,0,0,0
0,0,0,0,0,0,0,0,0,0,0,0,0,0,0,0,0,0,0,0,0,0,0,0,0
0,0,0,0,0,0,0,2,0,0,0,0,0,0,0,0,0,2,0,0,0,0,0,0,0
0,0,0,0,0,0,0,0,0,0,0,0,0,0,0,0,0,0,0,0,0,0,0,0,0
0,0,0,0,0,0,0,0,0,0,11,11,11,11,11,0,0,0,0,0,0,0,0,0,0
0,0,0,0,0,0,0,0,2,11,11,11,11,11,11,11,2,0,0,0,0,0,0,0,0
0,0,0,0,0,0,0,1,2,11,12,12,12,12,12,11,2,1,0,0,0,0,0,0,0
0,0,2,0,0,0,1,1,12,12,12,12,12,12,12,12,12,1,1,0,0,0,2,0,0
0,0,0,0,0,2,2,12,12,12,12,12,12,12,12,12,12,12,2,2,0,0,0,0,0
0,0,0,0,0,11,11,12,12,12,12,12,12,12,12,12,12,12,11,11,0,0,0,0,0
0,0,0,0,11,11,12,12,12,12,12,12,12,12,12,12,12,12,12,11,11,0,0,0,0
0,0,0,0,11,11,12,12,12,12,12,12,12,12,12,12,12,12,12,11,11,0,0,0,0
0,0,0,0,11,11,12,12,12,12,12,12,12,12,12,12,12,12,12,11,11,0,0,0,0
0,0,0,0,11,11,12,12,12,12,12,12,12,12,12,12,12,12,12,11,11,0,0,0,0
0,0,0,0,11,11,12,12,12,12,12,12,12,12,12,12,12,12,12,11,11,0,0,0,0
0,0,0,0,0,11,11,12,12,12,12,12,12,12,12,12,12,12,11,11,0,0,0,0,0
0,0,0,0,0,2,2,12,12,12,12,12,12,12,12,12,12,12,2,2,0,0,0,0,0
0,0,2,0,0,0,1,1,12,12,12,12,12,12,12,12,12,1,1,0,0,0,2,0,0
0,0,0,0,0,0,0,1,2,11,12,12,12,12,12,11,2,1,0,0,0,0,0,0,0
0,0,0,0,0,0,0,0,2,11,11,11,11,11,11,11,2,0,0,0,0,0,0,0,0
0,0,0,0,0,0,0,0,0,0,11,11,11,11,11,0,0,0,0,0,0,0,0,0,0
0,0,0,0,0,0,0,0,0,0,0,0,0,0,0,0,0,0,0,0,0,0,0,0,0
0,0,0,0,0,0,0,2,0,0,0,0,0,0,0,0,0,2,0,0,0,0,0,0,0
0,0,0,0,0,0,0,0,0,0,0,0,0,0,0,0,0,0,0,0,0,0,0,0,0
0,0,0,0,0,0,0,0,0,0,0,0,0,0,0,0,0,0,0,0,0,0,0,0,0
endlayer

layer
0,0,0,0,0,0,0,0,0,0,0,0,0,0,0,0,0,0,0,0,0,0,0,0,0
0,0,0,0,0,0,0,0,0,0,0,0,0,0,0,0,0,0,0,0,0,0,0,0,0
0,0,0,0,0,0,0,0,0,0,0,0,0,0,0,0,0,0,0,0,0,0,0,0,0
0,0,0,0,0,0,0,0,0,0,0,0,0,0,0,0,0,0,0,0,0,0,0,0,0
0,0,0,0,0,0,0,0,0,0,0,0,0,0,0,0,0,0,0,0,0,0,0,0,0
0,0,0,0,0,0,0,0,0,0,0,0,0,0,0,0,0,0,0,0,0,0,0,0,0
0,0,0,0,0,0,0,0,0,0,11,11,11,11,11,0,0,0,0,0,0,0,0,0,0
0,0,0,0,0,0,0,0,2,11,11,11,11,11,11,11,2,0,0,0,0,0,0,0,0
0,0,0,0,0,0,0,2,11,11,11,11,11,11,11,11,11,2,0,0,0,0,0,0,0
0,0,0,0,0,0,0,11,11,11,12,12,12,12,12,11,11,11,0,0,0,0,0,0,0
0,0,0,0,0,0,11,11,11,12,12,12,12,12,12,12,11,11,11,0,0,0,0,0,0
0,0,0,0,0,0,11,11,11,12,12,12,12,12,12,12,11,11,11,0,0,0,0,0,0
0,0,0,0,0,0,11,11,11,12,12,12,12,12,12,12,11,11,11,0,0,0,0,0,0
0,0,0,0,0,0,11,11,11,12,12,12,12,12,12,12,11,11,11,0,0,0,0,0,0
0,0,0,0,0,0,11,11,11,12,12,12,12,12,12,12,11,11,11,0,0,0,0,0,0
0,0,0,0,0,0,0,11,11,11,12,12,12,12,12,11,11,11,0,0,0,0,0,0,0
0,0,0,0,0,0,0,2,11,11,11,11,11,11,11,11,11,2,0,0,0,0,0,0,0
0,0,0,0,0,0,0,0,2,11,11,11,11,11,11,11,2,0,0,0,0,0,0,0,0
0,0,0,0,0,0,0,0,0,0,11,11,11,11,11,0,0,0,0,0,0,0,0,0,0
0,0,0,0,0,0,0,0,0,0,0,0,0,0,0,0,0,0,0,0,0,0,0,0,0
0,0,0,0,0,0,0,0,0,0,0,0,0,0,0,0,0,0,0,0,0,0,0,0,0
0,0,0,0,0,0,0,0,0,0,0,0,0,0,0,0,0,0,0,0,0,0,0,0,0
0,0,0,0,0,0,0,0,0,0,0,0,0,0,0,0,0,0,0,0,0,0,0,0,0
0,0,0,0,0,0,0,0,0,0,0,0,0,0,0,0,0,0,0,0,0,0,0,0,0
0,0,0,0,0,0,0,0,0,0,0,0,0,0,0,0,0,0,0,0,0,0,0,0,0
endlayer

layer
0,0,0,0,0,0,0,0,0,0,0,0,0,0,0,0,0,0,0,0,0,0,0,0,0
0,0,0,0,0,0,0,0,0,0,0,0,0,0,0,0,0,0,0,0,0,0,0,0,0
0,0,0,0,0,0,0,0,0,0,0,0,0,0,0,0,0,0,0,0,0,0,0,0,0
0,0,0,0,0,0,0,0,0,0,0,0,0,0,0,0,0,0,0,0,0,0,0,0,0
0,0,0,0,0,0,0,0,0,0,0,0,0,0,0,0,0,0,0,0,0,0,0,0,0
0,0,0,0,0,0,0,0,0,0,0,0,0,0,0,0,0,0,0,0,0,0,0,0,0
0,0,0,0,0,0,0,0,0,0,0,0,0,0,0,0,0,0,0,0,0,0,0,0,0
0,0,0,0,0,0,0,0,0,0,0,0,0,0,0,0,0,0,0,0,0,0,0,0,0
0,0,0,0,0,0,0,0,0,0,0,0,0,0,0,0,0,0,0,0,0,0,0,0,0
0,0,0,0,0,0,0,0,0,0,11,11,11,11,11,0,0,0,0,0,0,0,0,0,0
0,0,0,0,0,0,0,0,0,11,11,11,11,11,11,11,0,0,0,0,0,0,0,0,0
0,0,0,0,0,0,0,0,0,11,11,11,11,11,11,11,0,0,0,0,0,0,0,0,0
0,0,0,0,0,0,0,0,0,11,11,11,11,11,11,11,0,0,0,0,0,0,0,0,0
0,0,0,0,0,0,0,0,0,11,11,11,11,11,11,11,0,0,0,0,0,0,0,0,0
0,0,0,0,0,0,0,0,0,11,11,11,11,11,11,11,0,0,0,0,0,0,0,0,0
0,0,0,0,0,0,0,0,0,0,11,11,11,11,11,0,0,0,0,0,0,0,0,0,0
0,0,0,0,0,0,0,0,0,0,0,0,0,0,0,0,0,0,0,0,0,0,0,0,0
0,0,0,0,0,0,0,0,0,0,0,0,0,0,0,0,0,0,0,0,0,0,0,0,0
0,0,0,0,0,0,0,0,0,0,0,0,0,0,0,0,0,0,0,0,0,0,0,0,0
0,0,0,0,0,0,0,0,0,0,0,0,0,0,0,0,0,0,0,0,0,0,0,0,0
0,0,0,0,0,0,0,0,0,0,0,0,0,0,0,0,0,0,0,0,0,0,0,0,0
0,0,0,0,0,0,0,0,0,0,0,0,0,0,0,0,0,0,0,0,0,0,0,0,0
0,0,0,0,0,0,0,0,0,0,0,0,0,0,0,0,0,0,0,0,0,0,0,0,0
0,0,0,0,0,0,0,0,0,0,0,0,0,0,0,0,0,0,0,0,0,0,0,0,0
0,0,0,0,0,0,0,0,0,0,0,0,0,0,0,0,0,0,0,0,0,0,0,0,0
endlayer

