# Savanna Hut (intact)
# 17 Oct 2014 -- MC 1.7.10
# Created by Ruins mod version 13.8 Ingame Parser
# authoring Player: Jordan_Greywolf
# Updated for MC 1.8: 23 Jul 2015
# Updated for MC 1.11: 13 Jan 2017
# Verified for MC 1.12: 23 Jun 2017
# Updated to MC 1.12.1: 10 Sep 2017

biomesToSpawnIn=savanna,savanna plateau,savanna_rock,mutated_savanna,mutated_savanna_rock

weight=1
embed_into_distance=3
acceptable_target_blocks=

unacceptable_target_blocks=flowing_water,water,flowing_lava,lava,cloud,Natura:Cloud,slime_congealed,slime_dirt,slime_grass,command_block

dimensions=11,7,7
allowable_overhang=0
max_leveling=2
leveling_buffer=-1
preserve_water=0
preserve_lava=0

# Stained Hardened Clay (brown)
rule1=0,100,minecraft:stained_hardened_clay-12

# Acacia Logs (up/down)
rule2=0,100,minecraft:log2-0

# Acacia Planks
rule3=0,100,minecraft:planks-4

# Central hut support pole (Fence)
rule4=0,100,minecraft:acacia_fence-0

# Wool (window and door tops)
rule5=0,100,minecraft:wool-7

# Wool (rooftop -- overhang)
rule6=0,100,minecraft:wool-8

# Wool (rooftop -- blocks supported by other blocks)
rule7=0,100,minecraft:wool-8

layer
1,1,1,1,1,1,1
1,2,1,1,1,2,1
1,1,1,1,1,1,1
1,1,1,1,1,1,1
1,1,1,1,1,1,1
1,2,1,1,1,2,1
1,1,1,1,1,1,1
endlayer

layer
1,1,1,1,1,1,1
1,2,1,1,1,2,1
1,1,1,1,1,1,1
1,1,1,1,1,1,1
1,1,1,1,1,1,1
1,2,1,1,1,2,1
1,1,1,1,1,1,1
endlayer


layer
1,1,1,1,1,1,1
1,2,1,1,1,2,1
1,1,1,1,1,1,1
1,1,1,1,1,1,1
1,1,1,1,1,1,1
1,2,1,1,1,2,1
1,1,1,1,1,1,1
endlayer

layer
0,0,0,0,0,0,0
0,2,3,3,3,2,0
0,3,0,0,0,3,0
0,3,0,4,0,3,0
0,3,0,0,0,3,0
0,2,3,0,3,2,0
0,0,0,0,0,0,0
endlayer

layer
0,0,0,0,0,0,0
0,2,3,0,3,2,0
0,3,0,0,0,3,0
0,0,0,4,0,0,0
0,3,0,0,0,3,0
0,2,3,0,3,2,0
0,0,0,0,0,0,0
endlayer

layer
0,0,0,0,0,0,0
0,2,3,5,3,2,0
0,3,0,0,0,3,0
0,5,0,4,0,5,0
0,3,0,0,0,3,0
0,2,3,5,3,2,0
0,0,0,0,0,0,0
endlayer

layer
0,6,6,6,6,6,0
6,2,7,7,7,2,6
6,7,0,0,0,7,6
6,7,0,4,0,7,6
6,7,0,0,0,7,6
6,2,7,7,7,2,6
0,6,6,6,6,6,0
endlayer

layer
0,0,0,7,0,0,0
0,7,7,7,7,7,0
0,7,6,6,6,7,0
7,7,6,4,6,7,7
0,7,6,6,6,7,0
0,7,7,7,7,7,0
0,0,0,7,0,0,0
endlayer

layer
0,0,0,0,0,0,0
0,0,0,7,0,0,0
0,0,7,7,7,0,0
0,7,7,7,7,7,0
0,0,7,7,7,0,0
0,0,0,7,0,0,0
0,0,0,0,0,0,0
endlayer

layer
0,0,0,0,0,0,0
0,0,0,0,0,0,0
0,0,0,7,0,0,0
0,0,7,7,7,0,0
0,0,0,7,0,0,0
0,0,0,0,0,0,0
0,0,0,0,0,0,0
endlayer

layer
0,0,0,0,0,0,0
0,0,0,0,0,0,0
0,0,0,0,0,0,0
0,0,0,7,0,0,0
0,0,0,0,0,0,0
0,0,0,0,0,0,0
0,0,0,0,0,0,0
endlayer

