
# ForestPool
# 7 Mar 2014; updated to MC 1.7.10, 9 Oct 2014
# Updated to MC 1.8: 22 Jul 2015
# Created by Ruins mod version 12.3 Ingame Parser
# authoring Player: Jordan_Greywolf
# Last Updated 28 Feb 2016
# Verified for MC 1.12: 23 Jun 2017

biomesToSpawnIn=autumn hills,autumn woods,bamboo forest,birch forest,birch_forest,extreme hills,extreme_hills,extreme_hills_with_trees,extreme hills edge,fen,field,flower field,flower forest,forest,forested field,forested hills,forested island,foresthills,fungi forest,garden,grassland,green hills,grove,heathland,highland,hot springs,jade cliffs,lavender fields,lush redwoods,lush swamp,magical forest,majestic meadow,mangrove,maplewoods,meadow,meadow forest,mutated_birch_forest,mutated_forest,mutated_plains,mystic grove,ominous woods,orchard,origin island,origin valley,overgrown greens,pasture,pasture meadow,pine forest,plains,prairie,rwg_coldforest,rwg_snowforest,rwg_temperateforest,sacred springs,silkglades,smaller_extreme_hills,sunflower plains,taiga,taigahills,taiga_hills,thick ominous woods,thinned mystic grove,thinned pasture,wonderous woods,woodland,woodlands,wyvern biome,mining biome

weight=1
embed_into_distance=4


unacceptable_target_blocks=lava,flowing_lava,cloud,Natura:Cloud,red_mushroom_block,brown_mushroom_block,slime_congealed,slime_dirt,slime_grass,command_block

dimensions=13,12,12
allowable_overhang=15
max_cut_in=0
cut_in_buffer=0
max_leveling=4
leveling_buffer=-1
preserve_water=0
preserve_lava=0
preserve_plants=1

rule1=0,100,preserveBlock
rule2=0,100,minecraft:log-0
rule3=0,100,minecraft:grass-0
rule4=0,100,minecraft:flowing_water
rule5=0,100,minecraft:grass-0
rule6=0,100,minecraft:log-8
rule7=0,100,minecraft:log-4
rule8=0,100,minecraft:log-12
rule9=0,100,minecraft:tallgrass-1,minecraft:tallgrass-1,minecraft:tallgrass-2,minecraft:red_flower,minecraft:yellow_flower,minecraft:red_flower-1,minecraft:red_flower-2
rule10=0,100,minecraft:leaves-4

layer
1,1,1,1,1,1,1,1,1,1,1,1
1,2,1,1,1,1,1,1,1,1,1,1
1,1,1,1,3,1,3,3,3,1,1,1
1,1,1,1,3,3,3,4,2,3,1,1
1,1,1,3,3,4,4,3,3,1,1,1
1,1,1,3,3,4,4,4,3,1,1,1
1,1,1,3,4,4,4,3,3,1,1,1
1,1,3,3,4,4,4,3,1,1,1,1
1,1,3,3,3,3,3,3,1,1,1,1
1,1,2,1,1,1,3,1,1,1,1,1
1,1,1,1,1,1,1,1,1,1,1,1
1,1,1,1,1,1,1,1,1,1,1,1
endlayer

layer
1,1,1,1,1,1,1,1,1,2,1,1
1,2,1,1,1,1,3,1,1,1,1,1
1,1,1,3,3,1,2,5,2,1,1,1
1,1,3,3,4,3,4,4,2,2,1,1
1,1,3,3,4,4,4,4,3,1,1,1
1,1,3,4,4,4,4,4,3,3,1,1
1,1,3,4,4,4,4,4,3,1,1,1
1,1,3,4,4,4,4,4,3,1,1,1
1,1,3,4,4,4,4,3,3,1,1,1
1,2,2,3,3,3,3,3,1,1,1,1
1,1,2,1,1,3,1,1,1,1,1,1
1,1,1,1,1,1,1,1,1,1,1,1
endlayer

layer
1,2,1,1,1,1,1,3,1,2,1,1
2,2,3,1,3,1,3,3,3,1,1,1
1,3,3,3,3,3,2,1,2,2,1,1
1,3,3,3,4,4,4,4,2,2,2,1
1,1,3,4,4,4,4,4,3,3,3,1
1,3,3,4,4,4,4,4,3,3,3,1
1,1,3,4,4,4,4,4,4,3,1,1
1,3,4,4,4,4,4,4,4,3,1,1
1,3,4,4,4,4,4,4,4,3,1,1
1,2,2,4,4,4,4,3,3,1,1,1
1,2,2,2,3,3,3,1,1,1,1,1
1,1,1,1,1,3,1,1,1,1,1,1
endlayer

layer
2,2,5,5,1,1,1,5,5,2,1,1
2,2,6,5,4,5,5,5,5,2,1,1
5,7,5,5,4,6,2,2,2,2,5,1
1,5,5,5,4,4,4,4,2,2,2,1
1,5,5,4,4,4,4,4,7,2,5,5
1,4,4,4,4,4,4,4,5,5,5,5
5,5,4,4,4,4,4,4,4,5,5,5
5,7,4,4,4,4,4,4,4,4,1,1
5,7,5,4,4,4,4,4,4,5,5,1
5,2,2,5,4,4,4,4,5,5,1,1
1,2,2,2,5,4,4,5,5,1,1,1
1,7,5,5,5,5,1,5,1,1,1,1
endlayer

layer
2,2,9,9,1,1,1,9,9,8,1,1
2,2,0,9,0,9,9,9,9,2,1,1
1,8,9,9,0,0,8,2,2,2,9,1
1,9,9,9,0,0,0,0,2,2,8,1
1,9,9,0,0,0,0,0,0,2,9,9
1,1,0,0,0,0,0,0,9,9,9,9
9,9,0,0,0,0,0,0,0,9,9,9
9,0,0,0,0,0,0,0,0,0,1,1
9,8,9,0,0,0,0,0,0,9,9,1
9,2,2,9,0,0,0,0,9,9,1,1
1,2,2,8,9,0,0,9,9,1,1,1
1,1,9,9,9,9,1,9,1,1,1,1
endlayer

layer
8,2,0,0,0,0,0,0,0,0,0,1
2,2,0,0,0,0,0,0,0,8,0,0
0,0,0,0,0,0,0,8,2,2,0,0
0,0,0,0,0,0,0,0,2,2,0,0
0,0,0,0,0,0,0,0,0,8,0,0
0,0,0,0,0,0,0,0,0,0,0,0
0,0,0,0,0,0,0,0,0,0,0,0
0,0,0,0,0,0,0,0,0,0,0,0
0,0,0,0,0,0,0,0,0,0,0,0
0,2,2,0,0,0,0,0,0,0,0,1
0,2,2,0,0,0,0,0,0,0,1,1
1,0,0,0,0,0,0,0,0,1,1,1
endlayer

layer
10,8,0,0,0,0,0,0,0,0,0,0
8,2,8,0,0,0,0,0,0,0,0,0
0,8,0,0,0,0,0,0,2,8,0,0
0,0,0,0,0,0,0,0,2,2,0,0
0,0,0,0,0,0,0,0,0,0,0,0
0,0,0,0,0,0,0,0,0,0,0,0
0,0,0,0,0,0,0,0,0,0,0,0
0,0,0,0,0,0,0,0,0,0,0,0
0,0,0,0,0,0,0,0,0,0,0,0
0,2,2,10,0,0,0,0,0,0,0,0
0,8,2,0,0,0,0,0,0,0,0,1
0,0,0,0,0,0,0,0,0,0,1,1
endlayer

layer
0,10,0,0,0,0,0,0,0,0,0,0
10,2,2,0,10,0,0,0,0,0,0,0
10,8,0,10,10,10,0,0,2,0,0,0
0,7,0,0,10,0,0,0,2,8,0,0
0,8,0,0,0,0,0,0,0,0,0,0
0,0,0,0,0,0,0,0,0,0,0,0
0,0,0,0,0,0,0,0,0,0,0,0
0,0,0,0,0,0,0,0,0,0,0,0
0,0,0,10,0,0,0,0,0,0,0,0
0,2,2,10,10,0,0,0,0,0,0,0
0,0,8,10,0,0,0,0,0,0,0,0
0,0,0,0,0,0,0,0,0,0,0,1
endlayer

layer
0,0,10,0,0,0,0,0,0,0,0,0
0,2,8,6,10,0,0,0,0,0,0,0
0,0,0,10,6,10,0,0,8,0,0,0
0,0,0,10,10,10,0,0,8,0,0,0
10,10,10,0,0,0,0,0,7,0,0,0
10,7,10,0,0,0,0,0,7,0,0,0
10,10,10,0,0,0,0,10,10,10,0,0
0,0,0,0,0,0,0,0,10,0,0,0
10,10,8,8,0,0,0,0,0,0,0,0
10,8,8,8,10,0,0,0,0,0,0,0
10,10,10,0,0,0,0,0,0,0,0,0
0,0,0,0,0,0,0,0,0,0,0,0
endlayer

layer
0,0,0,0,0,0,0,0,10,10,0,0
0,8,10,0,10,0,0,10,10,10,10,0
0,10,2,10,10,10,10,6,10,10,10,0
0,10,10,10,10,10,0,10,10,10,0,0
0,10,10,10,0,10,0,0,10,10,0,0
10,10,10,0,10,10,10,0,10,10,10,0
0,10,10,10,10,10,10,10,7,10,10,0
10,10,10,8,0,10,0,10,10,10,10,0
10,10,10,8,8,10,10,10,0,0,0,0
10,10,10,10,10,0,0,0,0,0,0,0
0,0,0,0,0,0,0,0,0,0,0,0
0,0,0,0,0,0,0,0,0,0,0,0
endlayer

layer
0,0,0,0,0,0,0,0,0,0,0,0
0,0,10,10,0,0,0,0,10,10,0,0
0,10,2,10,0,10,10,10,10,10,0,0
0,10,10,10,10,10,8,10,0,0,0,0
0,0,10,10,10,10,10,10,0,0,0,0
0,0,10,10,7,10,10,10,10,0,0,0
0,0,0,10,7,10,10,10,10,10,0,0
0,0,10,10,10,10,10,10,10,0,0,0
0,0,10,10,10,6,10,10,0,0,0,0
0,0,0,10,10,10,10,10,0,0,0,0
0,0,0,0,0,10,10,0,0,0,0,0
0,0,0,0,0,0,0,0,0,0,0,0
endlayer

layer
0,0,0,0,0,0,0,0,0,0,0,0
0,0,10,10,0,0,0,0,0,0,0,0
0,10,10,10,0,10,10,10,0,0,0,0
0,10,10,10,10,10,10,10,0,0,0,0
0,0,0,10,10,10,10,10,0,0,0,0
0,0,0,0,10,10,10,10,0,0,0,0
0,0,0,0,10,10,10,0,0,0,0,0
0,0,0,10,10,10,10,0,0,0,0,0
0,0,0,10,10,10,10,0,0,0,0,0
0,0,0,0,10,10,10,0,0,0,0,0
0,0,0,0,0,0,0,0,0,0,0,0
0,0,0,0,0,0,0,0,0,0,0,0
endlayer

layer
0,0,0,0,0,0,0,0,0,0,0,0
0,0,0,0,0,0,0,0,0,0,0,0
0,0,10,0,0,0,10,0,0,0,0,0
0,0,10,0,0,10,10,10,0,0,0,0
0,0,0,0,0,0,10,0,0,0,0,0
0,0,0,0,10,0,0,0,0,0,0,0
0,0,0,0,0,0,0,0,0,0,0,0
0,0,0,0,0,0,0,0,0,0,0,0
0,0,0,0,10,10,10,0,0,0,0,0
0,0,0,0,0,10,0,0,0,0,0,0
0,0,0,0,0,0,0,0,0,0,0,0
0,0,0,0,0,0,0,0,0,0,0,0
endlayer

