
# Created by Ruins mod version 17.0 Ingame Parser
# authoring Player: ST753M

# A small birch and sandstone house

weight=1
embed_into_distance=5
acceptable_target_blocks=dirt,grass,mycelium,podzol,sand,sandstone,red_sand
unacceptable_target_blocks=flowing_water,water,flowing_lava,lava
dimensions=15,11,11
allowable_overhang=5
max_leveling=2
leveling_buffer=-1
preserve_water=0
preserve_lava=0

biomesToSpawnIn=birch_forest,birch_forest_hills,mutated_birch_forest,mutated_birch_forest_hills,birch_forested_hills,desert_shrubland,arid_highland,oasis,mutated_desert,xeric_shrubland,mountainous_desert

=0,100,air
rule1=0,100,preserveBlock
rule2=0,100,minecraft:sandstone-0
rule3=0,100,minecraft:planks-2
rule4=0,100,minecraft:sandstone-2
rule5=0,100,minecraft:ladder-2
rule6=0,50,ChestGenHook:chests/simple_dungeon:3-3,air
rule7=0,50,MobSpawner:skeleton,MobSpawner:zombie
rule8=0,100,minecraft:trapdoor-11
rule9=0,100,minecraft:birch_stairs-2
rule10=0,100,minecraft:birch_stairs-7
rule11=0,100,minecraft:wooden_door-1
rule12=0,100,minecraft:oak_stairs-3
rule13=0,100,minecraft:fence-0
rule14=0,100,minecraft:oak_stairs-2
rule15=0,100,minecraft:glass_pane-0
rule16=0,100,minecraft:wooden_door-8

rule17=0,100,minecraft:carpet-14
^0,100,minecraft:carpet-0
^0,100,minecraft:carpet-1
^0,100,minecraft:carpet-2
^0,100,minecraft:carpet-3
^0,100,minecraft:carpet-4
^0,100,minecraft:carpet-5
^0,100,minecraft:carpet-6
^0,100,minecraft:carpet-7
^0,100,minecraft:carpet-8
^0,100,minecraft:carpet-9
^0,100,minecraft:carpet-10
^0,100,minecraft:carpet-11
^0,100,minecraft:carpet-12
^0,100,minecraft:carpet-13
^0,100,minecraft:carpet-14
^0,100,minecraft:carpet-15

rule18=0,100,minecraft:birch_stairs-4
rule19=0,100,minecraft:birch_stairs-6
rule20=2,100,minecraft:torch-3
rule21=2,100,minecraft:torch-4
rule22=2,100,minecraft:torch-2
rule23=0,100,minecraft:birch_stairs-5
rule24=0,100,minecraft:oak_stairs-1
rule25=0,100,minecraft:oak_stairs-0
rule26=0,100,minecraft:bed-3

rule27=0,50,IInventory;minecraft:chest;minecraft:bow#{ench:[{lvl:1s,id:48s}],RepairCost:0,display:{Name:"Birch Bow"}}#0#5+minecraft:potion#{Potion:"minecraft:swiftness"}#0#12+minecraft:carrot#6#0#24-3,IInventory;minecraft:chest;minecraft:fishing_rod#{ench:[{lvl:1s,id:34s}],RepairCost:0,display:{Name:"Birch Fishing Rod"}}#0#13+minecraft:potion#{Potion:"minecraft:fire_resistance"}#0#15+minecraft:lead#1#0#16+minecraft:bread#4#0#20-3,IInventory;minecraft:chest;minecraft:apple#6#0#13+minecraft:potion#{Potion:"minecraft:swiftness"}#0#20+minecraft:leather_boots#{ench:[{lvl:2s,id:4s},{lvl:1s,id:34s}],RepairCost:0,display:{Name:"Birch Boots"}}#0#24-3,IInventory;minecraft:chest;minecraft:cookie#5#0#12+minecraft:potion#{Potion:"minecraft:invisibility"}#0#14+minecraft:lead#1#0#19+minecraft:leather_chestplate#{ench:[{lvl:2s,id:0s}],RepairCost:0,display:{Name:"Birch Armor"}}#0#24-3,IInventory;minecraft:chest;minecraft:potion#{Potion:"minecraft:leaping"}#0#5+minecraft:apple#5#0#10+minecraft:fishing_rod#{ench:[{lvl:1s,id:34s}],RepairCost:0,display:{Name:"Birch Fishing Rod"}}#0#22-3,IInventory;minecraft:chest;minecraft:wooden_pickaxe#{ench:[{lvl:2s,id:32s}],RepairCost:0,display:{Name:"Birch Pickaxe"}}#0#2+minecraft:lead#1#0#14+minecraft:melon#5#0#22+minecraft:potion#{Potion:"minecraft:regeneration"}#0#25-3,IInventory;minecraft:chest;minecraft:lead#1#0#4+minecraft:potion#{Potion:"minecraft:regeneration"}#0#11+minecraft:melon#5#0#14+minecraft:wooden_shovel#{ench:[{lvl:1s,id:32s},{lvl:1s,id:34s}],RepairCost:0,display:{Name:"Birch Shovel"}}#0#21-3,IInventory;minecraft:chest;minecraft:potion#{Potion:"minecraft:strength"}#0#13+minecraft:apple#5#0#19+minecraft:leather_helmet#{ench:[{lvl:2s,id:4s}],RepairCost:0,display:{Name:"Birch Cap"}}#0#24-3,IInventory;minecraft:chest;minecraft:potion#{Potion:"minecraft:invisibility"}#0#11+minecraft:melon#6#0#22+minecraft:leather_leggings#{ench:[{lvl:1s,id:34s},{lvl:1s,id:3s}],RepairCost:0,display:{Name:"Birch Greaves"}}#0#24-3,IInventory;minecraft:chest;minecraft:shears#1#0#1+minecraft:wooden_sword#{ench:[{lvl:1s,id:19s}],RepairCost:0,display:{Name:"Birch Sword"}}#0#12+minecraft:potion#{Potion:"minecraft:strength"}#0#15+minecraft:carrot#5#0#23-3,IInventory;minecraft:chest;minecraft:cookie#5#0#12+minecraft:flint_and_steel#1#0#16+minecraft:wooden_pickaxe#{ench:[{lvl:2s,id:32s}],RepairCost:0,display:{Name:"Birch Pickaxe"}}#0#22+minecraft:potion#{Potion:"minecraft:strength"}#0#24-3,IInventory;minecraft:chest;minecraft:bow#{ench:[{lvl:1s,id:34s}],RepairCost:0,display:{Name:"Birch Bow"}}#0#10+minecraft:shears#1#0#13+minecraft:potion#{Potion:"minecraft:leaping"}#0#15+minecraft:cookie#6#0#20-3,IInventory;minecraft:chest;minecraft:flint_and_steel#1#0#8+minecraft:leather_boots#{ench:[{lvl:1s,id:1s}],RepairCost:0,display:{Name:"Birch Boots"}}#0#11+minecraft:bread#2#0#22+minecraft:potion#{Potion:"minecraft:strong_healing"}#0#24-3,IInventory;minecraft:chest;minecraft:wooden_axe#{ench:[{lvl:1s,id:32s},{lvl:1s,id:34s}],RepairCost:0,display:{Name:"Birch Axe"}}#0#10+minecraft:potion#{Potion:"minecraft:swiftness"}#0#12+minecraft:carrot#5#0#15+minecraft:flint_and_steel#1#0#23-3,IInventory;minecraft:chest;minecraft:shears#1#0#6+minecraft:bread#2#0#12+minecraft:leather_chestplate#{ench:[{lvl:2s,id:4s}],RepairCost:0,display:{Name:"Birch Armor"}}#0#18+minecraft:potion#{Potion:"minecraft:fire_resistance"}#0#24-3

rule28=0,100,minecraft:bed-11
rule29=2,100,minecraft:torch-1
rule30=1,100,minecraft:torch-5

layer
1,1,1,1,1,1,1,1,1,1,1
1,2,2,2,2,2,2,2,2,2,1
1,2,3,3,3,3,3,3,3,2,1
1,2,3,3,3,3,3,3,3,2,1
1,2,3,3,3,3,3,3,3,2,1
1,2,3,3,3,3,3,3,3,2,1
1,2,3,3,3,3,3,3,3,2,1
1,2,3,3,3,3,3,3,3,2,1
1,2,3,3,3,3,3,3,3,2,1
1,2,2,2,2,2,2,2,2,2,1
1,1,1,1,1,1,1,1,1,1,1
endlayer

layer
1,1,1,1,1,1,1,1,1,1,1
1,2,4,4,4,2,4,4,4,2,1
1,4,5,0,0,0,0,0,0,4,1
1,4,0,0,0,0,0,0,0,4,1
1,4,0,0,0,0,0,0,0,4,1
1,2,0,0,0,2,0,0,0,2,1
1,4,0,0,0,0,0,0,0,4,1
1,4,0,0,0,0,0,0,6,4,1
1,4,0,0,0,0,0,0,6,4,1
1,2,4,4,4,2,4,4,4,2,1
1,1,1,1,1,1,1,1,1,1,1
endlayer

layer
1,1,1,1,1,1,1,1,1,1,1
1,2,4,2,4,2,4,2,4,2,1
1,4,5,0,0,0,0,0,0,4,1
1,2,0,0,0,0,0,0,0,2,1
1,4,0,0,0,0,0,0,0,4,1
1,2,0,0,0,7,0,0,0,2,1
1,4,0,0,0,0,0,0,0,4,1
1,2,0,0,0,0,0,0,0,2,1
1,4,0,0,0,0,0,0,0,4,1
1,2,4,2,4,2,4,2,4,2,1
1,1,1,1,1,1,1,1,1,1,1
endlayer

layer
1,1,1,1,1,1,1,1,1,1,1
1,2,4,4,4,2,4,4,4,2,1
1,4,5,0,0,0,0,0,0,4,1
1,4,0,0,0,0,0,0,0,4,1
1,4,0,0,0,0,0,0,0,4,1
1,2,0,0,0,2,0,0,0,2,1
1,4,0,0,0,0,0,0,0,4,1
1,4,0,0,0,0,0,0,0,4,1
1,4,0,0,0,0,0,0,0,4,1
1,2,4,4,4,2,4,4,4,2,1
1,1,1,1,1,1,1,1,1,1,1
endlayer

layer
1,1,1,1,1,1,1,1,1,1,1
1,2,2,2,2,2,2,2,2,2,1
1,2,8,3,3,3,3,3,3,2,1
1,2,3,3,3,3,3,3,3,2,1
1,2,3,3,3,3,3,3,3,2,1
1,2,3,3,3,3,3,3,3,2,1
1,2,3,3,3,3,3,3,3,2,1
1,2,3,3,3,3,3,3,3,2,1
1,2,3,3,3,3,3,3,3,2,1
1,2,2,2,2,2,2,2,2,2,1
1,1,1,1,1,1,1,1,1,1,1
endlayer

layer
1,1,1,1,1,1,1,1,1,1,1
1,2,4,4,4,2,4,4,4,2,1
0,4,0,0,0,0,10,9,0,4,1
0,11,0,0,0,0,0,0,0,4,1
0,4,0,0,0,0,0,0,0,4,1
1,2,0,0,0,0,0,0,0,2,1
1,4,0,0,14,13,12,0,0,4,1
1,4,0,0,0,0,0,0,0,4,1
1,4,0,0,0,0,0,0,0,4,1
1,2,4,4,4,2,4,4,4,2,1
1,1,1,1,1,1,1,1,1,1,1
endlayer

layer
1,1,1,1,1,1,1,1,1,1,1
1,2,4,15,4,2,4,15,4,2,1
0,4,0,0,0,10,9,0,0,4,1
0,16,0,0,0,0,0,0,0,15,1
0,4,0,0,0,0,0,0,0,4,1
1,2,0,0,0,0,0,0,0,2,1
1,4,0,0,0,17,0,0,0,4,1
1,15,0,0,0,0,0,0,0,15,1
1,4,0,0,0,0,0,0,0,4,1
1,2,4,15,4,2,4,15,4,2,1
1,1,1,1,1,1,1,1,1,1,1
endlayer

layer
0,18,0,0,0,18,0,0,0,18,0
10,2,4,4,4,2,4,4,4,2,19
0,4,0,0,10,9,0,0,0,4,0
0,4,0,0,0,0,0,0,0,4,0
0,4,0,0,0,0,0,0,0,4,0
10,2,21,0,0,0,0,0,20,2,19
0,4,0,0,0,0,0,0,0,4,0
0,4,0,0,0,0,0,0,0,4,0
0,4,0,0,0,22,0,0,0,4,0
10,2,4,4,4,2,4,4,4,2,19
0,23,0,0,0,23,0,0,0,23,0
endlayer

layer
3,3,18,18,18,3,18,18,18,3,3
3,2,2,2,2,2,2,2,2,2,3
10,2,3,3,9,0,0,0,0,2,19
10,2,3,3,3,3,3,3,3,2,19
10,2,3,3,3,3,3,3,3,2,19
3,2,3,3,3,3,3,3,3,2,3
10,2,3,3,3,3,3,3,3,2,19
10,2,3,3,3,3,3,3,3,2,19
10,2,3,3,3,3,3,3,3,2,19
3,2,2,2,2,2,2,2,2,2,3
3,3,23,23,23,3,23,23,23,3,3
endlayer

layer
0,0,0,0,0,0,0,0,0,0,0
0,2,4,4,4,2,4,4,4,2,0
0,4,5,0,0,0,0,0,0,4,0
0,4,0,0,13,13,13,13,13,4,0
0,4,0,0,0,0,0,0,0,4,0
0,2,0,0,0,0,0,0,24,2,0
0,4,0,0,0,0,0,0,25,4,0
0,4,0,0,0,26,0,0,0,4,0
0,4,0,0,0,28,0,0,27,4,0
0,2,4,4,4,2,4,4,4,2,0
0,0,0,0,0,0,0,0,0,0,0
endlayer

layer
0,0,0,0,0,0,0,0,0,0,0
0,2,4,15,4,2,4,15,4,2,0
0,4,5,0,0,0,0,0,0,4,0
0,15,0,0,0,0,0,0,0,15,0
0,4,0,0,0,0,0,0,0,4,0
0,2,0,0,0,0,0,0,0,2,0
0,4,0,0,0,0,0,0,0,4,0
0,15,0,0,0,0,0,0,0,15,0
0,4,0,0,0,0,0,0,0,4,0
0,2,4,15,4,2,4,15,4,2,0
0,0,0,0,0,0,0,0,0,0,0
endlayer

layer
0,18,0,0,0,18,0,0,0,18,0
10,2,4,4,4,2,4,4,4,2,19
0,4,5,0,0,29,0,0,0,4,0
0,4,0,0,0,0,0,0,0,4,0
0,4,0,0,0,0,0,0,0,4,0
10,2,21,0,0,0,0,0,20,2,19
0,4,0,0,0,0,0,0,0,4,0
0,4,0,0,0,0,0,0,0,4,0
0,4,0,0,0,22,0,0,0,4,0
10,2,4,4,4,2,4,4,4,2,19
0,23,0,0,0,23,0,0,0,23,0
endlayer

layer
3,3,18,18,18,3,18,18,18,3,3
3,2,2,2,2,2,2,2,2,2,3
10,2,8,3,3,3,3,3,3,2,19
10,2,3,3,3,3,3,3,3,2,19
10,2,3,3,3,3,3,3,3,2,19
3,2,3,3,3,3,3,3,3,2,3
10,2,3,3,3,3,3,3,3,2,19
10,2,3,3,3,3,3,3,3,2,19
10,2,3,3,3,3,3,3,3,2,19
3,2,2,2,2,2,2,2,2,2,3
3,3,23,23,23,3,23,23,23,3,3
endlayer

layer
13,13,13,13,13,13,13,13,13,13,13
13,0,0,0,0,0,0,0,0,0,13
13,0,0,0,0,0,0,0,0,0,13
13,0,0,0,0,0,0,0,0,0,13
13,0,0,0,0,0,0,0,0,0,13
13,0,0,0,0,0,0,0,0,0,13
13,0,0,0,0,0,0,0,0,0,13
13,0,0,0,0,0,0,0,0,0,13
13,0,0,0,0,0,0,0,0,0,13
13,0,0,0,0,0,0,0,0,0,13
13,13,13,13,13,13,13,13,13,13,13
endlayer

layer
30,0,0,0,0,0,0,0,0,0,30
0,0,0,0,0,0,0,0,0,0,0
0,0,0,0,0,0,0,0,0,0,0
0,0,0,0,0,0,0,0,0,0,0
0,0,0,0,0,0,0,0,0,0,0
0,0,0,0,0,0,0,0,0,0,0
0,0,0,0,0,0,0,0,0,0,0
0,0,0,0,0,0,0,0,0,0,0
0,0,0,0,0,0,0,0,0,0,0
0,0,0,0,0,0,0,0,0,0,0
30,0,0,0,0,0,0,0,0,0,30
endlayer

