
# Created by Ruins mod version 17.0 Ingame Parser
# authoring Player: ST753M

weight=1
spawnMinDistance=500
embed_into_distance=2
acceptable_target_blocks=
unacceptable_target_blocks=flowing_water,water,flowing_lava,lava,ice,bedrock,netherrack,nether_brick,nether_brick_fence,soul_sand,quartz_ore,end_stone,obsidian,iron_bars,Natura:Cloud,slime_grass,slime_congealed,slime_dirt,clouds,natura:clouds
dimensions=13,12,17
allowable_overhang=2
max_leveling=2
leveling_buffer=-1
preserve_water=0
preserve_lava=0

biomesToSpawnIn=maple_woods,woodland,forest,mutated_birch_forest,mutated_forest,plains,prairie,shrubland,chaparral,grassland,meadow,orchard,rocky_plains,rocky_plateau,lavender_fields,flower_field,mutated_plains,origin_island

=0,100,air
rule1=0,100,preserveBlock
rule2=0,100,minecraft:log-0
rule3=0,100,minecraft:stone-0
rule4=0,100,minecraft:brick_block-0
rule5=0,100,minecraft:spruce_stairs-2
rule6=0,100,minecraft:spruce_stairs-0
rule7=0,100,minecraft:spruce_stairs-3
rule8=0,100,minecraft:planks-1
rule9=0,100,minecraft:log-8
rule10=0,100,minecraft:log-4
rule11=0,100,minecraft:netherrack-0
rule12=0,100,minecraft:wooden_door-2
rule13=0,100,minecraft:stone_slab-15
rule14=0,100,minecraft:carpet-0
rule15=0,100,minecraft:quartz_stairs-6
rule16=0,100,minecraft:spruce_fence_gate-0
rule17=0,100,IInventory;minecraft:chest;minecraft:sugar#4#0#1+harvestcraft:freshmilkitem#3#0#3+harvestcraft:mixingbowlitem#1#0#5+minecraft:cookie#3#0#7+minecraft:cookie#1#0#10+harvestcraft:flouritem#2#0#11+harvestcraft:bakewareitem#1#0#13+minecraft:egg#3#0#15+harvestcraft:cherryitem#3#0#17+minecraft:sugar#4#0#18+minecraft:cookie#2#0#20+harvestcraft:flouritem#3#0#22+harvestcraft:freshmilkitem#4#0#23+harvestcraft:cocoapowderitem#2#0#25-2
rule18=0,100,minecraft:crafting_table-0
rule19=0,100,minecraft:iron_bars-0
rule20=0,100,minecraft:fire-15
rule21=0,100,minecraft:wooden_door-9
rule22=0,100,minecraft:glass_pane-0
rule23=0,100,minecraft:cake-0
rule24=0,100,harvestcraft:cherrycheesecake-0
rule25=0,100,harvestcraft:holidaycake-0
rule26=1,100,minecraft:torch-5
rule27=0,100,harvestcraft:chocolatesprinklecake-0
rule28=0,100,harvestcraft:carrotcake-0
rule29=0,100,minecraft:brick_stairs-0
rule30=0,100,minecraft:furnace-4
rule31=0,100,minecraft:stone_slab-4
rule32=0,100,minecraft:brick_stairs-4
rule33=0,100,minecraft:purpur_slab-8
rule34=0,100,minecraft:brick_stairs-3
rule35=0,100,minecraft:brick_stairs-2
rule36=0,100,minecraft:purpur_stairs-0
rule37=0,100,minecraft:quartz_stairs-0
rule38=0,100,minecraft:spruce_stairs-1
rule39=0,100,minecraft:wooden_slab-1
rule40=0,100,minecraft:purpur_slab-0
rule41=0,100,minecraft:stone_slab-7
rule42=0,100,minecraft:brick_stairs-1
rule43=0,100,minecraft:brick_stairs-6
rule44=0,100,minecraft:brick_stairs-7
rule45=0,100,minecraft:brick_stairs-5
rule46=0,100,minecraft:stone_slab-12

layer
1,1,1,1,1,1,1,1,1,1,1,1,1,1,1,1,1
1,1,1,1,1,1,1,1,1,1,1,1,1,1,1,1,1
1,2,1,1,1,1,2,1,1,1,1,2,1,1,1,2,1
1,1,3,3,3,3,3,3,3,3,3,3,3,3,3,1,1
1,1,3,3,3,3,3,3,3,3,3,3,3,3,3,1,1
1,1,3,3,3,3,3,3,3,3,3,3,3,3,3,1,1
1,1,3,3,3,3,3,3,3,3,3,3,3,3,3,1,1
1,1,3,3,3,3,3,3,3,3,3,3,3,3,3,1,1
1,1,3,3,3,3,3,3,3,3,3,3,3,3,3,1,1
1,2,1,4,4,4,4,1,2,1,1,1,1,1,1,2,1
1,1,1,4,4,4,4,1,1,1,1,1,1,1,1,1,1
1,1,1,1,1,1,1,1,1,1,1,1,1,1,1,1,1
endlayer

layer
1,1,1,1,1,1,1,1,1,1,1,1,1,1,1,1,1
1,1,1,1,1,1,1,1,1,1,1,1,1,1,1,1,1
1,2,1,1,1,1,2,1,1,1,1,2,1,1,1,2,1
1,1,3,3,3,3,3,3,3,3,3,3,3,3,3,1,1
1,1,3,3,3,3,3,3,3,3,3,3,3,3,3,1,1
1,1,3,3,3,3,3,3,3,3,3,3,3,3,3,1,1
1,1,3,3,3,3,3,3,3,3,3,3,3,3,3,1,1
1,1,3,3,3,3,3,3,3,3,3,3,3,3,3,1,1
1,1,3,3,3,3,3,3,3,3,3,3,3,3,3,1,1
1,2,1,4,4,4,4,1,2,1,1,1,1,1,1,2,1
1,1,1,4,4,4,4,1,1,1,1,1,1,1,1,1,1
1,1,1,1,1,1,1,1,1,1,1,1,1,1,1,1,1
endlayer

layer
1,7,6,6,6,6,6,6,6,6,6,6,6,6,6,5,1
1,7,8,8,8,8,8,8,8,8,8,8,8,8,8,5,1
1,2,9,9,9,9,2,9,9,9,9,2,9,9,9,2,1
1,10,8,8,8,8,8,8,8,8,8,8,8,8,8,10,1
1,10,8,8,8,8,8,8,8,8,8,8,8,8,8,10,1
1,10,8,8,8,8,8,8,8,8,8,8,8,8,8,10,1
1,10,8,8,8,8,8,8,8,8,8,8,8,8,8,10,1
1,10,8,8,8,8,8,8,8,8,8,8,8,8,8,10,1
1,10,8,4,4,4,4,8,8,8,8,8,8,8,8,10,1
1,2,9,4,11,11,4,9,2,9,9,9,9,9,9,2,1
1,1,1,4,4,4,4,1,1,1,1,1,1,1,1,1,1
1,1,1,1,1,1,1,1,1,1,1,1,1,1,1,1,1
endlayer

layer
1,0,0,0,0,0,0,0,0,0,0,0,0,0,0,0,1
1,0,0,0,0,0,0,0,0,0,0,0,0,0,0,0,1
1,2,4,4,4,4,2,4,4,4,4,2,4,12,4,2,1
1,4,13,13,13,13,13,13,13,13,13,0,0,0,0,4,1
1,4,0,0,0,0,0,0,0,0,0,0,0,0,0,4,1
1,4,13,15,13,15,13,15,0,14,14,14,14,14,0,4,1
1,4,17,0,0,0,0,16,0,14,14,14,14,14,0,4,1
1,4,18,0,0,0,0,15,0,0,0,0,0,0,0,4,1
1,4,4,4,19,19,4,15,13,13,13,13,13,13,13,4,1
1,2,4,4,20,20,4,4,2,4,4,4,4,4,4,2,1
1,1,1,4,4,4,4,1,1,1,1,1,1,1,1,1,1
1,1,1,1,1,1,1,1,1,1,1,1,1,1,1,1,1
endlayer

layer
1,0,0,0,0,0,0,0,0,0,0,0,0,0,0,0,1
1,0,0,0,0,0,0,0,0,0,0,0,0,0,0,0,1
1,2,22,22,22,22,2,22,22,22,22,2,4,21,4,2,1
1,4,25,0,24,0,0,0,23,0,0,0,0,0,0,4,1
1,22,0,0,0,0,0,0,0,0,0,0,0,0,0,22,1
1,22,0,0,0,0,0,26,0,0,0,0,0,0,0,22,1
1,22,0,0,0,0,0,0,0,0,0,0,0,0,0,22,1
1,22,0,0,0,0,0,0,0,0,0,0,0,0,0,22,1
1,4,0,29,0,0,29,0,0,0,28,0,27,0,0,4,1
1,2,4,4,30,30,4,4,2,4,4,4,4,4,4,2,1
1,1,1,4,4,4,4,1,1,1,1,1,1,1,1,1,1
1,1,1,1,1,1,1,1,1,1,1,1,1,1,1,1,1
endlayer

layer
1,0,0,0,0,0,0,0,0,0,0,0,0,0,0,0,1
1,0,0,0,0,0,0,0,0,0,0,0,0,0,0,0,1
1,2,22,22,22,22,2,22,22,22,22,2,4,31,4,2,1
1,4,0,0,0,0,0,0,0,0,0,0,0,0,0,4,1
1,22,0,0,0,0,0,0,0,0,0,0,0,0,0,22,1
1,22,0,0,0,0,0,0,0,0,0,0,0,0,0,22,1
1,22,0,0,0,0,0,0,0,0,0,0,0,0,0,22,1
1,22,0,0,0,0,0,0,0,0,0,0,0,0,0,22,1
1,4,0,32,0,0,32,0,0,0,0,0,0,0,0,4,1
1,2,4,4,0,0,4,4,2,4,22,22,22,22,4,2,1
1,1,1,4,4,4,4,1,1,1,1,1,1,1,1,1,1
1,1,1,1,1,1,1,1,1,1,1,1,1,1,1,1,1
endlayer

layer
1,0,33,13,33,13,33,13,33,13,33,13,33,13,33,0,1
1,0,33,0,0,0,0,0,0,0,0,0,0,0,33,0,1
1,2,4,4,4,4,2,4,4,4,4,2,4,4,4,2,1
1,4,0,0,0,0,0,0,0,0,0,0,0,0,0,4,1
1,4,0,0,0,0,0,0,0,0,0,0,0,0,0,4,1
1,4,0,0,0,0,0,0,0,0,0,0,0,0,0,4,1
1,4,0,0,0,0,0,0,0,0,0,0,0,0,0,4,1
1,4,0,29,0,0,29,0,0,0,0,0,0,0,0,4,1
1,4,0,4,35,34,4,0,0,0,0,0,0,0,0,4,1
1,2,4,4,0,0,4,4,2,4,4,4,4,4,4,2,1
1,1,1,4,4,4,4,1,1,1,1,1,1,1,1,1,1
1,1,1,1,1,1,1,1,1,1,1,1,1,1,1,1,1
endlayer

layer
0,0,0,0,0,0,0,0,0,0,0,0,0,0,0,0,0
7,6,36,37,36,37,36,37,36,37,36,37,36,37,36,6,6
7,8,9,9,9,9,2,9,9,9,9,2,9,9,9,8,5
7,10,13,13,13,13,13,13,10,13,13,13,13,13,13,10,5
7,10,13,0,0,0,0,13,10,13,0,0,0,0,13,10,5
7,10,13,0,0,0,0,13,10,13,0,0,0,0,13,10,5
7,10,13,0,0,0,0,13,10,13,0,0,0,0,13,10,5
7,10,13,13,13,13,13,13,10,13,0,0,0,0,13,10,5
7,10,32,4,4,4,4,32,10,13,13,13,13,13,13,10,5
7,2,9,4,0,0,4,9,2,9,9,9,9,9,9,2,5
38,38,38,4,4,4,4,38,38,38,38,38,38,38,38,38,5
1,1,1,1,1,1,1,1,1,1,1,1,1,1,1,1,1
endlayer

layer
0,0,0,0,0,0,0,0,0,0,0,0,0,0,0,0,0
0,0,0,0,0,0,0,0,0,0,0,0,0,0,0,0,0
0,39,40,41,40,41,40,41,40,41,40,41,40,41,40,39,0
0,39,39,39,39,39,39,39,39,39,39,39,39,39,39,39,0
0,7,8,8,8,8,8,8,8,8,8,8,8,8,8,5,0
0,7,8,8,8,8,8,8,8,8,8,8,8,8,8,5,0
0,7,8,8,8,8,8,8,8,8,8,8,8,8,8,5,0
0,7,8,8,8,8,8,8,8,8,8,8,8,8,8,5,0
0,7,8,4,4,4,29,8,8,8,8,8,8,8,8,5,0
0,38,38,4,0,0,4,38,38,38,38,38,38,38,38,5,0
0,0,0,4,4,4,4,0,0,0,0,0,0,0,0,0,0
1,1,1,1,1,1,1,1,1,1,1,1,1,1,1,1,1
endlayer

layer
0,0,0,0,0,0,0,0,0,0,0,0,0,0,0,0,0
0,0,0,0,0,0,0,0,0,0,0,0,0,0,0,0,0
0,0,0,0,0,0,0,0,0,0,0,0,0,0,0,0,0
0,0,0,0,0,0,0,0,0,0,0,0,0,0,0,0,0
0,0,0,0,0,0,0,0,0,0,0,0,0,0,0,0,0
0,0,0,0,0,0,0,0,0,0,0,0,0,0,0,0,0
0,0,0,0,0,0,0,0,0,0,0,0,0,0,0,0,0
0,0,0,0,0,0,0,0,0,0,0,0,0,0,0,0,0
0,0,0,4,4,4,4,0,0,0,0,0,0,0,0,0,0
0,0,0,4,0,0,4,0,0,0,0,0,0,0,0,0,0
0,0,0,4,4,4,4,0,0,0,0,0,0,0,0,0,0
1,1,1,1,1,1,1,1,1,1,1,1,1,1,1,1,1
endlayer

layer
0,0,0,0,0,0,0,0,0,0,0,0,0,0,0,0,0
0,0,0,0,0,0,0,0,0,0,0,0,0,0,0,0,0
0,0,0,0,0,0,0,0,0,0,0,0,0,0,0,0,0
0,0,0,0,0,0,0,0,0,0,0,0,0,0,0,0,0
0,0,0,0,0,0,0,0,0,0,0,0,0,0,0,0,0
0,0,0,0,0,0,0,0,0,0,0,0,0,0,0,0,0
0,0,0,0,0,0,0,0,0,0,0,0,0,0,0,0,0
0,0,0,0,0,0,0,0,0,0,0,0,0,0,0,0,0
0,0,0,29,29,29,29,0,0,0,0,0,0,0,0,0,0
0,0,0,34,0,0,35,0,0,0,0,0,0,0,0,0,0
0,0,0,42,42,42,42,0,0,0,0,0,0,0,0,0,0
1,1,1,1,1,1,1,0,0,0,1,1,1,1,1,1,1
endlayer

layer
0,0,0,0,0,0,0,0,0,0,0,0,0,0,0,0,0
0,0,0,0,0,0,0,0,0,0,0,0,0,0,0,0,0
0,0,0,0,0,0,0,0,0,0,0,0,0,0,0,0,0
0,0,0,0,0,0,0,0,0,0,0,0,0,0,0,0,0
0,0,0,0,0,0,0,0,0,0,0,0,0,0,0,0,0
0,0,0,0,0,0,0,0,0,0,0,0,0,0,0,0,0
0,0,0,0,0,0,0,0,0,0,0,0,0,0,0,0,0
0,0,0,0,0,0,0,0,0,0,0,0,0,0,0,0,0
0,0,0,32,32,32,32,0,0,0,0,0,0,0,0,0,0
0,0,0,44,0,0,43,0,0,0,0,0,0,0,0,0,0
0,0,0,44,45,45,45,0,0,0,0,0,0,0,0,0,0
1,1,1,1,1,0,0,0,0,0,0,0,1,1,1,1,1
endlayer

layer
0,0,0,0,0,0,0,0,0,0,0,0,0,0,0,0,0
0,0,0,0,0,0,0,0,0,0,0,0,0,0,0,0,0
0,0,0,0,0,0,0,0,0,0,0,0,0,0,0,0,0
0,0,0,0,0,0,0,0,0,0,0,0,0,0,0,0,0
0,0,0,0,0,0,0,0,0,0,0,0,0,0,0,0,0
0,0,0,0,0,0,0,0,0,0,0,0,0,0,0,0,0
0,0,0,0,0,0,0,0,0,0,0,0,0,0,0,0,0
0,0,0,0,0,0,0,0,0,0,0,0,0,0,0,0,0
0,0,0,0,0,0,0,0,0,0,0,0,0,0,0,0,0
0,0,0,34,46,46,35,0,0,0,0,0,0,0,0,0,0
0,0,0,0,0,0,0,0,0,0,0,0,0,0,0,0,0
1,1,1,0,0,0,0,0,0,0,0,0,0,0,1,1,1
endlayer

