
# Created by Ruins mod version 17.0 Ingame Parser
# authoring Player: ST753M

weight=1
uniqueMinDistance=1000
embed_into_distance=3
acceptable_target_blocks=grass,dirt,coarse_dirt,podzol
unacceptable_target_blocks=flowing_water,water,flowing_lava,lava
dimensions=14,20,15
allowable_overhang=2
max_leveling=3
leveling_buffer=-1
preserve_water=0
preserve_lava=0

biomesToSpawnIn=forest,maple_woods,seasonal_forest,grove,shield,smaller_extreme_hills,plains,prairie,shrubland,chaparral,grassland,meadow,orchard,rocky_plains,rocky_plateau,mutated_plains,mystic_grove,savanna,savanna_rock,mutated_savanna,mutated_savanna_rock,brushland,steppe,tundra

=0,100,air
rule1=0,100,preserveBlock
rule2=0,100,minecraft:dirt-1
rule3=0,100,minecraft:log-0
rule4=0,100,minecraft:planks-4
^0,100,minecraft:planks-4
^0,100,minecraft:planks-4
^0,100,minecraft:hardened_clay-0
^0,100,minecraft:hardened_clay-0
^0,100,minecraft:planks-3
^0,100,minecraft:planks-0

#	CBs summon horses
rule5=0,50,CommandBlock:RUINSTRIGGER /summon horse ~ ~ ~:@-1,CommandBlock:RUINSTRIGGER /summon horse ~ ~ ~:@-1,CommandBlock:RUINSTRIGGER /summon donkey ~ ~ ~:@-1,CommandBlock:RUINSTRIGGER /summon mule ~ ~ ~:@-1,CommandBlock:RUINSTRIGGER /summon mule ~ ~ ~:@-1,CommandBlock:RUINSTRIGGER /summon llama ~ ~ ~:@-1

rule6=0,100,minecraft:spruce_fence-0
rule7=0,100,minecraft:spruce_fence_gate-1
rule8=0,100,minecraft:ladder-2
rule9=0,100,minecraft:spruce_fence_gate-3
rule10=0,100,minecraft:stained_glass_pane-8
rule11=0,100,minecraft:spruce_stairs-0
rule12=0,100,minecraft:spruce_stairs-5
rule13=0,100,minecraft:log-8
rule14=0,100,minecraft:log-4
rule15=0,100,minecraft:wooden_slab-9
rule16=0,100,minecraft:spruce_stairs-4
rule17=0,100,minecraft:spruce_stairs-1
rule18=0,100,minecraft:planks-1
rule19=0,100,minecraft:hay_block-0
rule20=0,70,minecraft:web-0
rule21=0,100,minecraft:wooden_slab-1

layer
0,0,0,0,0,0,0,0,0,0,0,0,0,0,0
1,1,1,1,1,1,1,1,1,1,1,1,1,1,1
1,2,2,2,2,2,2,2,2,2,2,2,2,2,1
1,2,2,2,2,2,2,2,2,2,2,2,2,2,1
1,2,2,2,2,2,2,2,2,2,2,2,2,2,1
1,2,2,2,2,2,2,2,2,2,2,2,2,2,1
1,2,2,2,2,2,2,2,2,2,2,2,2,2,1
1,2,2,2,2,2,2,2,2,2,2,2,2,2,1
1,2,2,2,2,2,2,2,2,2,2,2,2,2,1
1,2,2,2,2,2,2,2,2,2,2,2,2,2,1
1,2,2,2,2,2,2,2,2,2,2,2,2,2,1
1,2,2,2,2,2,2,2,2,2,2,2,2,2,1
1,2,2,2,2,2,2,2,2,2,2,2,2,2,1
1,2,2,2,2,2,2,2,2,2,2,2,2,2,1
1,2,2,2,2,2,2,2,2,2,2,2,2,2,1
1,2,2,2,2,2,2,2,2,2,2,2,2,2,1
1,2,2,2,2,2,2,2,2,2,2,2,2,2,1
1,2,2,2,2,2,2,2,2,2,2,2,2,2,1
1,2,2,2,2,2,2,2,2,2,2,2,2,2,1
1,1,1,1,1,1,1,1,1,1,1,1,1,1,1
endlayer

layer
0,0,0,0,0,0,0,0,0,0,0,0,0,0,0
1,1,1,1,1,1,1,1,1,1,1,1,1,1,1
1,2,2,2,2,2,2,2,2,2,2,2,2,2,1
1,2,2,2,2,2,2,2,2,2,2,2,2,2,1
1,2,2,2,2,2,2,2,2,2,2,2,2,2,1
1,2,2,2,2,2,2,2,2,2,2,2,2,2,1
1,2,2,2,2,2,2,2,2,2,2,2,2,2,1
1,2,2,2,2,2,2,2,2,2,2,2,2,2,1
1,2,2,2,2,2,2,2,2,2,2,2,2,2,1
1,2,2,2,2,2,2,2,2,2,2,2,2,2,1
1,2,2,2,2,2,2,2,2,2,2,2,2,2,1
1,2,2,2,2,2,2,2,2,2,2,2,2,2,1
1,2,2,2,2,2,2,2,2,2,2,2,2,2,1
1,2,2,2,2,2,2,2,2,2,2,2,2,2,1
1,2,2,2,2,2,2,2,2,2,2,2,2,2,1
1,2,2,2,2,2,2,2,2,2,2,2,2,2,1
1,2,2,2,2,2,2,2,2,2,2,2,2,2,1
1,2,2,2,2,2,2,2,2,2,2,2,2,2,1
1,2,2,2,2,2,2,2,2,2,2,2,2,2,1
1,1,1,1,1,1,1,1,1,1,1,1,1,1,1
endlayer

layer
0,0,0,0,0,0,0,0,0,0,0,0,0,0,0
1,1,1,1,1,1,1,1,1,1,1,1,1,1,1
1,2,2,2,2,2,2,2,2,2,2,2,2,2,1
1,2,2,2,2,2,2,2,2,2,2,2,2,2,1
1,2,2,2,2,2,2,2,2,2,2,2,2,2,1
1,2,2,2,2,2,2,2,2,2,2,2,2,2,1
1,2,2,2,2,2,2,2,2,2,2,2,2,2,1
1,2,2,2,2,2,2,2,2,2,2,2,2,2,1
1,2,2,2,2,2,2,2,2,2,2,2,2,2,1
1,2,2,2,2,2,2,2,2,2,2,2,2,2,1
1,2,2,2,2,2,2,2,2,2,2,2,2,2,1
1,2,2,2,2,2,2,2,2,2,2,2,2,2,1
1,2,2,2,2,2,2,2,2,2,2,2,2,2,1
1,2,2,2,2,2,2,2,2,2,2,2,2,2,1
1,2,2,2,2,2,2,2,2,2,2,2,2,2,1
1,2,2,2,2,2,2,2,2,2,2,2,2,2,1
1,2,2,2,2,2,2,2,2,2,2,2,2,2,1
1,2,2,2,2,2,2,2,2,2,2,2,2,2,1
1,2,2,2,2,2,2,2,2,2,2,2,2,2,1
1,1,1,1,1,1,1,1,1,1,1,1,1,1,1
endlayer

layer
0,0,0,0,0,0,0,0,0,0,0,0,0,0,0
1,1,1,1,1,1,1,1,1,1,1,1,1,1,1
1,3,4,4,4,3,4,4,4,3,4,4,4,3,1
1,4,0,0,0,4,0,0,0,4,0,0,0,4,1
1,4,0,5,0,4,0,5,0,4,0,5,0,4,1
1,4,0,0,0,4,0,0,0,4,0,0,0,4,1
1,3,6,7,6,3,6,7,6,3,6,7,6,3,1
1,4,8,0,0,0,0,0,0,0,0,0,0,4,1
1,6,0,0,0,0,0,0,0,0,0,0,0,6,1
0,0,0,0,0,0,0,0,0,0,0,0,0,0,0
0,0,0,0,0,0,0,0,0,0,0,0,0,0,0
0,0,0,0,0,0,0,0,0,0,0,0,0,0,0
1,6,0,0,0,0,0,0,0,0,0,0,0,6,1
1,4,0,0,0,0,0,0,0,0,0,0,0,4,1
1,3,6,9,6,3,6,9,6,3,6,9,6,3,1
1,4,0,0,0,4,0,0,0,4,0,0,0,4,1
1,4,0,5,0,4,0,5,0,4,0,5,0,4,1
1,4,0,0,0,4,0,0,0,4,0,0,0,4,1
1,3,4,4,4,3,4,4,4,3,4,4,4,3,1
1,1,1,1,1,1,1,1,1,1,1,1,1,1,1
endlayer

layer
0,0,0,0,0,0,0,0,0,0,0,0,0,0,0
1,1,1,1,1,1,1,1,1,1,1,1,1,1,1
1,3,4,10,4,3,4,10,4,3,4,10,4,3,1
1,4,0,0,0,4,0,0,0,4,0,0,0,4,1
1,10,0,0,0,4,0,0,0,4,0,0,0,10,1
1,4,0,0,0,4,0,0,0,4,0,0,0,4,1
1,3,0,0,0,3,0,0,0,3,0,0,0,3,1
1,4,8,0,0,0,0,0,0,0,0,0,0,4,1
1,6,0,0,0,0,0,0,0,0,0,0,0,6,1
0,0,0,0,0,0,0,0,0,0,0,0,0,0,0
0,0,0,0,0,0,0,0,0,0,0,0,0,0,0
0,0,0,0,0,0,0,0,0,0,0,0,0,0,0
1,6,0,0,0,0,0,0,0,0,0,0,0,6,1
1,4,0,0,0,0,0,0,0,0,0,0,0,4,1
1,3,0,0,0,3,0,0,0,3,0,0,0,3,1
1,4,0,0,0,4,0,0,0,4,0,0,0,4,1
1,10,0,0,0,4,0,0,0,4,0,0,0,10,1
1,4,0,0,0,4,0,0,0,4,0,0,0,4,1
1,3,4,10,4,3,4,10,4,3,4,10,4,3,1
1,1,1,1,1,1,1,1,1,1,1,1,1,1,1
endlayer

layer
0,0,0,0,0,0,0,0,0,0,0,0,0,0,0
1,1,1,1,1,1,1,1,1,1,1,1,1,1,1
1,3,4,10,4,3,4,10,4,3,4,10,4,3,1
1,4,0,0,0,6,0,0,0,6,0,0,0,4,1
1,10,0,0,0,6,0,0,0,6,0,0,0,10,1
1,4,0,0,0,6,0,0,0,6,0,0,0,4,1
1,3,0,0,0,3,0,0,0,3,0,0,0,3,1
1,4,8,0,0,0,0,0,0,0,0,0,0,4,1
1,6,0,0,0,0,0,0,0,0,0,0,0,6,1
0,0,0,0,0,0,0,0,0,0,0,0,0,0,0
0,0,0,0,0,0,0,0,0,0,0,0,0,0,0
0,0,0,0,0,0,0,0,0,0,0,0,0,0,0
1,6,0,0,0,0,0,0,0,0,0,0,0,6,1
1,4,0,0,0,0,0,0,0,0,0,0,0,4,1
1,3,0,0,0,3,0,0,0,3,0,0,0,3,1
1,4,0,0,0,6,0,0,0,6,0,0,0,4,1
1,10,0,0,0,6,0,0,0,6,0,0,0,10,1
1,4,0,0,0,6,0,0,0,6,0,0,0,4,1
1,3,4,10,4,3,4,10,4,3,4,10,4,3,1
1,1,1,1,1,1,1,1,1,1,1,1,1,1,1
endlayer

layer
0,0,0,0,0,0,0,0,0,0,0,0,0,0,0
11,11,11,11,11,11,11,11,11,11,11,11,11,11,11
12,3,13,13,13,3,13,13,13,3,13,13,13,3,12
1,14,15,15,15,14,15,15,15,14,15,15,15,14,1
1,14,15,15,15,14,15,15,15,14,15,15,15,14,1
1,14,15,15,15,14,15,15,15,14,15,15,15,14,1
1,3,13,13,13,3,13,13,13,3,13,13,13,3,1
1,14,8,15,15,14,0,0,0,14,15,15,15,14,1
1,14,15,15,15,14,0,0,0,14,15,15,15,14,1
1,14,15,15,15,14,0,0,0,14,15,15,15,14,1
1,14,15,15,15,14,0,0,0,14,15,15,15,14,1
1,14,15,15,15,14,0,0,0,14,15,15,15,14,1
1,14,15,15,15,14,0,0,0,14,15,15,15,14,1
1,14,15,15,15,14,0,0,0,14,15,15,15,14,1
1,3,13,13,13,3,13,13,13,3,13,13,13,3,1
1,14,15,15,15,14,15,15,15,14,15,15,15,14,1
1,14,15,15,15,14,15,15,15,14,15,15,15,14,1
1,14,15,15,15,14,15,15,15,14,15,15,15,14,1
16,3,13,13,13,3,13,13,13,3,13,13,13,3,16
17,17,17,17,17,17,17,17,17,17,17,17,17,17,17
endlayer

layer
0,0,0,0,0,0,0,0,0,0,0,0,0,0,0
0,0,0,0,0,0,0,0,0,0,0,0,0,0,0
11,11,11,11,11,11,11,11,11,11,11,11,11,11,11
12,4,18,18,18,18,18,18,18,18,18,18,18,4,12
0,4,0,0,0,0,0,19,19,0,0,0,0,4,0
0,4,0,0,0,0,0,19,0,0,0,0,0,4,0
0,3,0,0,0,3,0,0,0,3,0,0,20,3,0
0,4,8,0,0,0,0,0,0,0,0,0,0,4,0
0,4,0,0,0,0,0,0,0,0,0,0,0,4,0
0,4,0,0,0,0,0,0,0,19,0,0,0,4,0
0,3,0,0,0,3,0,0,0,3,0,0,0,3,0
0,4,19,19,0,0,0,0,0,0,0,0,0,4,0
0,4,0,0,0,19,0,0,0,0,0,0,0,4,0
0,4,0,0,19,0,0,0,0,0,0,0,0,4,0
0,3,0,0,19,3,0,0,0,3,0,0,0,3,0
0,4,0,0,0,0,0,0,0,0,0,0,19,4,0
0,4,0,0,0,0,0,0,0,0,0,0,0,4,0
16,4,18,18,18,18,18,18,18,18,18,18,18,4,16
17,17,17,17,17,17,17,17,17,17,17,17,17,17,17
0,0,0,0,0,0,0,0,0,0,0,0,0,0,0
endlayer

layer
0,0,0,0,0,0,0,0,0,0,0,0,0,0,0
0,0,0,0,0,0,0,0,0,0,0,0,0,0,0
0,0,0,0,0,0,0,0,0,0,0,0,0,0,0
11,11,11,11,11,11,11,11,11,11,11,11,11,11,11
12,4,0,0,0,0,0,0,0,0,0,0,0,4,12
0,4,0,0,0,0,0,0,0,0,0,0,0,4,0
0,3,0,0,0,3,0,0,0,3,0,0,0,3,0
0,4,8,0,0,0,0,0,0,0,0,0,0,4,0
0,10,0,0,0,0,0,0,0,0,0,0,0,10,0
0,4,0,0,0,0,0,0,0,0,0,0,0,4,0
0,3,20,0,0,3,0,0,0,3,0,0,0,3,0
0,4,0,0,0,0,0,0,0,0,0,0,0,4,0
0,10,0,0,0,0,0,0,0,0,0,0,0,10,0
0,4,0,0,19,0,0,0,0,0,0,0,0,4,0
0,3,0,0,0,3,0,0,0,3,0,0,0,3,0
0,4,0,0,0,0,0,0,0,0,0,0,0,4,0
16,4,0,0,0,0,0,0,0,0,20,0,0,4,16
17,17,17,17,17,17,17,17,17,17,17,17,17,17,17
0,0,0,0,0,0,0,0,0,0,0,0,0,0,0
0,0,0,0,0,0,0,0,0,0,0,0,0,0,0
endlayer

layer
0,0,0,0,0,0,0,0,0,0,0,0,0,0,0
0,0,0,0,0,0,0,0,0,0,0,0,0,0,0
0,0,0,0,0,0,0,0,0,0,0,0,0,0,0
0,0,0,0,0,0,0,0,0,0,0,0,0,0,0
11,11,11,11,11,11,11,11,11,11,11,11,11,11,11
12,4,0,0,0,0,0,0,0,0,0,0,20,4,12
0,3,0,0,0,3,0,0,0,3,0,0,0,3,0
0,4,8,0,0,0,0,0,0,0,0,0,0,4,0
0,10,0,0,0,0,0,0,0,0,0,0,0,10,0
0,4,0,0,0,0,0,0,0,0,0,0,0,4,0
0,3,0,20,0,3,0,0,0,3,0,0,0,3,0
0,4,0,0,0,0,0,0,0,0,0,0,0,4,0
0,10,0,0,0,0,0,0,0,0,0,0,0,10,0
0,4,0,0,0,0,0,0,0,0,0,0,0,4,0
0,3,0,0,0,3,0,0,0,3,0,0,0,3,0
16,4,0,0,0,0,0,0,20,0,0,0,0,4,16
17,17,17,17,17,17,17,17,17,17,17,17,17,17,17
0,0,0,0,0,0,0,0,0,0,0,0,0,0,0
0,0,0,0,0,0,0,0,0,0,0,0,0,0,0
0,0,0,0,0,0,0,0,0,0,0,0,0,0,0
endlayer

layer
0,0,0,0,0,0,0,0,0,0,0,0,0,0,0
0,0,0,0,0,0,0,0,0,0,0,0,0,0,0
0,0,0,0,0,0,0,0,0,0,0,0,0,0,0
0,0,0,0,0,0,0,0,0,0,0,0,0,0,0
0,0,0,0,0,0,0,0,0,0,0,0,0,0,0
11,11,11,11,11,11,11,11,11,11,11,11,11,11,11
12,3,0,0,0,3,0,0,20,3,0,0,20,3,12
0,14,0,0,0,20,0,0,0,0,0,0,0,14,0
0,14,0,0,0,0,0,0,0,0,0,0,0,14,0
0,14,20,0,0,0,0,0,0,0,0,0,20,14,0
0,3,13,13,13,3,13,13,13,3,13,13,13,3,0
0,14,0,0,0,0,0,0,20,0,0,0,0,14,0
0,14,0,0,0,0,0,0,0,0,0,0,0,14,0
0,14,0,0,0,0,0,0,0,0,0,0,0,14,0
16,3,20,0,0,3,20,0,0,3,0,0,0,3,16
17,17,17,17,17,17,17,17,17,17,17,17,17,17,17
0,0,0,0,0,0,0,0,0,0,0,0,0,0,0
0,0,0,0,0,0,0,0,0,0,0,0,0,0,0
0,0,0,0,0,0,0,0,0,0,0,0,0,0,0
0,0,0,0,0,0,0,0,0,0,0,0,0,0,0
endlayer

layer
0,0,0,0,0,0,0,0,0,0,0,0,0,0,0
0,0,0,0,0,0,0,0,0,0,0,0,0,0,0
0,0,0,0,0,0,0,0,0,0,0,0,0,0,0
0,0,0,0,0,0,0,0,0,0,0,0,0,0,0
0,0,0,0,0,0,0,0,0,0,0,0,0,0,0
0,0,0,0,0,0,0,0,0,0,0,0,0,0,0
21,21,21,21,21,21,21,21,21,21,21,21,21,21,21
18,18,18,18,18,18,18,18,18,18,18,18,18,18,18
15,4,15,15,15,15,15,15,15,15,15,15,15,4,15
0,4,0,0,0,20,0,0,0,20,0,0,20,4,0
0,4,20,0,0,3,0,20,20,3,0,0,0,4,0
0,4,0,0,0,20,0,0,0,20,0,0,0,4,0
15,4,15,15,15,15,15,15,15,15,15,15,15,4,15
18,18,18,18,18,18,18,18,18,18,18,18,18,18,18
21,21,21,21,21,21,21,21,21,21,21,21,21,21,21
0,0,0,0,0,0,0,0,0,0,0,0,0,0,0
0,0,0,0,0,0,0,0,0,0,0,0,0,0,0
0,0,0,0,0,0,0,0,0,0,0,0,0,0,0
0,0,0,0,0,0,0,0,0,0,0,0,0,0,0
0,0,0,0,0,0,0,0,0,0,0,0,0,0,0
endlayer

layer
0,0,0,0,0,0,0,0,0,0,0,0,0,0,0
0,0,0,0,0,0,0,0,0,0,0,0,0,0,0
0,0,0,0,0,0,0,0,0,0,0,0,0,0,0
0,0,0,0,0,0,0,0,0,0,0,0,0,0,0
0,0,0,0,0,0,0,0,0,0,0,0,0,0,0
0,0,0,0,0,0,0,0,0,0,0,0,0,0,0
0,0,0,0,0,0,0,0,0,0,0,0,0,0,0
0,0,0,0,0,0,0,0,0,0,0,0,0,0,0
21,21,21,21,21,21,21,21,21,21,21,21,21,21,21
18,18,18,18,18,18,18,18,18,18,18,18,18,18,18
18,18,18,18,18,18,18,18,18,18,18,18,18,18,18
18,18,18,18,18,18,18,18,18,18,18,18,18,18,18
21,21,21,21,21,21,21,21,21,21,21,21,21,21,21
0,0,0,0,0,0,0,0,0,0,0,0,0,0,0
0,0,0,0,0,0,0,0,0,0,0,0,0,0,0
0,0,0,0,0,0,0,0,0,0,0,0,0,0,0
0,0,0,0,0,0,0,0,0,0,0,0,0,0,0
0,0,0,0,0,0,0,0,0,0,0,0,0,0,0
0,0,0,0,0,0,0,0,0,0,0,0,0,0,0
0,0,0,0,0,0,0,0,0,0,0,0,0,0,0
endlayer

layer
0,0,0,0,0,0,0,0,0,0,0,0,0,0,0
0,0,0,0,0,0,0,0,0,0,0,0,0,0,0
0,0,0,0,0,0,0,0,0,0,0,0,0,0,0
0,0,0,0,0,0,0,0,0,0,0,0,0,0,0
0,0,0,0,0,0,0,0,0,0,0,0,0,0,0
0,0,0,0,0,0,0,0,0,0,0,0,0,0,0
0,0,0,0,0,0,0,0,0,0,0,0,0,0,0
0,0,0,0,0,0,0,0,0,0,0,0,0,0,0
0,0,0,0,0,0,0,0,0,0,0,0,0,0,0
0,0,0,0,0,0,0,0,0,0,0,0,0,0,0
21,21,21,21,21,21,21,21,21,21,21,21,21,21,21
0,0,0,0,0,0,0,0,0,0,0,0,0,0,0
0,0,0,0,0,0,0,0,0,0,0,0,0,0,0
0,0,0,0,0,0,0,0,0,0,0,0,0,0,0
0,0,0,0,0,0,0,0,0,0,0,0,0,0,0
0,0,0,0,0,0,0,0,0,0,0,0,0,0,0
0,0,0,0,0,0,0,0,0,0,0,0,0,0,0
0,0,0,0,0,0,0,0,0,0,0,0,0,0,0
0,0,0,0,0,0,0,0,0,0,0,0,0,0,0
0,0,0,0,0,0,0,0,0,0,0,0,0,0,0
endlayer

