
# Created by Ruins mod version 17.0 Ingame Parser
# authoring Player: ST753M

# A house with a 3-tree orchard and a small garden

weight=1
embed_into_distance=2
uniqueMinDistance=500
acceptable_target_blocks=grass,dirt,emerald_block
unacceptable_target_blocks=flowing_water,water,flowing_lava,lava
dimensions=12,19,17
allowable_overhang=2
max_leveling=2
leveling_buffer=-1
preserve_water=0
preserve_lava=0

biomesToSpawnIn=orchard,plains,prairie,shrubland,chaparral,grassland,meadow,orchard,rocky_plains,rocky_plateau,lavender_fields

=0,100,air
rule1=0,100,preserveBlock
rule2=0,100,minecraft:dirt-0
rule3=0,100,minecraft:log-0
rule4=0,100,minecraft:brick_block-0
rule5=0,100,minecraft:grass-0
rule6=0,100,minecraft:farmland-7
rule7=0,100,minecraft:spruce_fence-0
rule8=0,100,minecraft:tallgrass-1

#	Possible ground garden plants
rule9=0,100,harvestcraft:pamstrawberrycrop-1
^0,100,harvestcraft:pamtomatocrop-1
^0,100,harvestcraft:pambellpeppercrop-1
^0,100,harvestcraft:pamgrapecrop-1
^0,100,harvestcraft:pamtealeafcrop-1
^0,100,harvestcraft:pamgingercrop-1
^0,100,harvestcraft:pamradishcrop-1
^0,100,harvestcraft:pamlettucecrop-1
^0,100,harvestcraft:pamcucumbercrop-1
^0,100,harvestcraft:pamonioncrop-1
^0,100,harvestcraft:pamsweetpotatocrop-1
^0,100,harvestcraft:pamcandleberrycrop-1
^0,100,minecraft:wheat-1
^0,100,minecraft:beetroots-1
^0,100,minecraft:potatoes-1
^0,100,minecraft:carrots-1
^0,100,harvestcraft:pamblackberrycrop-1
^0,100,harvestcraft:pamblueberrycrop-1

rule10=0,100,minecraft:red_flower-0
rule11=0,100,minecraft:log-8
rule12=0,100,minecraft:log-4
rule13=0,100,minecraft:planks-1
rule14=0,100,minecraft:spruce_stairs-0
rule15=0,100,minecraft:spruce_stairs-3
rule16=0,100,minecraft:spruce_stairs-1
rule17=0,100,minecraft:spruce_stairs-2
rule18=0,100,minecraft:netherrack-0
rule19=0,100,minecraft:planks-0
rule20=0,100,minecraft:bed-9
rule21=0,100,minecraft:bed-1
rule22=0,100,minecraft:spruce_door-1
rule23=0,100,minecraft:spruce_door-3
rule24=2,100,WallSign:null:null:null:null-2
rule25=0,100,minecraft:oak_stairs-1
rule26=2,100,WallSign:null:null:null:null-3
rule27=0,100,minecraft:iron_bars-0
rule28=0,100,minecraft:fire-15

#	What tree fruit do you get?
rule29=0,100,harvestcraft:pamcherry-2
^0,100,harvestcraft:pamplum-1
^0,100,harvestcraft:pamolive-0
^0,100,harvestcraft:pampear-2
^0,100,harvestcraft:pamlemon-2
^0,100,harvestcraft:pamavocado-1
^0,100,harvestcraft:pamalmond-0
^0,100,harvestcraft:pampeach-0
^0,100,harvestcraft:pampersimmon-0
^0,100,harvestcraft:pamapricot-0
^0,100,harvestcraft:pamorange-0
^0,100,harvestcraft:pamwalnut-0
^0,100,harvestcraft:pamapple-0

rule30=0,100,minecraft:glass_pane-0
rule31=0,100,minecraft:trapdoor-3
rule32=0,100,minecraft:spruce_door-9
rule33=0,100,minecraft:spruce_door-8
rule34=0,100,minecraft:brick_stairs-0
rule35=0,100,minecraft:leaves-12
rule36=0,100,minecraft:leaves-4
rule37=0,100,minecraft:oak_stairs-7
rule38=0,100,minecraft:oak_stairs-6
rule39=0,100,minecraft:brick_stairs-4
rule40=0,100,minecraft:brick_stairs-3
rule41=0,100,minecraft:brick_stairs-2
rule42=0,100,minecraft:spruce_stairs-7
rule43=0,100,minecraft:spruce_stairs-5
rule44=0,100,minecraft:spruce_stairs-6
rule45=0,100,minecraft:spruce_stairs-4
rule46=0,100,minecraft:brick_stairs-1
rule47=0,100,minecraft:brick_stairs-7
rule48=0,100,minecraft:brick_stairs-6
rule49=0,100,minecraft:brick_stairs-5

layer
1,1,1,1,1,2,2,2,2,2,1,1,1,1,1,1,1
1,1,2,2,2,2,2,2,2,2,2,2,2,2,2,1,1
1,2,2,2,2,2,2,2,2,2,2,2,2,2,2,2,1
1,2,2,2,2,2,2,2,2,2,2,2,2,2,2,2,1
1,2,2,2,2,2,2,2,2,2,2,2,2,2,2,2,1
2,2,2,2,2,2,2,2,2,2,2,2,2,2,2,2,1
2,2,2,2,2,2,2,2,2,2,2,2,2,2,2,2,2
2,2,3,2,2,2,2,3,2,2,2,2,2,2,2,2,2
2,2,2,2,2,2,2,2,2,2,2,2,2,2,2,2,2
2,2,2,2,2,2,2,2,2,2,2,2,2,2,2,2,2
2,2,2,2,2,2,2,2,2,2,2,2,2,2,2,2,2
1,2,2,2,2,2,2,2,2,2,2,2,2,2,2,2,1
1,1,3,2,2,2,2,3,2,2,2,2,3,2,2,2,1
1,1,1,4,2,2,2,2,2,2,2,2,2,2,2,2,1
1,1,1,4,2,2,2,2,2,2,2,2,2,2,2,2,1
1,1,1,4,2,2,2,2,2,2,2,2,2,2,2,1,1
1,1,1,4,4,4,4,2,4,4,4,4,2,2,2,1,1
1,1,3,4,4,4,4,3,1,1,1,1,3,1,1,1,1
1,1,1,4,4,4,4,1,1,1,1,1,1,1,1,1,1
endlayer

layer
1,1,1,1,5,5,5,5,5,5,5,1,1,1,1,1,1
1,1,5,5,5,5,5,5,5,5,5,5,5,5,5,1,1
1,5,5,5,5,5,5,5,5,5,5,5,5,5,5,5,1
1,5,5,5,5,2,5,5,5,5,5,2,5,5,5,5,1
5,5,5,5,5,5,5,5,5,5,5,5,5,5,5,5,1
5,5,5,5,5,5,5,5,5,5,5,5,5,5,6,6,5
5,5,5,5,5,5,5,5,5,5,5,5,5,5,6,6,5
5,5,3,2,2,2,2,3,5,5,5,5,5,5,6,6,5
2,2,2,2,2,2,2,2,5,5,5,2,5,5,6,6,5
5,2,2,2,2,2,2,2,5,5,5,5,5,5,6,6,5
5,2,2,2,2,2,2,2,5,5,5,5,5,5,6,6,5
2,2,2,2,2,2,2,2,5,5,5,5,5,5,6,6,5
1,1,3,2,2,2,2,3,2,2,2,2,3,5,5,5,1
1,1,1,4,2,2,2,2,2,2,2,2,2,5,5,5,1
1,1,1,4,2,2,2,2,2,2,2,2,2,2,5,5,1
1,1,1,4,2,2,2,2,2,2,2,2,2,2,5,5,1
1,1,1,4,4,4,4,2,4,4,4,4,2,5,5,1,1
1,1,3,4,4,4,4,3,1,1,1,1,3,1,1,1,1
1,1,1,4,4,4,4,1,1,1,1,1,1,1,1,1,1
endlayer

layer
1,1,1,1,7,7,7,8,7,7,7,1,1,1,1,1,1
1,1,7,7,7,8,0,0,0,8,7,7,7,7,7,1,1
1,7,7,0,0,0,0,0,0,0,0,0,0,8,7,8,1
1,7,0,0,0,3,0,0,0,0,0,3,0,8,7,8,1
8,7,0,0,0,0,0,0,0,0,0,0,0,0,0,0,1
8,0,0,0,10,0,0,0,0,0,0,0,0,0,9,9,7
0,10,0,8,0,8,10,0,0,0,0,0,0,0,9,9,7
0,0,3,11,11,11,11,3,8,0,0,0,0,0,9,9,7
14,14,12,13,13,13,13,12,10,0,0,3,0,0,9,9,7
15,13,13,13,13,13,13,12,0,0,0,0,0,0,9,9,7
15,13,13,13,13,13,13,12,8,10,8,0,0,0,9,9,7
16,16,12,13,13,13,13,12,8,8,0,8,0,0,9,9,7
1,1,3,13,13,13,13,3,11,11,11,11,3,0,0,0,1
1,1,12,13,13,13,13,13,13,13,13,13,12,14,14,0,1
1,1,12,13,13,13,13,13,13,13,13,13,13,13,17,0,1
1,1,12,13,13,13,13,13,13,13,13,13,13,13,17,0,1
1,1,12,4,4,4,4,13,13,13,13,13,12,16,16,1,1
1,1,3,4,18,18,4,3,11,11,11,11,3,1,1,1,1
1,1,1,4,4,4,4,1,1,1,1,1,1,1,1,1,1
endlayer

layer
1,1,1,0,0,0,0,0,0,0,0,0,0,1,1,1,1
1,0,0,0,0,0,0,0,0,0,0,0,0,0,0,0,1
1,0,0,0,0,0,0,0,0,0,0,0,0,0,0,0,1
0,0,0,0,0,3,0,0,0,0,0,3,0,0,0,0,1
0,0,0,0,0,0,0,0,0,0,0,0,0,0,0,0,0
0,0,0,0,0,0,0,0,0,0,0,0,0,0,0,0,0
0,0,0,0,0,0,0,0,0,0,0,0,0,0,0,0,0
0,0,3,19,19,19,19,3,0,0,0,0,0,0,0,0,0
0,0,19,0,0,7,20,19,0,0,0,3,0,0,0,0,0
0,0,22,0,0,0,21,19,0,0,0,0,0,0,0,0,0
0,0,22,0,0,0,0,19,0,0,0,0,0,0,0,0,0
0,0,19,0,0,0,0,19,0,0,0,0,0,0,0,0,0
0,0,3,0,0,0,0,3,19,19,19,19,3,0,0,0,0
0,0,19,0,0,0,0,0,17,7,15,0,19,0,0,0,0
1,0,19,26,25,25,24,0,0,0,0,0,23,0,0,0,0
1,0,19,0,0,0,0,0,0,0,0,0,23,0,0,0,1
1,0,19,4,27,27,4,0,0,0,0,0,19,0,0,0,1
1,0,3,4,28,28,4,3,19,19,19,19,3,0,0,1,1
1,1,1,4,4,4,4,0,0,0,0,0,0,1,1,1,1
endlayer

layer
1,1,0,0,0,0,0,0,0,0,0,0,0,0,1,1,1
1,0,0,0,0,29,0,0,0,0,0,0,0,0,0,0,1
0,0,0,29,0,0,29,0,0,0,0,0,0,0,0,0,1
0,0,0,29,0,3,0,0,0,0,0,3,0,0,0,0,0
0,0,0,0,29,0,29,0,0,0,0,0,0,0,0,0,0
0,0,0,0,29,29,0,0,0,0,0,0,0,0,0,0,0
0,0,0,0,0,0,0,0,0,0,29,29,0,0,0,0,0
0,0,3,19,30,30,19,3,0,0,0,0,29,0,0,0,0
0,0,19,0,0,31,0,19,0,0,0,3,0,29,0,0,0
0,0,32,0,0,0,0,30,0,29,0,0,29,0,0,0,0
0,0,33,0,0,0,0,30,0,0,29,0,0,0,0,0,0
0,0,19,0,0,0,0,19,0,0,0,0,0,0,0,0,0
0,0,3,0,0,0,0,3,19,30,30,19,3,0,0,0,0
0,0,19,0,0,0,0,0,0,31,0,0,19,0,0,0,0
0,0,30,0,0,0,0,0,0,0,0,0,33,0,0,0,0
0,0,30,0,0,0,0,0,0,0,0,0,32,0,0,0,0
1,0,19,34,0,0,34,0,0,0,0,0,19,0,0,0,1
1,0,3,4,0,0,4,3,19,30,30,19,3,0,0,0,1
1,1,0,4,4,4,4,0,0,0,0,0,0,0,1,1,1
endlayer

layer
1,0,0,0,0,0,0,0,0,0,0,0,0,0,0,1,1
0,0,0,0,35,36,35,0,0,0,29,29,0,0,0,0,1
0,0,0,35,35,36,35,35,0,0,0,0,29,0,0,0,0
0,0,0,36,36,3,36,36,0,0,0,3,0,29,0,0,0
0,0,0,36,36,36,36,36,0,29,29,0,0,0,0,0,0
0,0,0,0,36,36,36,0,0,0,0,0,29,0,0,0,0
0,0,0,0,0,0,0,0,0,0,35,35,35,0,0,0,0
0,0,3,19,30,30,19,3,0,36,36,36,36,36,0,0,0
0,0,19,0,0,0,0,19,0,36,36,3,36,36,0,0,0
0,0,37,0,0,0,0,30,0,36,36,36,36,36,0,0,0
0,0,37,0,0,0,0,30,0,0,36,36,36,0,0,0,0
0,0,19,0,0,0,0,19,0,0,0,0,0,0,0,0,0
0,0,3,0,0,0,0,3,19,30,30,19,3,0,0,0,0
0,0,19,0,0,0,0,0,0,0,0,0,19,0,0,0,0
0,0,30,0,0,0,0,0,0,0,0,0,38,0,0,0,0
0,0,30,0,0,0,0,0,0,0,0,0,38,0,0,0,0
0,0,19,27,0,0,27,0,0,0,0,0,19,0,0,0,0
1,0,3,4,0,0,4,3,19,30,30,19,3,0,0,0,1
1,0,0,4,4,4,4,0,0,0,0,0,0,0,0,1,1
endlayer

layer
0,0,0,0,0,0,0,0,0,0,0,0,0,0,0,0,1
0,0,0,0,35,36,35,0,0,0,36,36,36,0,0,0,0
0,0,0,35,35,36,35,35,0,36,36,36,36,36,0,0,0
0,0,0,36,36,3,36,36,0,36,36,3,36,36,0,0,0
0,0,0,36,36,36,36,36,0,36,36,36,36,36,0,0,0
0,0,0,0,36,36,36,0,0,0,36,36,36,0,0,0,0
0,0,0,0,0,0,0,0,0,0,35,35,35,0,0,0,0
0,0,3,19,19,19,19,3,0,36,36,36,36,36,0,0,0
0,0,19,0,0,0,0,19,0,36,36,3,36,36,0,0,0
0,0,37,0,0,0,0,19,0,36,36,36,36,36,0,0,0
0,0,37,0,0,0,0,19,0,0,36,36,36,0,0,0,0
0,0,19,0,0,0,0,19,0,0,0,0,0,0,0,0,0
0,0,3,0,0,0,0,3,19,19,19,19,3,0,0,0,0
0,0,19,0,0,0,0,0,0,0,0,0,19,0,0,0,0
0,0,19,0,0,0,0,0,0,0,0,0,38,0,0,0,0
0,0,19,0,0,0,0,0,0,0,0,0,38,0,0,0,0
0,0,19,39,39,39,39,0,0,0,0,0,19,0,0,0,0
0,0,3,4,0,0,4,3,19,19,19,19,3,0,0,0,0
1,0,0,4,4,4,4,0,0,0,0,0,0,0,0,0,1
endlayer

layer
0,0,0,0,0,0,0,0,0,0,0,0,0,0,0,0,0
0,0,0,0,0,0,0,0,0,0,36,36,36,0,0,0,0
0,0,0,0,35,36,35,0,0,36,36,36,36,36,0,0,0
0,0,0,0,36,36,36,0,0,36,36,3,36,36,0,0,0
0,0,0,0,36,36,36,0,0,36,36,36,36,36,0,0,0
0,0,0,0,0,0,0,0,0,0,36,36,36,0,0,0,0
0,15,14,14,14,14,14,14,17,0,0,0,0,0,0,0,0
0,15,3,11,11,11,11,3,17,0,36,36,36,0,0,0,0
0,15,12,0,0,0,0,12,17,0,36,35,35,0,0,0,0
0,15,12,0,0,0,0,12,17,0,36,35,35,0,0,0,0
0,15,12,0,0,0,0,12,17,0,0,0,0,0,0,0,0
0,15,12,0,0,0,0,12,17,14,14,14,14,17,0,0,0
0,15,3,11,11,11,11,3,11,11,11,11,3,17,0,0,0
0,15,12,0,0,0,0,12,0,0,0,0,12,17,0,0,0
0,15,12,0,0,0,0,12,0,0,0,0,12,17,0,0,0
0,15,12,0,0,0,0,12,0,0,0,0,12,17,0,0,0
0,15,12,41,34,34,40,12,0,0,0,0,12,17,0,0,0
0,15,3,4,0,0,4,3,11,11,11,11,3,17,0,0,0
0,15,16,4,4,4,4,16,16,16,16,16,16,16,0,0,0
endlayer

layer
0,0,0,0,0,0,0,0,0,0,0,0,0,0,0,0,0
0,0,0,0,0,0,0,0,0,0,0,0,0,0,0,0,0
0,0,0,0,0,36,0,0,0,0,35,35,36,0,0,0,0
0,0,0,0,36,36,36,0,0,0,35,35,36,0,0,0,0
0,0,0,0,0,36,0,0,0,0,36,36,36,0,0,0,0
0,0,0,0,0,0,0,0,0,0,0,0,0,0,0,0,0
0,0,0,0,0,0,0,0,0,0,0,0,0,0,0,0,0
0,0,14,14,14,14,14,14,0,0,0,36,0,0,0,0,0
0,0,15,44,43,43,42,17,0,0,36,36,36,0,0,0,0
0,0,15,44,0,0,42,17,0,0,0,35,0,0,0,0,0
0,0,15,44,0,0,42,17,0,0,0,0,0,0,0,0,0
0,0,15,44,0,0,42,17,0,0,0,0,0,0,0,0,0
0,0,15,44,0,0,42,17,14,14,14,14,14,0,0,0,0
0,0,15,44,0,0,43,43,43,43,43,43,17,0,0,0,0
0,0,15,44,0,0,0,0,0,0,0,42,17,0,0,0,0
0,0,15,44,0,0,0,0,0,0,0,42,17,0,0,0,0
0,0,15,4,39,39,4,13,45,45,45,42,17,0,0,0,0
0,0,16,4,4,4,4,16,16,16,16,16,17,0,0,0,0
0,0,0,46,4,4,46,0,0,0,0,0,0,0,0,0,0
endlayer

layer
0,0,0,0,0,0,0,0,0,0,0,0,0,0,0,0,0
0,0,0,0,0,0,0,0,0,0,0,0,0,0,0,0,0
0,0,0,0,0,0,0,0,0,0,0,35,0,0,0,0,0
0,0,0,0,0,0,0,0,0,0,36,35,36,0,0,0,0
0,0,0,0,0,0,0,0,0,0,0,36,0,0,0,0,0
0,0,0,0,0,0,0,0,0,0,0,0,0,0,0,0,0
0,0,0,0,0,0,0,0,0,0,0,0,0,0,0,0,0
0,0,0,0,0,0,0,0,0,0,0,0,0,0,0,0,0
0,0,0,15,14,14,17,0,0,0,0,0,0,0,0,0,0
0,0,0,15,44,43,17,0,0,0,0,0,0,0,0,0,0
0,0,0,15,44,42,17,0,0,0,0,0,0,0,0,0,0
0,0,0,15,44,42,17,0,0,0,0,0,0,0,0,0,0
0,0,0,15,44,42,17,0,0,0,0,0,0,0,0,0,0
0,0,0,15,44,42,17,14,14,14,14,14,0,0,0,0,0
0,0,0,15,44,42,43,43,43,43,42,17,0,0,0,0,0
0,0,0,15,44,45,45,45,45,45,45,17,0,0,0,0,0
0,0,0,16,16,16,16,16,16,16,16,17,0,0,0,0,0
0,0,0,0,4,4,0,0,0,0,0,0,0,0,0,0,0
0,0,0,0,4,4,0,0,0,0,0,0,0,0,0,0,0
endlayer

layer
0,0,0,0,0,0,0,0,0,0,0,0,0,0,0,0,0
0,0,0,0,0,0,0,0,0,0,0,0,0,0,0,0,0
0,0,0,0,0,0,0,0,0,0,0,0,0,0,0,0,0
0,0,0,0,0,0,0,0,0,0,0,0,0,0,0,0,0
0,0,0,0,0,0,0,0,0,0,0,0,0,0,0,0,0
0,0,0,0,0,0,0,0,0,0,0,0,0,0,0,0,0
0,0,0,0,0,0,0,0,0,0,0,0,0,0,0,0,0
0,0,0,0,0,0,0,0,0,0,0,0,0,0,0,0,0
0,0,0,0,0,0,0,0,0,0,0,0,0,0,0,0,0
0,0,0,0,14,14,0,0,0,0,0,0,0,0,0,0,0
0,0,0,0,15,17,0,0,0,0,0,0,0,0,0,0,0
0,0,0,0,15,17,0,0,0,0,0,0,0,0,0,0,0
0,0,0,0,15,17,0,0,0,0,0,0,0,0,0,0,0
0,0,0,0,15,17,0,0,0,0,0,0,0,0,0,0,0
0,0,0,0,15,17,14,14,14,14,17,0,0,0,0,0,0
0,0,0,0,16,16,16,16,16,16,17,0,0,0,0,0,0
0,0,0,0,0,0,0,0,0,0,0,0,0,0,0,0,0
0,0,0,0,4,4,0,0,0,0,0,0,0,0,0,0,0
0,0,0,0,4,4,0,0,0,0,0,0,0,0,0,0,0
endlayer

layer
0,0,0,0,0,0,0,0,0,0,0,0,0,0,0,0,0
0,0,0,0,0,0,0,0,0,0,0,0,0,0,0,0,0
0,0,0,0,0,0,0,0,0,0,0,0,0,0,0,0,0
0,0,0,0,0,0,0,0,0,0,0,0,0,0,0,0,0
0,0,0,0,0,0,0,0,0,0,0,0,0,0,0,0,0
0,0,0,0,0,0,0,0,0,0,0,0,0,0,0,0,0
0,0,0,0,0,0,0,0,0,0,0,0,0,0,0,0,0
0,0,0,0,0,0,0,0,0,0,0,0,0,0,0,0,0
0,0,0,0,0,0,0,0,0,0,0,0,0,0,0,0,0
0,0,0,0,0,0,0,0,0,0,0,0,0,0,0,0,0
0,0,0,0,0,0,0,0,0,0,0,0,0,0,0,0,0
0,0,0,0,0,0,0,0,0,0,0,0,0,0,0,0,0
0,0,0,0,0,0,0,0,0,0,0,0,0,0,0,0,0
0,0,0,0,0,0,0,0,0,0,0,0,0,0,0,0,0
0,0,0,0,0,0,0,0,0,0,0,0,0,0,0,0,0
0,0,0,0,0,0,0,0,0,0,0,0,0,0,0,0,0
0,0,0,0,0,0,0,0,0,0,0,0,0,0,0,0,0
0,0,0,0,47,39,0,0,0,0,0,0,0,0,0,0,0
0,0,0,0,49,48,0,0,0,0,0,0,0,0,0,0,0
endlayer

