
# Created by Ruins mod version 16.5 Ingame Parser
# authoring Player: ST753M

# Hot air balloon (swirling pattern) with a little treasure in the basket
# (some random food and a random enchanted book)

weight=1
embed_into_distance=-40
random_height_offset=-20,20
acceptable_target_blocks=water,sand,grass,gravel,end_stone
unacceptable_target_blocks=
dimensions=20,13,13
allowable_overhang=9999
max_cut_in=0
cut_in_buffer=0
max_leveling=0
leveling_buffer=-1
preserve_water=0
preserve_lava=0
uniqueMinDistance=2000

biomesToSpawnIn=beaches,white_beach,stone_beach,gravel_beach,beach,sky,void

rule1=0,100,minecraft:oak_stairs-3
^0,100,minecraft:spruce_stairs-3
^0,100,minecraft:birch_stairs-3
^0,100,minecraft:jungle_stairs-3
rule2^0,100,minecraft:oak_stairs-1
^0,100,minecraft:spruce_stairs-1
^0,100,minecraft:birch_stairs-1
^0,100,minecraft:jungle_stairs-1
rule3^0,100,minecraft:wooden_slab-0
^0,100,minecraft:wooden_slab-1
^0,100,minecraft:wooden_slab-2
^0,100,minecraft:wooden_slab-3
rule4^0,100,minecraft:oak_stairs-2
^0,100,minecraft:spruce_stairs-2
^0,100,minecraft:birch_stairs-2
^0,100,minecraft:jungle_stairs-2
rule5^0,100,minecraft:oak_stairs-0
^0,100,minecraft:spruce_stairs-0
^0,100,minecraft:birch_stairs-0
^0,100,minecraft:jungle_stairs-0
rule6^0,100,minecraft:fence-0
^0,100,minecraft:spruce_fence-0
^0,100,minecraft:birch_fence-0
^0,100,minecraft:jungle_fence-0

rule7=0,100,IInventory;minecraft:chest;minecraft:enchanted_book#{StoredEnchantments:[{lvl:1s,id:9s}]}#0#7+harvestcraft:coffeeconlecheitem#3#0#11+harvestcraft:zucchinifriesitem#4#0#23-4,IInventory;minecraft:chest;harvestcraft:strawberrysodaitem#3#0#12+harvestcraft:blueberrypancakesitem#4#0#14+minecraft:enchanted_book#{StoredEnchantments:[{lvl:1s,id:61s}]}#0#17-4,IInventory;minecraft:chest;minecraft:enchanted_book#{StoredEnchantments:[{lvl:3s,id:17s}]}#0#11+harvestcraft:pomegranatesmoothieitem#3#0#13+harvestcraft:zucchinifriesitem#4#0#26-4,IInventory;minecraft:chest;harvestcraft:raspberryicedteaitem#3#0#14+minecraft:enchanted_book#{StoredEnchantments:[{lvl:1s,id:49s}]}#0#19+harvestcraft:mushroomrisottoitem#4#0#20-4,IInventory;minecraft:chest;harvestcraft:peachcobbleritem#4#0#6+harvestcraft:strawberrymilkshakeitem#3#0#11+minecraft:enchanted_book#{StoredEnchantments:[{lvl:1s,id:20s}]}#0#22-4,IInventory;minecraft:chest;harvestcraft:chocolatemilkitem#3#0#11+harvestcraft:fishsandwichitem#4#0#23+minecraft:enchanted_book#{StoredEnchantments:[{lvl:1s,id:50s}]}#0#26-4,IInventory;minecraft:chest;harvestcraft:cherryjuiceitem#3#0#14+harvestcraft:hotdogitem#4#0#22+minecraft:enchanted_book#{StoredEnchantments:[{lvl:2s,id:61s}]}#0#25-4,IInventory;minecraft:chest;harvestcraft:colasodaitem#3#0#3+minecraft:enchanted_book#{StoredEnchantments:[{lvl:2s,id:16s}]}#0#17+harvestcraft:stuffedmushroomitem#4#0#23-4,IInventory;minecraft:chest;harvestcraft:lemonlimesodaitem#3#0#15+harvestcraft:pbandjitem#4#0#19+minecraft:enchanted_book#{StoredEnchantments:[{lvl:2s,id:3s}]}#0#21-4,IInventory;minecraft:chest;minecraft:enchanted_book#{StoredEnchantments:[{lvl:1s,id:35s}]}#0#2+harvestcraft:leafychickensandwichitem#4#0#13+harvestcraft:blueberrysmoothieitem#3#0#15-4,IInventory;minecraft:chest;minecraft:enchanted_book#{StoredEnchantments:[{lvl:2s,id:2s}]}#0#10+harvestcraft:starfruitjuiceitem#3#0#15+harvestcraft:leafyfishsandwichitem#4#0#21-4,IInventory;minecraft:chest;minecraft:enchanted_book#{StoredEnchantments:[{lvl:1s,id:21s}]}#0#9+harvestcraft:keylimepieitem#4#0#15+harvestcraft:energydrinkitem#3#0#21-4,IInventory;minecraft:chest;harvestcraft:pecanpieitem#4#0#11+harvestcraft:grapesodaitem#3#0#13+minecraft:enchanted_book#{StoredEnchantments:[{lvl:2s,id:8s}]}#0#25-4,IInventory;minecraft:chest;harvestcraft:fruitpunchitem#3#0#14+harvestcraft:gingerchickenitem#4#0#20+minecraft:enchanted_book#{StoredEnchantments:[{lvl:2s,id:34s}]}#0#22-4,IInventory;minecraft:chest;harvestcraft:chocolatesprinklecake#4#0#14+harvestcraft:coconutsmoothieitem#3#0#19+minecraft:enchanted_book#{StoredEnchantments:[{lvl:1s,id:6s}]}#0#25-4,IInventory;minecraft:chest;harvestcraft:grapefruitsodaitem#3#0#11+harvestcraft:beansandriceitem#4#0#14+minecraft:enchanted_book#{StoredEnchantments:[{lvl:2s,id:4s}]}#0#25-4,IInventory;minecraft:chest;minecraft:enchanted_book#{StoredEnchantments:[{lvl:5s,id:18s}]}#0#4+harvestcraft:espressoitem#3#0#11+harvestcraft:cherrypieitem#4#0#23-4,IInventory;minecraft:chest;harvestcraft:fishandchipsitem#4#0#2+harvestcraft:chaiteaitem#3#0#13+minecraft:enchanted_book#{StoredEnchantments:[{lvl:1s,id:5s}]}#0#24-4,IInventory;minecraft:chest;harvestcraft:fruitcrumbleitem#4#0#11+minecraft:enchanted_book#{StoredEnchantments:[{lvl:2s,id:2s}]}#0#21+harvestcraft:limesmoothieitem#3#0#24-4,IInventory;minecraft:chest;harvestcraft:chickensandwichitem#4#0#11+harvestcraft:applecideritem#3#0#14+minecraft:enchanted_book#{StoredEnchantments:[{lvl:3s,id:32s}]}#0#24-4,IInventory;minecraft:chest;minecraft:enchanted_book#{StoredEnchantments:[{lvl:2s,id:18s}]}#0#2+harvestcraft:eggplantparmitem#4#0#13+harvestcraft:pinacoladaitem#3#0#15-4

rule8=0,100,minecraft:wool-0
^0,100,minecraft:wool-3
^0,100,minecraft:wool-9
^0,100,minecraft:wool-8
rule9=0,100,minecraft:wool-1
^0,100,minecraft:wool-2
^0,100,minecraft:wool-4
^0,100,minecraft:wool-5
^0,100,minecraft:wool-6
^0,100,minecraft:wool-10
^0,100,minecraft:wool-11
^0,100,minecraft:wool-13
^0,100,minecraft:wool-14
rule10=0,100,minecraft:wool-0
^0,100,minecraft:wool-3
^0,100,minecraft:wool-9
^0,100,minecraft:wool-8
rule11=0,100,minecraft:wool-1
^0,100,minecraft:wool-2
^0,100,minecraft:wool-4
^0,100,minecraft:wool-5
^0,100,minecraft:wool-6
^0,100,minecraft:wool-10
^0,100,minecraft:wool-11
^0,100,minecraft:wool-13
^0,100,minecraft:wool-14

layer
0,0,0,0,0,0,0,0,0,0,0,0,0
0,0,0,0,0,0,0,0,0,0,0,0,0
0,0,0,0,0,0,0,0,0,0,0,0,0
0,0,0,0,0,0,0,0,0,0,0,0,0
0,0,0,0,0,0,0,0,0,0,0,0,0
0,0,0,0,0,2,2,1,0,0,0,0,0
0,0,0,0,0,4,3,1,0,0,0,0,0
0,0,0,0,0,4,5,5,0,0,0,0,0
0,0,0,0,0,0,0,0,0,0,0,0,0
0,0,0,0,0,0,0,0,0,0,0,0,0
0,0,0,0,0,0,0,0,0,0,0,0,0
0,0,0,0,0,0,0,0,0,0,0,0,0
0,0,0,0,0,0,0,0,0,0,0,0,0
endlayer

layer
0,0,0,0,0,0,0,0,0,0,0,0,0
0,0,0,0,0,0,0,0,0,0,0,0,0
0,0,0,0,0,0,0,0,0,0,0,0,0
0,0,0,0,0,0,0,0,0,0,0,0,0
0,0,0,0,0,0,0,0,0,0,0,0,0
0,0,0,0,0,6,6,6,0,0,0,0,0
0,0,0,0,0,6,7,6,0,0,0,0,0
0,0,0,0,0,6,6,6,0,0,0,0,0
0,0,0,0,0,0,0,0,0,0,0,0,0
0,0,0,0,0,0,0,0,0,0,0,0,0
0,0,0,0,0,0,0,0,0,0,0,0,0
0,0,0,0,0,0,0,0,0,0,0,0,0
0,0,0,0,0,0,0,0,0,0,0,0,0
endlayer

layer
0,0,0,0,0,0,0,0,0,0,0,0,0
0,0,0,0,0,0,0,0,0,0,0,0,0
0,0,0,0,0,0,0,0,0,0,0,0,0
0,0,0,0,0,0,0,0,0,0,0,0,0
0,0,0,0,0,0,0,0,0,0,0,0,0
0,0,0,0,0,6,0,6,0,0,0,0,0
0,0,0,0,0,0,0,0,0,0,0,0,0
0,0,0,0,0,6,0,6,0,0,0,0,0
0,0,0,0,0,0,0,0,0,0,0,0,0
0,0,0,0,0,0,0,0,0,0,0,0,0
0,0,0,0,0,0,0,0,0,0,0,0,0
0,0,0,0,0,0,0,0,0,0,0,0,0
0,0,0,0,0,0,0,0,0,0,0,0,0
endlayer

layer
0,0,0,0,0,0,0,0,0,0,0,0,0
0,0,0,0,0,0,0,0,0,0,0,0,0
0,0,0,0,0,0,0,0,0,0,0,0,0
0,0,0,0,0,0,0,0,0,0,0,0,0
0,0,0,0,0,0,0,0,0,0,0,0,0
0,0,0,0,0,6,0,6,0,0,0,0,0
0,0,0,0,0,0,0,0,0,0,0,0,0
0,0,0,0,0,6,0,6,0,0,0,0,0
0,0,0,0,0,0,0,0,0,0,0,0,0
0,0,0,0,0,0,0,0,0,0,0,0,0
0,0,0,0,0,0,0,0,0,0,0,0,0
0,0,0,0,0,0,0,0,0,0,0,0,0
0,0,0,0,0,0,0,0,0,0,0,0,0
endlayer

layer
0,0,0,0,0,0,0,0,0,0,0,0,0
0,0,0,0,0,0,0,0,0,0,0,0,0
0,0,0,0,0,0,0,0,0,0,0,0,0
0,0,0,0,0,0,0,0,0,0,0,0,0
0,0,0,0,0,0,0,0,0,0,0,0,0
0,0,0,0,0,10,9,8,0,0,0,0,0
0,0,0,0,0,11,0,11,0,0,0,0,0
0,0,0,0,0,8,9,10,0,0,0,0,0
0,0,0,0,0,0,0,0,0,0,0,0,0
0,0,0,0,0,0,0,0,0,0,0,0,0
0,0,0,0,0,0,0,0,0,0,0,0,0
0,0,0,0,0,0,0,0,0,0,0,0,0
0,0,0,0,0,0,0,0,0,0,0,0,0
endlayer

layer
0,0,0,0,0,0,0,0,0,0,0,0,0
0,0,0,0,0,0,0,0,0,0,0,0,0
0,0,0,0,0,0,0,0,0,0,0,0,0
0,0,0,0,0,0,0,0,0,0,0,0,0
0,0,0,0,0,9,9,8,0,0,0,0,0
0,0,0,0,10,0,0,0,11,0,0,0,0
0,0,0,0,11,0,0,0,11,0,0,0,0
0,0,0,0,11,0,0,0,10,0,0,0,0
0,0,0,0,0,8,9,9,0,0,0,0,0
0,0,0,0,0,0,0,0,0,0,0,0,0
0,0,0,0,0,0,0,0,0,0,0,0,0
0,0,0,0,0,0,0,0,0,0,0,0,0
0,0,0,0,0,0,0,0,0,0,0,0,0
endlayer

layer
0,0,0,0,0,0,0,0,0,0,0,0,0
0,0,0,0,0,0,0,0,0,0,0,0,0
0,0,0,0,0,0,0,0,0,0,0,0,0
0,0,0,0,0,9,8,8,0,0,0,0,0
0,0,0,0,9,0,0,0,11,0,0,0,0
0,0,0,10,0,0,0,0,0,11,0,0,0
0,0,0,10,0,0,0,0,0,10,0,0,0
0,0,0,11,0,0,0,0,0,10,0,0,0
0,0,0,0,11,0,0,0,9,0,0,0,0
0,0,0,0,0,8,8,9,0,0,0,0,0
0,0,0,0,0,0,0,0,0,0,0,0,0
0,0,0,0,0,0,0,0,0,0,0,0,0
0,0,0,0,0,0,0,0,0,0,0,0,0
endlayer

layer
0,0,0,0,0,0,0,0,0,0,0,0,0
0,0,0,0,0,0,0,0,0,0,0,0,0
0,0,0,0,0,8,8,8,0,0,0,0,0
0,0,0,0,9,0,0,0,11,0,0,0,0
0,0,0,9,0,0,0,0,0,11,0,0,0
0,0,10,0,0,0,0,0,0,0,10,0,0
0,0,10,0,0,0,0,0,0,0,10,0,0
0,0,10,0,0,0,0,0,0,0,10,0,0
0,0,0,11,0,0,0,0,0,9,0,0,0
0,0,0,0,11,0,0,0,9,0,0,0,0
0,0,0,0,0,8,8,8,0,0,0,0,0
0,0,0,0,0,0,0,0,0,0,0,0,0
0,0,0,0,0,0,0,0,0,0,0,0,0
endlayer

layer
0,0,0,0,0,0,0,0,0,0,0,0,0
0,0,0,0,0,0,8,0,0,0,0,0,0
0,0,0,0,8,8,0,8,11,0,0,0,0
0,0,0,9,0,0,0,0,0,11,0,0,0
0,0,9,0,0,0,0,0,0,0,10,0,0
0,0,10,0,0,0,0,0,0,0,10,0,0
0,10,0,0,0,0,0,0,0,0,0,10,0
0,0,10,0,0,0,0,0,0,0,10,0,0
0,0,10,0,0,0,0,0,0,0,9,0,0
0,0,0,11,0,0,0,0,0,9,0,0,0
0,0,0,0,11,8,0,8,8,0,0,0,0
0,0,0,0,0,0,8,0,0,0,0,0,0
0,0,0,0,0,0,0,0,0,0,0,0,0
endlayer

layer
0,0,0,0,0,0,0,0,0,0,0,0,0
0,0,0,0,0,8,8,11,0,0,0,0,0
0,0,0,8,8,0,0,0,11,11,0,0,0
0,0,9,0,0,0,0,0,0,0,10,0,0
0,0,9,0,0,0,0,0,0,0,10,0,0
0,9,0,0,0,0,0,0,0,0,0,10,0
0,10,0,0,0,0,0,0,0,0,0,10,0
0,10,0,0,0,0,0,0,0,0,0,9,0
0,0,10,0,0,0,0,0,0,0,9,0,0
0,0,10,0,0,0,0,0,0,0,9,0,0
0,0,0,11,11,0,0,0,8,8,0,0,0
0,0,0,0,0,11,8,8,0,0,0,0,0
0,0,0,0,0,0,0,0,0,0,0,0,0
endlayer

layer
0,0,0,0,0,0,11,0,0,0,0,0,0
0,0,0,0,8,8,0,11,11,0,0,0,0
0,0,8,8,0,0,0,0,0,10,10,0,0
0,0,8,0,0,0,0,0,0,0,10,0,0
0,9,0,0,0,0,0,0,0,0,0,10,0
0,9,0,0,0,0,0,0,0,0,0,10,0
9,0,0,0,0,0,0,0,0,0,0,0,9
0,10,0,0,0,0,0,0,0,0,0,9,0
0,10,0,0,0,0,0,0,0,0,0,9,0
0,0,10,0,0,0,0,0,0,0,8,0,0
0,0,10,10,0,0,0,0,0,8,8,0,0
0,0,0,0,11,11,0,8,8,0,0,0,0
0,0,0,0,0,0,11,0,0,0,0,0,0
endlayer

layer
0,0,0,0,0,11,11,11,0,0,0,0,0
0,0,0,8,8,0,0,0,10,10,0,0,0
0,0,8,0,0,0,0,0,0,0,10,0,0
0,8,0,0,0,0,0,0,0,0,0,10,0
0,8,0,0,0,0,0,0,0,0,0,10,0
9,0,0,0,0,0,0,0,0,0,0,0,9
9,0,0,0,0,0,0,0,0,0,0,0,9
9,0,0,0,0,0,0,0,0,0,0,0,9
0,10,0,0,0,0,0,0,0,0,0,8,0
0,10,0,0,0,0,0,0,0,0,0,8,0
0,0,10,0,0,0,0,0,0,0,8,0,0
0,0,0,10,10,0,0,0,8,8,0,0,0
0,0,0,0,0,11,11,11,0,0,0,0,0
endlayer

layer
0,0,0,0,11,11,11,11,10,0,0,0,0
0,0,8,11,0,0,0,0,0,10,10,0,0
0,8,0,0,0,0,0,0,0,0,0,10,0
0,8,0,0,0,0,0,0,0,0,0,9,0
8,0,0,0,0,0,0,0,0,0,0,0,9
9,0,0,0,0,0,0,0,0,0,0,0,9
9,0,0,0,0,0,0,0,0,0,0,0,9
9,0,0,0,0,0,0,0,0,0,0,0,9
9,0,0,0,0,0,0,0,0,0,0,0,8
0,9,0,0,0,0,0,0,0,0,0,8,0
0,10,0,0,0,0,0,0,0,0,0,8,0
0,0,10,10,0,0,0,0,0,11,8,0,0
0,0,0,0,10,11,11,11,11,0,0,0,0
endlayer

layer
0,0,0,0,11,11,11,10,10,0,0,0,0
0,0,11,11,0,0,0,0,0,10,10,0,0
0,8,0,0,0,0,0,0,0,0,0,9,0
0,8,0,0,0,0,0,0,0,0,0,9,0
8,0,0,0,0,0,0,0,0,0,0,0,9
8,0,0,0,0,0,0,0,0,0,0,0,9
9,0,0,0,0,0,0,0,0,0,0,0,9
9,0,0,0,0,0,0,0,0,0,0,0,8
9,0,0,0,0,0,0,0,0,0,0,0,8
0,9,0,0,0,0,0,0,0,0,0,8,0
0,9,0,0,0,0,0,0,0,0,0,8,0
0,0,10,10,0,0,0,0,0,11,11,0,0
0,0,0,0,10,10,11,11,11,0,0,0,0
endlayer

layer
0,0,0,0,11,11,10,10,10,0,0,0,0
0,0,11,11,0,0,0,0,0,10,9,0,0
0,8,0,0,0,0,0,0,0,0,0,9,0
0,8,0,0,0,0,0,0,0,0,0,9,0
8,0,0,0,0,0,0,0,0,0,0,0,9
8,0,0,0,0,0,0,0,0,0,0,0,9
8,0,0,0,0,0,0,0,0,0,0,0,8
9,0,0,0,0,0,0,0,0,0,0,0,8
9,0,0,0,0,0,0,0,0,0,0,0,8
0,9,0,0,0,0,0,0,0,0,0,8,0
0,9,0,0,0,0,0,0,0,0,0,11,0
0,0,9,10,0,0,0,0,0,11,11,0,0
0,0,0,0,10,10,10,11,11,0,0,0,0
endlayer

layer
0,0,0,0,0,10,10,10,0,0,0,0,0
0,0,0,11,11,0,0,0,10,9,0,0,0
0,0,11,0,0,0,0,0,0,0,9,0,0
0,8,0,0,0,0,0,0,0,0,0,9,0
0,8,0,0,0,0,0,0,0,0,0,9,0
8,0,0,0,0,0,0,0,0,0,0,0,8
8,0,0,0,0,0,0,0,0,0,0,0,8
8,0,0,0,0,0,0,0,0,0,0,0,8
0,9,0,0,0,0,0,0,0,0,0,8,0
0,9,0,0,0,0,0,0,0,0,0,11,0
0,0,9,0,0,0,0,0,0,0,11,0,0
0,0,0,9,10,0,0,0,11,11,0,0,0
0,0,0,0,0,10,10,10,0,0,0,0,0
endlayer

layer
0,0,0,0,0,0,0,0,0,0,0,0,0
0,0,0,0,10,10,10,10,9,0,0,0,0
0,0,11,11,0,0,0,0,0,9,9,0,0
0,0,11,0,0,0,0,0,0,0,9,0,0
0,8,0,0,0,0,0,0,0,0,0,8,0
0,8,0,0,0,0,0,0,0,0,0,8,0
0,8,0,0,0,0,0,0,0,0,0,8,0
0,8,0,0,0,0,0,0,0,0,0,8,0
0,8,0,0,0,0,0,0,0,0,0,11,0
0,0,9,0,0,0,0,0,0,0,11,0,0
0,0,9,9,0,0,0,0,0,11,11,0,0
0,0,0,0,9,10,10,10,10,0,0,0,0
0,0,0,0,0,0,0,0,0,0,0,0,0
endlayer

layer
0,0,0,0,0,0,0,0,0,0,0,0,0
0,0,0,0,0,10,10,9,0,0,0,0,0
0,0,0,10,10,0,0,0,9,9,0,0,0
0,0,11,10,0,0,0,0,0,8,8,0,0
0,0,11,0,0,0,0,0,0,0,8,0,0
0,8,0,0,0,0,0,0,0,0,0,8,0
0,8,0,0,0,0,0,0,0,0,0,8,0
0,8,0,0,0,0,0,0,0,0,0,11,0
0,0,8,0,0,0,0,0,0,0,11,0,0
0,0,8,8,0,0,0,0,0,10,11,0,0
0,0,0,9,9,0,0,0,10,10,0,0,0
0,0,0,0,0,9,10,10,0,0,0,0,0
0,0,0,0,0,0,0,0,0,0,0,0,0
endlayer

layer
0,0,0,0,0,0,0,0,0,0,0,0,0
0,0,0,0,0,0,0,0,0,0,0,0,0
0,0,0,0,0,10,9,9,0,0,0,0,0
0,0,0,0,10,10,9,9,8,0,0,0,0
0,0,0,10,10,0,0,0,8,8,0,0,0
0,0,11,11,0,0,0,0,0,8,8,0,0
0,0,11,11,0,0,0,0,0,11,11,0,0
0,0,8,8,0,0,0,0,0,11,11,0,0
0,0,0,8,8,0,0,0,10,10,0,0,0
0,0,0,0,8,9,9,10,10,0,0,0,0
0,0,0,0,0,9,9,10,0,0,0,0,0
0,0,0,0,0,0,0,0,0,0,0,0,0
0,0,0,0,0,0,0,0,0,0,0,0,0
endlayer

layer
0,0,0,0,0,0,0,0,0,0,0,0,0
0,0,0,0,0,0,0,0,0,0,0,0,0
0,0,0,0,0,0,0,0,0,0,0,0,0
0,0,0,0,0,0,0,0,0,0,0,0,0
0,0,0,0,0,9,8,8,0,0,0,0,0
0,0,0,0,10,9,8,11,11,0,0,0,0
0,0,0,0,10,10,10,10,10,0,0,0,0
0,0,0,0,11,11,8,9,10,0,0,0,0
0,0,0,0,0,8,8,9,0,0,0,0,0
0,0,0,0,0,0,0,0,0,0,0,0,0
0,0,0,0,0,0,0,0,0,0,0,0,0
0,0,0,0,0,0,0,0,0,0,0,0,0
0,0,0,0,0,0,0,0,0,0,0,0,0
endlayer

