
# Created by Ruins mod version 16.8 Ingame Parser
# authoring Player: ST753M

weight=1
uniqueMinDistance=1200
embed_into_distance=5
acceptable_target_blocks=sand,water,grass
unacceptable_target_blocks=
dimensions=16,12,10
allowable_overhang=99
max_leveling=0
leveling_buffer=-1
preserve_water=0
preserve_lava=0

biomesToSpawnIn=beaches,beach,gravel_beach,white_beach

=0,100,air
rule1=0,100,preserveBlock
rule2=0,100,minecraft:log2-0
rule3=0,100,minecraft:sandstone-0
rule4=0,100,minecraft:sandstone_stairs-0
rule5=0,100,minecraft:sandstone_stairs-5
rule6=0,100,minecraft:log2-8
rule7=0,100,minecraft:log2-4
rule8=0,100,minecraft:sandstone_stairs-4
rule9=0,100,minecraft:sandstone_stairs-7
rule10=0,100,minecraft:sandstone_stairs-6
rule11=0,100,minecraft:acacia_stairs-1
rule12=0,100,minecraft:acacia_stairs-3
rule13=0,100,minecraft:acacia_fence-0
rule14=0,100,minecraft:acacia_stairs-2
rule15=0,100,minecraft:acacia_stairs-0
rule16=0,100,minecraft:planks-4
rule17=0,100,minecraft:wooden_slab-12
rule18=0,100,minecraft:acacia_fence_gate-3
rule19=0,100,CommandBlock:RUINSTRIGGER /summon villager ~ ~1 ~ {Profession:4,Offers:{Recipes:[{rewardExp:0b,maxUses:2147483647,uses:0,buy:{id:"minecraft:emerald",Count:1b},sell:{id:"harvestcraft:crabcookeditem",Count:2b}},{rewardExp:0b,maxUses:2147483647,uses:0,buy:{id:"minecraft:emerald",Count:2b},sell:{id:"harvestcraft:coconutshrimpitem",Count:1b}},{rewardExp:0b,maxUses:2147483647,uses:0,buy:{id:"minecraft:fish",Count:16b},sell:{id:"minecraft:emerald",Count:1b}},{rewardExp:0b,maxUses:2147483647,uses:0,buy:{id:"harvestcraft:crabrawitem",Count:16b},sell:{id:"minecraft:emerald",Count:1b}}]}}:@-1
rule20=0,100,minecraft:crafting_table-0
rule21=0,100,minecraft:cauldron-3
rule22=0,100,IInventory;minecraft:chest;harvestcraft:butteritem#4#0#3+harvestcraft:fishtrapbaititem#2#0#9+minecraft:cod#3#0#16+harvestcraft:fishtrapbaititem#4#0#19+harvestcraft:octopusrawitem#1#0#24-4
rule23=0,100,minecraft:furnace-4
rule24=0,100,minecraft:wooden_pressure_plate-0
rule25=2,100,WallSign:null:null:null:null-4
rule26=0,100,minecraft:glass_pane-0
rule27=0,100,minecraft:sandstone_stairs-1
rule28=0,100,minecraft:acacia_stairs-7
rule29=0,100,minecraft:acacia_stairs-6
rule30=2,100,minecraft:torch-1
rule31=0,100,minecraft:wooden_slab-4
rule32=0,100,minecraft:double_wooden_slab-4

layer
1,1,1,1,1,1,1,1,1,1
1,2,1,1,1,1,1,1,2,1
1,1,1,1,1,1,1,1,1,1
1,1,1,1,1,1,1,1,1,1
1,1,1,1,1,1,1,1,1,1
1,1,1,1,1,1,1,1,1,1
1,1,1,1,1,1,1,1,1,1
1,1,1,1,1,1,1,1,1,1
1,1,1,1,1,1,1,1,1,1
1,1,1,1,1,1,1,1,1,1
1,2,1,1,1,1,1,1,2,1
1,1,1,1,1,1,1,1,1,1
endlayer

layer
1,1,1,1,1,1,1,1,1,1
1,2,1,1,1,1,1,1,2,1
1,1,1,1,1,1,1,1,1,1
1,1,1,1,1,1,1,1,1,1
1,1,1,1,1,1,1,1,1,1
1,1,1,1,1,1,1,1,1,1
1,1,1,1,1,1,1,1,1,1
1,1,1,1,1,1,1,1,1,1
1,1,1,1,1,1,1,1,1,1
1,1,1,1,1,1,1,1,1,1
1,2,1,1,1,1,1,1,2,1
1,1,1,1,1,1,1,1,1,1
endlayer

layer
1,1,1,1,1,1,1,1,1,1
1,2,1,1,1,1,1,1,2,1
1,1,1,1,1,1,1,1,1,1
1,1,1,1,1,1,1,1,1,1
1,1,1,1,1,1,1,1,1,1
1,1,1,1,1,1,1,1,1,1
1,1,1,1,1,1,1,1,1,1
1,1,1,1,1,1,1,1,1,1
1,1,1,1,1,1,1,1,1,1
1,1,1,1,1,1,1,1,1,1
1,2,1,1,1,1,1,1,2,1
1,1,1,1,1,1,1,1,1,1
endlayer

layer
1,1,1,1,1,1,1,1,1,1
1,2,1,1,1,1,1,1,2,1
1,1,1,1,1,1,1,1,1,1
1,1,1,1,1,1,1,1,1,1
1,1,1,1,1,1,1,1,1,1
1,1,1,1,1,1,1,1,1,1
1,1,1,1,1,1,1,1,1,1
1,1,1,1,1,1,1,1,1,1
1,1,1,1,1,1,1,1,1,1
1,1,1,1,1,1,1,1,1,1
1,2,1,1,1,1,1,1,2,1
1,1,1,1,1,1,1,1,1,1
endlayer

layer
1,1,1,1,1,1,1,3,3,3
1,2,1,1,1,1,1,3,2,3
1,1,1,1,1,1,1,3,3,3
1,1,1,1,1,1,1,1,1,1
1,1,1,1,1,1,1,1,1,1
1,1,1,1,1,1,1,1,1,1
1,1,1,1,1,1,1,1,1,1
1,1,1,1,1,1,1,1,1,1
1,1,1,1,1,1,1,1,1,1
1,1,1,1,1,1,1,1,1,1
1,2,1,1,1,1,1,1,2,1
1,1,1,1,1,1,1,1,1,1
endlayer

layer
1,1,1,1,1,1,1,1,1,1
1,2,1,1,1,1,1,1,2,4
1,1,1,1,1,1,1,1,0,5
1,1,1,1,1,1,1,1,1,1
1,1,1,1,1,1,1,1,1,1
1,1,1,1,1,1,1,1,1,1
1,1,1,1,1,1,1,1,1,1
1,1,1,1,1,1,1,1,1,1
1,1,1,1,1,1,1,1,1,1
1,1,1,1,1,1,1,1,1,1
1,2,1,1,1,1,1,1,2,1
1,1,1,1,1,1,1,1,1,1
endlayer

layer
1,1,1,1,1,1,1,1,1,1
1,2,1,1,1,1,1,1,2,1
1,1,1,1,1,1,1,1,0,4
1,1,1,1,1,1,1,1,1,5
1,1,1,1,1,1,1,1,1,1
1,1,1,1,1,1,1,1,1,1
1,1,1,1,1,1,1,1,1,1
1,1,1,1,1,1,1,1,1,1
1,1,1,1,1,1,1,1,1,1
1,1,1,1,1,1,1,1,1,1
1,2,1,1,1,1,1,1,2,1
1,1,1,1,1,1,1,1,1,1
endlayer

layer
1,1,1,1,1,1,1,1,1,1
1,2,6,6,6,6,6,6,2,1
1,7,0,0,0,0,0,0,7,1
1,7,0,0,0,0,0,0,7,4
1,7,0,0,0,0,0,0,7,5
1,7,0,0,0,0,0,0,7,1
1,7,0,0,0,0,0,0,7,1
1,7,0,0,0,0,0,0,7,1
1,7,0,0,0,0,0,0,7,1
1,7,0,0,0,0,0,0,7,1
1,2,6,6,6,6,6,6,2,1
1,1,1,1,1,1,1,1,1,1
endlayer

layer
9,8,8,8,8,8,8,8,8,1
9,3,3,3,3,3,3,3,9,1
9,3,3,3,3,3,3,3,9,1
9,3,3,3,3,3,3,3,9,1
9,3,3,3,3,3,3,3,9,4
9,2,3,3,3,3,3,3,2,10
9,3,3,3,3,3,3,3,3,10
9,3,3,3,3,3,3,3,3,10
9,3,3,3,3,3,3,3,3,10
9,3,3,3,3,3,3,3,3,10
9,2,3,3,3,3,3,3,2,10
9,5,5,5,5,5,5,5,5,5
endlayer

layer
0,0,0,0,0,0,0,0,0,1
0,0,11,0,0,0,11,0,0,1
0,14,13,12,0,14,13,12,0,1
0,0,15,0,0,0,15,0,0,1
0,0,0,0,0,0,0,0,0,1
1,2,16,18,16,17,17,16,2,1
1,3,0,0,0,0,0,0,3,1
1,3,0,0,0,19,0,0,3,1
1,3,0,0,0,0,0,0,3,1
1,3,23,22,21,21,21,20,3,1
1,2,3,3,3,3,3,3,2,1
1,1,1,1,1,1,1,1,1,1
endlayer

layer
0,0,0,0,0,0,0,0,0,1
0,0,0,0,0,0,0,0,0,1
0,0,24,0,0,0,24,0,0,0
0,0,0,0,0,0,0,0,0,0
0,0,0,0,0,0,0,0,0,1
1,2,0,0,0,0,0,0,2,1
1,3,0,0,0,0,0,0,3,1
1,3,0,0,0,0,0,0,3,1
1,3,0,0,0,0,0,0,3,1
1,3,0,0,0,0,0,0,3,1
1,2,3,3,3,3,3,3,2,1
1,1,1,1,1,1,1,1,1,1
endlayer

layer
0,0,0,0,0,0,0,0,0,1
0,0,0,0,0,0,0,0,0,0
0,0,0,0,0,0,0,0,0,0
0,0,0,0,0,0,0,0,0,0
0,8,25,25,25,25,25,25,8,1
1,2,17,17,17,17,17,17,2,1
1,3,0,0,0,0,0,0,3,1
1,26,0,0,0,0,0,0,26,1
1,26,0,0,0,0,0,0,26,1
1,3,0,25,25,0,0,0,3,1
1,2,3,3,3,3,3,3,2,1
1,1,1,1,1,1,1,1,1,1
endlayer

layer
0,0,0,0,0,0,0,0,0,1
0,0,0,0,0,0,0,0,0,0
0,0,0,0,0,0,0,0,0,0
1,8,0,0,0,0,0,0,8,1
1,27,0,0,0,0,0,0,27,1
1,2,16,16,29,17,17,28,2,1
1,3,0,30,0,0,0,0,3,1
1,3,0,0,0,0,0,0,3,1
1,3,0,0,0,0,0,0,3,1
1,3,0,0,0,25,25,0,3,1
1,2,3,3,3,3,3,3,2,1
1,1,1,1,1,1,1,1,1,1
endlayer

layer
0,0,0,0,0,0,0,0,0,0
0,0,0,0,0,0,0,0,0,0
31,31,31,31,31,31,31,31,31,31
31,31,31,31,31,31,31,31,31,31
16,16,16,16,16,16,16,16,16,16
16,16,16,16,16,16,16,16,16,16
17,3,0,0,0,0,0,0,3,17
17,3,0,0,0,0,0,0,3,17
0,3,0,0,0,0,0,0,3,0
0,3,0,0,0,0,0,0,3,0
0,2,3,3,3,3,3,3,2,0
0,0,0,0,0,0,0,0,0,0
endlayer

layer
0,0,0,0,0,0,0,0,0,0
0,0,0,0,0,0,0,0,0,0
0,0,0,0,0,0,0,0,0,0
0,0,0,0,0,0,0,0,0,0
0,0,0,0,0,0,0,0,0,0
0,0,0,0,0,0,0,0,0,0
31,31,31,31,31,31,31,31,31,31
31,31,31,31,31,31,31,31,31,31
32,16,16,16,16,16,16,16,16,32
32,16,16,16,16,16,16,16,16,32
17,2,3,3,3,3,3,3,2,17
17,17,17,17,17,17,17,17,17,17
endlayer

layer
0,0,0,0,0,0,0,0,0,0
0,0,0,0,0,0,0,0,0,0
0,0,0,0,0,0,0,0,0,0
0,0,0,0,0,0,0,0,0,0
0,0,0,0,0,0,0,0,0,0
0,0,0,0,0,0,0,0,0,0
0,0,0,0,0,0,0,0,0,0
0,0,0,0,0,0,0,0,0,0
0,0,0,0,0,0,0,0,0,0
0,0,0,0,0,0,0,0,0,0
31,31,31,31,31,31,31,31,31,31
31,31,31,31,31,31,31,31,31,31
endlayer

