
# Created by Ruins mod version 16.5 Ingame Parser
# authoring Player: ST753M

# Hot air balloon (vertical rainbow pattern) with a treasure in the basket
# (specifically a random tool, some candles, and a boat)

weight=1
embed_into_distance=-40
random_height_offset=-20,20
acceptable_target_blocks=water,sand,grass,gravel,end_stone
unacceptable_target_blocks=
dimensions=20,13,13
allowable_overhang=9999
max_cut_in=0
cut_in_buffer=0
max_leveling=0
leveling_buffer=-1
preserve_water=0
preserve_lava=0
uniqueMinDistance=1500

biomesToSpawnIn=beaches,white_beach,stone_beach,gravel_beach,beach,sky,void

rule1=0,100,minecraft:oak_stairs-3
^0,100,minecraft:spruce_stairs-3
^0,100,minecraft:birch_stairs-3
^0,100,minecraft:jungle_stairs-3
rule2^0,100,minecraft:oak_stairs-1
^0,100,minecraft:spruce_stairs-1
^0,100,minecraft:birch_stairs-1
^0,100,minecraft:jungle_stairs-1
rule3^0,100,minecraft:wooden_slab-0
^0,100,minecraft:wooden_slab-1
^0,100,minecraft:wooden_slab-2
^0,100,minecraft:wooden_slab-3
rule4^0,100,minecraft:oak_stairs-2
^0,100,minecraft:spruce_stairs-2
^0,100,minecraft:birch_stairs-2
^0,100,minecraft:jungle_stairs-2
rule5^0,100,minecraft:oak_stairs-0
^0,100,minecraft:spruce_stairs-0
^0,100,minecraft:birch_stairs-0
^0,100,minecraft:jungle_stairs-0
rule6^0,100,minecraft:fence-0
^0,100,minecraft:spruce_fence-0
^0,100,minecraft:birch_fence-0
^0,100,minecraft:jungle_fence-0

rule7=0,100,IInventory;minecraft:chest;minecraft:boat#1#0#4+minecraft:iron_sword#{"Quark:RuneColor":5,ench:[{lvl:3s,id:34s},{lvl:3s,id:16s}],RepairCost:3,"Quark:ItemNameDye":10,display:{Name:"Lime Sword"},"Quark:RuneAttached":1b}#0#10+quark:candle#17#5#24-3,IInventory;minecraft:chest;minecraft:iron_pickaxe#{"Quark:RuneColor":4,ench:[{lvl:3s,id:34s},{lvl:3s,id:32s}],RepairCost:3,"Quark:ItemNameDye":11,display:{Name:"Yellow Pickaxe"},"Quark:RuneAttached":1b}#0#12+minecraft:boat#1#0#16+quark:candle#14#4#23-3,IInventory;minecraft:chest;minecraft:dark_oak_boat#1#0#7+minecraft:iron_axe#{"Quark:RuneColor":12,ench:[{lvl:3s,id:34s},{lvl:3s,id:32s}],RepairCost:3,"Quark:ItemNameDye":3,display:{Name:"Brown Axe"},"Quark:RuneAttached":1b}#0#20+quark:candle#19#12#24-3,IInventory;minecraft:chest;minecraft:spruce_boat#1#0#10+minecraft:iron_shovel#{"Quark:RuneColor":3,ench:[{lvl:3s,id:34s},{lvl:3s,id:32s}],RepairCost:3,"Quark:ItemNameDye":12,display:{Name:"Sky Shovel"},"Quark:RuneAttached":1b}#0#13+quark:candle#19#3#24-3,IInventory;minecraft:chest;minecraft:iron_pickaxe#{"Quark:RuneColor":13,ench:[{lvl:3s,id:34s},{lvl:3s,id:32s}],RepairCost:3,"Quark:ItemNameDye":2,display:{Name:"Green Pickaxe"},"Quark:RuneAttached":1b}#0#4+minecraft:birch_boat#1#0#12+quark:candle#17#13#16-3,IInventory;minecraft:chest;minecraft:iron_sword#{"Quark:RuneColor":1,ench:[{lvl:3s,id:34s},{lvl:3s,id:16s}],RepairCost:3,"Quark:ItemNameDye":14,display:{Name:"Orange Sword"},"Quark:RuneAttached":1b}#0#4+minecraft:spruce_boat#1#0#11+quark:candle#20#1#22-3,IInventory;minecraft:chest;minecraft:boat#1#0#11+minecraft:iron_pickaxe#{"Quark:RuneColor":14,ench:[{lvl:3s,id:34s},{lvl:3s,id:32s}],RepairCost:3,"Quark:ItemNameDye":1,display:{Name:"Red Pickaxe"},"Quark:RuneAttached":1b}#0#13+quark:candle#19#14#24-3,IInventory;minecraft:chest;minecraft:dark_oak_boat#1#0#5+minecraft:iron_sword#{"Quark:RuneColor":10,ench:[{lvl:3s,id:34s},{lvl:3s,id:16s}],RepairCost:3,"Quark:ItemNameDye":5,display:{Name:"Purple Sword"},"Quark:RuneAttached":1b}#0#11+quark:candle#16#10#22-3,IInventory;minecraft:chest;minecraft:birch_boat#1#0#14+minecraft:iron_shovel#{"Quark:RuneColor":0,ench:[{lvl:3s,id:34s},{lvl:3s,id:32s}],RepairCost:3,"Quark:ItemNameDye":15,display:{Name:"White Shovel"},"Quark:RuneAttached":1b}#0#21+quark:candle#16#0#25-3,IInventory;minecraft:chest;minecraft:jungle_boat#1#0#2+quark:candle#17#2#12+minecraft:iron_sword#{"Quark:RuneColor":2,ench:[{lvl:3s,id:34s},{lvl:3s,id:16s}],RepairCost:3,"Quark:ItemNameDye":13,display:{Name:"Magenta Sword"},"Quark:RuneAttached":1b}#0#15-3,IInventory;minecraft:chest;minecraft:boat#1#0#1+minecraft:iron_axe#{"Quark:RuneColor":7,ench:[{lvl:3s,id:34s},{lvl:3s,id:32s}],RepairCost:3,"Quark:ItemNameDye":8,display:{Name:"Gray Axe"},"Quark:RuneAttached":1b}#0#13+quark:candle#16#7#25-3,IInventory;minecraft:chest;minecraft:iron_pickaxe#{"Quark:RuneColor":11,ench:[{lvl:3s,id:34s},{lvl:3s,id:32s}],RepairCost:3,"Quark:ItemNameDye":4,display:{Name:"Blue Pickaxe"},"Quark:RuneAttached":1b}#0#5+quark:candle#17#11#11+minecraft:jungle_boat#1#0#24-3,IInventory;minecraft:chest;minecraft:spruce_boat#1#0#5+minecraft:iron_axe#{"Quark:RuneColor":8,ench:[{lvl:3s,id:34s},{lvl:3s,id:32s}],RepairCost:3,"Quark:ItemNameDye":7,display:{Name:"Light Gray Axe"},"Quark:RuneAttached":1b}#0#12+quark:candle#19#8#24-3,IInventory;minecraft:chest;minecraft:jungle_boat#1#0#3+minecraft:iron_shovel#{"Quark:RuneColor":6,ench:[{lvl:3s,id:34s},{lvl:3s,id:32s}],RepairCost:3,"Quark:ItemNameDye":9,display:{Name:"Pink Shovel"},"Quark:RuneAttached":1b}#0#14+quark:candle#20#6#25-3,IInventory;minecraft:chest;minecraft:spruce_boat#1#0#11+minecraft:iron_axe#{"Quark:RuneColor":9,ench:[{lvl:3s,id:34s},{lvl:3s,id:32s}],RepairCost:3,"Quark:ItemNameDye":6,display:{Name:"Cyan Axe"},"Quark:RuneAttached":1b}#0#14+quark:candle#17#9#25-3,IInventory;minecraft:chest;minecraft:iron_shovel#{"Quark:RuneColor":15,ench:[{lvl:3s,id:34s},{lvl:3s,id:32s}],RepairCost:3,"Quark:ItemNameDye":0,display:{Name:"Black Shovel"},"Quark:RuneAttached":1b}#0#2+quark:candle#19#15#14+minecraft:dark_oak_boat#1#0#21-3

rule8=0,100,minecraft:wool-14
rule9=0,100,minecraft:wool-1
rule10=0,100,minecraft:wool-4
rule11=0,100,minecraft:wool-2
rule12=0,100,minecraft:wool-5
rule13=0,100,minecraft:wool-10
rule14=0,100,minecraft:wool-3
rule15=0,100,minecraft:wool-9

layer
0,0,0,0,0,0,0,0,0,0,0,0,0
0,0,0,0,0,0,0,0,0,0,0,0,0
0,0,0,0,0,0,0,0,0,0,0,0,0
0,0,0,0,0,0,0,0,0,0,0,0,0
0,0,0,0,0,0,0,0,0,0,0,0,0
0,0,0,0,0,2,2,1,0,0,0,0,0
0,0,0,0,0,4,3,1,0,0,0,0,0
0,0,0,0,0,4,5,5,0,0,0,0,0
0,0,0,0,0,0,0,0,0,0,0,0,0
0,0,0,0,0,0,0,0,0,0,0,0,0
0,0,0,0,0,0,0,0,0,0,0,0,0
0,0,0,0,0,0,0,0,0,0,0,0,0
0,0,0,0,0,0,0,0,0,0,0,0,0
endlayer

layer
0,0,0,0,0,0,0,0,0,0,0,0,0
0,0,0,0,0,0,0,0,0,0,0,0,0
0,0,0,0,0,0,0,0,0,0,0,0,0
0,0,0,0,0,0,0,0,0,0,0,0,0
0,0,0,0,0,0,0,0,0,0,0,0,0
0,0,0,0,0,6,6,6,0,0,0,0,0
0,0,0,0,0,6,7,6,0,0,0,0,0
0,0,0,0,0,6,6,6,0,0,0,0,0
0,0,0,0,0,0,0,0,0,0,0,0,0
0,0,0,0,0,0,0,0,0,0,0,0,0
0,0,0,0,0,0,0,0,0,0,0,0,0
0,0,0,0,0,0,0,0,0,0,0,0,0
0,0,0,0,0,0,0,0,0,0,0,0,0
endlayer

layer
0,0,0,0,0,0,0,0,0,0,0,0,0
0,0,0,0,0,0,0,0,0,0,0,0,0
0,0,0,0,0,0,0,0,0,0,0,0,0
0,0,0,0,0,0,0,0,0,0,0,0,0
0,0,0,0,0,0,0,0,0,0,0,0,0
0,0,0,0,0,6,0,6,0,0,0,0,0
0,0,0,0,0,0,0,0,0,0,0,0,0
0,0,0,0,0,6,0,6,0,0,0,0,0
0,0,0,0,0,0,0,0,0,0,0,0,0
0,0,0,0,0,0,0,0,0,0,0,0,0
0,0,0,0,0,0,0,0,0,0,0,0,0
0,0,0,0,0,0,0,0,0,0,0,0,0
0,0,0,0,0,0,0,0,0,0,0,0,0
endlayer

layer
0,0,0,0,0,0,0,0,0,0,0,0,0
0,0,0,0,0,0,0,0,0,0,0,0,0
0,0,0,0,0,0,0,0,0,0,0,0,0
0,0,0,0,0,0,0,0,0,0,0,0,0
0,0,0,0,0,0,0,0,0,0,0,0,0
0,0,0,0,0,6,0,6,0,0,0,0,0
0,0,0,0,0,0,0,0,0,0,0,0,0
0,0,0,0,0,6,0,6,0,0,0,0,0
0,0,0,0,0,0,0,0,0,0,0,0,0
0,0,0,0,0,0,0,0,0,0,0,0,0
0,0,0,0,0,0,0,0,0,0,0,0,0
0,0,0,0,0,0,0,0,0,0,0,0,0
0,0,0,0,0,0,0,0,0,0,0,0,0
endlayer

layer
0,0,0,0,0,0,0,0,0,0,0,0,0
0,0,0,0,0,0,0,0,0,0,0,0,0
0,0,0,0,0,0,0,0,0,0,0,0,0
0,0,0,0,0,0,0,0,0,0,0,0,0
0,0,0,0,0,0,0,0,0,0,0,0,0
0,0,0,0,0,10,9,8,0,0,0,0,0
0,0,0,0,0,12,0,11,0,0,0,0,0
0,0,0,0,0,15,14,13,0,0,0,0,0
0,0,0,0,0,0,0,0,0,0,0,0,0
0,0,0,0,0,0,0,0,0,0,0,0,0
0,0,0,0,0,0,0,0,0,0,0,0,0
0,0,0,0,0,0,0,0,0,0,0,0,0
0,0,0,0,0,0,0,0,0,0,0,0,0
endlayer

layer
0,0,0,0,0,0,0,0,0,0,0,0,0
0,0,0,0,0,0,0,0,0,0,0,0,0
0,0,0,0,0,0,0,0,0,0,0,0,0
0,0,0,0,0,0,0,0,0,0,0,0,0
0,0,0,0,0,10,9,9,0,0,0,0,0
0,0,0,0,12,0,0,0,8,0,0,0,0
0,0,0,0,12,0,0,0,11,0,0,0,0
0,0,0,0,15,0,0,0,11,0,0,0,0
0,0,0,0,0,14,14,13,0,0,0,0,0
0,0,0,0,0,0,0,0,0,0,0,0,0
0,0,0,0,0,0,0,0,0,0,0,0,0
0,0,0,0,0,0,0,0,0,0,0,0,0
0,0,0,0,0,0,0,0,0,0,0,0,0
endlayer

layer
0,0,0,0,0,0,0,0,0,0,0,0,0
0,0,0,0,0,0,0,0,0,0,0,0,0
0,0,0,0,0,0,0,0,0,0,0,0,0
0,0,0,0,0,10,9,9,0,0,0,0,0
0,0,0,0,10,0,0,0,8,0,0,0,0
0,0,0,12,0,0,0,0,0,8,0,0,0
0,0,0,12,0,0,0,0,0,11,0,0,0
0,0,0,15,0,0,0,0,0,11,0,0,0
0,0,0,0,15,0,0,0,13,0,0,0,0
0,0,0,0,0,14,14,13,0,0,0,0,0
0,0,0,0,0,0,0,0,0,0,0,0,0
0,0,0,0,0,0,0,0,0,0,0,0,0
0,0,0,0,0,0,0,0,0,0,0,0,0
endlayer

layer
0,0,0,0,0,0,0,0,0,0,0,0,0
0,0,0,0,0,0,0,0,0,0,0,0,0
0,0,0,0,0,10,9,9,0,0,0,0,0
0,0,0,0,10,0,0,0,8,0,0,0,0
0,0,0,10,0,0,0,0,0,8,0,0,0
0,0,12,0,0,0,0,0,0,0,8,0,0
0,0,12,0,0,0,0,0,0,0,11,0,0
0,0,15,0,0,0,0,0,0,0,11,0,0
0,0,0,15,0,0,0,0,0,11,0,0,0
0,0,0,0,14,0,0,0,13,0,0,0,0
0,0,0,0,0,14,14,13,0,0,0,0,0
0,0,0,0,0,0,0,0,0,0,0,0,0
0,0,0,0,0,0,0,0,0,0,0,0,0
endlayer

layer
0,0,0,0,0,0,0,0,0,0,0,0,0
0,0,0,0,0,0,9,0,0,0,0,0,0
0,0,0,0,10,10,0,9,9,0,0,0,0
0,0,0,10,0,0,0,0,0,8,0,0,0
0,0,12,0,0,0,0,0,0,0,8,0,0
0,0,12,0,0,0,0,0,0,0,8,0,0
0,12,0,0,0,0,0,0,0,0,0,11,0
0,0,15,0,0,0,0,0,0,0,11,0,0
0,0,15,0,0,0,0,0,0,0,11,0,0
0,0,0,15,0,0,0,0,0,13,0,0,0
0,0,0,0,14,14,0,13,13,0,0,0,0
0,0,0,0,0,0,14,0,0,0,0,0,0
0,0,0,0,0,0,0,0,0,0,0,0,0
endlayer

layer
0,0,0,0,0,0,0,0,0,0,0,0,0
0,0,0,0,0,10,9,9,0,0,0,0,0
0,0,0,10,10,0,0,0,9,8,0,0,0
0,0,10,0,0,0,0,0,0,0,8,0,0
0,0,12,0,0,0,0,0,0,0,8,0,0
0,12,0,0,0,0,0,0,0,0,0,8,0
0,12,0,0,0,0,0,0,0,0,0,11,0
0,15,0,0,0,0,0,0,0,0,0,11,0
0,0,15,0,0,0,0,0,0,0,11,0,0
0,0,15,0,0,0,0,0,0,0,13,0,0
0,0,0,15,14,0,0,0,13,13,0,0,0
0,0,0,0,0,14,14,13,0,0,0,0,0
0,0,0,0,0,0,0,0,0,0,0,0,0
endlayer

layer
0,0,0,0,0,0,9,0,0,0,0,0,0
0,0,0,0,10,9,0,9,9,0,0,0,0
0,0,10,10,0,0,0,0,0,8,8,0,0
0,0,10,0,0,0,0,0,0,0,8,0,0
0,12,0,0,0,0,0,0,0,0,0,8,0
0,12,0,0,0,0,0,0,0,0,0,11,0
12,0,0,0,0,0,0,0,0,0,0,0,11
0,12,0,0,0,0,0,0,0,0,0,11,0
0,15,0,0,0,0,0,0,0,0,0,11,0
0,0,15,0,0,0,0,0,0,0,13,0,0
0,0,15,15,0,0,0,0,0,13,13,0,0
0,0,0,0,14,14,0,14,13,0,0,0,0
0,0,0,0,0,0,14,0,0,0,0,0,0
endlayer

layer
0,0,0,0,0,9,9,9,0,0,0,0,0
0,0,0,10,10,0,0,0,9,9,0,0,0
0,0,10,0,0,0,0,0,0,0,8,0,0
0,12,0,0,0,0,0,0,0,0,0,8,0
0,12,0,0,0,0,0,0,0,0,0,8,0
12,0,0,0,0,0,0,0,0,0,0,0,11
12,0,0,0,0,0,0,0,0,0,0,0,11
12,0,0,0,0,0,0,0,0,0,0,0,11
0,15,0,0,0,0,0,0,0,0,0,11,0
0,15,0,0,0,0,0,0,0,0,0,11,0
0,0,15,0,0,0,0,0,0,0,13,0,0
0,0,0,14,14,0,0,0,13,13,0,0,0
0,0,0,0,0,14,14,14,0,0,0,0,0
endlayer

layer
0,0,0,0,10,9,9,9,9,0,0,0,0
0,0,10,10,0,0,0,0,0,9,8,0,0
0,10,0,0,0,0,0,0,0,0,0,8,0
0,12,0,0,0,0,0,0,0,0,0,8,0
12,0,0,0,0,0,0,0,0,0,0,0,8
12,0,0,0,0,0,0,0,0,0,0,0,11
12,0,0,0,0,0,0,0,0,0,0,0,11
12,0,0,0,0,0,0,0,0,0,0,0,11
15,0,0,0,0,0,0,0,0,0,0,0,11
0,15,0,0,0,0,0,0,0,0,0,11,0
0,15,0,0,0,0,0,0,0,0,0,13,0
0,0,15,14,0,0,0,0,0,13,13,0,0
0,0,0,0,14,14,14,14,13,0,0,0,0
endlayer

layer
0,0,0,0,10,9,9,9,9,0,0,0,0
0,0,10,10,0,0,0,0,0,9,8,0,0
0,10,0,0,0,0,0,0,0,0,0,8,0
0,12,0,0,0,0,0,0,0,0,0,8,0
12,0,0,0,0,0,0,0,0,0,0,0,8
12,0,0,0,0,0,0,0,0,0,0,0,11
12,0,0,0,0,0,0,0,0,0,0,0,11
12,0,0,0,0,0,0,0,0,0,0,0,11
15,0,0,0,0,0,0,0,0,0,0,0,11
0,15,0,0,0,0,0,0,0,0,0,11,0
0,15,0,0,0,0,0,0,0,0,0,13,0
0,0,15,14,0,0,0,0,0,13,13,0,0
0,0,0,0,14,14,14,14,13,0,0,0,0
endlayer

layer
0,0,0,0,10,9,9,9,9,0,0,0,0
0,0,10,10,0,0,0,0,0,9,8,0,0
0,10,0,0,0,0,0,0,0,0,0,8,0
0,12,0,0,0,0,0,0,0,0,0,8,0
12,0,0,0,0,0,0,0,0,0,0,0,8
12,0,0,0,0,0,0,0,0,0,0,0,11
12,0,0,0,0,0,0,0,0,0,0,0,11
12,0,0,0,0,0,0,0,0,0,0,0,11
15,0,0,0,0,0,0,0,0,0,0,0,11
0,15,0,0,0,0,0,0,0,0,0,11,0
0,15,0,0,0,0,0,0,0,0,0,13,0
0,0,15,14,0,0,0,0,0,13,13,0,0
0,0,0,0,14,14,14,14,13,0,0,0,0
endlayer

layer
0,0,0,0,0,9,9,9,0,0,0,0,0
0,0,0,10,10,0,0,0,9,9,0,0,0
0,0,10,0,0,0,0,0,0,0,8,0,0
0,12,0,0,0,0,0,0,0,0,0,8,0
0,12,0,0,0,0,0,0,0,0,0,8,0
12,0,0,0,0,0,0,0,0,0,0,0,11
12,0,0,0,0,0,0,0,0,0,0,0,11
12,0,0,0,0,0,0,0,0,0,0,0,11
0,15,0,0,0,0,0,0,0,0,0,11,0
0,15,0,0,0,0,0,0,0,0,0,11,0
0,0,15,0,0,0,0,0,0,0,13,0,0
0,0,0,14,14,0,0,0,13,13,0,0,0
0,0,0,0,0,14,14,14,0,0,0,0,0
endlayer

layer
0,0,0,0,0,0,0,0,0,0,0,0,0
0,0,0,0,10,9,9,9,9,0,0,0,0
0,0,10,10,0,0,0,0,0,8,8,0,0
0,0,10,0,0,0,0,0,0,0,8,0,0
0,12,0,0,0,0,0,0,0,0,0,8,0
0,12,0,0,0,0,0,0,0,0,0,11,0
0,12,0,0,0,0,0,0,0,0,0,11,0
0,12,0,0,0,0,0,0,0,0,0,11,0
0,15,0,0,0,0,0,0,0,0,0,11,0
0,0,15,0,0,0,0,0,0,0,13,0,0
0,0,15,15,0,0,0,0,0,13,13,0,0
0,0,0,0,14,14,14,14,13,0,0,0,0
0,0,0,0,0,0,0,0,0,0,0,0,0
endlayer

layer
0,0,0,0,0,0,0,0,0,0,0,0,0
0,0,0,0,0,10,9,9,0,0,0,0,0
0,0,0,10,10,0,0,0,9,8,0,0,0
0,0,10,10,0,0,0,0,0,8,8,0,0
0,0,12,0,0,0,0,0,0,0,8,0,0
0,12,0,0,0,0,0,0,0,0,0,8,0
0,12,0,0,0,0,0,0,0,0,0,11,0
0,15,0,0,0,0,0,0,0,0,0,11,0
0,0,15,0,0,0,0,0,0,0,11,0,0
0,0,15,15,0,0,0,0,0,13,13,0,0
0,0,0,15,14,0,0,0,13,13,0,0,0
0,0,0,0,0,14,14,13,0,0,0,0,0
0,0,0,0,0,0,0,0,0,0,0,0,0
endlayer

layer
0,0,0,0,0,0,0,0,0,0,0,0,0
0,0,0,0,0,0,0,0,0,0,0,0,0
0,0,0,0,0,10,9,9,0,0,0,0,0
0,0,0,0,10,10,9,9,9,0,0,0,0
0,0,0,12,10,0,0,0,8,8,0,0,0
0,0,12,12,0,0,0,0,0,8,8,0,0
0,0,12,12,0,0,0,0,0,11,11,0,0
0,0,15,15,0,0,0,0,0,11,11,0,0
0,0,0,15,15,0,0,0,13,11,0,0,0
0,0,0,0,14,14,14,13,13,0,0,0,0
0,0,0,0,0,14,14,13,0,0,0,0,0
0,0,0,0,0,0,0,0,0,0,0,0,0
0,0,0,0,0,0,0,0,0,0,0,0,0
endlayer

layer
0,0,0,0,0,0,0,0,0,0,0,0,0
0,0,0,0,0,0,0,0,0,0,0,0,0
0,0,0,0,0,0,0,0,0,0,0,0,0
0,0,0,0,0,0,0,0,0,0,0,0,0
0,0,0,0,0,10,9,9,0,0,0,0,0
0,0,0,0,12,10,9,8,8,0,0,0,0
0,0,0,0,12,12,11,11,11,0,0,0,0
0,0,0,0,15,15,14,13,11,0,0,0,0
0,0,0,0,0,14,14,13,0,0,0,0,0
0,0,0,0,0,0,0,0,0,0,0,0,0
0,0,0,0,0,0,0,0,0,0,0,0,0
0,0,0,0,0,0,0,0,0,0,0,0,0
0,0,0,0,0,0,0,0,0,0,0,0,0
endlayer

