
# Created by Ruins mod version 16.7 Ingame Parser
# authoring Player: ST753M

weight=1
embed_into_distance=2
acceptable_target_blocks=sand,sandstone
unacceptable_target_blocks=flowing_water,water,flowing_lava,lava
dimensions=12,11,11
allowable_overhang=2
max_leveling=2
leveling_buffer=-1
preserve_water=0
preserve_lava=0

biomesToSpawnIn=desert

rule1=0,100,minecraft:sandstone-0
rule2=0,100,minecraft:water-0
^0,100,minecraft:water-0
^0,100,minecraft:water-0
^0,100,minecraft:water-0
^0,100,minecraft:water-0
^0,100,minecraft:lava-0
rule3=0,100,minecraft:sandstone_stairs-2
rule4=0,100,minecraft:sandstone_stairs-0
rule5=0,100,minecraft:sandstone_stairs-3
rule6=0,100,minecraft:sandstone-2
rule7=0,100,minecraft:stained_hardened_clay-0
^0,100,minecraft:stained_hardened_clay-1
^0,100,minecraft:stained_hardened_clay-2
^0,100,minecraft:stained_hardened_clay-3
^0,100,minecraft:stained_hardened_clay-4
^0,100,minecraft:stained_hardened_clay-5
^0,100,minecraft:stained_hardened_clay-6
^0,100,minecraft:stained_hardened_clay-7
^0,100,minecraft:stained_hardened_clay-8
^0,100,minecraft:stained_hardened_clay-9
^0,100,minecraft:stained_hardened_clay-10
^0,100,minecraft:stained_hardened_clay-11
^0,100,minecraft:stained_hardened_clay-12
^0,100,minecraft:stained_hardened_clay-13
^0,100,minecraft:stained_hardened_clay-14
^0,100,minecraft:stained_hardened_clay-15
rule8=0,100,minecraft:sandstone_stairs-1
rule9=0,100,minecraft:sandstone-1
rule10=0,100,minecraft:stone_slab-9
rule11=0,100,minecraft:sandstone_stairs-5
rule12=0,100,minecraft:sandstone_stairs-7
rule13=0,100,minecraft:sandstone_stairs-6
rule14=0,100,minecraft:sandstone_stairs-4
rule15=0,100,minecraft:glowstone-0
rule16=0,100,minecraft:stone_slab-1

layer
1,1,1,1,1,1,1,1,1,1,1
1,1,1,1,1,1,1,1,1,1,1
1,1,1,1,1,1,1,1,1,1,1
1,1,1,1,1,1,1,1,1,1,1
1,1,1,1,2,2,2,1,1,1,1
1,1,1,1,2,2,2,1,1,1,1
1,1,1,1,2,2,2,1,1,1,1
1,1,1,1,1,1,1,1,1,1,1
1,1,1,1,1,1,1,1,1,1,1
1,1,1,1,1,1,1,1,1,1,1
1,1,1,1,1,1,1,1,1,1,1
endlayer

layer
1,1,1,1,1,1,1,1,1,1,1
1,1,1,1,1,1,1,1,1,1,1
1,1,1,1,1,1,1,1,1,1,1
1,1,1,1,1,1,1,1,1,1,1
1,1,1,1,2,2,2,1,1,1,1
1,1,1,1,2,2,2,1,1,1,1
1,1,1,1,2,2,2,1,1,1,1
1,1,1,1,1,1,1,1,1,1,1
1,1,1,1,1,1,1,1,1,1,1
1,1,1,1,1,1,1,1,1,1,1
1,1,1,1,1,1,1,1,1,1,1
endlayer

layer
5,4,4,4,4,4,4,4,4,4,3
5,1,6,1,1,1,1,1,1,1,3
5,1,7,7,7,7,7,7,7,1,3
5,1,7,1,1,1,1,1,7,1,3
5,1,7,1,2,2,2,1,7,1,3
5,1,7,1,2,2,2,1,7,1,3
5,1,7,1,2,2,2,1,7,1,3
5,1,7,1,1,1,1,1,7,1,3
5,1,7,7,7,7,7,7,7,1,3
5,1,1,1,1,1,1,1,1,1,3
5,8,8,8,8,8,8,8,8,8,8
endlayer

layer
0,0,0,0,0,0,0,0,0,0,0
0,6,0,0,0,6,0,0,0,6,0
0,0,0,0,0,0,0,0,0,0,0
0,0,0,5,4,4,4,4,0,0,0
0,0,0,5,2,2,2,3,0,0,0
0,6,0,5,2,2,2,3,0,6,0
0,0,0,5,2,2,2,3,0,0,0
0,0,0,8,8,8,8,8,0,0,0
0,0,0,0,0,0,0,0,0,0,0
0,6,0,0,0,6,0,0,0,6,0
0,0,0,0,0,0,0,0,0,0,0
endlayer

layer
0,0,0,0,0,0,0,0,0,0,0
0,9,0,0,0,9,0,0,0,9,0
0,0,0,0,0,0,0,0,0,0,0
0,0,0,0,0,0,0,0,0,0,0
0,0,0,0,0,0,0,0,0,0,0
0,9,0,0,0,0,0,0,0,9,0
0,0,0,0,0,0,0,0,0,0,0
0,0,0,0,0,0,0,0,0,0,0
0,0,0,0,0,0,0,0,0,0,0
0,9,0,0,0,9,0,0,0,9,0
0,0,0,0,0,0,0,0,0,0,0
endlayer

layer
0,0,0,0,0,0,0,0,0,0,0
0,6,10,10,10,6,10,10,10,6,0
0,10,0,0,0,0,0,0,0,10,0
0,10,0,0,0,0,0,0,0,10,0
0,10,0,0,0,0,0,0,0,10,0
0,6,0,0,0,0,0,0,0,6,0
0,10,0,0,0,0,0,0,0,10,0
0,10,0,0,0,0,0,0,0,10,0
0,10,0,0,0,0,0,0,0,10,0
0,6,10,10,10,6,10,10,10,6,0
0,0,0,0,0,0,0,0,0,0,0
endlayer

layer
4,4,4,4,4,4,4,4,4,4,3
5,1,6,6,6,1,6,6,6,1,3
5,6,0,0,0,11,0,0,0,6,3
5,6,0,0,0,0,0,0,0,6,3
5,6,0,0,0,0,0,0,0,6,3
5,1,13,0,0,0,0,0,12,1,3
5,6,0,0,0,0,0,0,0,6,3
5,6,0,0,0,0,0,0,0,6,3
5,6,0,0,0,14,0,0,0,6,3
5,1,6,6,6,1,6,6,6,1,3
8,8,8,8,8,8,8,8,8,8,8
endlayer

layer
0,0,0,0,0,0,0,0,0,0,0
0,5,4,4,4,4,4,4,4,4,0
0,5,11,11,11,9,11,11,11,3,0
0,5,13,0,0,0,0,0,12,3,0
0,5,13,0,0,0,0,0,12,3,0
0,5,9,0,0,0,0,0,9,3,0
0,5,13,0,0,0,0,0,12,3,0
0,5,13,0,0,0,0,0,12,3,0
0,5,13,14,14,9,14,14,14,3,0
0,5,8,8,8,8,8,8,8,3,0
0,0,0,0,0,0,0,0,0,0,0
endlayer

layer
0,0,0,0,0,0,0,0,0,0,0
0,0,0,0,0,0,0,0,0,0,0
0,0,5,4,4,4,4,4,3,0,0
0,0,5,11,11,11,11,12,3,0,0
0,0,5,13,0,0,0,12,3,0,0
0,0,5,13,0,0,0,12,3,0,0
0,0,5,13,0,0,0,12,3,0,0
0,0,5,13,14,14,14,12,3,0,0
0,0,8,8,8,8,8,8,3,0,0
0,0,0,0,0,0,0,0,0,0,0
0,0,0,0,0,0,0,0,0,0,0
endlayer

layer
0,0,0,0,0,0,0,0,0,0,0
0,0,0,0,0,0,0,0,0,0,0
0,0,0,0,0,0,0,0,0,0,0
0,0,0,4,4,4,4,4,0,0,0
0,0,0,5,11,11,12,3,0,0,0
0,0,0,5,13,0,12,3,0,0,0
0,0,0,5,13,14,12,3,0,0,0
0,0,0,8,8,8,8,3,0,0,0
0,0,0,0,0,0,0,0,0,0,0
0,0,0,0,0,0,0,0,0,0,0
0,0,0,0,0,0,0,0,0,0,0
endlayer

layer
0,0,0,0,0,0,0,0,0,0,0
0,0,0,0,0,0,0,0,0,0,0
0,0,0,0,0,0,0,0,0,0,0
0,0,0,0,0,0,0,0,0,0,0
0,0,0,0,4,4,4,0,0,0,0
0,0,0,0,5,15,3,0,0,0,0
0,0,0,0,8,8,8,0,0,0,0
0,0,0,0,0,0,0,0,0,0,0
0,0,0,0,0,0,0,0,0,0,0
0,0,0,0,0,0,0,0,0,0,0
0,0,0,0,0,0,0,0,0,0,0
endlayer

layer
0,0,0,0,0,0,0,0,0,0,0
0,0,0,0,0,0,0,0,0,0,0
0,0,0,0,0,0,0,0,0,0,0
0,0,0,0,0,0,0,0,0,0,0
0,0,0,0,0,0,0,0,0,0,0
0,0,0,0,0,16,0,0,0,0,0
0,0,0,0,0,0,0,0,0,0,0
0,0,0,0,0,0,0,0,0,0,0
0,0,0,0,0,0,0,0,0,0,0
0,0,0,0,0,0,0,0,0,0,0
0,0,0,0,0,0,0,0,0,0,0
endlayer

