
# Created by Ruins mod version 15.1 Ingame Parser
# authoring Player: ST753M

weight=1
embed_into_distance=0
spawnMinDistance=256
acceptable_target_blocks=snow,ice,packed ice,hardened ice,grass,dirt,podzol,stone
unacceptable_target_blocks=
dimensions=21,12,8
allowable_overhang=3
max_leveling=2
leveling_buffer=-1
preserve_water=1
preserve_lava=1

biomesToSpawnIn=snowy_forest,mutated_taiga_cold,snowy_coniferous_forest,taiga_cold,taiga_cold_hills,ice_flats,ice_mountains,glacier,mutated_ice_flats,frozen_ocean,frozen_river,cold_beach,cold_desert,ice_mountains,glacier,glacier_spikes,twilight_glacier,ice_plains_defiled

=0,100,preserveBlock
rule1=0,100,preserveBlock
rule2=0,100,minecraft:packed_ice-0
^0,100,minecraft:packed_ice-0

layer
1,1,1,1,1,1,1,1
1,1,2,2,2,2,1,1
1,2,2,2,2,2,2,1
1,2,2,2,2,2,2,1
1,2,2,2,2,2,2,1
1,2,2,2,2,2,2,1
1,2,2,2,2,2,2,1
1,2,2,2,2,2,2,1
1,2,2,2,2,2,2,1
1,1,2,2,2,2,1,1
1,1,1,1,1,1,1,1
1,1,1,1,1,1,1,1
endlayer

layer
1,1,1,1,1,1,1,1
1,1,2,2,2,2,1,1
1,2,2,2,2,2,2,1
1,2,2,2,2,2,2,1
1,2,2,2,2,2,2,1
1,2,2,2,2,2,2,1
1,2,2,2,2,2,2,1
1,2,2,2,2,2,2,1
1,2,2,2,2,2,2,1
1,1,2,2,2,2,1,1
1,1,1,1,1,1,1,1
1,1,1,1,1,1,1,1
endlayer

layer
1,1,1,1,1,1,1,1
1,1,2,2,2,2,1,1
1,2,2,2,2,2,2,1
1,2,2,2,2,2,2,1
1,2,2,2,2,2,2,1
1,2,2,2,2,2,2,1
1,2,2,2,2,2,2,1
1,2,2,2,2,2,2,1
1,2,2,2,2,2,2,1
1,1,2,2,2,2,1,1
1,1,1,1,1,1,1,1
1,1,1,1,1,1,1,1
endlayer

layer
0,0,0,0,0,0,0,0
0,0,2,2,2,2,0,0
0,2,2,2,2,2,2,0
0,2,2,2,2,2,2,0
0,2,2,2,2,2,2,0
0,2,2,2,2,2,2,0
0,2,2,2,2,2,2,0
0,2,2,2,2,2,2,0
0,2,2,2,2,2,2,0
0,0,0,2,2,0,0,0
0,0,0,0,0,0,0,0
0,0,0,0,0,0,0,0
endlayer

layer
0,0,0,0,0,0,0,0
0,0,2,2,2,2,0,0
0,0,2,2,2,2,0,0
0,2,2,2,2,2,2,0
0,2,2,2,2,2,2,0
0,2,2,2,2,2,2,0
0,2,2,2,2,2,2,0
0,2,2,2,2,2,2,0
0,0,2,2,2,2,0,0
0,0,0,0,0,0,0,0
0,0,0,0,0,0,0,0
0,0,0,0,0,0,0,0
endlayer

layer
0,0,0,0,0,0,0,0
0,0,2,2,2,2,0,0
0,0,2,2,2,2,0,0
0,0,2,2,2,2,0,0
0,2,2,2,2,2,2,0
0,2,2,2,2,2,2,0
0,2,2,2,2,2,2,0
0,0,2,2,2,2,0,0
0,0,2,2,2,2,0,0
0,0,0,0,0,0,0,0
0,0,0,0,0,0,0,0
0,0,0,0,0,0,0,0
endlayer

layer
0,0,0,0,0,0,0,0
0,0,0,2,2,0,0,0
0,0,2,2,2,2,0,0
0,0,2,2,2,2,0,0
0,0,2,2,2,2,0,0
0,0,2,2,2,2,0,0
0,0,2,2,2,2,0,0
0,0,2,2,2,2,0,0
0,0,0,2,2,0,0,0
0,0,0,0,0,0,0,0
0,0,0,0,0,0,0,0
0,0,0,0,0,0,0,0
endlayer

layer
0,0,0,0,0,0,0,0
0,0,0,0,0,0,0,0
0,0,2,2,2,2,0,0
0,0,2,2,2,2,0,0
0,0,2,2,2,2,0,0
0,0,2,2,2,2,0,0
0,0,2,2,2,2,0,0
0,0,2,2,2,2,0,0
0,0,0,2,2,0,0,0
0,0,0,0,0,0,0,0
0,0,0,0,0,0,0,0
0,0,0,0,0,0,0,0
endlayer

layer
0,0,0,0,0,0,0,0
0,0,0,0,0,0,0,0
0,0,0,2,2,0,0,0
0,0,2,2,2,2,0,0
0,0,2,2,2,2,0,0
0,0,2,2,2,2,0,0
0,0,2,2,2,2,0,0
0,0,2,2,2,2,0,0
0,0,2,2,2,2,0,0
0,0,0,2,2,0,0,0
0,0,0,0,0,0,0,0
0,0,0,0,0,0,0,0
endlayer

layer
0,0,0,0,0,0,0,0
0,0,0,0,0,0,0,0
0,0,0,0,0,0,0,0
0,0,0,2,2,0,0,0
0,0,2,2,2,2,0,0
0,0,2,2,2,2,0,0
0,0,2,2,2,2,0,0
0,0,2,2,2,2,0,0
0,0,2,2,2,2,0,0
0,0,0,2,2,0,0,0
0,0,0,0,0,0,0,0
0,0,0,0,0,0,0,0
endlayer

layer
0,0,0,0,0,0,0,0
0,0,0,0,0,0,0,0
0,0,0,0,0,0,0,0
0,0,0,0,0,0,0,0
0,0,0,0,0,0,0,0
0,0,0,0,0,0,0,0
0,0,0,2,2,0,0,0
0,0,2,2,2,2,0,0
0,0,2,2,2,2,0,0
0,0,0,2,2,0,0,0
0,0,0,2,2,0,0,0
0,0,0,0,0,0,0,0
endlayer

layer
0,0,0,0,0,0,0,0
0,0,0,0,0,0,0,0
0,0,0,0,0,0,0,0
0,0,0,0,0,0,0,0
0,0,0,0,0,0,0,0
0,0,0,0,0,0,0,0
0,0,0,0,0,0,0,0
0,0,0,2,2,0,0,0
0,0,2,2,2,2,0,0
0,0,2,2,2,2,0,0
0,0,0,2,2,0,0,0
0,0,0,0,0,0,0,0
endlayer

layer
0,0,0,0,0,0,0,0
0,0,0,0,0,0,0,0
0,0,0,0,0,0,0,0
0,0,0,0,0,0,0,0
0,0,0,0,0,0,0,0
0,0,0,0,0,0,0,0
0,0,0,0,0,0,0,0
0,0,0,2,2,0,0,0
0,0,2,2,2,2,0,0
0,0,2,2,2,2,0,0
0,0,0,2,2,0,0,0
0,0,0,0,0,0,0,0
endlayer

layer
0,0,0,0,0,0,0,0
0,0,0,0,0,0,0,0
0,0,0,0,0,0,0,0
0,0,0,0,0,0,0,0
0,0,0,0,0,0,0,0
0,0,0,0,0,0,0,0
0,0,0,0,0,0,0,0
0,0,0,2,2,0,0,0
0,0,2,2,2,2,0,0
0,0,0,2,2,0,0,0
0,0,0,2,2,0,0,0
0,0,0,0,0,0,0,0
endlayer

layer
0,0,0,0,0,0,0,0
0,0,0,0,0,0,0,0
0,0,0,0,0,0,0,0
0,0,0,0,0,0,0,0
0,0,0,0,0,0,0,0
0,0,0,0,0,0,0,0
0,0,0,2,2,0,0,0
0,0,0,2,2,0,0,0
0,0,0,2,2,0,0,0
0,0,0,2,2,0,0,0
0,0,0,2,2,0,0,0
0,0,0,0,0,0,0,0
endlayer

layer
0,0,0,0,0,0,0,0
0,0,0,0,0,0,0,0
0,0,0,0,0,0,0,0
0,0,0,0,0,0,0,0
0,0,0,0,0,0,0,0
0,0,0,0,0,0,0,0
0,0,0,2,2,0,0,0
0,0,0,2,2,0,0,0
0,0,0,2,2,0,0,0
0,0,0,2,2,0,0,0
0,0,0,0,0,0,0,0
0,0,0,0,0,0,0,0
endlayer

layer
0,0,0,2,2,0,0,0
0,0,0,2,2,0,0,0
0,0,2,2,2,2,0,0
0,0,2,2,2,2,0,0
0,0,2,2,2,2,0,0
0,0,2,2,2,2,0,0
0,0,2,2,2,2,0,0
0,0,2,2,2,2,0,0
0,0,0,2,2,0,0,0
0,0,0,2,2,0,0,0
0,0,0,0,0,0,0,0
0,0,0,0,0,0,0,0
endlayer

layer
0,0,2,2,2,2,0,0
0,0,2,2,2,2,0,0
0,0,2,2,2,2,0,0
0,0,2,2,2,2,0,0
0,0,2,2,2,2,0,0
0,0,2,2,2,2,0,0
0,0,2,2,2,2,0,0
0,0,2,2,2,2,0,0
0,0,0,2,2,0,0,0
0,0,0,0,0,0,0,0
0,0,0,0,0,0,0,0
0,0,0,0,0,0,0,0
endlayer

layer
0,0,2,0,0,2,0,0
0,0,0,0,0,0,0,0
0,0,0,2,2,0,0,0
0,0,2,2,2,2,0,0
0,0,0,2,2,0,0,0
0,0,0,2,2,0,0,0
0,0,2,2,2,2,0,0
0,2,2,2,2,2,2,0
0,0,0,0,0,0,0,0
0,0,0,0,0,0,0,0
0,0,0,0,0,0,0,0
0,0,0,0,0,0,0,0
endlayer

layer
0,0,0,0,0,0,0,0
0,0,0,0,0,0,0,0
0,0,0,0,0,0,0,0
0,0,2,2,2,2,0,0
0,0,2,2,2,2,0,0
0,0,2,2,2,2,0,0
0,2,2,2,2,2,2,0
2,2,2,2,2,2,2,2
2,2,2,0,0,2,2,2
0,2,0,0,0,0,2,0
0,0,0,0,0,0,0,0
0,0,0,0,0,0,0,0
endlayer

layer
0,0,0,0,0,0,0,0
0,0,0,0,0,0,0,0
0,0,0,0,0,0,0,0
0,0,0,0,0,0,0,0
0,0,0,0,0,0,0,0
0,0,0,2,2,0,0,0
0,0,2,2,2,2,0,0
0,2,0,0,0,0,2,0
2,0,0,0,0,0,0,2
2,0,0,0,0,0,0,2
2,0,0,0,0,0,0,2
2,0,0,0,0,0,0,2
endlayer

