
# Created by Ruins mod version 16.8 Ingame Parser
# authoring Player: ST753M

weight=1
uniqueMinDistance=2000
embed_into_distance=1
acceptable_target_blocks=grass,dirt
unacceptable_target_blocks=flowing_water,water,flowing_lava,lava,ice,bedrock,netherrack,nether_brick,nether_brick_fence,soul_sand,quartz_ore,end_stone,obsidian,iron_bars,Natura:Cloud,slime_grass,slime_congealed,slime_dirt,clouds,natura:clouds
dimensions=8,11,15
allowable_overhang=1
max_leveling=2
leveling_buffer=-1
preserve_water=0
preserve_lava=0

biomesToSpawnIn=mutated_birch_forest,plains,rocky_plains,ocean,prairie,chaparral,grassland,orchard

=0,100,air
rule1=0,100,minecraft:fence-0
rule2=0,100,preserveBlock
rule3=0,100,minecraft:stone-0
rule4=0,100,minecraft:brick_block-0
rule5=0,100,minecraft:stone-3
rule6=0,100,minecraft:oak_stairs-3
rule7=0,100,minecraft:oak_stairs-2
rule8=0,100,minecraft:oak_stairs-1
rule9=0,100,minecraft:wooden_door-2
rule10=0,100,minecraft:oak_stairs-7
rule11=0,100,minecraft:fence_gate-2
rule12=0,100,minecraft:oak_stairs-0
rule13=0,100,minecraft:cauldron-0
rule14=0,100,CommandBlock:RUINSTRIGGER /summon villager ~ ~1 ~ {CustomName:"Barista",CustomNameVisible:1,Profession:4,Offers:{Recipes:[{rewardExp:0b,maxUses:2147483647,uses:0,buy:{id:"minecraft:emerald",Count:1b},sell:{id:"harvestcraft:teaitem",Count:1b}},{rewardExp:0b,maxUses:2147483647,uses:0,buy:{id:"minecraft:emerald",Count:1b},sell:{id:"harvestcraft:coffeeitem",Count:1b}},{rewardExp:0b,maxUses:2147483647,uses:0,buy:{id:"minecraft:emerald",Count:3b},sell:{id:"harvestcraft:chaiteaitem",Count:1b}},{rewardExp:0b,maxUses:2147483647,uses:0,buy:{id:"minecraft:emerald",Count:3b},sell:{id:"harvestcraft:coffeeconlecheitem",Count:1b}}]}}:@-1
rule15=0,100,minecraft:oak_stairs-5
rule16=0,100,minecraft:carpet-11
^0,100,minecraft:carpet-14
^0,100,minecraft:carpet-7
^0,100,minecraft:carpet-8
^0,100,air
rule17=0,100,minecraft:furnace-3
rule18=0,100,minecraft:oak_stairs-4
rule19=0,100,minecraft:wooden_door-1
rule20=0,100,IInventory;minecraft:chest;harvestcraft:teaitem#1#0#2+minecraft:cookie#1#0#7+minecraft:cookie#2#0#9+harvestcraft:heavycreamitem#2#0#14+minecraft:milk_bucket#1#0#20+harvestcraft:soymilkitem#1#0#25-2
rule21=0,100,minecraft:wooden_door-0
rule22=0,100,minecraft:wooden_pressure_plate-0
rule23=0,100,minecraft:wooden_door-8
rule24=0,100,minecraft:flower_pot-0
rule25=0,100,minecraft:unpowered_comparator-0
rule26=0,100,minecraft:hopper-0
rule27=0,100,minecraft:wool-3
^0,100,minecraft:wool-14
rule28=0,100,minecraft:wool-0
rule29=2,100,minecraft:torch-1
rule30=2,100,WallSign:null:null:null:null-3
rule31=2,100,minecraft:torch-2
rule32=0,100,minecraft:stone_slab-8
rule33=0,100,minecraft:wooden_slab-1
rule34=0,100,minecraft:spruce_stairs-0
rule35=0,100,minecraft:spruce_stairs-2
rule36=0,100,minecraft:planks-1
rule37=0,100,minecraft:spruce_stairs-1
rule38=0,100,minecraft:wooden_slab-9

layer
3,3,3,3,3,3,3,3,3,3,3,3,2,2,1
3,3,3,3,3,3,3,3,3,3,3,3,2,2,2
3,3,4,4,4,4,3,4,4,4,4,4,4,2,2
3,3,4,5,5,5,5,5,5,5,5,5,4,2,2
3,3,4,5,5,5,5,5,5,5,5,5,4,2,2
3,3,3,5,5,5,5,5,5,5,5,5,4,2,2
3,3,4,5,5,5,5,5,5,5,5,5,4,2,2
3,3,4,5,5,5,5,5,5,5,5,5,4,2,2
3,3,4,4,4,4,3,4,4,4,4,4,4,2,2
3,3,3,3,3,3,3,3,3,3,3,3,2,2,2
3,3,3,3,3,3,3,3,3,3,3,3,2,2,1
endlayer

layer
1,0,7,1,6,0,0,0,7,1,6,0,2,2,1
8,0,0,0,0,0,0,0,0,0,0,0,2,2,2
1,0,4,4,4,4,9,4,4,4,4,4,4,2,2
12,0,4,7,1,6,0,0,11,0,0,10,4,2,2
0,0,4,0,16,16,16,16,15,14,0,13,4,2,2
0,0,19,0,16,16,16,16,18,0,0,17,4,2,2
0,0,4,0,16,16,16,16,4,4,0,10,4,2,2
8,0,4,7,1,6,0,0,4,20,0,10,4,2,2
1,0,4,4,4,4,21,4,4,4,4,4,4,2,2
12,0,0,0,0,0,0,0,0,0,0,0,2,2,2
1,0,7,1,6,0,0,0,7,1,6,0,2,2,1
endlayer

layer
1,0,0,22,0,0,0,0,0,22,0,0,0,2,1
0,0,0,0,0,0,0,0,0,0,0,0,0,2,2
22,0,4,4,4,4,23,4,4,4,4,4,4,2,2
0,0,4,0,22,0,0,0,0,0,0,24,4,2,2
0,0,4,0,0,0,0,0,0,0,0,0,4,2,2
0,0,23,0,0,0,0,0,24,0,0,24,4,2,2
0,0,4,0,0,0,0,0,4,4,0,25,4,2,2
0,0,4,0,22,0,0,0,4,0,0,26,4,2,2
22,0,4,4,4,4,23,4,4,4,4,4,4,2,2
0,0,0,0,0,0,0,0,0,0,0,0,0,2,2
1,0,0,22,0,0,0,0,0,22,0,0,0,2,1
endlayer

layer
27,27,27,28,28,27,27,28,28,27,27,28,28,27,27
27,0,0,0,0,0,0,0,0,0,0,0,0,0,27
28,0,4,4,4,4,4,4,4,4,4,4,4,0,27
28,0,4,0,29,0,0,0,1,0,29,0,4,0,28
27,0,4,0,0,0,0,0,1,0,0,30,4,0,28
27,0,4,0,0,0,0,0,1,0,0,30,4,0,27
28,0,4,0,0,0,0,0,4,4,0,0,4,0,27
28,0,4,0,31,0,0,0,4,0,0,0,4,0,28
27,0,4,4,4,4,4,4,4,4,4,4,4,0,28
27,0,0,0,0,0,0,0,0,0,0,0,0,0,27
27,27,28,28,27,27,28,28,27,27,28,28,27,27,27
endlayer

layer
2,2,2,2,2,2,2,2,2,2,2,2,2,2,2
2,27,27,28,28,27,27,28,28,27,27,28,28,27,2
2,28,4,4,4,4,4,4,4,4,4,4,4,27,2
2,28,4,32,32,32,32,32,4,32,32,32,4,28,2
2,27,4,32,32,32,32,32,4,32,32,32,4,28,2
2,27,4,32,32,32,32,32,4,32,32,32,4,27,2
2,28,4,32,32,32,32,32,4,4,32,32,4,27,2
2,28,4,32,32,32,32,32,4,32,32,32,4,28,2
2,27,4,4,4,4,4,4,4,4,4,4,4,28,2
2,27,28,28,27,27,28,28,27,27,28,28,27,27,2
2,2,2,2,2,2,2,2,2,2,2,2,2,2,2
endlayer

layer
2,2,2,2,2,2,2,2,2,2,2,2,2,2,2
2,2,2,2,2,2,2,2,2,2,2,2,2,2,2
2,2,33,33,33,33,33,33,33,33,33,33,33,2,2
2,2,33,34,34,34,34,34,34,34,34,34,33,2,2
2,2,33,36,36,36,36,36,36,36,36,35,33,2,2
2,2,33,36,36,36,36,36,36,36,36,35,33,2,2
2,2,33,36,36,36,36,36,36,36,36,35,33,2,2
2,2,33,37,37,37,37,37,37,37,37,35,33,2,2
2,2,33,33,33,33,33,33,33,33,33,33,33,2,2
2,2,2,2,2,2,2,2,2,2,2,2,2,2,2
2,2,2,2,2,2,2,2,2,2,2,2,2,2,2
endlayer

layer
2,2,2,2,2,2,2,2,2,2,2,2,2,2,2
2,2,2,2,2,2,2,2,2,2,2,2,2,2,2
2,2,2,2,2,2,2,2,2,2,2,2,2,2,2
2,2,2,2,2,2,2,2,2,2,2,2,2,2,2
2,2,2,2,34,34,34,34,34,34,34,2,2,2,2
2,2,2,2,38,36,36,36,36,36,38,2,2,2,2
2,2,2,2,37,37,37,37,37,37,37,2,2,2,2
2,2,2,2,2,2,2,2,2,2,2,2,2,2,2
2,2,2,2,2,2,2,2,2,2,2,2,2,2,2
2,2,2,2,2,2,2,2,2,2,2,2,2,2,2
2,2,2,2,2,2,2,2,2,2,2,2,2,2,2
endlayer

layer
2,2,2,2,2,2,2,2,2,2,2,2,2,2,2
2,2,2,2,2,2,2,2,2,2,2,2,2,2,2
2,2,2,2,2,2,2,2,2,2,2,2,2,2,2
2,2,2,2,2,2,2,2,2,2,2,2,2,2,2
2,2,2,2,2,2,2,2,2,2,2,2,2,2,2
2,2,2,2,33,33,33,33,33,33,33,2,2,2,2
2,2,2,2,2,2,2,2,2,2,2,2,2,2,2
2,2,2,2,2,2,2,2,2,2,2,2,2,2,2
2,2,2,2,2,2,2,2,2,2,2,2,2,2,2
2,2,2,2,2,2,2,2,2,2,2,2,2,2,2
2,2,2,2,2,2,2,2,2,2,2,2,2,2,2
endlayer

