
# Created by Ruins mod version 16.7 Ingame Parser
# authoring Player: ST753M

weight=1
uniqueMinDistance=1000
spawnMinDistance=1000
embed_into_distance=0
acceptable_target_blocks=end_stone,endstone
unacceptable_target_blocks=flowing_water,water,flowing_lava,lava
dimensions=8,8,8
allowable_overhang=8
max_leveling=3
leveling_buffer=-1
preserve_water=1
preserve_lava=1

rule1=0,100,minecraft:obsidian-0
rule2=0,100,MobSpawner:Enderman,minecraft:obsidian-0
rule3=0,100,minecraft:end_stone-0
rule4=0,100,minecraft:purpur_block-0

layer
1,1,1,1,1,1,1,1
1,1,1,1,1,1,1,1
1,1,1,1,1,1,1,1
1,1,1,1,1,1,1,1
1,1,1,1,1,1,1,1
1,1,1,1,1,1,1,1
1,1,1,1,1,1,1,1
1,1,1,1,1,1,1,1
endlayer

layer
1,1,1,1,1,1,1,1
1,0,0,0,0,0,0,1
1,0,0,0,0,0,0,1
1,0,0,1,1,0,0,1
1,0,0,1,1,0,0,1
1,0,0,0,0,0,0,1
1,0,0,0,0,0,0,1
1,1,1,1,1,1,1,1
endlayer

layer
1,1,1,1,1,1,1,1
1,0,0,0,0,0,0,1
1,0,0,0,0,0,0,1
1,0,0,1,2,0,0,1
1,0,0,1,1,0,0,1
1,0,0,0,0,0,0,1
1,0,0,0,0,0,0,1
1,1,1,1,1,1,1,1
endlayer

layer
3,4,3,1,1,3,4,3
4,0,0,0,0,0,0,4
3,0,0,0,0,0,0,3
1,0,0,1,1,0,0,1
1,0,0,1,1,0,0,1
3,0,0,0,0,0,0,3
4,0,0,0,0,0,0,4
3,4,3,1,1,3,4,3
endlayer

layer
1,1,1,1,1,1,1,1
1,0,0,0,0,0,0,1
1,0,0,0,0,0,0,1
1,0,0,1,1,0,0,1
1,0,0,1,1,0,0,1
1,0,0,0,0,0,0,1
1,0,0,0,0,0,0,1
1,1,1,1,1,1,1,1
endlayer

layer
1,1,1,1,1,1,1,1
1,0,0,0,0,0,0,1
1,0,0,0,0,0,0,1
1,0,0,1,1,0,0,1
1,0,0,1,1,0,0,1
1,0,0,0,0,0,0,1
1,0,0,0,0,0,0,1
1,1,1,1,1,1,1,1
endlayer

layer
1,1,1,1,1,1,1,1
1,0,0,0,0,0,0,1
1,0,0,0,0,0,0,1
1,0,0,1,1,0,0,1
1,0,0,1,1,0,0,1
1,0,0,0,0,0,0,1
1,0,0,0,0,0,0,1
1,1,1,1,1,1,1,1
endlayer

layer
1,1,1,1,1,1,1,1
1,1,1,1,1,1,1,1
1,1,1,1,1,1,1,1
1,1,1,1,1,1,1,1
1,1,1,1,1,1,1,1
1,1,1,1,1,1,1,1
1,1,1,1,1,1,1,1
1,1,1,1,1,1,1,1
endlayer

