
# Created by Ruins mod version 17.0 Ingame Parser
# authoring Player: ST753M

weight=1
embed_into_distance=5
acceptable_target_blocks=
unacceptable_target_blocks=flowing_water,water,flowing_lava,lava
dimensions=17,17,17
allowable_overhang=0
max_leveling=0
leveling_buffer=-1
preserve_water=0
preserve_lava=0

rule1=0,100,preserveBlock
rule2=0,100,minecraft:stone-0
rule3=0,100,minecraft:prismarine-2
rule4=0,100,minecraft:water-0
rule5=0,100,minecraft:prismarine-1
rule6=0,100,minecraft:sea_lantern-0
rule7=0,100,IInventory;minecraft:blue_shulker_box;minecraft:dye#2#4#1+quark:crystal#2#6#5+quark:crystal#3#6#8+quark:crystal#3#6#9+minecraft:leather_boots#{"Quark:RuneColor":11,ench:[{lvl:3s,id:5s},{lvl:3s,id:8s},{lvl:1s,id:6s}],RepairCost:7,display:{color:3949738,Name:"The Blue Boots"},"Quark:RuneAttached":1b}#0#13+minecraft:dye#2#4#16+quark:crystal#4#6#19+minecraft:dye#3#4#20+minecraft:diamond_horse_armor#1#0#23+quark:crystal#4#6#24-1

layer
1,1,1,1,1,1,1,1,1,1,1,1,1,1,1,1,1
1,1,1,1,1,1,1,1,1,1,1,1,1,1,1,1,1
1,1,1,1,1,1,1,1,1,1,1,1,1,1,1,1,1
1,1,1,1,1,1,1,1,1,1,1,1,1,1,1,1,1
1,1,1,1,1,1,1,1,1,1,1,1,1,1,1,1,1
1,1,1,1,1,1,1,1,1,1,1,1,1,1,1,1,1
1,1,1,1,1,1,1,2,2,2,1,1,1,1,1,1,1
1,1,1,1,1,1,2,2,2,2,2,1,1,1,1,1,1
1,1,1,1,1,1,2,2,2,2,2,1,1,1,1,1,1
1,1,1,1,1,1,2,2,2,2,2,1,1,1,1,1,1
1,1,1,1,1,1,1,2,2,2,1,1,1,1,1,1,1
1,1,1,1,1,1,1,1,1,1,1,1,1,1,1,1,1
1,1,1,1,1,1,1,1,1,1,1,1,1,1,1,1,1
1,1,1,1,1,1,1,1,1,1,1,1,1,1,1,1,1
1,1,1,1,1,1,1,1,1,1,1,1,1,1,1,1,1
1,1,1,1,1,1,1,1,1,1,1,1,1,1,1,1,1
1,1,1,1,1,1,1,1,1,1,1,1,1,1,1,1,1
endlayer

layer
1,1,1,1,1,1,1,1,1,1,1,1,1,1,1,1,1
1,1,1,1,1,1,1,1,1,1,1,1,1,1,1,1,1
1,1,1,1,1,1,1,1,1,1,1,1,1,1,1,1,1
1,1,1,1,1,1,1,1,1,1,1,1,1,1,1,1,1
1,1,1,1,1,1,2,2,2,2,2,1,1,1,1,1,1
1,1,1,1,1,2,2,2,2,2,2,2,1,1,1,1,1
1,1,1,1,2,2,2,3,3,3,2,2,2,1,1,1,1
1,1,1,1,2,2,3,3,3,3,3,2,2,1,1,1,1
1,1,1,1,2,2,3,3,3,3,3,2,2,1,1,1,1
1,1,1,1,2,2,3,3,3,3,3,2,2,1,1,1,1
1,1,1,1,2,2,2,3,3,3,2,2,2,1,1,1,1
1,1,1,1,1,2,2,2,2,2,2,2,1,1,1,1,1
1,1,1,1,1,1,2,2,2,2,2,1,1,1,1,1,1
1,1,1,1,1,1,1,1,1,1,1,1,1,1,1,1,1
1,1,1,1,1,1,1,1,1,1,1,1,1,1,1,1,1
1,1,1,1,1,1,1,1,1,1,1,1,1,1,1,1,1
1,1,1,1,1,1,1,1,1,1,1,1,1,1,1,1,1
endlayer

layer
1,1,1,1,1,1,1,1,1,1,1,1,1,1,1,1,1
1,1,1,1,1,1,1,1,1,1,1,1,1,1,1,1,1
1,1,1,1,1,1,1,1,1,1,1,1,1,1,1,1,1
1,1,1,1,1,2,2,2,2,2,2,2,1,1,1,1,1
1,1,1,1,2,2,4,4,4,4,4,2,2,1,1,1,1
1,1,1,2,2,4,4,4,4,4,4,4,2,2,1,1,1
1,1,1,2,4,4,4,4,4,4,4,4,4,2,1,1,1
1,1,1,2,4,4,4,3,3,3,4,4,4,2,1,1,1
1,1,1,2,4,4,4,3,3,3,4,4,4,2,1,1,1
1,1,1,2,4,4,4,3,3,3,4,4,4,2,1,1,1
1,1,1,2,4,4,4,4,4,4,4,4,4,2,1,1,1
1,1,1,2,2,4,4,4,4,4,4,4,2,2,1,1,1
1,1,1,1,2,2,4,4,4,4,4,2,2,1,1,1,1
1,1,1,1,1,2,2,2,2,2,2,2,1,1,1,1,1
1,1,1,1,1,1,1,1,1,1,1,1,1,1,1,1,1
1,1,1,1,1,1,1,1,1,1,1,1,1,1,1,1,1
1,1,1,1,1,1,1,1,1,1,1,1,1,1,1,1,1
endlayer

layer
1,1,1,1,1,1,1,1,1,1,1,1,1,1,1,1,1
1,1,1,1,1,1,1,1,1,1,1,1,1,1,1,1,1
1,1,1,1,1,2,2,2,2,2,2,2,1,1,1,1,1
1,1,1,1,2,4,4,4,4,4,4,4,2,1,1,1,1
1,1,1,2,4,4,4,4,4,4,4,4,4,2,1,1,1
1,1,2,4,4,4,4,4,4,4,4,4,4,4,2,1,1
1,1,2,4,4,4,4,4,4,4,4,4,4,4,2,1,1
1,1,2,4,4,4,4,4,4,4,4,4,4,4,2,1,1
1,1,2,4,4,4,4,4,5,4,4,4,4,4,2,1,1
1,1,2,4,4,4,4,4,4,4,4,4,4,4,2,1,1
1,1,2,4,4,4,4,4,4,4,4,4,4,4,2,1,1
1,1,2,4,4,4,4,4,4,4,4,4,4,4,2,1,1
1,1,1,2,4,4,4,4,4,4,4,4,4,2,1,1,1
1,1,1,1,2,4,4,4,4,4,4,4,2,1,1,1,1
1,1,1,1,1,2,2,2,2,2,2,2,1,1,1,1,1
1,1,1,1,1,1,1,1,1,1,1,1,1,1,1,1,1
1,1,1,1,1,1,1,1,1,1,1,1,1,1,1,1,1
endlayer

layer
1,1,1,1,1,1,1,1,1,1,1,1,1,1,1,1,1
1,1,1,1,1,1,2,2,2,2,2,1,1,1,1,1,1
1,1,1,1,2,2,4,4,4,4,4,2,2,1,1,1,1
1,1,1,2,4,4,4,4,4,4,4,4,4,2,1,1,1
1,1,2,4,4,4,4,4,4,4,4,4,4,4,2,1,1
1,1,2,4,4,4,4,4,4,4,4,4,4,4,2,1,1
1,2,4,4,4,4,4,4,4,4,4,4,4,4,4,2,1
1,2,4,4,4,4,4,4,4,4,4,4,4,4,4,2,1
1,2,4,4,4,4,4,4,5,4,4,4,4,4,4,2,1
1,2,4,4,4,4,4,4,4,4,4,4,4,4,4,2,1
1,2,4,4,4,4,4,4,4,4,4,4,4,4,4,2,1
1,1,2,4,4,4,4,4,4,4,4,4,4,4,2,1,1
1,1,2,4,4,4,4,4,4,4,4,4,4,4,2,1,1
1,1,1,2,4,4,4,4,4,4,4,4,4,2,1,1,1
1,1,1,1,2,2,4,4,4,4,4,2,2,1,1,1,1
1,1,1,1,1,1,2,2,2,2,2,1,1,1,1,1,1
1,1,1,1,1,1,1,1,1,1,1,1,1,1,1,1,1
endlayer

layer
1,1,1,1,1,1,1,1,1,1,1,1,1,1,1,1,1
1,1,1,1,1,2,2,2,2,2,2,2,1,1,1,1,1
1,1,1,2,2,4,4,4,4,4,4,4,2,2,1,1,1
1,1,2,4,4,4,4,4,4,4,4,4,4,4,2,1,1
1,1,2,4,4,4,4,4,4,4,4,4,4,4,2,1,1
1,2,4,4,4,4,4,4,4,4,4,4,4,4,4,2,1
1,2,4,4,4,4,4,4,4,4,4,4,4,4,4,2,1
1,2,4,4,4,4,4,4,4,4,4,4,4,4,4,2,1
1,2,4,4,4,4,4,4,5,4,4,4,4,4,4,2,1
1,2,4,4,4,4,4,4,4,4,4,4,4,4,4,2,1
1,2,4,4,4,4,4,4,4,4,4,4,4,4,4,2,1
1,2,4,4,4,4,4,4,4,4,4,4,4,4,4,2,1
1,1,2,4,4,4,4,4,4,4,4,4,4,4,2,1,1
1,1,2,4,4,4,4,4,4,4,4,4,4,4,2,1,1
1,1,1,2,2,4,4,4,4,4,4,4,2,2,1,1,1
1,1,1,1,1,2,2,2,2,2,2,2,1,1,1,1,1
1,1,1,1,1,1,1,1,1,1,1,1,1,1,1,1,1
endlayer

layer
1,1,1,1,1,1,1,2,2,2,1,1,1,1,1,1,1
1,1,1,1,2,2,2,4,4,4,2,2,2,1,1,1,1
1,1,1,2,4,4,4,4,4,4,4,4,4,2,1,1,1
1,1,2,4,4,4,4,4,4,4,4,4,4,4,2,1,1
1,2,4,4,4,4,4,4,4,4,4,4,4,4,4,2,1
1,2,4,4,4,4,4,4,4,4,4,4,4,4,4,2,1
1,2,4,4,4,4,4,4,4,4,4,4,4,4,4,2,1
2,4,4,4,4,4,4,4,4,4,4,4,4,4,4,4,2
2,4,4,4,4,4,4,4,5,4,4,4,4,4,4,4,2
2,4,4,4,4,4,4,4,4,4,4,4,4,4,4,4,2
1,2,4,4,4,4,4,4,4,4,4,4,4,4,4,2,1
1,2,4,4,4,4,4,4,4,4,4,4,4,4,4,2,1
1,2,4,4,4,4,4,4,4,4,4,4,4,4,4,2,1
1,1,2,4,4,4,4,4,4,4,4,4,4,4,2,1,1
1,1,1,2,4,4,4,4,4,4,4,4,4,2,1,1,1
1,1,1,1,2,2,2,4,4,4,2,2,2,1,1,1,1
1,1,1,1,1,1,1,2,2,2,1,1,1,1,1,1,1
endlayer

layer
1,1,1,1,1,1,2,2,2,2,2,1,1,1,1,1,1
1,1,1,1,2,2,4,4,4,4,4,2,2,1,1,1,1
1,1,1,2,4,4,4,4,4,4,4,4,4,2,1,1,1
1,1,2,4,4,4,4,4,4,4,4,4,4,4,2,1,1
1,2,4,4,4,4,4,4,4,4,4,4,4,4,4,2,1
1,2,4,4,4,4,4,4,4,4,4,4,4,4,4,2,1
2,4,4,4,4,4,4,4,4,4,4,4,4,4,4,4,2
2,4,4,4,4,4,4,3,3,3,4,4,4,4,4,4,2
2,4,4,4,4,4,4,3,6,3,4,4,4,4,4,4,2
2,4,4,4,4,4,4,3,3,3,4,4,4,4,4,4,2
2,4,4,4,4,4,4,4,4,4,4,4,4,4,4,4,2
1,2,4,4,4,4,4,4,4,4,4,4,4,4,4,2,1
1,2,4,4,4,4,4,4,4,4,4,4,4,4,4,2,1
1,1,2,4,4,4,4,4,4,4,4,4,4,4,2,1,1
1,1,1,2,4,4,4,4,4,4,4,4,4,2,1,1,1
1,1,1,1,2,2,4,4,4,4,4,2,2,1,1,1,1
1,1,1,1,1,1,2,2,2,2,2,1,1,1,1,1,1
endlayer

layer
1,1,1,1,1,1,2,2,2,2,2,1,1,1,1,1,1
1,1,1,1,2,2,4,4,4,4,4,2,2,1,1,1,1
1,1,1,2,4,4,4,4,4,4,4,4,4,2,1,1,1
1,1,2,4,4,4,4,4,4,4,4,4,4,4,2,1,1
1,2,4,4,4,4,4,4,4,4,4,4,4,4,4,2,1
1,2,4,4,4,4,4,4,4,4,4,4,4,4,4,2,1
2,4,4,4,4,4,4,4,4,4,4,4,4,4,4,4,2
2,4,4,4,4,4,4,4,4,4,4,4,4,4,4,4,2
2,4,4,4,4,4,4,4,7,4,4,4,4,4,4,4,2
2,4,4,4,4,4,4,4,4,4,4,4,4,4,4,4,2
2,4,4,4,4,4,4,4,4,4,4,4,4,4,4,4,2
1,2,4,4,4,4,4,4,4,4,4,4,4,4,4,2,1
1,2,4,4,4,4,4,4,4,4,4,4,4,4,4,2,1
1,1,2,4,4,4,4,4,4,4,4,4,4,4,2,1,1
1,1,1,2,4,4,4,4,4,4,4,4,4,2,1,1,1
1,1,1,1,2,2,4,4,4,4,4,2,2,1,1,1,1
1,1,1,1,1,1,2,2,2,2,2,1,1,1,1,1,1
endlayer

layer
1,1,1,1,1,1,2,2,2,2,2,1,1,1,1,1,1
1,1,1,1,2,2,4,4,4,4,4,2,2,1,1,1,1
1,1,1,2,4,4,4,4,4,4,4,4,4,2,1,1,1
1,1,2,4,4,4,4,4,4,4,4,4,4,4,2,1,1
1,2,4,4,4,4,4,4,4,4,4,4,4,4,4,2,1
1,2,4,4,4,4,4,4,4,4,4,4,4,4,4,2,1
2,4,4,4,4,4,4,4,4,4,4,4,4,4,4,4,2
2,4,4,4,4,4,4,4,4,4,4,4,4,4,4,4,2
2,4,4,4,4,4,4,4,4,4,4,4,4,4,4,4,2
2,4,4,4,4,4,4,4,4,4,4,4,4,4,4,4,2
2,4,4,4,4,4,4,4,4,4,4,4,4,4,4,4,2
1,2,4,4,4,4,4,4,4,4,4,4,4,4,4,2,1
1,2,4,4,4,4,4,4,4,4,4,4,4,4,4,2,1
1,1,2,4,4,4,4,4,4,4,4,4,4,4,2,1,1
1,1,1,2,4,4,4,4,4,4,4,4,4,2,1,1,1
1,1,1,1,2,2,4,4,4,4,4,2,2,1,1,1,1
1,1,1,1,1,1,2,2,2,2,2,1,1,1,1,1,1
endlayer

layer
1,1,1,1,1,1,1,2,2,2,1,1,1,1,1,1,1
1,1,1,1,2,2,2,4,4,4,2,2,2,1,1,1,1
1,1,1,2,4,4,4,4,4,4,4,4,4,2,1,1,1
1,1,2,4,4,4,4,4,4,4,4,4,4,4,2,1,1
1,2,4,4,4,4,4,4,4,4,4,4,4,4,4,2,1
1,2,4,4,4,4,4,4,4,4,4,4,4,4,4,2,1
1,2,4,4,4,4,4,4,4,4,4,4,4,4,4,2,1
2,4,4,4,4,4,4,4,4,4,4,4,4,4,4,4,2
2,4,4,4,4,4,4,4,4,4,4,4,4,4,4,4,2
2,4,4,4,4,4,4,4,4,4,4,4,4,4,4,4,2
1,2,4,4,4,4,4,4,4,4,4,4,4,4,4,2,1
1,2,4,4,4,4,4,4,4,4,4,4,4,4,4,2,1
1,2,4,4,4,4,4,4,4,4,4,4,4,4,4,2,1
1,1,2,4,4,4,4,4,4,4,4,4,4,4,2,1,1
1,1,1,2,4,4,4,4,4,4,4,4,4,2,1,1,1
1,1,1,1,2,2,2,4,4,4,2,2,2,1,1,1,1
1,1,1,1,1,1,1,2,2,2,1,1,1,1,1,1,1
endlayer

layer
1,1,1,1,1,1,1,1,1,1,1,1,1,1,1,1,1
1,1,1,1,1,2,2,2,2,2,2,2,1,1,1,1,1
1,1,1,2,2,4,4,4,4,4,4,4,2,2,1,1,1
1,1,2,4,4,4,4,4,4,4,4,4,4,4,2,1,1
1,1,2,4,4,4,4,4,4,4,4,4,4,4,2,1,1
1,2,4,4,4,4,4,4,4,4,4,4,4,4,4,2,1
1,2,4,4,4,4,4,4,4,4,4,4,4,4,4,2,1
1,2,4,4,4,4,4,4,4,4,4,4,4,4,4,2,1
1,2,4,4,4,4,4,4,4,4,4,4,4,4,4,2,1
1,2,4,4,4,4,4,4,4,4,4,4,4,4,4,2,1
1,2,4,4,4,4,4,4,4,4,4,4,4,4,4,2,1
1,2,4,4,4,4,4,4,4,4,4,4,4,4,4,2,1
1,1,2,4,4,4,4,4,4,4,4,4,4,4,2,1,1
1,1,2,4,4,4,4,4,4,4,4,4,4,4,2,1,1
1,1,1,2,2,4,4,4,4,4,4,4,2,2,1,1,1
1,1,1,1,1,2,2,2,2,2,2,2,1,1,1,1,1
1,1,1,1,1,1,1,1,1,1,1,1,1,1,1,1,1
endlayer

layer
1,1,1,1,1,1,1,1,1,1,1,1,1,1,1,1,1
1,1,1,1,1,1,2,2,2,2,2,1,1,1,1,1,1
1,1,1,1,2,2,4,4,4,4,4,2,2,1,1,1,1
1,1,1,2,4,4,4,4,4,4,4,4,4,2,1,1,1
1,1,2,4,4,4,4,4,4,4,4,4,4,4,2,1,1
1,1,2,4,4,4,4,4,4,4,4,4,4,4,2,1,1
1,2,4,4,4,4,4,4,4,4,4,4,4,4,4,2,1
1,2,4,4,4,4,4,4,4,4,4,4,4,4,4,2,1
1,2,4,4,4,4,4,4,4,4,4,4,4,4,4,2,1
1,2,4,4,4,4,4,4,4,4,4,4,4,4,4,2,1
1,2,4,4,4,4,4,4,4,4,4,4,4,4,4,2,1
1,1,2,4,4,4,4,4,4,4,4,4,4,4,2,1,1
1,1,2,4,4,4,4,4,4,4,4,4,4,4,2,1,1
1,1,1,2,4,4,4,4,4,4,4,4,4,2,1,1,1
1,1,1,1,2,2,4,4,4,4,4,2,2,1,1,1,1
1,1,1,1,1,1,2,2,2,2,2,1,1,1,1,1,1
1,1,1,1,1,1,1,1,1,1,1,1,1,1,1,1,1
endlayer

layer
1,1,1,1,1,1,1,1,1,1,1,1,1,1,1,1,1
1,1,1,1,1,1,1,1,1,1,1,1,1,1,1,1,1
1,1,1,1,1,2,2,2,2,2,2,2,1,1,1,1,1
1,1,1,1,2,4,4,4,4,4,4,4,2,1,1,1,1
1,1,1,2,4,4,4,4,4,4,4,4,4,2,1,1,1
1,1,2,4,4,4,4,4,4,4,4,4,4,4,2,1,1
1,1,2,4,4,4,4,4,4,4,4,4,4,4,2,1,1
1,1,2,4,4,4,4,4,4,4,4,4,4,4,2,1,1
1,1,2,4,4,4,4,4,4,4,4,4,4,4,2,1,1
1,1,2,4,4,4,4,4,4,4,4,4,4,4,2,1,1
1,1,2,4,4,4,4,4,4,4,4,4,4,4,2,1,1
1,1,2,4,4,4,4,4,4,4,4,4,4,4,2,1,1
1,1,1,2,4,4,4,4,4,4,4,4,4,2,1,1,1
1,1,1,1,2,4,4,4,4,4,4,4,2,1,1,1,1
1,1,1,1,1,2,2,2,2,2,2,2,1,1,1,1,1
1,1,1,1,1,1,1,1,1,1,1,1,1,1,1,1,1
1,1,1,1,1,1,1,1,1,1,1,1,1,1,1,1,1
endlayer

layer
1,1,1,1,1,1,1,1,1,1,1,1,1,1,1,1,1
1,1,1,1,1,1,1,1,1,1,1,1,1,1,1,1,1
1,1,1,1,1,1,1,1,1,1,1,1,1,1,1,1,1
1,1,1,1,1,2,2,2,2,2,2,2,1,1,1,1,1
1,1,1,1,2,2,4,4,4,4,4,2,2,1,1,1,1
1,1,1,2,2,4,4,4,4,4,4,4,2,2,1,1,1
1,1,1,2,4,4,4,4,4,4,4,4,4,2,1,1,1
1,1,1,2,4,4,4,4,4,4,4,4,4,2,1,1,1
1,1,1,2,4,4,4,4,4,4,4,4,4,2,1,1,1
1,1,1,2,4,4,4,4,4,4,4,4,4,2,1,1,1
1,1,1,2,4,4,4,4,4,4,4,4,4,2,1,1,1
1,1,1,2,2,4,4,4,4,4,4,4,2,2,1,1,1
1,1,1,1,2,2,4,4,4,4,4,2,2,1,1,1,1
1,1,1,1,1,2,2,2,2,2,2,2,1,1,1,1,1
1,1,1,1,1,1,1,1,1,1,1,1,1,1,1,1,1
1,1,1,1,1,1,1,1,1,1,1,1,1,1,1,1,1
1,1,1,1,1,1,1,1,1,1,1,1,1,1,1,1,1
endlayer

layer
1,1,1,1,1,1,1,1,1,1,1,1,1,1,1,1,1
1,1,1,1,1,1,1,1,1,1,1,1,1,1,1,1,1
1,1,1,1,1,1,1,1,1,1,1,1,1,1,1,1,1
1,1,1,1,1,1,1,1,1,1,1,1,1,1,1,1,1
1,1,1,1,1,1,2,2,2,2,2,1,1,1,1,1,1
1,1,1,1,1,2,2,2,2,2,2,2,1,1,1,1,1
1,1,1,1,2,2,2,4,4,4,2,2,2,1,1,1,1
1,1,1,1,2,2,4,4,4,4,4,2,2,1,1,1,1
1,1,1,1,2,2,4,4,4,4,4,2,2,1,1,1,1
1,1,1,1,2,2,4,4,4,4,4,2,2,1,1,1,1
1,1,1,1,2,2,2,4,4,4,2,2,2,1,1,1,1
1,1,1,1,1,2,2,2,2,2,2,2,1,1,1,1,1
1,1,1,1,1,1,2,2,2,2,2,1,1,1,1,1,1
1,1,1,1,1,1,1,1,1,1,1,1,1,1,1,1,1
1,1,1,1,1,1,1,1,1,1,1,1,1,1,1,1,1
1,1,1,1,1,1,1,1,1,1,1,1,1,1,1,1,1
1,1,1,1,1,1,1,1,1,1,1,1,1,1,1,1,1
endlayer

layer
1,1,1,1,1,1,1,1,1,1,1,1,1,1,1,1,1
1,1,1,1,1,1,1,1,1,1,1,1,1,1,1,1,1
1,1,1,1,1,1,1,1,1,1,1,1,1,1,1,1,1
1,1,1,1,1,1,1,1,1,1,1,1,1,1,1,1,1
1,1,1,1,1,1,1,1,1,1,1,1,1,1,1,1,1
1,1,1,1,1,1,1,1,1,1,1,1,1,1,1,1,1
1,1,1,1,1,1,1,2,2,2,1,1,1,1,1,1,1
1,1,1,1,1,1,2,2,2,2,2,1,1,1,1,1,1
1,1,1,1,1,1,2,2,2,2,2,1,1,1,1,1,1
1,1,1,1,1,1,2,2,2,2,2,1,1,1,1,1,1
1,1,1,1,1,1,1,2,2,2,1,1,1,1,1,1,1
1,1,1,1,1,1,1,1,1,1,1,1,1,1,1,1,1
1,1,1,1,1,1,1,1,1,1,1,1,1,1,1,1,1
1,1,1,1,1,1,1,1,1,1,1,1,1,1,1,1,1
1,1,1,1,1,1,1,1,1,1,1,1,1,1,1,1,1
1,1,1,1,1,1,1,1,1,1,1,1,1,1,1,1,1
1,1,1,1,1,1,1,1,1,1,1,1,1,1,1,1,1
endlayer

