
# Created by Ruins mod version 17.0 Ingame Parser
# authoring Player: ST753M

weight=1
embed_into_distance=4
acceptable_target_blocks=
unacceptable_target_blocks=flowing_water,water,flowing_lava,lava
dimensions=15,25,17
allowable_overhang=0
max_leveling=0
leveling_buffer=-1
preserve_water=0
preserve_lava=0

=0,100,air
rule1=0,100,preserveBlock
rule2=0,100,minecraft:stone-0
rule3=0,100,minecraft:stained_hardened_clay-2
rule4=0,100,minecraft:water-8
rule5=0,100,minecraft:water-0
rule6=0,100,quark:stained_clay_tiles-2
rule7=0,100,quark:stained_clay_tiles_magenta_slab-0
rule8=0,100,quark:crystal-7
rule9=0,100,IInventory;minecraft:magenta_shulker_box;minecraft:red_flower#3#2#2+quark:crystal#18#7#8+minecraft:dye#9#13#9+minecraft:iron_pickaxe#{"Quark:RuneColor":2,ench:[{lvl:3s,id:32s},{lvl:3s,id:34s}],RepairCost:3,"Quark:ItemNameDye":13,display:{Name:"The Magenta Pickaxe"},"Quark:RuneAttached":1b}#0#13+minecraft:double_plant#4#1#24-0

layer
1,1,1,1,1,1,1,1,1,1,1,1,1,1,1,1,1
1,1,1,1,1,1,1,1,1,1,1,1,1,1,1,1,1
1,1,1,1,1,1,1,1,1,1,1,1,1,1,1,1,1
1,1,1,1,1,1,1,1,1,1,1,1,1,1,1,1,1
1,1,1,1,1,1,1,2,2,2,1,1,1,1,1,1,1
1,1,1,1,1,1,2,3,3,3,2,1,1,1,1,1,1
1,1,1,1,1,1,2,3,3,3,2,1,1,1,1,1,1
1,1,1,1,1,2,3,3,3,3,3,2,1,1,1,1,1
1,1,1,1,1,2,3,3,3,3,3,2,1,1,1,1,1
1,1,1,1,1,2,3,3,3,3,3,2,1,1,1,1,1
1,1,1,1,2,3,3,3,3,3,3,3,2,1,1,1,1
1,1,1,1,2,3,3,3,3,3,3,3,2,1,1,1,1
1,1,1,1,2,3,3,3,3,3,3,3,2,1,1,1,1
1,1,1,1,2,3,3,3,3,3,3,3,2,1,1,1,1
1,1,1,1,2,3,3,3,3,3,3,3,2,1,1,1,1
1,1,1,1,1,2,3,3,3,3,3,2,1,1,1,1,1
1,1,1,1,1,2,3,3,3,3,3,2,1,1,1,1,1
1,1,1,1,1,2,3,3,3,3,3,2,1,1,1,1,1
1,1,1,1,1,1,2,3,3,3,2,1,1,1,1,1,1
1,1,1,1,1,1,2,3,3,3,2,1,1,1,1,1,1
1,1,1,1,1,1,1,2,2,2,1,1,1,1,1,1,1
1,1,1,1,1,1,1,1,1,1,1,1,1,1,1,1,1
1,1,1,1,1,1,1,1,1,1,1,1,1,1,1,1,1
1,1,1,1,1,1,1,1,1,1,1,1,1,1,1,1,1
1,1,1,1,1,1,1,1,1,1,1,1,1,1,1,1,1
endlayer

layer
1,1,1,1,1,1,1,1,1,1,1,1,1,1,1,1,1
1,1,1,1,1,1,1,1,1,1,1,1,1,1,1,1,1
1,1,1,1,1,1,1,1,1,1,1,1,1,1,1,1,1
1,1,1,1,1,1,1,2,2,2,1,1,1,1,1,1,1
1,1,1,1,1,1,2,3,3,3,2,1,1,1,1,1,1
1,1,1,1,1,2,3,3,3,3,3,2,1,1,1,1,1
1,1,1,1,1,2,3,4,4,4,3,2,1,1,1,1,1
1,1,1,1,2,3,5,5,5,5,5,3,2,1,1,1,1
1,1,1,1,2,3,5,5,5,5,5,3,2,1,1,1,1
1,1,1,1,2,3,5,5,5,5,5,3,2,1,1,1,1
1,1,1,2,3,5,5,5,5,5,5,5,3,2,1,1,1
1,1,1,2,3,5,5,5,5,5,5,5,3,2,1,1,1
1,1,1,2,3,5,5,5,5,5,5,5,3,2,1,1,1
1,1,1,2,3,5,5,5,5,5,5,5,3,2,1,1,1
1,1,1,2,3,5,5,5,5,5,5,5,3,2,1,1,1
1,1,1,1,2,3,5,5,5,5,5,3,2,1,1,1,1
1,1,1,1,2,3,5,5,5,5,5,3,2,1,1,1,1
1,1,1,1,2,3,5,5,5,5,5,3,2,1,1,1,1
1,1,1,1,1,2,3,5,5,5,3,2,1,1,1,1,1
1,1,1,1,1,2,3,3,3,3,3,2,1,1,1,1,1
1,1,1,1,1,1,2,3,3,3,2,1,1,1,1,1,1
1,1,1,1,1,1,1,2,2,2,1,1,1,1,1,1,1
1,1,1,1,1,1,1,1,1,1,1,1,1,1,1,1,1
1,1,1,1,1,1,1,1,1,1,1,1,1,1,1,1,1
1,1,1,1,1,1,1,1,1,1,1,1,1,1,1,1,1
endlayer

layer
1,1,1,1,1,1,1,1,1,1,1,1,1,1,1,1,1
1,1,1,1,1,1,1,1,1,1,1,1,1,1,1,1,1
1,1,1,1,1,1,1,1,1,1,1,1,1,1,1,1,1
1,1,1,1,1,1,1,2,2,2,1,1,1,1,1,1,1
1,1,1,1,1,1,2,3,3,3,2,1,1,1,1,1,1
1,1,1,1,1,2,3,3,3,3,3,2,1,1,1,1,1
1,1,1,1,1,2,3,5,5,5,3,2,1,1,1,1,1
1,1,1,1,2,3,5,5,5,5,5,3,2,1,1,1,1
1,1,1,1,2,3,5,5,5,5,5,3,2,1,1,1,1
1,1,1,1,2,3,5,5,5,5,5,3,2,1,1,1,1
1,1,1,2,3,5,5,5,5,5,5,5,3,2,1,1,1
1,1,1,2,3,5,5,5,5,5,5,5,3,2,1,1,1
1,1,1,2,3,5,5,5,5,5,5,5,3,2,1,1,1
1,1,1,2,3,5,5,5,5,5,5,5,3,2,1,1,1
1,1,1,2,3,5,5,5,5,5,5,5,3,2,1,1,1
1,1,1,1,2,3,5,5,5,5,5,3,2,1,1,1,1
1,1,1,1,2,3,5,5,5,5,5,3,2,1,1,1,1
1,1,1,1,2,3,5,5,5,5,5,3,2,1,1,1,1
1,1,1,1,1,2,3,5,5,5,3,2,1,1,1,1,1
1,1,1,1,1,2,3,3,3,3,3,2,1,1,1,1,1
1,1,1,1,1,1,2,3,3,3,2,1,1,1,1,1,1
1,1,1,1,1,1,1,2,2,2,1,1,1,1,1,1,1
1,1,1,1,1,1,1,1,1,1,1,1,1,1,1,1,1
1,1,1,1,1,1,1,1,1,1,1,1,1,1,1,1,1
1,1,1,1,1,1,1,1,1,1,1,1,1,1,1,1,1
endlayer

layer
1,1,1,1,1,1,1,1,1,1,1,1,1,1,1,1,1
1,1,1,1,1,1,2,2,2,2,2,1,1,1,1,1,1
1,1,1,1,1,2,3,3,3,3,3,2,1,1,1,1,1
1,1,1,1,2,3,3,3,3,3,3,3,2,1,1,1,1
1,1,1,2,3,3,3,3,3,3,3,3,3,2,1,1,1
1,1,1,2,3,3,6,6,6,6,6,3,3,2,1,1,1
1,1,2,3,3,6,6,5,5,5,6,6,3,3,2,1,1
1,1,2,3,3,6,5,5,5,5,5,6,3,3,2,1,1
1,1,2,3,3,6,5,5,5,5,5,6,3,3,2,1,1
1,2,3,3,6,6,5,5,5,5,5,6,6,3,3,2,1
1,2,3,3,6,5,5,5,5,5,5,5,6,3,3,2,1
1,2,3,3,6,5,5,5,5,5,5,5,6,3,3,2,1
1,2,3,3,6,5,5,5,5,5,5,5,6,3,3,2,1
1,2,3,3,6,5,5,5,5,5,5,5,6,3,3,2,1
1,2,3,3,6,5,5,5,5,5,5,5,6,3,3,2,1
1,2,3,3,6,6,5,5,5,5,5,6,6,3,3,2,1
1,1,2,3,3,6,5,5,5,5,5,6,3,3,2,1,1
1,1,2,3,3,6,5,5,5,5,5,6,3,3,2,1,1
1,1,2,3,3,6,6,5,5,5,6,6,3,3,2,1,1
1,1,1,2,3,3,6,6,6,6,6,3,3,2,1,1,1
1,1,1,2,3,3,3,3,3,3,3,3,3,2,1,1,1
1,1,1,1,2,3,3,3,3,3,3,3,2,1,1,1,1
1,1,1,1,1,2,3,3,3,3,3,2,1,1,1,1,1
1,1,1,1,1,1,2,2,2,2,2,1,1,1,1,1,1
1,1,1,1,1,1,1,1,1,1,1,1,1,1,1,1,1
endlayer

layer
1,1,1,1,1,1,2,2,2,2,2,1,1,1,1,1,1
1,1,1,1,1,2,3,3,3,3,3,2,1,1,1,1,1
1,1,1,1,2,3,0,0,0,0,0,3,2,1,1,1,1
1,1,1,2,3,0,0,0,0,0,0,0,3,2,1,1,1
1,1,2,3,0,0,0,0,0,0,0,0,0,3,2,1,1
1,1,2,3,0,0,7,7,7,7,7,0,0,3,2,1,1
1,2,3,0,0,7,7,0,0,0,7,7,0,0,3,2,1
1,2,3,0,0,7,0,0,0,0,0,7,0,0,3,2,1
1,2,3,0,0,7,0,0,0,0,0,7,0,0,3,2,1
2,3,0,0,7,7,0,0,0,0,0,7,7,0,0,3,2
2,3,0,0,7,0,0,0,0,0,0,0,7,0,0,3,2
2,3,0,0,7,0,0,0,0,0,0,0,7,0,0,3,2
2,3,0,0,7,0,0,0,0,0,0,0,7,0,0,3,2
2,3,0,0,7,0,0,0,0,0,0,0,7,0,0,3,2
2,3,0,0,7,0,0,0,0,0,0,0,7,0,0,3,2
2,3,0,0,7,7,0,0,0,0,0,7,7,0,0,3,2
1,2,3,0,0,7,0,0,0,0,0,7,0,0,3,2,1
1,2,3,0,0,7,0,0,0,0,0,7,0,0,3,2,1
1,2,3,0,0,7,7,0,0,0,7,7,0,0,3,2,1
1,1,2,3,0,0,7,7,7,7,7,0,0,3,2,1,1
1,1,2,3,0,0,0,0,0,0,0,0,0,3,2,1,1
1,1,1,2,3,0,0,0,0,0,0,0,3,2,1,1,1
1,1,1,1,2,3,0,0,0,0,0,3,2,1,1,1,1
1,1,1,1,1,2,3,3,3,3,3,2,1,1,1,1,1
1,1,1,1,1,1,2,2,2,2,2,1,1,1,1,1,1
endlayer

layer
1,1,1,1,1,1,1,1,2,1,1,1,1,1,1,1,1
1,1,1,1,1,1,0,2,3,2,0,1,1,1,1,1,1
1,1,1,1,2,0,0,0,0,0,0,0,2,1,1,1,1
1,1,1,2,3,0,0,0,0,0,0,0,3,2,1,1,1
1,1,1,0,0,0,0,0,0,0,0,0,0,0,1,1,1
1,1,1,0,0,0,0,0,0,0,0,0,0,0,1,1,1
1,2,3,0,0,0,0,0,0,0,0,0,0,0,3,2,1
1,1,0,0,0,0,0,0,0,0,0,0,0,0,0,1,1
1,1,0,0,0,0,0,0,0,0,0,0,0,0,0,1,1
2,3,0,0,0,0,0,0,0,0,0,0,0,0,0,3,2
1,0,0,0,0,0,0,0,0,0,0,0,0,0,0,0,1
1,0,0,0,0,0,0,0,0,0,0,0,0,0,0,0,1
2,3,0,0,0,0,0,0,0,0,0,0,0,0,0,3,2
1,0,0,0,0,0,0,0,0,0,0,0,0,0,0,0,1
1,0,0,0,0,0,0,0,0,0,0,0,0,0,0,0,1
2,3,0,0,0,0,0,0,0,0,0,0,0,0,0,3,2
1,1,0,0,0,0,0,0,0,0,0,0,0,0,0,1,1
1,1,0,0,0,0,0,0,0,0,0,0,0,0,0,1,1
1,2,3,0,0,0,0,0,0,0,0,0,0,0,3,2,1
1,1,1,0,0,0,0,0,0,0,0,0,0,0,1,1,1
1,1,1,0,0,0,0,0,0,0,0,0,0,0,1,1,1
1,1,1,2,3,0,0,0,0,0,0,0,3,2,1,1,1
1,1,1,1,2,0,0,0,0,0,0,0,2,1,1,1,1
1,1,1,1,1,1,0,2,3,2,0,1,1,1,1,1,1
1,1,1,1,1,1,1,1,2,1,1,1,1,1,1,1,1
endlayer

layer
1,1,1,1,1,1,1,1,2,1,1,1,1,1,1,1,1
1,1,1,1,1,1,0,2,3,2,0,1,1,1,1,1,1
1,1,1,1,2,0,0,0,0,0,0,0,2,1,1,1,1
1,1,1,2,3,0,0,0,0,0,0,0,3,2,1,1,1
1,1,1,0,0,0,0,0,0,0,0,0,0,0,1,1,1
1,1,1,0,0,0,0,0,0,0,0,0,0,0,1,1,1
1,2,3,0,0,0,0,0,0,0,0,0,0,0,3,2,1
1,1,0,0,0,0,0,0,0,0,0,0,0,0,0,1,1
1,1,0,0,0,0,0,0,0,0,0,0,0,0,0,1,1
2,3,0,0,0,0,0,0,0,0,0,0,0,0,0,3,2
1,0,0,0,0,0,0,0,0,0,0,0,0,0,0,0,1
1,0,0,0,0,0,0,0,0,0,0,0,0,0,0,0,1
2,3,0,0,0,0,0,0,0,0,0,0,0,0,0,3,2
1,0,0,0,0,0,0,0,0,0,0,0,0,0,0,0,1
1,0,0,0,0,0,0,0,0,0,0,0,0,0,0,0,1
2,3,0,0,0,0,0,0,0,0,0,0,0,0,0,3,2
1,1,0,0,0,0,0,0,0,0,0,0,0,0,0,1,1
1,1,0,0,0,0,0,0,0,0,0,0,0,0,0,1,1
1,2,3,0,0,0,0,0,0,0,0,0,0,0,3,2,1
1,1,1,0,0,0,0,0,0,0,0,0,0,0,1,1,1
1,1,1,0,0,0,0,0,0,0,0,0,0,0,1,1,1
1,1,1,2,3,0,0,0,0,0,0,0,3,2,1,1,1
1,1,1,1,2,0,0,0,0,0,0,0,2,1,1,1,1
1,1,1,1,1,1,0,2,3,2,0,1,1,1,1,1,1
1,1,1,1,1,1,1,1,2,1,1,1,1,1,1,1,1
endlayer

layer
1,1,1,1,1,1,1,2,2,2,1,1,1,1,1,1,1
1,1,1,1,1,1,0,2,3,2,0,1,1,1,1,1,1
1,1,1,1,2,0,0,0,0,0,0,0,2,1,1,1,1
1,1,1,2,3,0,0,0,0,0,0,0,3,2,1,1,1
1,1,1,0,0,0,0,0,0,0,0,0,0,0,1,1,1
1,1,1,0,0,0,0,0,0,0,0,0,0,0,1,1,1
1,2,3,0,0,0,0,0,0,0,0,0,0,0,3,2,1
1,1,0,0,0,0,0,0,0,0,0,0,0,0,0,1,1
1,1,0,0,0,0,0,0,0,0,0,0,0,0,0,1,1
2,3,0,0,0,0,0,0,0,0,0,0,0,0,0,3,2
1,0,0,0,0,0,0,0,0,0,0,0,0,0,0,0,1
1,0,0,0,0,0,0,0,0,0,0,0,0,0,0,0,1
2,3,0,0,0,0,0,0,0,0,0,0,0,0,0,3,2
1,0,0,0,0,0,0,0,0,0,0,0,0,0,0,0,1
1,0,0,0,0,0,0,0,0,0,0,0,0,0,0,0,1
2,3,0,0,0,0,0,0,0,0,0,0,0,0,0,3,2
1,1,0,0,0,0,0,0,0,0,0,0,0,0,0,1,1
1,1,0,0,0,0,0,0,0,0,0,0,0,0,0,1,1
1,2,3,0,0,0,0,0,0,0,0,0,0,0,3,2,1
1,1,1,0,0,0,0,0,0,0,0,0,0,0,1,1,1
1,1,1,0,0,0,0,0,0,0,0,0,0,0,1,1,1
1,1,1,2,3,0,0,0,0,0,0,0,3,2,1,1,1
1,1,1,1,2,0,0,0,0,0,0,0,2,1,1,1,1
1,1,1,1,1,1,0,2,3,2,0,1,1,1,1,1,1
1,1,1,1,1,1,1,2,2,2,1,1,1,1,1,1,1
endlayer

layer
1,1,1,1,1,1,2,2,8,2,2,1,1,1,1,1,1
1,1,1,1,1,2,3,3,3,3,3,2,1,1,1,1,1
1,1,1,1,2,3,0,0,0,0,0,3,2,1,1,1,1
1,1,1,2,3,0,0,0,0,0,0,0,3,2,1,1,1
1,1,2,3,0,0,0,0,0,0,0,0,0,3,2,1,1
1,1,2,3,0,0,0,0,0,0,0,0,0,3,2,1,1
1,2,3,0,0,0,0,0,0,0,0,0,0,0,3,2,1
1,2,3,0,0,0,0,0,0,0,0,0,0,0,3,2,1
1,2,3,0,0,0,0,0,0,0,0,0,0,0,3,2,1
2,3,0,0,0,0,0,0,0,0,0,0,0,0,0,3,2
2,3,0,0,0,0,0,0,0,0,0,0,0,0,0,3,2
2,3,0,0,0,0,0,0,0,0,0,0,0,0,0,3,2
2,3,0,0,0,0,0,0,0,0,0,0,0,0,0,3,2
2,3,0,0,0,0,0,0,0,0,0,0,0,0,0,3,2
2,3,0,0,0,0,0,0,0,0,0,0,0,0,0,3,2
2,3,0,0,0,0,0,0,0,0,0,0,0,0,0,3,2
1,2,3,0,0,0,0,0,0,0,0,0,0,0,3,2,1
1,2,3,0,0,0,0,0,0,0,0,0,0,0,3,2,1
1,2,3,0,0,0,0,0,0,0,0,0,0,0,3,2,1
1,1,2,3,0,0,0,0,0,0,0,0,0,3,2,1,1
1,1,2,3,0,0,0,0,0,0,0,0,0,3,2,1,1
1,1,1,2,3,0,0,0,0,0,0,0,3,2,1,1,1
1,1,1,1,2,3,0,0,0,0,0,3,2,1,1,1,1
1,1,1,1,1,2,3,3,3,3,3,2,1,1,1,1,1
1,1,1,1,1,1,2,2,8,2,2,1,1,1,1,1,1
endlayer

layer
1,1,1,1,1,1,1,2,2,2,1,1,1,1,1,1,1
1,1,1,1,1,2,2,2,6,2,2,2,1,1,1,1,1
1,1,1,1,2,6,6,6,6,6,6,6,2,1,1,1,1
1,1,1,2,6,0,0,0,0,0,0,0,6,2,1,1,1
1,1,2,6,0,0,0,0,0,0,0,0,0,6,2,1,1
1,1,2,6,0,0,0,0,0,0,0,0,0,6,2,1,1
1,2,6,0,0,0,0,0,0,0,0,0,0,0,6,2,1
1,2,6,0,0,0,0,0,0,0,0,0,0,0,6,2,1
1,2,6,0,0,0,0,0,0,0,0,0,0,0,6,2,1
1,2,6,0,0,0,0,0,0,0,0,0,0,0,6,2,1
2,6,0,0,0,0,0,0,0,0,0,0,0,0,0,6,2
2,6,0,0,0,0,0,0,0,0,0,0,0,0,0,6,2
2,6,0,0,0,0,0,0,0,0,0,0,0,0,0,6,2
2,6,0,0,0,0,0,0,0,0,0,0,0,0,0,6,2
2,6,0,0,0,0,0,0,0,0,0,0,0,0,0,6,2
1,2,6,0,0,0,0,0,0,0,0,0,0,0,6,2,1
1,2,6,0,0,0,0,0,0,0,0,0,0,0,6,2,1
1,2,6,0,0,0,0,0,0,0,0,0,0,0,6,2,1
1,2,6,0,0,0,0,0,0,0,0,0,0,0,6,2,1
1,1,2,6,0,0,0,0,0,0,0,0,0,6,2,1,1
1,1,2,6,0,0,0,0,0,0,0,0,0,6,2,1,1
1,1,1,2,6,0,0,0,0,0,0,0,6,2,1,1,1
1,1,1,1,2,6,6,6,6,6,6,6,2,1,1,1,1
1,1,1,1,1,2,2,2,6,2,2,2,1,1,1,1,1
1,1,1,1,1,1,1,2,2,2,1,1,1,1,1,1,1
endlayer

layer
1,1,1,1,1,1,1,1,1,1,1,1,1,1,1,1,1
1,1,1,1,1,1,2,2,2,2,2,1,1,1,1,1,1
1,1,1,1,1,2,3,6,6,6,3,2,1,1,1,1,1
1,1,1,1,2,6,6,0,0,0,6,6,2,1,1,1,1
1,1,1,2,6,0,0,0,0,0,0,0,6,2,1,1,1
1,1,2,6,0,0,0,0,0,0,0,0,0,6,2,1,1
1,1,2,6,0,0,0,0,0,0,0,0,0,6,2,1,1
1,2,6,0,0,0,0,0,0,0,0,0,0,0,6,2,1
1,2,6,0,0,0,0,0,0,0,0,0,0,0,6,2,1
1,2,6,0,0,0,0,0,0,0,0,0,0,0,6,2,1
1,2,6,0,0,0,0,0,0,0,0,0,0,0,6,2,1
1,2,6,0,0,0,0,0,0,0,0,0,0,0,6,2,1
1,2,6,0,0,0,0,0,0,0,0,0,0,0,6,2,1
1,2,6,0,0,0,0,0,0,0,0,0,0,0,6,2,1
1,2,6,0,0,0,0,0,0,0,0,0,0,0,6,2,1
1,2,6,0,0,0,0,0,0,0,0,0,0,0,6,2,1
1,2,6,0,0,0,0,0,0,0,0,0,0,0,6,2,1
1,2,6,0,0,0,0,0,0,0,0,0,0,0,6,2,1
1,1,2,6,0,0,0,0,0,0,0,0,0,6,2,1,1
1,1,2,6,0,0,0,0,0,0,0,0,0,6,2,1,1
1,1,1,2,6,0,0,0,0,0,0,0,6,2,1,1,1
1,1,1,1,2,6,6,0,0,0,6,6,2,1,1,1,1
1,1,1,1,1,2,3,6,6,6,3,2,1,1,1,1,1
1,1,1,1,1,1,2,2,2,2,2,1,1,1,1,1,1
1,1,1,1,1,1,1,1,1,1,1,1,1,1,1,1,1
endlayer

layer
1,1,1,1,1,1,1,1,1,1,1,1,1,1,1,1,1
1,1,1,1,1,1,1,1,1,1,1,1,1,1,1,1,1
1,1,1,1,1,1,2,2,2,2,2,1,1,1,1,1,1
1,1,1,1,1,2,2,3,3,3,2,2,1,1,1,1,1
1,1,1,1,2,3,3,3,3,3,3,3,2,1,1,1,1
1,1,1,2,3,3,3,0,0,0,3,3,3,2,1,1,1
1,1,1,2,3,0,0,0,0,0,0,0,3,2,1,1,1
1,1,2,3,3,0,0,0,0,0,0,0,3,3,2,1,1
1,1,2,3,0,0,0,0,0,0,0,0,0,3,2,1,1
1,1,2,3,0,0,0,0,0,0,0,0,0,3,2,1,1
1,2,3,3,0,0,0,0,0,0,0,0,0,3,3,2,1
1,2,3,0,0,0,0,0,0,0,0,0,0,0,3,2,1
1,2,3,0,0,0,0,0,0,0,0,0,0,0,3,2,1
1,2,3,0,0,0,0,0,0,0,0,0,0,0,3,2,1
1,2,3,3,0,0,0,0,0,0,0,0,0,3,3,2,1
1,1,2,3,0,0,0,0,0,0,0,0,0,3,2,1,1
1,1,2,3,0,0,0,0,0,0,0,0,0,3,2,1,1
1,1,2,3,3,0,0,0,0,0,0,0,3,3,2,1,1
1,1,1,2,3,0,0,0,0,0,0,0,3,2,1,1,1
1,1,1,2,3,3,3,0,0,0,3,3,3,2,1,1,1
1,1,1,1,2,3,3,3,3,3,3,3,2,1,1,1,1
1,1,1,1,1,2,2,3,3,3,2,2,1,1,1,1,1
1,1,1,1,1,1,2,2,2,2,2,1,1,1,1,1,1
1,1,1,1,1,1,1,1,1,1,1,1,1,1,1,1,1
1,1,1,1,1,1,1,1,1,1,1,1,1,1,1,1,1
endlayer

layer
1,1,1,1,1,1,1,1,1,1,1,1,1,1,1,1,1
1,1,1,1,1,1,1,1,1,1,1,1,1,1,1,1,1
1,1,1,1,1,1,1,1,1,1,1,1,1,1,1,1,1
1,1,1,1,1,1,1,2,2,2,1,1,1,1,1,1,1
1,1,1,1,1,2,2,2,2,2,2,2,1,1,1,1,1
1,1,1,1,2,2,2,3,3,3,2,2,2,1,1,1,1
1,1,1,1,2,3,3,3,3,3,3,3,2,1,1,1,1
1,1,1,2,2,3,3,3,0,3,3,3,2,2,1,1,1
1,1,1,2,3,3,3,0,0,0,3,3,3,2,1,1,1
1,1,1,2,3,3,0,0,0,0,0,3,3,2,1,1,1
1,1,2,2,3,3,0,0,0,0,0,3,3,2,2,1,1
1,1,2,3,3,3,0,0,0,0,0,3,3,3,2,1,1
1,1,2,3,3,3,0,0,9,0,0,3,3,3,2,1,1
1,1,2,3,3,3,0,0,0,0,0,3,3,3,2,1,1
1,1,2,2,3,3,0,0,0,0,0,3,3,2,2,1,1
1,1,1,2,3,3,0,0,0,0,0,3,3,2,1,1,1
1,1,1,2,3,3,3,0,0,0,3,3,3,2,1,1,1
1,1,1,2,2,3,3,3,0,3,3,3,2,2,1,1,1
1,1,1,1,2,3,3,3,3,3,3,3,2,1,1,1,1
1,1,1,1,2,2,2,3,3,3,2,2,2,1,1,1,1
1,1,1,1,1,2,2,2,2,2,2,2,1,1,1,1,1
1,1,1,1,1,1,1,2,2,2,1,1,1,1,1,1,1
1,1,1,1,1,1,1,1,1,1,1,1,1,1,1,1,1
1,1,1,1,1,1,1,1,1,1,1,1,1,1,1,1,1
1,1,1,1,1,1,1,1,1,1,1,1,1,1,1,1,1
endlayer

layer
1,1,1,1,1,1,1,1,1,1,1,1,1,1,1,1,1
1,1,1,1,1,1,1,1,1,1,1,1,1,1,1,1,1
1,1,1,1,1,1,1,1,1,1,1,1,1,1,1,1,1
1,1,1,1,1,1,1,1,1,1,1,1,1,1,1,1,1
1,1,1,1,1,1,1,1,1,1,1,1,1,1,1,1,1
1,1,1,1,1,1,1,2,2,2,1,1,1,1,1,1,1
1,1,1,1,1,2,2,2,2,2,2,2,1,1,1,1,1
1,1,1,1,1,2,2,2,6,2,2,2,1,1,1,1,1
1,1,1,1,2,2,2,6,6,6,2,2,2,1,1,1,1
1,1,1,1,2,2,6,6,3,6,6,2,2,1,1,1,1
1,1,1,1,2,2,6,3,3,3,6,2,2,1,1,1,1
1,1,1,2,2,2,3,3,6,3,3,2,2,2,1,1,1
1,1,1,2,2,2,3,6,6,6,3,2,2,2,1,1,1
1,1,1,2,2,2,3,3,6,3,3,2,2,2,1,1,1
1,1,1,1,2,2,6,3,3,3,6,2,2,1,1,1,1
1,1,1,1,2,2,6,6,3,6,6,2,2,1,1,1,1
1,1,1,1,2,2,2,6,6,6,2,2,2,1,1,1,1
1,1,1,1,1,2,2,2,6,2,2,2,1,1,1,1,1
1,1,1,1,1,2,2,2,2,2,2,2,1,1,1,1,1
1,1,1,1,1,1,1,2,2,2,1,1,1,1,1,1,1
1,1,1,1,1,1,1,1,1,1,1,1,1,1,1,1,1
1,1,1,1,1,1,1,1,1,1,1,1,1,1,1,1,1
1,1,1,1,1,1,1,1,1,1,1,1,1,1,1,1,1
1,1,1,1,1,1,1,1,1,1,1,1,1,1,1,1,1
1,1,1,1,1,1,1,1,1,1,1,1,1,1,1,1,1
endlayer

layer
1,1,1,1,1,1,1,1,1,1,1,1,1,1,1,1,1
1,1,1,1,1,1,1,1,1,1,1,1,1,1,1,1,1
1,1,1,1,1,1,1,1,1,1,1,1,1,1,1,1,1
1,1,1,1,1,1,1,1,1,1,1,1,1,1,1,1,1
1,1,1,1,1,1,1,1,1,1,1,1,1,1,1,1,1
1,1,1,1,1,1,1,1,1,1,1,1,1,1,1,1,1
1,1,1,1,1,1,1,1,1,1,1,1,1,1,1,1,1
1,1,1,1,1,1,1,1,2,1,1,1,1,1,1,1,1
1,1,1,1,1,1,1,2,2,2,1,1,1,1,1,1,1
1,1,1,1,1,1,2,2,2,2,2,1,1,1,1,1,1
1,1,1,1,1,1,2,2,2,2,2,1,1,1,1,1,1
1,1,1,1,1,1,2,2,2,2,2,1,1,1,1,1,1
1,1,1,1,1,2,2,2,2,2,2,2,1,1,1,1,1
1,1,1,1,1,1,2,2,2,2,2,1,1,1,1,1,1
1,1,1,1,1,1,2,2,2,2,2,1,1,1,1,1,1
1,1,1,1,1,1,2,2,2,2,2,1,1,1,1,1,1
1,1,1,1,1,1,1,2,2,2,1,1,1,1,1,1,1
1,1,1,1,1,1,1,1,2,1,1,1,1,1,1,1,1
1,1,1,1,1,1,1,1,1,1,1,1,1,1,1,1,1
1,1,1,1,1,1,1,1,1,1,1,1,1,1,1,1,1
1,1,1,1,1,1,1,1,1,1,1,1,1,1,1,1,1
1,1,1,1,1,1,1,1,1,1,1,1,1,1,1,1,1
1,1,1,1,1,1,1,1,1,1,1,1,1,1,1,1,1
1,1,1,1,1,1,1,1,1,1,1,1,1,1,1,1,1
1,1,1,1,1,1,1,1,1,1,1,1,1,1,1,1,1
endlayer

