
# Created by Ruins mod version 17.0 Ingame Parser
# authoring Player: ST753M

weight=1
embed_into_distance=3
acceptable_target_blocks=
unacceptable_target_blocks=flowing_water,water,flowing_lava,lava
dimensions=16,25,25
allowable_overhang=0
max_leveling=0
leveling_buffer=-1
preserve_water=0
preserve_lava=0

=0,100,air
rule1=0,100,preserveBlock
rule2=2,100,minecraft:stone-0
rule3=0,100,minecraft:stone-0
rule4=0,100,quark:crystal-0
rule5=0,100,quark:marble-1
rule6=0,100,quark:world_stone_bricks-4
rule7=0,100,quark:stone_marble_bricks_wall-0
rule8=0,100,quark:stone_marble_bricks_stairs-2
rule9=0,100,quark:stone_marble_bricks_stairs-0
rule10=0,100,quark:stone_marble_bricks_stairs-3
rule11=0,100,quark:stone_marble_bricks_stairs-1
rule12=0,100,IInventory;minecraft:white_shulker_box;minecraft:bone#2#0#2+minecraft:sugar#4#0#5+minecraft:bone#2#0#7+minecraft:snowball#9#0#10+minecraft:iron_sword#{ench:[{lvl:3s,id:22s},{lvl:3s,id:17s},{lvl:2s,id:19s}],RepairCost:7,display:{Name:"The White Sword"}}#0#13+minecraft:snowball#3#0#17+minecraft:sugar#5#0#18+minecraft:snowball#4#0#20+minecraft:bone#3#0#24-1
rule13=0,100,quark:stone_marble_bricks_slab-0
rule14=0,100,quark:stone_marble_bricks_slab_double-0

layer
1,1,1,1,1,1,2,2,2,2,2,2,2,2,2,2,2,2,2,1,1,1,1,1,1
1,1,1,1,1,3,3,3,3,3,3,3,3,3,3,3,3,3,3,3,1,1,1,1,1
1,1,1,1,3,3,3,3,3,3,3,3,3,3,3,3,3,3,3,3,3,1,1,1,1
1,1,1,3,3,3,3,3,3,3,3,3,3,3,3,3,3,3,3,3,3,3,1,1,1
1,1,3,3,3,3,3,3,3,3,3,3,3,3,3,3,3,3,3,3,3,3,3,1,1
1,3,3,3,3,3,3,3,3,3,3,3,3,3,3,3,3,3,3,3,3,3,3,3,1
2,3,3,3,3,3,3,3,3,3,3,3,3,3,3,3,3,3,3,3,3,3,3,3,2
2,3,3,3,3,3,3,3,3,3,3,3,3,3,3,3,3,3,3,3,3,3,3,3,2
2,3,3,3,3,3,3,3,3,3,3,3,3,3,3,3,3,3,3,3,3,3,3,3,2
2,3,3,3,3,3,3,3,3,3,3,3,3,3,3,3,3,3,3,3,3,3,3,3,2
2,3,3,3,3,3,3,3,3,3,3,3,3,3,3,3,3,3,3,3,3,3,3,3,2
2,3,3,3,3,3,3,3,3,3,3,3,3,3,3,3,3,3,3,3,3,3,3,3,2
2,3,3,3,3,3,3,3,3,3,3,3,3,3,3,3,3,3,3,3,3,3,3,3,2
2,3,3,3,3,3,3,3,3,3,3,3,3,3,3,3,3,3,3,3,3,3,3,3,2
2,3,3,3,3,3,3,3,3,3,3,3,3,3,3,3,3,3,3,3,3,3,3,3,2
2,3,3,3,3,3,3,3,3,3,3,3,3,3,3,3,3,3,3,3,3,3,3,3,2
2,3,3,3,3,3,3,3,3,3,3,3,3,3,3,3,3,3,3,3,3,3,3,3,2
2,3,3,3,3,3,3,3,3,3,3,3,3,3,3,3,3,3,3,3,3,3,3,3,2
2,3,3,3,3,3,3,3,3,3,3,3,3,3,3,3,3,3,3,3,3,3,3,3,2
1,3,3,3,3,3,3,3,3,3,3,3,3,3,3,3,3,3,3,3,3,3,3,3,1
1,1,3,3,3,3,3,3,3,3,3,3,3,3,3,3,3,3,3,3,3,3,3,1,1
1,1,1,3,3,3,3,3,3,3,3,3,3,3,3,3,3,3,3,3,3,3,1,1,1
1,1,1,1,3,3,3,3,3,3,3,3,3,3,3,3,3,3,3,3,3,1,1,1,1
1,1,1,1,1,3,3,3,3,3,3,3,3,3,3,3,3,3,3,3,1,1,1,1,1
1,1,1,1,1,1,2,2,2,2,2,2,2,2,2,2,2,2,2,1,1,1,1,1,1
endlayer

layer
1,1,1,1,1,2,2,2,2,2,2,2,2,2,2,2,2,2,2,2,1,1,1,1,1
1,1,1,1,2,0,0,0,0,0,0,0,0,0,0,0,0,0,0,0,2,1,1,1,1
1,1,1,2,0,0,0,0,0,4,4,4,4,4,4,4,0,0,0,0,0,2,1,1,1
1,1,2,0,0,0,4,4,4,4,5,5,5,5,5,4,4,4,4,0,0,0,2,1,1
1,2,0,0,4,4,4,5,5,5,5,6,6,6,5,5,5,5,4,4,4,0,0,2,1
2,0,0,0,4,5,5,5,5,5,5,6,6,6,5,5,5,5,5,5,4,0,0,0,2
2,0,0,4,4,5,6,6,6,5,5,6,6,6,5,5,6,6,6,5,4,4,0,0,2
2,0,0,4,5,5,6,6,6,5,5,5,5,5,5,5,6,6,6,5,5,4,0,0,2
2,0,0,4,5,5,6,6,6,5,6,5,6,5,6,5,6,6,6,5,5,4,0,0,2
2,0,4,4,5,5,5,5,5,5,6,6,6,6,6,5,5,5,5,5,5,4,4,0,2
2,0,4,5,5,5,5,5,6,6,6,5,5,5,6,6,6,5,5,5,5,5,4,0,2
2,0,4,5,6,6,6,5,5,6,5,6,6,6,5,6,5,5,6,6,6,5,4,0,2
2,0,4,5,6,6,6,5,6,6,5,6,6,6,5,6,6,5,6,6,6,5,4,0,2
2,0,4,5,6,6,6,5,5,6,5,6,6,6,5,6,5,5,6,6,6,5,4,0,2
2,0,4,5,5,5,5,5,6,6,6,5,5,5,6,6,6,5,5,5,5,5,4,0,2
2,0,4,4,5,5,5,5,5,5,6,6,6,6,6,5,5,5,5,5,5,4,4,0,2
2,0,0,4,5,5,6,6,6,5,6,5,6,5,6,5,6,6,6,5,5,4,0,0,2
2,0,0,4,5,5,6,6,6,5,5,5,5,5,5,5,6,6,6,5,5,4,0,0,2
2,0,0,4,4,5,6,6,6,5,5,6,6,6,5,5,6,6,6,5,4,4,0,0,2
2,0,0,0,4,5,5,5,5,5,5,6,6,6,5,5,5,5,5,5,4,0,0,0,2
1,2,0,0,4,4,4,5,5,5,5,6,6,6,5,5,5,5,4,4,4,0,0,2,1
1,1,2,0,0,0,4,4,4,4,5,5,5,5,5,4,4,4,4,0,0,0,2,1,1
1,1,1,2,0,0,0,0,0,4,4,4,4,4,4,4,0,0,0,0,0,2,1,1,1
1,1,1,1,2,0,0,0,0,0,0,0,0,0,0,0,0,0,0,0,2,1,1,1,1
1,1,1,1,1,2,2,2,2,2,2,2,2,2,2,2,2,2,2,2,1,1,1,1,1
endlayer

layer
1,1,1,1,2,2,2,2,2,2,2,2,2,2,2,2,2,2,2,2,2,1,1,1,1
1,1,1,2,0,0,0,0,0,0,0,0,0,0,0,0,0,0,0,0,0,2,1,1,1
1,1,2,0,0,0,0,0,0,0,0,0,0,0,0,0,0,0,0,0,0,0,2,1,1
1,2,0,0,0,0,0,0,0,0,0,0,0,0,0,0,0,0,0,0,0,0,0,2,1
2,0,0,0,0,0,0,0,0,0,0,7,7,7,0,0,0,0,0,0,0,0,0,0,2
2,0,0,0,0,0,0,0,0,0,0,7,6,7,0,0,0,0,0,0,0,0,0,0,2
2,0,0,0,0,0,7,7,7,0,0,7,7,7,0,0,7,7,7,0,0,0,0,0,2
2,0,0,0,0,0,7,6,7,0,0,0,0,0,0,0,7,6,7,0,0,0,0,0,2
2,0,0,0,0,0,7,7,7,0,0,0,0,0,0,0,7,7,7,0,0,0,0,0,2
2,0,0,0,0,0,0,0,0,0,0,0,0,0,0,0,0,0,0,0,0,0,0,0,2
2,0,0,0,0,0,0,0,0,0,4,4,4,4,4,0,0,0,0,0,0,0,0,0,2
2,0,0,0,7,7,7,0,0,0,4,5,5,5,4,0,0,0,7,7,7,0,0,0,2
2,0,0,0,7,6,7,0,0,0,4,5,5,5,4,0,0,0,7,6,7,0,0,0,2
2,0,0,0,7,7,7,0,0,0,4,5,5,5,4,0,0,0,7,7,7,0,0,0,2
2,0,0,0,0,0,0,0,0,0,4,4,4,4,4,0,0,0,0,0,0,0,0,0,2
2,0,0,0,0,0,0,0,0,0,0,0,0,0,0,0,0,0,0,0,0,0,0,0,2
2,0,0,0,0,0,7,7,7,0,0,0,0,0,0,0,7,7,7,0,0,0,0,0,2
2,0,0,0,0,0,7,6,7,0,0,0,0,0,0,0,7,6,7,0,0,0,0,0,2
2,0,0,0,0,0,7,7,7,0,0,7,7,7,0,0,7,7,7,0,0,0,0,0,2
2,0,0,0,0,0,0,0,0,0,0,7,6,7,0,0,0,0,0,0,0,0,0,0,2
2,0,0,0,0,0,0,0,0,0,0,7,7,7,0,0,0,0,0,0,0,0,0,0,2
1,2,0,0,0,0,0,0,0,0,0,0,0,0,0,0,0,0,0,0,0,0,0,2,1
1,1,2,0,0,0,0,0,0,0,0,0,0,0,0,0,0,0,0,0,0,0,2,1,1
1,1,1,2,0,0,0,0,0,0,0,0,0,0,0,0,0,0,0,0,0,2,1,1,1
1,1,1,1,2,2,2,2,2,2,2,2,2,2,2,2,2,2,2,2,2,1,1,1,1
endlayer

layer
1,1,1,1,2,2,2,2,2,2,2,2,2,2,2,2,2,2,2,2,2,1,1,1,1
1,1,1,2,0,0,0,0,0,0,0,0,0,0,0,0,0,0,0,0,0,2,1,1,1
1,1,2,0,0,0,0,0,0,0,0,0,0,0,0,0,0,0,0,0,0,0,2,1,1
1,2,0,0,0,0,0,0,0,0,0,0,0,0,0,0,0,0,0,0,0,0,0,2,1
2,0,0,0,0,0,0,0,0,0,0,10,9,8,0,0,0,0,0,0,0,0,0,0,2
2,0,0,0,0,0,0,0,0,0,0,10,6,8,0,0,0,0,0,0,0,0,0,0,2
2,0,0,0,0,0,9,9,9,0,0,11,11,8,0,0,10,9,8,0,0,0,0,0,2
2,0,0,0,0,0,10,6,8,0,0,0,0,0,0,0,10,6,8,0,0,0,0,0,2
2,0,0,0,0,0,10,11,11,0,0,0,0,0,0,0,11,11,11,0,0,0,0,0,2
2,0,0,0,0,0,0,0,0,0,0,0,0,0,0,0,0,0,0,0,0,0,0,0,2
2,0,0,0,0,0,0,0,0,0,0,0,0,0,0,0,0,0,0,0,0,0,0,0,2
2,0,0,0,10,9,9,0,0,0,0,0,0,0,0,0,0,0,10,9,9,0,0,0,2
2,0,0,0,10,6,8,0,0,0,0,0,12,0,0,0,0,0,10,6,8,0,0,0,2
2,0,0,0,11,11,11,0,0,0,0,0,0,0,0,0,0,0,10,11,8,0,0,0,2
2,0,0,0,0,0,0,0,0,0,0,0,0,0,0,0,0,0,0,0,0,0,0,0,2
2,0,0,0,0,0,0,0,0,0,0,0,0,0,0,0,0,0,0,0,0,0,0,0,2
2,0,0,0,0,0,10,9,9,0,0,0,0,0,0,0,9,9,8,0,0,0,0,0,2
2,0,0,0,0,0,10,6,8,0,0,0,0,0,0,0,10,6,8,0,0,0,0,0,2
2,0,0,0,0,0,10,11,11,0,0,10,9,9,0,0,11,11,11,0,0,0,0,0,2
2,0,0,0,0,0,0,0,0,0,0,10,6,8,0,0,0,0,0,0,0,0,0,0,2
2,0,0,0,0,0,0,0,0,0,0,10,11,8,0,0,0,0,0,0,0,0,0,0,2
1,2,0,0,0,0,0,0,0,0,0,0,0,0,0,0,0,0,0,0,0,0,0,2,1
1,1,2,0,0,0,0,0,0,0,0,0,0,0,0,0,0,0,0,0,0,0,2,1,1
1,1,1,2,0,0,0,0,0,0,0,0,0,0,0,0,0,0,0,0,0,2,1,1,1
1,1,1,1,2,2,2,2,2,2,2,2,2,2,2,2,2,2,2,2,2,1,1,1,1
endlayer

layer
1,1,1,1,2,2,2,2,2,2,2,2,2,2,2,2,2,2,2,2,2,1,1,1,1
1,1,1,2,0,0,0,0,0,0,0,0,0,0,0,0,0,0,0,0,0,2,1,1,1
1,1,2,0,0,0,0,0,0,0,0,0,0,0,0,0,0,0,0,0,0,0,2,1,1
1,2,0,0,0,0,0,0,0,0,0,0,0,0,0,0,0,0,0,0,0,0,0,2,1
2,0,0,0,0,0,0,0,0,0,0,13,13,13,0,0,0,0,0,0,0,0,0,0,2
2,0,0,0,0,0,0,0,0,0,0,13,6,13,0,0,0,0,0,0,0,0,0,0,2
2,0,0,0,0,0,13,13,13,0,0,13,13,13,0,0,13,13,13,0,0,0,0,0,2
2,0,0,0,0,0,13,6,13,0,0,0,0,0,0,0,13,6,13,0,0,0,0,0,2
2,0,0,0,0,0,13,13,13,0,0,0,0,0,0,0,13,13,13,0,0,0,0,0,2
2,0,0,0,0,0,0,0,0,0,0,0,0,0,0,0,0,0,0,0,0,0,0,0,2
2,0,0,0,0,0,0,0,0,0,0,0,0,0,0,0,0,0,0,0,0,0,0,0,2
2,0,0,0,13,13,13,0,0,0,0,0,0,0,0,0,0,0,13,13,13,0,0,0,2
2,0,0,0,13,6,13,0,0,0,0,0,0,0,0,0,0,0,13,6,13,0,0,0,2
2,0,0,0,13,13,13,0,0,0,0,0,0,0,0,0,0,0,13,13,13,0,0,0,2
2,0,0,0,0,0,0,0,0,0,0,0,0,0,0,0,0,0,0,0,0,0,0,0,2
2,0,0,0,0,0,0,0,0,0,0,0,0,0,0,0,0,0,0,0,0,0,0,0,2
2,0,0,0,0,0,13,13,13,0,0,0,0,0,0,0,13,13,13,0,0,0,0,0,2
2,0,0,0,0,0,13,6,13,0,0,0,0,0,0,0,13,6,13,0,0,0,0,0,2
2,0,0,0,0,0,13,13,13,0,0,13,13,13,0,0,13,13,13,0,0,0,0,0,2
2,0,0,0,0,0,0,0,0,0,0,13,6,13,0,0,0,0,0,0,0,0,0,0,2
2,0,0,0,0,0,0,0,0,0,0,13,13,13,0,0,0,0,0,0,0,0,0,0,2
1,2,0,0,0,0,0,0,0,0,0,0,0,0,0,0,0,0,0,0,0,0,0,2,1
1,1,2,0,0,0,0,0,0,0,0,0,0,0,0,0,0,0,0,0,0,0,2,1,1
1,1,1,2,0,0,0,0,0,0,0,0,0,0,0,0,0,0,0,0,0,2,1,1,1
1,1,1,1,2,2,2,2,2,2,2,2,2,2,2,2,2,2,2,2,2,1,1,1,1
endlayer

layer
1,1,1,1,2,2,2,2,2,2,2,2,2,2,2,2,2,2,2,2,2,1,1,1,1
1,1,1,2,0,0,0,0,0,0,0,0,0,0,0,0,0,0,0,0,0,2,1,1,1
1,1,2,0,0,0,0,0,0,0,0,0,0,0,0,0,0,0,0,0,0,0,2,1,1
1,2,0,0,0,0,0,0,0,0,0,0,0,0,0,0,0,0,0,0,0,0,0,2,1
2,0,0,0,0,0,0,0,0,0,0,0,0,0,0,0,0,0,0,0,0,0,0,0,2
2,0,0,0,0,0,0,0,0,0,0,0,6,0,0,0,0,0,0,0,0,0,0,0,2
2,0,0,0,0,0,0,0,0,0,0,0,0,0,0,0,0,0,0,0,0,0,0,0,2
2,0,0,0,0,0,0,6,0,0,0,0,0,0,0,0,0,6,0,0,0,0,0,0,2
2,0,0,0,0,0,0,0,0,0,0,0,0,0,0,0,0,0,0,0,0,0,0,0,2
2,0,0,0,0,0,0,0,0,0,0,0,0,0,0,0,0,0,0,0,0,0,0,0,2
2,0,0,0,0,0,0,0,0,0,0,0,0,0,0,0,0,0,0,0,0,0,0,0,2
2,0,0,0,0,0,0,0,0,0,0,0,0,0,0,0,0,0,0,0,0,0,0,0,2
2,0,0,0,0,6,0,0,0,0,0,0,0,0,0,0,0,0,0,6,0,0,0,0,2
2,0,0,0,0,0,0,0,0,0,0,0,0,0,0,0,0,0,0,0,0,0,0,0,2
2,0,0,0,0,0,0,0,0,0,0,0,0,0,0,0,0,0,0,0,0,0,0,0,2
2,0,0,0,0,0,0,0,0,0,0,0,0,0,0,0,0,0,0,0,0,0,0,0,2
2,0,0,0,0,0,0,0,0,0,0,0,0,0,0,0,0,0,0,0,0,0,0,0,2
2,0,0,0,0,0,0,6,0,0,0,0,0,0,0,0,0,6,0,0,0,0,0,0,2
2,0,0,0,0,0,0,0,0,0,0,0,0,0,0,0,0,0,0,0,0,0,0,0,2
2,0,0,0,0,0,0,0,0,0,0,0,6,0,0,0,0,0,0,0,0,0,0,0,2
2,0,0,0,0,0,0,0,0,0,0,0,0,0,0,0,0,0,0,0,0,0,0,0,2
1,2,0,0,0,0,0,0,0,0,0,0,0,0,0,0,0,0,0,0,0,0,0,2,1
1,1,2,0,0,0,0,0,0,0,0,0,0,0,0,0,0,0,0,0,0,0,2,1,1
1,1,1,2,0,0,0,0,0,0,0,0,0,0,0,0,0,0,0,0,0,2,1,1,1
1,1,1,1,2,2,2,2,2,2,2,2,2,2,2,2,2,2,2,2,2,1,1,1,1
endlayer

layer
1,1,1,1,1,2,2,2,2,2,2,2,2,2,2,2,2,2,2,2,1,1,1,1,1
1,1,1,2,2,0,0,0,0,0,0,0,0,0,0,0,0,0,0,0,2,2,1,1,1
1,1,2,0,0,0,0,0,0,0,0,0,0,0,0,0,0,0,0,0,0,0,2,1,1
1,2,0,0,0,0,0,0,0,0,0,0,0,0,0,0,0,0,0,0,0,0,0,2,1
1,2,0,0,0,0,0,0,0,0,0,0,0,0,0,0,0,0,0,0,0,0,0,2,1
2,0,0,0,0,0,0,0,0,0,0,0,6,0,0,0,0,0,0,0,0,0,0,0,2
2,0,0,0,0,0,0,0,0,0,0,0,0,0,0,0,0,0,0,0,0,0,0,0,2
2,0,0,0,0,0,0,6,0,0,0,0,0,0,0,0,0,6,0,0,0,0,0,0,2
2,0,0,0,0,0,0,0,0,0,0,0,0,0,0,0,0,0,0,0,0,0,0,0,2
2,0,0,0,0,0,0,0,0,0,0,0,0,0,0,0,0,0,0,0,0,0,0,0,2
2,0,0,0,0,0,0,0,0,0,0,0,0,0,0,0,0,0,0,0,0,0,0,0,2
2,0,0,0,0,0,0,0,0,0,0,0,0,0,0,0,0,0,0,0,0,0,0,0,2
2,0,0,0,0,6,0,0,0,0,0,0,0,0,0,0,0,0,0,6,0,0,0,0,2
2,0,0,0,0,0,0,0,0,0,0,0,0,0,0,0,0,0,0,0,0,0,0,0,2
2,0,0,0,0,0,0,0,0,0,0,0,0,0,0,0,0,0,0,0,0,0,0,0,2
2,0,0,0,0,0,0,0,0,0,0,0,0,0,0,0,0,0,0,0,0,0,0,0,2
2,0,0,0,0,0,0,0,0,0,0,0,0,0,0,0,0,0,0,0,0,0,0,0,2
2,0,0,0,0,0,0,6,0,0,0,0,0,0,0,0,0,6,0,0,0,0,0,0,2
2,0,0,0,0,0,0,0,0,0,0,0,0,0,0,0,0,0,0,0,0,0,0,0,2
2,0,0,0,0,0,0,0,0,0,0,0,6,0,0,0,0,0,0,0,0,0,0,0,2
1,2,0,0,0,0,0,0,0,0,0,0,0,0,0,0,0,0,0,0,0,0,0,2,1
1,2,0,0,0,0,0,0,0,0,0,0,0,0,0,0,0,0,0,0,0,0,0,2,1
1,1,2,0,0,0,0,0,0,0,0,0,0,0,0,0,0,0,0,0,0,0,2,1,1
1,1,1,2,2,0,0,0,0,0,0,0,0,0,0,0,0,0,0,0,2,2,1,1,1
1,1,1,1,1,2,2,2,2,2,2,2,2,2,2,2,2,2,2,2,1,1,1,1,1
endlayer

layer
1,1,1,1,1,1,2,2,2,2,2,2,2,2,2,2,2,2,2,1,1,1,1,1,1
1,1,1,1,2,2,0,0,0,0,0,0,0,0,0,0,0,0,0,2,2,1,1,1,1
1,1,1,2,0,0,0,0,0,0,0,0,0,0,0,0,0,0,0,0,0,2,1,1,1
1,1,2,0,0,0,0,0,0,0,0,0,0,0,0,0,0,0,0,0,0,0,2,1,1
1,2,0,0,0,0,0,0,0,0,0,0,7,0,0,0,0,0,0,0,0,0,0,2,1
1,2,0,0,0,0,0,0,0,0,0,7,6,7,0,0,0,0,0,0,0,0,0,2,1
2,0,0,0,0,0,0,7,0,0,0,0,7,0,0,0,0,7,0,0,0,0,0,0,2
2,0,0,0,0,0,7,6,7,0,0,0,0,0,0,0,7,6,7,0,0,0,0,0,2
2,0,0,0,0,0,0,7,0,0,0,0,0,0,0,0,0,7,0,0,0,0,0,0,2
2,0,0,0,0,0,0,0,0,0,0,0,0,0,0,0,0,0,0,0,0,0,0,0,2
2,0,0,0,0,0,0,0,0,0,0,0,0,0,0,0,0,0,0,0,0,0,0,0,2
2,0,0,0,0,7,0,0,0,0,0,0,0,0,0,0,0,0,0,7,0,0,0,0,2
2,0,0,0,7,6,7,0,0,0,0,0,0,0,0,0,0,0,7,6,7,0,0,0,2
2,0,0,0,0,7,0,0,0,0,0,0,0,0,0,0,0,0,0,7,0,0,0,0,2
2,0,0,0,0,0,0,0,0,0,0,0,0,0,0,0,0,0,0,0,0,0,0,0,2
2,0,0,0,0,0,0,0,0,0,0,0,0,0,0,0,0,0,0,0,0,0,0,0,2
2,0,0,0,0,0,0,7,0,0,0,0,0,0,0,0,0,7,0,0,0,0,0,0,2
2,0,0,0,0,0,7,6,7,0,0,0,0,0,0,0,7,6,7,0,0,0,0,0,2
2,0,0,0,0,0,0,7,0,0,0,0,7,0,0,0,0,7,0,0,0,0,0,0,2
1,2,0,0,0,0,0,0,0,0,0,7,6,7,0,0,0,0,0,0,0,0,0,2,1
1,2,0,0,0,0,0,0,0,0,0,0,7,0,0,0,0,0,0,0,0,0,0,2,1
1,1,2,0,0,0,0,0,0,0,0,0,0,0,0,0,0,0,0,0,0,0,2,1,1
1,1,1,2,0,0,0,0,0,0,0,0,0,0,0,0,0,0,0,0,0,2,1,1,1
1,1,1,1,2,2,0,0,0,0,0,0,0,0,0,0,0,0,0,2,2,1,1,1,1
1,1,1,1,1,1,2,2,2,2,2,2,2,2,2,2,2,2,2,1,1,1,1,1,1
endlayer

layer
1,1,1,1,1,1,1,2,2,2,2,2,2,2,2,2,2,2,1,1,1,1,1,1,1
1,1,1,1,1,2,2,0,0,0,0,0,0,0,0,0,0,0,2,2,1,1,1,1,1
1,1,1,1,2,0,0,0,0,0,0,0,0,0,0,0,0,0,0,0,2,1,1,1,1
1,1,1,2,0,0,0,0,0,0,0,0,0,0,0,0,0,0,0,0,0,2,1,1,1
1,1,2,0,0,0,0,0,0,0,0,9,9,8,0,0,0,0,0,0,0,0,2,1,1
1,2,0,0,0,0,0,0,0,0,0,10,6,8,0,0,0,0,0,0,0,0,0,2,1
1,2,0,0,0,0,9,9,9,0,0,11,11,11,0,0,9,9,9,0,0,0,0,2,1
2,0,0,0,0,0,10,6,8,0,0,0,0,0,0,0,10,6,8,0,0,0,0,0,2
2,0,0,0,0,0,10,11,11,0,0,0,0,0,0,0,10,11,11,0,0,0,0,0,2
2,0,0,0,0,0,0,0,0,0,0,0,0,0,0,0,0,0,0,0,0,0,0,0,2
2,0,0,0,0,0,0,0,0,0,0,0,0,0,0,0,0,0,0,0,0,0,0,0,2
2,0,0,0,10,9,8,0,0,0,0,0,0,0,0,0,0,0,9,9,9,0,0,0,2
2,0,0,0,10,6,8,0,0,0,0,0,0,0,0,0,0,0,10,6,8,0,0,0,2
2,0,0,0,11,11,8,0,0,0,0,0,0,0,0,0,0,0,10,11,8,0,0,0,2
2,0,0,0,0,0,0,0,0,0,0,0,0,0,0,0,0,0,0,0,0,0,0,0,2
2,0,0,0,0,0,0,0,0,0,0,0,0,0,0,0,0,0,0,0,0,0,0,0,2
2,0,0,0,0,0,10,9,8,0,0,0,0,0,0,0,9,9,8,0,0,0,0,0,2
2,0,0,0,0,0,10,6,8,0,0,0,0,0,0,0,10,6,8,0,0,0,0,0,2
1,2,0,0,0,0,10,11,11,0,0,9,9,8,0,0,10,11,8,0,0,0,0,2,1
1,2,0,0,0,0,0,0,0,0,0,10,6,8,0,0,0,0,0,0,0,0,0,2,1
1,1,2,0,0,0,0,0,0,0,0,11,11,11,0,0,0,0,0,0,0,0,2,1,1
1,1,1,2,0,0,0,0,0,0,0,0,0,0,0,0,0,0,0,0,0,2,1,1,1
1,1,1,1,2,0,0,0,0,0,0,0,0,0,0,0,0,0,0,0,2,1,1,1,1
1,1,1,1,1,2,2,0,0,0,0,0,0,0,0,0,0,0,2,2,1,1,1,1,1
1,1,1,1,1,1,1,2,2,2,2,2,2,2,2,2,2,2,1,1,1,1,1,1,1
endlayer

layer
1,1,1,1,1,1,1,1,1,2,2,2,2,2,2,2,1,1,1,1,1,1,1,1,1
1,1,1,1,1,1,2,2,2,0,0,0,0,0,0,0,2,2,2,1,1,1,1,1,1
1,1,1,1,1,2,0,0,0,0,0,0,0,0,0,0,0,0,0,2,1,1,1,1,1
1,1,1,1,2,0,0,0,0,0,0,0,0,0,0,0,0,0,0,0,2,1,1,1,1
1,1,1,2,0,0,0,0,0,0,0,13,13,13,0,0,0,0,0,0,0,2,1,1,1
1,1,2,0,0,0,0,0,0,13,13,14,6,14,13,13,0,0,0,0,0,0,2,1,1
1,2,0,0,0,0,13,13,13,14,14,13,13,13,14,14,13,13,13,0,0,0,0,2,1
1,2,0,0,0,0,13,6,14,13,13,0,0,0,13,13,14,6,13,0,0,0,0,2,1
1,2,0,0,0,0,13,14,13,0,0,0,0,0,0,0,13,14,13,0,0,0,0,2,1
2,0,0,0,0,13,14,13,0,0,0,0,0,0,0,0,0,13,14,13,0,0,0,0,2
2,0,0,0,0,13,14,13,0,0,0,0,0,0,0,0,0,13,14,13,0,0,0,0,2
2,0,0,0,13,14,13,0,0,0,0,0,0,0,0,0,0,0,13,14,13,0,0,0,2
2,0,0,0,13,6,13,0,0,0,0,0,0,0,0,0,0,0,13,6,13,0,0,0,2
2,0,0,0,13,14,13,0,0,0,0,0,0,0,0,0,0,0,13,14,13,0,0,0,2
2,0,0,0,0,13,14,13,0,0,0,0,0,0,0,0,0,13,14,13,0,0,0,0,2
2,0,0,0,0,13,14,13,0,0,0,0,0,0,0,0,0,13,14,13,0,0,0,0,2
1,2,0,0,0,0,13,14,13,0,0,0,0,0,0,0,13,14,13,0,0,0,0,2,1
1,2,0,0,0,0,13,6,14,13,13,0,0,0,13,13,14,6,13,0,0,0,0,2,1
1,2,0,0,0,0,13,13,13,14,14,13,13,13,14,14,13,13,13,0,0,0,0,2,1
1,1,2,0,0,0,0,0,0,13,13,14,6,14,13,13,0,0,0,0,0,0,2,1,1
1,1,1,2,0,0,0,0,0,0,0,13,13,13,0,0,0,0,0,0,0,2,1,1,1
1,1,1,1,2,0,0,0,0,0,0,0,0,0,0,0,0,0,0,0,2,1,1,1,1
1,1,1,1,1,2,0,0,0,0,0,0,0,0,0,0,0,0,0,2,1,1,1,1,1
1,1,1,1,1,1,2,2,2,0,0,0,0,0,0,0,2,2,2,1,1,1,1,1,1
1,1,1,1,1,1,1,1,1,2,2,2,2,2,2,2,1,1,1,1,1,1,1,1,1
endlayer

layer
1,1,1,1,1,1,1,1,1,1,1,1,1,1,1,1,1,1,1,1,1,1,1,1,1
1,1,1,1,1,1,1,1,2,2,2,2,2,2,2,2,2,1,1,1,1,1,1,1,1
1,1,1,1,1,1,2,2,0,0,0,0,0,0,0,0,0,2,2,1,1,1,1,1,1
1,1,1,1,1,2,0,0,0,0,0,0,0,0,0,0,0,0,0,2,1,1,1,1,1
1,1,1,1,2,0,0,0,0,0,0,0,0,0,0,0,0,0,0,0,2,1,1,1,1
1,1,1,2,0,0,0,0,0,0,0,0,4,0,0,0,0,0,0,0,0,2,1,1,1
1,1,2,0,0,0,0,0,0,0,0,0,0,0,0,0,0,0,0,0,0,0,2,1,1
1,1,2,0,0,0,0,4,0,0,0,0,0,0,0,0,0,4,0,0,0,0,2,1,1
1,2,0,0,0,0,0,0,0,0,0,0,0,0,0,0,0,0,0,0,0,0,0,2,1
1,2,0,0,0,0,0,0,0,0,0,0,0,0,0,0,0,0,0,0,0,0,0,2,1
1,2,0,0,0,0,0,0,0,0,0,0,0,0,0,0,0,0,0,0,0,0,0,2,1
1,2,0,0,0,0,0,0,0,0,0,0,0,0,0,0,0,0,0,0,0,0,0,2,1
1,2,0,0,0,4,0,0,0,0,0,0,0,0,0,0,0,0,0,4,0,0,0,2,1
1,2,0,0,0,0,0,0,0,0,0,0,0,0,0,0,0,0,0,0,0,0,0,2,1
1,2,0,0,0,0,0,0,0,0,0,0,0,0,0,0,0,0,0,0,0,0,0,2,1
1,2,0,0,0,0,0,0,0,0,0,0,0,0,0,0,0,0,0,0,0,0,0,2,1
1,2,0,0,0,0,0,0,0,0,0,0,0,0,0,0,0,0,0,0,0,0,0,2,1
1,1,2,0,0,0,0,4,0,0,0,0,0,0,0,0,0,4,0,0,0,0,2,1,1
1,1,2,0,0,0,0,0,0,0,0,0,0,0,0,0,0,0,0,0,0,0,2,1,1
1,1,1,2,0,0,0,0,0,0,0,0,4,0,0,0,0,0,0,0,0,2,1,1,1
1,1,1,1,2,0,0,0,0,0,0,0,0,0,0,0,0,0,0,0,2,1,1,1,1
1,1,1,1,1,2,0,0,0,0,0,0,0,0,0,0,0,0,0,2,1,1,1,1,1
1,1,1,1,1,1,2,2,0,0,0,0,0,0,0,0,0,2,2,1,1,1,1,1,1
1,1,1,1,1,1,1,1,2,2,2,2,2,2,2,2,2,1,1,1,1,1,1,1,1
1,1,1,1,1,1,1,1,1,1,1,1,1,1,1,1,1,1,1,1,1,1,1,1,1
endlayer

layer
1,1,1,1,1,1,1,1,1,1,1,1,1,1,1,1,1,1,1,1,1,1,1,1,1
1,1,1,1,1,1,1,1,1,1,1,1,1,1,1,1,1,1,1,1,1,1,1,1,1
1,1,1,1,1,1,1,1,2,2,2,2,2,2,2,2,2,1,1,1,1,1,1,1,1
1,1,1,1,1,1,2,2,2,0,0,0,0,0,0,0,2,2,2,1,1,1,1,1,1
1,1,1,1,1,2,2,0,0,0,0,0,0,0,0,0,0,0,2,2,1,1,1,1,1
1,1,1,1,2,2,0,0,0,0,0,0,0,0,0,0,0,0,0,2,2,1,1,1,1
1,1,1,2,2,0,0,0,0,0,0,0,0,0,0,0,0,0,0,0,2,2,1,1,1
1,1,1,2,0,0,0,0,0,0,0,0,0,0,0,0,0,0,0,0,0,2,1,1,1
1,1,2,2,0,0,0,0,0,0,0,0,0,0,0,0,0,0,0,0,0,2,2,1,1
1,1,2,0,0,0,0,0,0,0,0,0,0,0,0,0,0,0,0,0,0,0,2,1,1
1,1,2,0,0,0,0,0,0,0,0,0,0,0,0,0,0,0,0,0,0,0,2,1,1
1,1,2,0,0,0,0,0,0,0,0,0,0,0,0,0,0,0,0,0,0,0,2,1,1
1,1,2,0,0,0,0,0,0,0,0,0,0,0,0,0,0,0,0,0,0,0,2,1,1
1,1,2,0,0,0,0,0,0,0,0,0,0,0,0,0,0,0,0,0,0,0,2,1,1
1,1,2,0,0,0,0,0,0,0,0,0,0,0,0,0,0,0,0,0,0,0,2,1,1
1,1,2,0,0,0,0,0,0,0,0,0,0,0,0,0,0,0,0,0,0,0,2,1,1
1,1,2,2,0,0,0,0,0,0,0,0,0,0,0,0,0,0,0,0,0,2,2,1,1
1,1,1,2,0,0,0,0,0,0,0,0,0,0,0,0,0,0,0,0,0,2,1,1,1
1,1,1,2,2,0,0,0,0,0,0,0,0,0,0,0,0,0,0,0,2,2,1,1,1
1,1,1,1,2,2,0,0,0,0,0,0,0,0,0,0,0,0,0,2,2,1,1,1,1
1,1,1,1,1,2,2,0,0,0,0,0,0,0,0,0,0,0,2,2,1,1,1,1,1
1,1,1,1,1,1,2,2,2,0,0,0,0,0,0,0,2,2,2,1,1,1,1,1,1
1,1,1,1,1,1,1,1,2,2,2,2,2,2,2,2,2,1,1,1,1,1,1,1,1
1,1,1,1,1,1,1,1,1,1,1,1,1,1,1,1,1,1,1,1,1,1,1,1,1
1,1,1,1,1,1,1,1,1,1,1,1,1,1,1,1,1,1,1,1,1,1,1,1,1
endlayer

layer
1,1,1,1,1,1,1,1,1,1,1,1,1,1,1,1,1,1,1,1,1,1,1,1,1
1,1,1,1,1,1,1,1,1,1,1,1,1,1,1,1,1,1,1,1,1,1,1,1,1
1,1,1,1,1,1,1,1,1,1,1,1,1,1,1,1,1,1,1,1,1,1,1,1,1
1,1,1,1,1,1,1,1,1,2,2,2,2,2,2,2,1,1,1,1,1,1,1,1,1
1,1,1,1,1,1,1,2,2,2,0,0,0,0,0,2,2,2,1,1,1,1,1,1,1
1,1,1,1,1,1,2,2,0,0,0,0,0,0,0,0,0,2,2,1,1,1,1,1,1
1,1,1,1,1,2,2,0,0,0,0,0,0,0,0,0,0,0,2,2,1,1,1,1,1
1,1,1,1,2,2,0,0,0,0,0,0,0,0,0,0,0,0,0,2,2,1,1,1,1
1,1,1,1,2,0,0,0,0,0,0,0,0,0,0,0,0,0,0,0,2,1,1,1,1
1,1,1,2,2,0,0,0,0,0,0,0,0,0,0,0,0,0,0,0,2,2,1,1,1
1,1,1,2,0,0,0,0,0,0,0,0,0,0,0,0,0,0,0,0,0,2,1,1,1
1,1,1,2,0,0,0,0,0,0,0,0,0,0,0,0,0,0,0,0,0,2,1,1,1
1,1,1,2,0,0,0,0,0,0,0,0,0,0,0,0,0,0,0,0,0,2,1,1,1
1,1,1,2,0,0,0,0,0,0,0,0,0,0,0,0,0,0,0,0,0,2,1,1,1
1,1,1,2,0,0,0,0,0,0,0,0,0,0,0,0,0,0,0,0,0,2,1,1,1
1,1,1,2,2,0,0,0,0,0,0,0,0,0,0,0,0,0,0,0,2,2,1,1,1
1,1,1,1,2,0,0,0,0,0,0,0,0,0,0,0,0,0,0,0,2,1,1,1,1
1,1,1,1,2,2,0,0,0,0,0,0,0,0,0,0,0,0,0,2,2,1,1,1,1
1,1,1,1,1,2,2,0,0,0,0,0,0,0,0,0,0,0,2,2,1,1,1,1,1
1,1,1,1,1,1,2,2,0,0,0,0,0,0,0,0,0,2,2,1,1,1,1,1,1
1,1,1,1,1,1,1,2,2,2,0,0,0,0,0,2,2,2,1,1,1,1,1,1,1
1,1,1,1,1,1,1,1,1,2,2,2,2,2,2,2,1,1,1,1,1,1,1,1,1
1,1,1,1,1,1,1,1,1,1,1,1,1,1,1,1,1,1,1,1,1,1,1,1,1
1,1,1,1,1,1,1,1,1,1,1,1,1,1,1,1,1,1,1,1,1,1,1,1,1
1,1,1,1,1,1,1,1,1,1,1,1,1,1,1,1,1,1,1,1,1,1,1,1,1
endlayer

layer
1,1,1,1,1,1,1,1,1,1,1,1,1,1,1,1,1,1,1,1,1,1,1,1,1
1,1,1,1,1,1,1,1,1,1,1,1,1,1,1,1,1,1,1,1,1,1,1,1,1
1,1,1,1,1,1,1,1,1,1,1,1,1,1,1,1,1,1,1,1,1,1,1,1,1
1,1,1,1,1,1,1,1,1,1,1,1,1,1,1,1,1,1,1,1,1,1,1,1,1
1,1,1,1,1,1,1,1,1,1,2,2,2,2,2,1,1,1,1,1,1,1,1,1,1
1,1,1,1,1,1,1,1,2,2,2,2,2,2,2,2,2,1,1,1,1,1,1,1,1
1,1,1,1,1,1,1,2,2,2,0,0,0,0,0,2,2,2,1,1,1,1,1,1,1
1,1,1,1,1,1,2,2,0,0,0,0,0,0,0,0,0,2,2,1,1,1,1,1,1
1,1,1,1,1,2,2,0,0,0,0,0,0,0,0,0,0,0,2,2,1,1,1,1,1
1,1,1,1,1,2,2,0,0,0,0,0,0,0,0,0,0,0,2,2,1,1,1,1,1
1,1,1,1,2,2,0,0,0,0,0,0,0,0,0,0,0,0,0,2,2,1,1,1,1
1,1,1,1,2,2,0,0,0,0,0,0,0,0,0,0,0,0,0,2,2,1,1,1,1
1,1,1,1,2,2,0,0,0,0,0,0,0,0,0,0,0,0,0,2,2,1,1,1,1
1,1,1,1,2,2,0,0,0,0,0,0,0,0,0,0,0,0,0,2,2,1,1,1,1
1,1,1,1,2,2,0,0,0,0,0,0,0,0,0,0,0,0,0,2,2,1,1,1,1
1,1,1,1,1,2,2,0,0,0,0,0,0,0,0,0,0,0,2,2,1,1,1,1,1
1,1,1,1,1,2,2,0,0,0,0,0,0,0,0,0,0,0,2,2,1,1,1,1,1
1,1,1,1,1,1,2,2,0,0,0,0,0,0,0,0,0,2,2,1,1,1,1,1,1
1,1,1,1,1,1,1,2,2,2,0,0,0,0,0,2,2,2,1,1,1,1,1,1,1
1,1,1,1,1,1,1,1,2,2,2,2,2,2,2,2,2,1,1,1,1,1,1,1,1
1,1,1,1,1,1,1,1,1,1,2,2,2,2,2,1,1,1,1,1,1,1,1,1,1
1,1,1,1,1,1,1,1,1,1,1,1,1,1,1,1,1,1,1,1,1,1,1,1,1
1,1,1,1,1,1,1,1,1,1,1,1,1,1,1,1,1,1,1,1,1,1,1,1,1
1,1,1,1,1,1,1,1,1,1,1,1,1,1,1,1,1,1,1,1,1,1,1,1,1
1,1,1,1,1,1,1,1,1,1,1,1,1,1,1,1,1,1,1,1,1,1,1,1,1
endlayer

layer
1,1,1,1,1,1,1,1,1,1,1,1,1,1,1,1,1,1,1,1,1,1,1,1,1
1,1,1,1,1,1,1,1,1,1,1,1,1,1,1,1,1,1,1,1,1,1,1,1,1
1,1,1,1,1,1,1,1,1,1,1,1,1,1,1,1,1,1,1,1,1,1,1,1,1
1,1,1,1,1,1,1,1,1,1,1,1,1,1,1,1,1,1,1,1,1,1,1,1,1
1,1,1,1,1,1,1,1,1,1,1,1,1,1,1,1,1,1,1,1,1,1,1,1,1
1,1,1,1,1,1,1,1,1,1,1,1,1,1,1,1,1,1,1,1,1,1,1,1,1
1,1,1,1,1,1,1,1,1,1,2,2,2,2,2,1,1,1,1,1,1,1,1,1,1
1,1,1,1,1,1,1,1,2,2,2,2,2,2,2,2,2,1,1,1,1,1,1,1,1
1,1,1,1,1,1,1,2,2,2,2,2,2,2,2,2,2,2,1,1,1,1,1,1,1
1,1,1,1,1,1,1,2,2,2,0,0,0,0,0,2,2,2,1,1,1,1,1,1,1
1,1,1,1,1,1,2,2,2,0,0,0,0,0,0,0,2,2,2,1,1,1,1,1,1
1,1,1,1,1,1,2,2,2,0,0,0,0,0,0,0,2,2,2,1,1,1,1,1,1
1,1,1,1,1,1,2,2,2,0,0,0,0,0,0,0,2,2,2,1,1,1,1,1,1
1,1,1,1,1,1,2,2,2,0,0,0,0,0,0,0,2,2,2,1,1,1,1,1,1
1,1,1,1,1,1,2,2,2,0,0,0,0,0,0,0,2,2,2,1,1,1,1,1,1
1,1,1,1,1,1,1,2,2,2,0,0,0,0,0,2,2,2,1,1,1,1,1,1,1
1,1,1,1,1,1,1,2,2,2,2,2,2,2,2,2,2,2,1,1,1,1,1,1,1
1,1,1,1,1,1,1,1,2,2,2,2,2,2,2,2,2,1,1,1,1,1,1,1,1
1,1,1,1,1,1,1,1,1,1,2,2,2,2,2,1,1,1,1,1,1,1,1,1,1
1,1,1,1,1,1,1,1,1,1,1,1,1,1,1,1,1,1,1,1,1,1,1,1,1
1,1,1,1,1,1,1,1,1,1,1,1,1,1,1,1,1,1,1,1,1,1,1,1,1
1,1,1,1,1,1,1,1,1,1,1,1,1,1,1,1,1,1,1,1,1,1,1,1,1
1,1,1,1,1,1,1,1,1,1,1,1,1,1,1,1,1,1,1,1,1,1,1,1,1
1,1,1,1,1,1,1,1,1,1,1,1,1,1,1,1,1,1,1,1,1,1,1,1,1
1,1,1,1,1,1,1,1,1,1,1,1,1,1,1,1,1,1,1,1,1,1,1,1,1
endlayer

layer
1,1,1,1,1,1,1,1,1,1,1,1,1,1,1,1,1,1,1,1,1,1,1,1,1
1,1,1,1,1,1,1,1,1,1,1,1,1,1,1,1,1,1,1,1,1,1,1,1,1
1,1,1,1,1,1,1,1,1,1,1,1,1,1,1,1,1,1,1,1,1,1,1,1,1
1,1,1,1,1,1,1,1,1,1,1,1,1,1,1,1,1,1,1,1,1,1,1,1,1
1,1,1,1,1,1,1,1,1,1,1,1,1,1,1,1,1,1,1,1,1,1,1,1,1
1,1,1,1,1,1,1,1,1,1,1,1,1,1,1,1,1,1,1,1,1,1,1,1,1
1,1,1,1,1,1,1,1,1,1,1,1,1,1,1,1,1,1,1,1,1,1,1,1,1
1,1,1,1,1,1,1,1,1,1,1,1,1,1,1,1,1,1,1,1,1,1,1,1,1
1,1,1,1,1,1,1,1,1,1,1,1,1,1,1,1,1,1,1,1,1,1,1,1,1
1,1,1,1,1,1,1,1,1,1,2,2,2,2,2,1,1,1,1,1,1,1,1,1,1
1,1,1,1,1,1,1,1,1,2,2,2,2,2,2,2,1,1,1,1,1,1,1,1,1
1,1,1,1,1,1,1,1,1,2,2,2,2,2,2,2,1,1,1,1,1,1,1,1,1
1,1,1,1,1,1,1,1,1,2,2,2,2,2,2,2,1,1,1,1,1,1,1,1,1
1,1,1,1,1,1,1,1,1,2,2,2,2,2,2,2,1,1,1,1,1,1,1,1,1
1,1,1,1,1,1,1,1,1,2,2,2,2,2,2,2,1,1,1,1,1,1,1,1,1
1,1,1,1,1,1,1,1,1,1,2,2,2,2,2,1,1,1,1,1,1,1,1,1,1
1,1,1,1,1,1,1,1,1,1,1,1,1,1,1,1,1,1,1,1,1,1,1,1,1
1,1,1,1,1,1,1,1,1,1,1,1,1,1,1,1,1,1,1,1,1,1,1,1,1
1,1,1,1,1,1,1,1,1,1,1,1,1,1,1,1,1,1,1,1,1,1,1,1,1
1,1,1,1,1,1,1,1,1,1,1,1,1,1,1,1,1,1,1,1,1,1,1,1,1
1,1,1,1,1,1,1,1,1,1,1,1,1,1,1,1,1,1,1,1,1,1,1,1,1
1,1,1,1,1,1,1,1,1,1,1,1,1,1,1,1,1,1,1,1,1,1,1,1,1
1,1,1,1,1,1,1,1,1,1,1,1,1,1,1,1,1,1,1,1,1,1,1,1,1
1,1,1,1,1,1,1,1,1,1,1,1,1,1,1,1,1,1,1,1,1,1,1,1,1
1,1,1,1,1,1,1,1,1,1,1,1,1,1,1,1,1,1,1,1,1,1,1,1,1
endlayer

