
# Created by Ruins mod version 17.0 Ingame Parser
# authoring Player: ST753M

weight=1
embed_into_distance=0
acceptable_target_blocks=
unacceptable_target_blocks=flowing_water,water,flowing_lava,lava
dimensions=13,17,17
allowable_overhang=0
max_leveling=0
leveling_buffer=-1
preserve_water=0
preserve_lava=0

rule1=0,100,preserveBlock
rule2=0,100,quark:midori_block-0
rule3=2,100,minecraft:stone-0
rule4=2,100,minecraft:vine-2
rule5=0,100,quark:midori_pillar-0
rule6=0,100,quark:iron_ladder-5
rule7=2,100,minecraft:vine-1
rule8=2,100,minecraft:vine-8
rule9=0,100,quark:midori_block_stairs-0
rule10=0,100,quark:midori_block_stairs-2
rule11=0,100,quark:midori_block_slab-8
rule12=0,100,quark:midori_block_stairs-3
rule13=2,100,minecraft:vine-4
rule14=0,100,quark:midori_block_stairs-1
rule15=0,100,quark:midori_block_slab-0
rule16=0,100,quark:iron_ladder-4
rule17=2,100,minecraft:vine-6
rule18=0,100,MobSpawner:skeleton
rule19=0,100,air
rule20=0,100,IInventory;minecraft:green_shulker_box;minecraft:dye#4#2#2+minecraft:dye#2#2#8+minecraft:bow#{"Quark:RuneColor":13,ench:[{lvl:3s,id:48s},{lvl:3s,id:34s}],RepairCost:3,"Quark:ItemNameDye":2,display:{Name:"The Green Bow"},"Quark:RuneAttached":1b}#0#13+minecraft:skull#1#4#15+minecraft:dye#3#2#19-1

layer
1,1,1,1,1,1,1,1,1,1,1,1,1,1,1,1,1
1,1,1,1,1,1,2,2,2,2,2,1,1,1,1,1,1
1,1,1,1,2,2,2,2,2,2,2,2,2,1,1,1,1
1,1,1,2,2,2,2,2,2,2,2,2,2,2,1,1,1
1,1,2,2,2,2,2,2,2,2,2,2,2,2,2,1,1
1,1,2,2,2,2,2,2,2,2,2,2,2,2,2,1,1
1,2,2,2,2,2,2,2,2,2,2,2,2,2,2,2,1
1,2,2,2,2,2,2,2,2,2,2,2,2,2,2,2,1
1,2,2,2,2,2,2,2,2,2,2,2,2,2,2,2,1
1,2,2,2,2,2,2,2,2,2,2,2,2,2,2,2,1
1,2,2,2,2,2,2,2,2,2,2,2,2,2,2,2,1
1,1,2,2,2,2,2,2,2,2,2,2,2,2,2,1,1
1,1,2,2,2,2,2,2,2,2,2,2,2,2,2,1,1
1,1,1,2,2,2,2,2,2,2,2,2,2,2,1,1,1
1,1,1,1,2,2,2,2,2,2,2,2,2,1,1,1,1
1,1,1,1,1,1,2,2,2,2,2,1,1,1,1,1,1
1,1,1,1,1,1,1,1,1,1,1,1,1,1,1,1,1
endlayer

layer
1,1,1,1,1,1,3,3,3,3,3,1,1,1,1,1,1
1,1,1,1,3,3,0,0,0,4,0,3,3,1,1,1,1
1,1,1,3,0,0,0,0,0,0,0,0,0,3,1,1,1
1,1,3,0,0,0,0,0,0,0,0,0,0,0,3,1,1
1,3,0,0,0,0,0,0,0,0,0,0,0,0,0,3,1
1,3,0,0,0,5,0,0,0,0,0,5,0,0,0,3,1
3,0,0,0,0,0,0,0,0,0,0,0,0,0,0,0,3
3,0,0,0,0,0,0,0,0,0,0,0,0,0,0,0,3
3,0,0,0,0,0,0,0,5,0,0,0,0,0,0,0,3
3,0,0,0,0,0,0,0,6,0,0,0,0,0,0,0,3
3,0,0,0,0,0,0,0,0,0,0,0,0,0,0,0,3
1,3,7,0,0,5,0,0,0,0,0,5,0,0,0,3,1
1,3,0,0,0,0,0,0,0,0,0,0,0,0,0,3,1
1,1,3,0,0,0,0,0,0,0,0,0,0,0,3,1,1
1,1,1,3,0,0,0,0,0,0,0,0,0,3,1,1,1
1,1,1,1,3,3,0,0,0,0,0,3,3,1,1,1,1
1,1,1,1,1,1,3,3,3,3,3,1,1,1,1,1,1
endlayer

layer
1,1,1,1,1,1,3,3,3,3,3,1,1,1,1,1,1
1,1,1,1,3,3,0,4,0,4,4,3,3,1,1,1,1
1,1,1,3,0,4,0,0,0,0,0,0,0,3,1,1,1
1,1,3,0,0,0,0,0,0,0,0,0,0,0,3,1,1
1,3,0,0,0,0,0,0,0,0,0,0,0,0,4,3,1
1,3,0,0,0,5,0,0,0,0,0,5,0,0,0,3,1
3,0,0,0,0,0,0,0,0,0,0,0,0,0,0,4,3
3,0,0,0,0,0,0,0,0,0,0,0,0,0,0,0,3
3,0,0,0,0,0,0,0,5,0,0,0,0,0,0,0,3
3,0,0,0,0,0,0,0,6,0,0,0,0,0,0,0,3
3,0,0,0,0,0,0,0,0,0,0,0,0,0,0,0,3
1,3,7,0,0,5,0,0,0,0,0,5,0,0,0,3,1
1,3,8,0,0,0,0,0,0,0,0,0,0,0,0,3,1
1,1,3,0,0,0,0,0,0,0,0,0,0,0,3,1,1
1,1,1,3,0,8,0,0,0,0,0,0,0,3,1,1,1
1,1,1,1,3,3,8,0,0,0,0,3,3,1,1,1,1
1,1,1,1,1,1,3,3,3,3,3,1,1,1,1,1,1
endlayer

layer
1,1,1,1,1,1,3,3,3,3,3,1,1,1,1,1,1
1,1,1,1,3,3,4,4,4,0,0,3,3,1,1,1,1
1,1,1,3,0,0,0,0,0,0,0,0,0,3,1,1,1
1,1,3,7,0,0,0,0,0,0,0,0,0,0,3,1,1
1,3,7,0,0,8,0,0,0,0,0,0,0,0,4,3,1
1,3,0,0,0,5,9,9,9,9,9,5,0,0,0,3,1
3,0,0,0,0,12,11,11,11,11,11,10,0,0,0,4,3
3,0,0,0,0,12,11,11,11,11,11,10,0,0,0,13,3
3,7,0,0,0,12,11,11,5,11,11,10,0,0,0,0,3
3,7,0,0,0,12,11,11,6,11,11,10,0,0,0,0,3
3,7,0,0,0,12,11,11,11,11,11,10,0,0,0,13,3
1,3,0,0,0,5,14,14,14,14,14,5,0,0,13,3,1
1,3,0,0,0,0,0,0,0,0,0,0,0,0,0,3,1
1,1,3,0,0,0,0,0,0,0,0,0,0,0,3,1,1
1,1,1,3,0,0,0,0,0,0,0,0,0,3,1,1,1
1,1,1,1,3,3,0,0,0,0,0,3,3,1,1,1,1
1,1,1,1,1,1,3,3,3,3,3,1,1,1,1,1,1
endlayer

layer
1,1,1,1,1,1,3,3,3,3,3,1,1,1,1,1,1
1,1,1,1,3,3,4,0,4,0,0,3,3,1,1,1,1
1,1,1,3,4,4,0,0,0,0,0,4,4,3,1,1,1
1,1,3,0,0,0,0,0,0,0,0,0,0,0,3,1,1
1,3,0,0,0,8,0,0,0,0,0,0,0,13,13,3,1
1,3,7,0,0,5,15,15,15,15,15,5,0,0,0,3,1
3,0,0,0,0,15,0,0,0,0,0,15,0,0,0,0,3
3,0,0,0,0,15,0,0,16,0,0,15,0,0,0,0,3
3,0,0,0,0,15,0,0,5,0,0,15,0,0,0,0,3
3,0,0,0,0,15,0,0,6,0,0,15,0,0,0,0,3
3,7,0,0,0,15,0,0,0,0,0,15,0,0,0,0,3
1,3,0,0,0,5,15,15,15,15,15,5,0,0,13,3,1
1,3,8,0,0,0,0,0,0,0,0,0,0,0,0,3,1
1,1,3,0,0,0,0,0,0,0,0,0,0,13,3,1,1
1,1,1,3,7,0,0,0,0,0,0,8,0,3,1,1,1
1,1,1,1,3,3,0,0,0,0,0,3,3,1,1,1,1
1,1,1,1,1,1,3,3,3,3,3,1,1,1,1,1,1
endlayer

layer
1,1,1,1,1,1,3,3,3,3,3,1,1,1,1,1,1
1,1,1,1,3,3,0,0,4,0,13,3,3,1,1,1,1
1,1,1,3,7,0,0,0,0,0,0,0,0,3,1,1,1
1,1,3,7,0,0,0,0,0,0,0,0,0,0,3,1,1
1,3,4,0,0,8,0,0,0,0,0,0,0,13,4,3,1
1,3,0,0,0,5,0,0,0,0,0,5,0,0,0,3,1
3,0,0,0,0,0,0,0,0,0,0,0,0,0,0,0,3
3,7,0,0,0,0,0,0,16,0,0,0,0,0,0,13,3
3,7,0,0,0,0,0,0,5,0,0,0,0,0,0,13,3
3,0,0,0,0,0,0,0,0,0,0,0,0,0,0,0,3
3,7,0,0,0,0,0,0,0,0,0,0,0,0,0,13,3
1,3,0,0,0,5,0,0,0,0,0,5,0,0,13,3,1
1,3,0,0,0,0,0,0,0,0,0,0,0,0,13,3,1
1,1,3,8,0,0,0,0,0,0,0,0,0,13,3,1,1
1,1,1,3,0,0,0,0,0,0,0,0,0,3,1,1,1
1,1,1,1,3,3,0,0,0,8,0,3,3,1,1,1,1
1,1,1,1,1,1,3,3,3,3,3,1,1,1,1,1,1
endlayer

layer
1,1,1,1,1,1,1,3,3,3,1,1,1,1,1,1,1
1,1,1,1,3,3,3,4,4,13,3,3,3,1,1,1,1
1,1,1,3,7,4,4,0,0,0,4,0,4,3,1,1,1
1,1,3,0,0,0,0,0,0,0,0,0,0,4,3,1,1
1,3,4,7,0,8,0,0,0,0,0,0,0,13,4,3,1
1,3,0,0,0,5,9,9,9,9,9,5,0,0,13,3,1
1,3,0,0,0,12,11,11,11,11,11,10,0,0,0,3,1
3,4,0,0,0,12,11,11,16,11,11,10,0,0,0,4,3
3,0,0,0,0,12,11,11,5,11,11,10,0,0,0,0,3
3,0,7,0,0,12,11,11,11,11,11,10,0,0,0,0,3
1,3,7,0,0,12,11,11,11,11,11,10,0,0,0,3,1
1,3,0,0,0,5,14,14,14,14,14,5,0,0,13,3,1
1,3,7,0,0,0,0,0,0,0,0,0,0,0,0,3,1
1,1,3,0,0,0,0,0,0,0,0,0,0,13,3,1,1
1,1,1,3,0,0,0,0,8,0,8,8,13,3,1,1,1
1,1,1,1,3,3,3,0,0,8,3,3,3,1,1,1,1
1,1,1,1,1,1,1,3,3,3,1,1,1,1,1,1,1
endlayer

layer
1,1,1,1,1,1,1,1,1,1,1,1,1,1,1,1,1
1,1,1,1,1,3,3,3,3,3,3,3,1,1,1,1,1
1,1,1,3,3,7,0,0,4,4,4,13,3,3,1,1,1
1,1,3,7,7,0,0,0,0,0,0,0,0,4,3,1,1
1,1,3,7,0,8,0,0,0,0,0,8,0,13,3,1,1
1,3,4,0,0,5,15,15,15,15,15,5,0,0,4,3,1
1,3,0,0,0,15,0,0,0,0,0,15,0,0,17,3,1
1,3,0,0,0,15,0,0,16,0,0,15,0,0,0,3,1
1,3,0,0,0,15,0,0,5,0,0,15,0,0,0,3,1
1,3,7,0,0,15,0,0,6,0,0,15,0,13,0,3,1
1,3,0,0,0,15,0,0,0,0,0,15,0,0,13,3,1
1,3,8,0,0,5,15,15,15,15,15,5,0,0,8,3,1
1,1,3,0,0,0,0,0,0,0,0,0,0,13,3,1,1
1,1,3,0,8,0,0,0,0,0,0,8,0,0,3,1,1
1,1,1,3,3,7,0,0,8,0,0,0,3,3,1,1,1
1,1,1,1,1,3,3,3,3,3,3,3,1,1,1,1,1
1,1,1,1,1,1,1,1,1,1,1,1,1,1,1,1,1
endlayer

layer
1,1,1,1,1,1,1,1,1,1,1,1,1,1,1,1,1
1,1,1,1,1,1,3,3,3,3,3,1,1,1,1,1,1
1,1,1,1,3,3,7,0,4,0,4,3,3,1,1,1,1
1,1,1,3,7,0,0,0,0,4,0,0,4,3,1,1,1
1,1,3,0,0,8,0,0,0,0,0,0,0,4,3,1,1
1,1,3,0,0,5,0,0,0,0,0,5,0,0,3,1,1
1,3,4,0,0,0,0,0,0,0,0,0,0,0,4,3,1
1,3,7,0,0,0,0,0,0,0,0,0,0,0,0,3,1
1,3,0,0,0,0,0,0,18,0,0,0,0,0,0,3,1
1,3,0,0,0,0,0,0,6,0,0,0,0,13,13,3,1
1,3,8,0,0,0,0,0,0,0,0,0,0,0,13,3,1
1,1,3,0,0,5,0,0,0,0,0,5,0,0,3,1,1
1,1,3,8,0,0,0,0,0,0,0,0,0,13,3,1,1
1,1,1,3,8,0,0,0,0,0,0,8,13,3,1,1,1
1,1,1,1,3,3,8,8,8,0,0,3,3,1,1,1,1
1,1,1,1,1,1,3,3,3,3,3,1,1,1,1,1,1
1,1,1,1,1,1,1,1,1,1,1,1,1,1,1,1,1
endlayer

layer
1,1,1,1,1,1,1,1,1,1,1,1,1,1,1,1,1
1,1,1,1,1,1,1,1,1,1,1,1,1,1,1,1,1
1,1,1,1,1,3,3,3,3,3,3,3,1,1,1,1,1
1,1,1,1,3,7,0,0,0,4,0,4,3,1,1,1,1
1,1,1,3,0,8,0,0,0,0,0,8,13,3,1,1,1
1,1,3,0,0,5,9,9,9,9,9,5,7,4,3,1,1
1,1,3,0,0,12,11,11,11,11,11,10,0,0,3,1,1
1,1,3,0,0,12,11,11,11,11,11,10,0,13,3,1,1
1,1,3,7,0,12,11,11,5,11,11,10,0,13,3,1,1
1,1,3,7,0,12,11,11,6,11,11,10,0,13,3,1,1
1,1,3,0,0,12,11,11,11,11,11,10,8,0,3,1,1
1,1,3,8,13,5,14,14,14,14,14,5,7,8,3,1,1
1,1,1,3,0,4,0,0,0,0,0,4,8,3,1,1,1
1,1,1,1,3,0,0,0,0,0,8,0,3,1,1,1,1
1,1,1,1,1,3,3,3,3,3,3,3,1,1,1,1,1
1,1,1,1,1,1,1,1,1,1,1,1,1,1,1,1,1
1,1,1,1,1,1,1,1,1,1,1,1,1,1,1,1,1
endlayer

layer
1,1,1,1,1,1,1,1,1,1,1,1,1,1,1,1,1
1,1,1,1,1,1,1,1,1,1,1,1,1,1,1,1,1
1,1,1,1,1,1,1,1,1,1,1,1,1,1,1,1,1
1,1,1,1,1,3,3,3,3,3,3,3,1,1,1,1,1
1,1,1,1,3,3,7,4,4,0,13,3,3,1,1,1,1
1,1,1,3,3,0,15,15,15,15,15,0,3,3,1,1,1
1,1,1,3,7,15,0,0,0,0,19,15,4,3,1,1,1
1,1,1,3,0,15,0,0,0,0,0,15,0,3,1,1,1
1,1,1,3,7,15,0,0,5,0,0,15,13,3,1,1,1
1,1,1,3,7,15,0,0,6,0,0,15,0,3,1,1,1
1,1,1,3,0,15,0,0,0,0,0,15,8,3,1,1,1
1,1,1,3,3,0,15,15,15,15,15,0,3,3,1,1,1
1,1,1,1,3,3,7,0,8,8,13,3,3,1,1,1,1
1,1,1,1,1,3,3,3,3,3,3,3,1,1,1,1,1
1,1,1,1,1,1,1,1,1,1,1,1,1,1,1,1,1
1,1,1,1,1,1,1,1,1,1,1,1,1,1,1,1,1
1,1,1,1,1,1,1,1,1,1,1,1,1,1,1,1,1
endlayer

layer
1,1,1,1,1,1,1,1,1,1,1,1,1,1,1,1,1
1,1,1,1,1,1,1,1,1,1,1,1,1,1,1,1,1
1,1,1,1,1,1,1,1,1,1,1,1,1,1,1,1,1
1,1,1,1,1,1,1,1,1,1,1,1,1,1,1,1,1
1,1,1,1,1,1,3,3,3,3,3,1,1,1,1,1,1
1,1,1,1,1,3,3,3,3,3,3,3,1,1,1,1,1
1,1,1,1,3,3,3,0,0,0,3,3,3,1,1,1,1
1,1,1,1,3,3,0,0,0,0,0,3,3,1,1,1,1
1,1,1,1,3,3,0,0,20,0,0,3,3,1,1,1,1
1,1,1,1,3,3,0,0,0,0,0,3,3,1,1,1,1
1,1,1,1,3,3,3,0,0,0,3,3,3,1,1,1,1
1,1,1,1,1,3,3,3,3,3,3,3,1,1,1,1,1
1,1,1,1,1,1,3,3,3,3,3,1,1,1,1,1,1
1,1,1,1,1,1,1,1,1,1,1,1,1,1,1,1,1
1,1,1,1,1,1,1,1,1,1,1,1,1,1,1,1,1
1,1,1,1,1,1,1,1,1,1,1,1,1,1,1,1,1
1,1,1,1,1,1,1,1,1,1,1,1,1,1,1,1,1
endlayer

layer
1,1,1,1,1,1,1,1,1,1,1,1,1,1,1,1,1
1,1,1,1,1,1,1,1,1,1,1,1,1,1,1,1,1
1,1,1,1,1,1,1,1,1,1,1,1,1,1,1,1,1
1,1,1,1,1,1,1,1,1,1,1,1,1,1,1,1,1
1,1,1,1,1,1,1,1,1,1,1,1,1,1,1,1,1
1,1,1,1,1,1,1,1,1,1,1,1,1,1,1,1,1
1,1,1,1,1,1,1,3,3,3,1,1,1,1,1,1,1
1,1,1,1,1,1,3,3,3,3,3,1,1,1,1,1,1
1,1,1,1,1,1,3,3,0,3,3,1,1,1,1,1,1
1,1,1,1,1,1,3,3,3,3,3,1,1,1,1,1,1
1,1,1,1,1,1,1,3,3,3,1,1,1,1,1,1,1
1,1,1,1,1,1,1,1,1,1,1,1,1,1,1,1,1
1,1,1,1,1,1,1,1,1,1,1,1,1,1,1,1,1
1,1,1,1,1,1,1,1,1,1,1,1,1,1,1,1,1
1,1,1,1,1,1,1,1,1,1,1,1,1,1,1,1,1
1,1,1,1,1,1,1,1,1,1,1,1,1,1,1,1,1
1,1,1,1,1,1,1,1,1,1,1,1,1,1,1,1,1
endlayer

