
# Created by Ruins mod version 17.0 Ingame Parser
# authoring Player: ST753M

weight=1
embed_into_distance=3
acceptable_target_blocks=
unacceptable_target_blocks=flowing_water,water,flowing_lava,lava
dimensions=16,25,25
allowable_overhang=0
max_leveling=0
leveling_buffer=-1
preserve_water=0
preserve_lava=0

=0,100,air
rule1=0,100,preserveBlock
rule2=2,100,minecraft:stone-0
rule3=0,100,minecraft:grass-0
rule4=0,100,minecraft:water-0
rule5=0,100,minecraft:dirt-0
rule6=0,100,minecraft:reeds-0
rule7=0,100,minecraft:reeds-1
rule8=0,100,minecraft:yellow_flower-0,minecraft:red_flower-2,minecraft:red_flower-3,minecraft:red_flower-1,minecraft:red_flower-0,minecraft:red_flower-4,minecraft:red_flower-7,minecraft:red_flower-6,minecraft:red_flower-5,minecraft:tallgrass-2,minecraft:red_flower-8
rule9=0,100,minecraft:reeds-2
rule10=0,100,quark:stone_marble_bricks_slab-0
rule11=0,100,quark:world_stone_bricks-4
rule12=0,100,quark:stone_marble_bricks_stairs-2
rule13=0,100,quark:stone_marble_bricks_stairs-0
rule14=0,100,quark:stone_marble_bricks_stairs-3
rule15=0,100,quark:stone_marble_bricks_stairs-1
rule16=0,100,quark:stone_marble_bricks_wall-0
rule17=2,100,minecraft:vine-2
rule18=0,100,IInventory;minecraft:lime_shulker_box;minecraft:slime_ball#2#0#0+minecraft:wheat_seeds#2#0#3+minecraft:wheat_seeds#3#0#6+minecraft:slime_ball#1#0#11+minecraft:iron_sword#{"Quark:RuneColor":5,ench:[{lvl:4s,id:18s},{lvl:4s,id:22s}],RepairCost:1,"Quark:ItemNameDye":10,display:{Name:"The Lime Sword"},"Quark:RuneAttached":1b}#0#13+minecraft:lingering_potion#{Potion:"minecraft:poison"}#0#16+minecraft:wheat_seeds#3#0#19+minecraft:potion#{Potion:"minecraft:leaping"}#0#20+minecraft:slime_ball#2#0#24+minecraft:wheat_seeds#2#0#26-0
rule19=2,100,minecraft:vine-8
rule20=2,100,minecraft:vine-4
rule21=2,100,minecraft:vine-1
rule22=2,100,minecraft:vine-9

layer
1,1,1,1,1,1,2,2,2,2,2,2,2,2,2,2,2,2,2,1,1,1,1,1,1
1,1,1,1,1,3,3,3,3,3,3,3,3,3,3,3,3,3,3,3,1,1,1,1,1
1,1,1,1,3,4,4,4,4,4,4,4,4,4,4,4,4,4,4,4,3,1,1,1,1
1,1,1,3,4,4,3,3,3,3,3,3,3,3,3,3,3,3,3,4,4,3,1,1,1
1,1,3,4,4,3,3,3,3,3,3,3,3,3,3,3,3,3,3,3,4,4,3,1,1
1,3,4,4,3,3,3,3,3,3,3,3,3,3,3,3,3,3,3,3,3,4,4,3,1
2,3,4,3,3,3,3,3,3,3,3,3,3,3,3,3,3,3,3,3,3,3,4,3,2
2,3,4,3,3,3,3,3,3,5,3,5,5,5,5,5,3,3,3,3,3,3,4,3,2
2,3,4,3,3,3,3,3,5,5,5,5,5,5,5,5,5,3,3,3,3,3,4,3,2
2,3,4,3,3,3,3,5,5,5,5,5,5,5,5,5,5,5,3,3,3,3,4,3,2
2,3,4,3,3,3,3,3,5,5,5,5,5,5,5,5,5,3,3,3,3,3,4,3,2
2,3,4,3,3,3,3,5,5,5,5,5,5,5,5,5,5,5,5,3,3,3,4,3,2
2,3,4,3,3,3,5,5,5,5,5,5,5,5,5,5,5,5,3,3,3,3,4,3,2
2,3,4,3,3,3,5,5,5,5,5,5,5,5,5,5,5,5,3,3,3,3,4,3,2
2,3,4,3,3,3,3,5,5,5,5,5,5,5,5,5,5,3,3,3,3,3,4,3,2
2,3,4,3,3,3,3,5,5,5,5,5,5,5,5,5,5,5,3,3,3,3,4,3,2
2,3,4,3,3,3,3,3,5,5,5,5,5,5,5,5,5,3,3,3,3,3,4,3,2
2,3,4,3,3,3,3,3,3,5,3,5,5,5,3,5,3,3,3,3,3,3,4,3,2
2,3,4,3,3,3,3,3,3,3,3,3,3,3,3,3,3,3,3,3,3,3,4,3,2
1,3,4,4,3,3,3,3,3,3,3,3,3,3,3,3,3,3,3,3,3,4,4,3,1
1,1,3,4,4,3,3,3,3,3,3,3,3,3,3,3,3,3,3,3,4,4,3,1,1
1,1,1,3,4,4,3,3,3,3,3,3,3,3,3,3,3,3,3,4,4,3,1,1,1
1,1,1,1,3,4,4,4,4,4,4,4,4,4,4,4,4,4,4,4,3,1,1,1,1
1,1,1,1,1,3,3,3,3,3,3,3,3,3,3,3,3,3,3,3,1,1,1,1,1
1,1,1,1,1,1,2,2,2,2,2,2,2,2,2,2,2,2,2,1,1,1,1,1,1
endlayer

layer
1,1,1,1,1,2,2,2,2,2,2,2,2,2,2,2,2,2,2,2,1,1,1,1,1
1,1,1,1,2,6,6,6,6,6,6,6,7,6,6,6,6,6,6,6,2,1,1,1,1
1,1,1,2,6,0,0,0,0,0,0,0,0,0,0,0,0,0,0,0,6,2,1,1,1
1,1,2,6,0,0,8,0,8,0,8,8,8,0,8,8,0,8,8,0,0,6,2,1,1
1,2,6,0,0,8,8,8,0,8,8,8,8,8,8,8,8,8,0,8,0,0,7,2,1
2,6,0,0,8,0,8,0,8,8,8,0,8,8,8,8,8,0,8,8,8,0,0,6,2
2,6,0,8,0,8,8,8,8,8,0,10,10,10,8,8,8,8,8,8,8,8,0,9,2
2,6,0,8,8,8,8,8,8,10,10,11,11,11,10,10,8,8,8,0,8,8,0,6,2
2,6,0,8,8,8,8,0,10,11,11,11,11,11,11,11,10,0,8,8,8,8,0,6,2
2,6,0,8,8,8,8,10,11,11,11,11,11,11,11,11,11,10,8,8,8,8,0,6,2
2,6,0,8,8,8,8,10,11,11,11,11,11,11,11,11,11,10,8,0,8,8,0,7,2
2,6,0,8,8,0,10,11,11,11,11,11,11,11,11,11,11,11,10,8,8,8,0,6,2
2,6,0,8,8,8,10,11,11,11,11,11,11,11,11,11,11,11,10,8,8,8,0,6,2
2,6,0,8,8,8,10,11,11,11,11,11,11,11,11,11,11,11,10,0,8,8,0,6,2
2,6,0,8,8,8,8,10,11,11,11,11,11,11,11,11,11,10,8,8,8,8,0,6,2
2,6,0,8,8,8,8,10,11,11,11,11,11,11,11,11,11,10,0,8,8,8,0,6,2
2,6,0,8,8,0,8,8,10,11,11,11,11,11,11,11,10,8,8,8,8,8,0,6,2
2,6,0,8,8,8,8,8,8,10,10,11,11,11,10,10,8,8,8,8,8,8,0,6,2
2,6,0,0,8,8,8,8,8,8,8,10,10,10,8,8,8,8,8,8,8,8,0,6,2
2,6,0,0,8,8,8,8,8,8,8,8,8,8,0,8,8,8,8,8,8,0,0,6,2
1,2,6,0,0,8,8,8,8,8,8,0,8,8,8,8,8,8,8,0,0,0,6,2,1
1,1,2,6,0,0,0,8,8,0,8,8,8,8,8,8,0,8,8,0,0,6,2,1,1
1,1,1,2,6,0,0,0,0,0,0,0,0,0,0,0,0,0,0,0,6,2,1,1,1
1,1,1,1,2,6,6,6,6,6,6,6,6,6,6,6,6,6,6,6,2,1,1,1,1
1,1,1,1,1,2,2,2,2,2,2,2,2,2,2,2,2,2,2,2,1,1,1,1,1
endlayer

layer
1,1,1,1,2,2,2,2,2,2,2,2,2,2,2,2,2,2,2,2,2,1,1,1,1
1,1,1,2,0,6,6,6,6,6,6,6,6,6,6,6,6,6,6,6,0,2,1,1,1
1,1,2,0,6,0,0,0,0,0,0,0,0,0,0,0,0,0,0,0,6,0,2,1,1
1,2,0,6,0,0,0,0,0,0,0,0,0,0,0,0,0,0,0,0,0,6,0,2,1
2,0,6,0,0,0,0,0,0,0,0,0,0,0,0,0,0,0,0,0,0,0,6,0,2
2,6,0,0,0,0,0,0,0,0,0,0,0,0,0,0,0,0,0,0,0,0,0,6,2
2,6,0,0,0,0,0,0,0,0,0,0,0,0,0,0,0,0,0,0,0,0,0,6,2
2,6,0,0,0,0,0,0,0,0,0,0,0,0,0,0,0,0,0,0,0,0,0,6,2
2,6,0,0,0,0,0,0,0,0,0,0,0,0,0,0,0,0,0,0,0,0,0,6,2
2,6,0,0,0,0,0,0,0,0,14,13,13,13,12,0,0,0,0,0,0,0,0,6,2
2,6,0,0,0,0,0,0,0,13,13,11,11,11,13,12,0,0,0,0,0,0,0,6,2
2,6,0,0,0,0,0,0,0,14,11,11,11,11,11,12,0,0,0,0,0,0,0,6,2
2,6,0,0,0,0,0,0,0,14,11,11,11,11,11,12,0,0,0,0,0,0,0,6,2
2,6,0,0,0,0,0,0,0,14,11,11,11,11,11,12,0,0,0,0,0,0,0,6,2
2,6,0,0,0,0,0,0,0,15,14,11,11,11,12,15,0,0,0,0,0,0,0,6,2
2,6,0,0,0,0,0,0,0,0,14,15,15,15,12,0,0,0,0,0,0,0,0,6,2
2,6,0,0,0,0,0,0,0,0,0,0,0,0,0,0,0,0,0,0,0,0,0,6,2
2,6,0,0,0,0,0,0,0,0,0,0,0,0,0,0,0,0,0,0,0,0,0,6,2
2,6,0,0,0,0,0,0,0,0,0,0,0,0,0,0,0,0,0,0,0,0,0,6,2
2,6,0,0,0,0,0,0,0,0,0,0,0,0,0,0,0,0,0,0,0,0,0,6,2
2,0,6,0,0,0,0,0,0,0,0,0,0,0,0,0,0,0,0,0,0,0,6,0,2
1,2,0,6,0,0,0,0,0,0,0,0,0,0,0,0,0,0,0,0,0,6,0,2,1
1,1,2,0,6,0,0,0,0,0,0,0,0,0,0,0,0,0,0,0,6,0,2,1,1
1,1,1,2,0,6,6,6,6,6,6,6,6,6,6,6,6,6,6,6,0,2,1,1,1
1,1,1,1,2,2,2,2,2,2,2,2,2,2,2,2,2,2,2,2,2,1,1,1,1
endlayer

layer
1,1,1,1,2,2,2,2,2,2,2,2,2,2,2,2,2,2,2,2,2,1,1,1,1
1,1,1,2,0,6,6,6,6,6,6,6,6,6,6,6,6,6,6,6,0,2,1,1,1
1,1,2,0,6,0,0,0,0,0,0,0,0,0,0,0,0,0,0,0,6,0,2,1,1
1,2,0,6,0,0,0,0,0,0,0,0,0,0,0,0,0,0,0,0,0,6,0,2,1
2,0,6,0,0,0,0,0,0,0,0,0,0,0,0,0,0,0,0,0,0,0,6,0,2
2,6,0,0,0,0,0,0,0,0,0,0,0,0,0,0,0,0,0,0,0,0,0,6,2
2,6,0,0,0,0,0,0,0,0,0,0,0,0,0,0,0,0,0,0,0,0,0,6,2
2,6,0,0,0,0,0,0,0,0,0,0,0,0,0,0,0,0,0,0,0,0,0,6,2
2,6,0,0,0,0,0,0,0,0,0,0,0,0,0,0,0,0,0,0,0,0,0,6,2
2,6,0,0,0,0,0,0,0,0,0,0,0,0,0,0,0,0,0,0,0,0,0,6,2
2,6,0,0,0,0,0,0,0,0,0,16,0,16,0,0,0,0,0,0,0,0,0,6,2
2,6,0,0,0,0,0,0,0,0,16,0,0,0,16,0,0,0,0,0,0,0,0,6,2
2,6,0,0,0,0,0,0,0,0,0,0,0,0,0,0,0,0,0,0,0,0,0,6,2
2,6,0,0,0,0,0,0,0,0,16,0,0,0,16,0,0,0,0,0,0,0,0,6,2
2,6,0,0,0,0,0,0,0,0,0,16,0,16,0,0,0,0,0,0,0,0,0,6,2
2,6,0,0,0,0,0,0,0,0,0,0,0,0,0,0,0,0,0,0,0,0,0,6,2
2,6,0,0,0,0,0,0,0,0,0,0,0,0,0,0,0,0,0,0,0,0,0,6,2
2,6,0,0,0,0,0,0,0,0,0,0,0,0,0,0,0,0,0,0,0,0,0,6,2
2,6,0,0,0,0,0,0,0,0,0,0,0,0,0,0,0,0,0,0,0,0,0,6,2
2,6,0,0,0,0,0,0,0,0,0,0,0,0,0,0,0,0,0,0,0,0,0,6,2
2,0,6,0,0,0,0,0,0,0,0,0,0,0,0,0,0,0,0,0,0,0,6,0,2
1,2,0,6,0,0,0,0,0,0,0,0,0,0,0,0,0,0,0,0,0,6,0,2,1
1,1,2,0,6,0,0,0,0,0,0,0,0,0,0,0,0,0,0,0,6,0,2,1,1
1,1,1,2,0,6,6,6,6,6,6,6,6,6,6,6,6,6,6,6,0,2,1,1,1
1,1,1,1,2,2,2,2,2,2,2,2,2,2,2,2,2,2,2,2,2,1,1,1,1
endlayer

layer
1,1,1,1,2,2,2,2,2,2,2,2,2,2,2,2,2,2,2,2,2,1,1,1,1
1,1,1,2,0,0,0,0,0,0,0,0,0,0,0,0,0,17,0,0,0,2,1,1,1
1,1,2,0,0,0,0,0,0,0,0,0,0,0,0,0,0,0,0,0,0,0,2,1,1
1,2,0,0,0,0,0,0,0,0,0,0,0,0,0,0,0,0,0,0,0,0,0,2,1
2,0,0,0,0,0,0,0,0,0,0,0,0,0,0,0,0,0,0,0,0,0,0,0,2
2,0,0,0,0,0,0,0,0,0,0,0,0,0,0,0,0,0,0,0,0,0,0,0,2
2,0,0,0,0,0,0,0,0,0,0,0,0,0,0,0,0,0,0,0,0,0,0,0,2
2,0,0,0,0,0,0,0,0,0,0,0,0,0,0,0,0,0,0,0,0,0,0,0,2
2,0,0,0,0,0,0,0,0,0,0,0,0,0,0,0,0,0,0,0,0,0,0,0,2
2,0,0,0,0,0,0,0,0,0,0,0,0,0,0,0,0,0,0,0,0,0,0,0,2
2,0,0,0,0,0,0,0,0,0,0,16,0,16,0,0,0,0,0,0,0,0,0,0,2
2,0,0,0,0,0,0,0,0,0,16,0,0,0,16,0,0,0,0,0,0,0,0,0,2
2,0,0,0,0,0,0,0,0,0,0,0,18,0,0,0,0,0,0,0,0,0,0,0,2
2,0,0,0,0,0,0,0,0,0,16,0,0,0,16,0,0,0,0,0,0,0,0,0,2
2,0,0,0,0,0,0,0,0,0,0,16,0,16,0,0,0,0,0,0,0,0,0,0,2
2,0,0,0,0,0,0,0,0,0,0,0,0,0,0,0,0,0,0,0,0,0,0,0,2
2,0,0,0,0,0,0,0,0,0,0,0,0,0,0,0,0,0,0,0,0,0,0,0,2
2,0,0,0,0,0,0,0,0,0,0,0,0,0,0,0,0,0,0,0,0,0,0,0,2
2,0,0,0,0,0,0,0,0,0,0,0,0,0,0,0,0,0,0,0,0,0,0,0,2
2,0,0,0,0,0,0,0,0,0,0,0,0,0,0,0,0,0,0,0,0,0,0,0,2
2,0,0,0,0,0,0,0,0,0,0,0,0,0,0,0,0,0,0,0,0,0,0,0,2
1,2,0,0,0,0,0,0,0,0,0,0,0,0,0,0,0,0,0,0,0,0,0,2,1
1,1,2,0,0,0,0,0,0,0,0,0,0,0,0,0,0,0,0,0,0,0,2,1,1
1,1,1,2,0,0,0,0,0,0,0,0,0,0,0,0,0,0,0,0,19,2,1,1,1
1,1,1,1,2,2,2,2,2,2,2,2,2,2,2,2,2,2,2,2,2,1,1,1,1
endlayer

layer
1,1,1,1,2,2,2,2,2,2,2,2,2,2,2,2,2,2,2,2,2,1,1,1,1
1,1,1,2,0,0,0,0,0,0,0,0,0,17,0,0,0,17,0,0,0,2,1,1,1
1,1,2,0,0,0,0,0,0,0,0,0,0,0,0,0,0,0,0,0,17,0,2,1,1
1,2,0,0,0,0,0,0,0,0,0,0,0,0,0,0,0,0,0,0,0,0,0,2,1
2,0,0,0,0,0,0,0,0,0,0,0,0,0,0,0,0,0,0,0,0,0,0,0,2
2,0,0,0,0,0,0,0,0,0,0,0,0,0,0,0,0,0,0,0,0,0,0,20,2
2,0,0,0,0,0,0,0,0,0,0,0,0,0,0,0,0,0,0,0,0,0,0,0,2
2,0,0,0,0,0,0,0,0,0,0,0,0,0,0,0,0,0,0,0,0,0,0,0,2
2,0,0,0,0,0,0,0,0,0,0,0,0,0,0,0,0,0,0,0,0,0,0,0,2
2,0,0,0,0,0,0,0,0,0,0,0,0,0,0,0,0,0,0,0,0,0,0,0,2
2,0,0,0,0,0,0,0,0,0,0,10,10,10,0,0,0,0,0,0,0,0,0,0,2
2,0,0,0,0,0,0,0,0,0,10,10,11,10,10,0,0,0,0,0,0,0,0,0,2
2,0,0,0,0,0,0,0,0,0,10,11,11,11,10,0,0,0,0,0,0,0,0,0,2
2,0,0,0,0,0,0,0,0,0,10,10,11,10,10,0,0,0,0,0,0,0,0,0,2
2,0,0,0,0,0,0,0,0,0,0,10,10,10,0,0,0,0,0,0,0,0,0,0,2
2,0,0,0,0,0,0,0,0,0,0,0,0,0,0,0,0,0,0,0,0,0,0,0,2
2,0,0,0,0,0,0,0,0,0,0,0,0,0,0,0,0,0,0,0,0,0,0,0,2
2,0,0,0,0,0,0,0,0,0,0,0,0,0,0,0,0,0,0,0,0,0,0,0,2
2,21,0,0,0,0,0,0,0,0,0,0,0,0,0,0,0,0,0,0,0,0,0,0,2
2,0,0,0,0,0,0,0,0,0,0,0,0,0,0,0,0,0,0,0,0,0,0,0,2
2,0,0,0,0,0,0,0,0,0,0,0,0,0,0,0,0,0,0,0,0,0,0,20,2
1,2,0,0,0,0,0,0,0,0,0,0,0,0,0,0,0,0,0,0,0,0,0,2,1
1,1,2,0,0,0,0,0,0,0,0,0,0,0,0,0,0,0,0,0,0,0,2,1,1
1,1,1,2,0,19,0,0,19,0,0,0,0,0,0,0,0,0,0,0,19,2,1,1,1
1,1,1,1,2,2,2,2,2,2,2,2,2,2,2,2,2,2,2,2,2,1,1,1,1
endlayer

layer
1,1,1,1,1,2,2,2,2,2,2,2,2,2,2,2,2,2,2,2,1,1,1,1,1
1,1,1,2,2,0,0,0,0,0,0,17,0,0,0,0,0,0,0,0,2,2,1,1,1
1,1,2,17,0,0,0,0,0,0,0,0,0,0,0,0,0,0,0,0,17,17,2,1,1
1,2,0,0,0,0,0,0,0,0,0,0,0,0,0,0,0,0,0,0,0,0,0,2,1
1,2,0,0,0,0,0,0,0,0,0,0,0,0,0,0,0,0,0,0,0,0,0,2,1
2,21,0,0,0,0,0,0,0,0,0,0,0,0,0,0,0,0,0,0,0,0,0,0,2
2,0,0,0,0,0,0,0,0,0,0,0,0,0,0,0,0,0,0,0,0,0,0,20,2
2,0,0,0,0,0,0,0,0,0,0,0,0,0,0,0,0,0,0,0,0,0,0,0,2
2,0,0,0,0,0,0,0,0,0,0,0,0,0,0,0,0,0,0,0,0,0,0,0,2
2,0,0,0,0,0,0,0,0,0,0,0,0,0,0,0,0,0,0,0,0,0,0,0,2
2,0,0,0,0,0,0,0,0,0,0,0,0,0,0,0,0,0,0,0,0,0,0,0,2
2,0,0,0,0,0,0,0,0,0,0,0,0,0,0,0,0,0,0,0,0,0,0,0,2
2,21,0,0,0,0,0,0,0,0,0,0,0,0,0,0,0,0,0,0,0,0,0,0,2
2,21,0,0,0,0,0,0,0,0,0,0,0,0,0,0,0,0,0,0,0,0,0,0,2
2,0,0,0,0,0,0,0,0,0,0,0,0,0,0,0,0,0,0,0,0,0,0,0,2
2,0,0,0,0,0,0,0,0,0,0,0,0,0,0,0,0,0,0,0,0,0,0,0,2
2,0,0,0,0,0,0,0,0,0,0,0,0,0,0,0,0,0,0,0,0,0,0,0,2
2,0,0,0,0,0,0,0,0,0,0,0,0,0,0,0,0,0,0,0,0,0,0,0,2
2,0,0,0,0,0,0,0,0,0,0,0,0,0,0,0,0,0,0,0,0,0,0,0,2
2,0,0,0,0,0,0,0,0,0,0,0,0,0,0,0,0,0,0,0,0,0,0,20,2
1,2,0,0,0,0,0,0,0,0,0,0,0,0,0,0,0,0,0,0,0,0,0,2,1
1,2,21,0,0,0,0,0,0,0,0,0,0,0,0,0,0,0,0,0,0,0,0,2,1
1,1,2,0,0,0,0,0,0,0,0,0,0,0,0,0,0,0,0,0,0,0,2,1,1
1,1,1,2,2,0,19,0,0,0,0,0,0,0,0,0,0,19,0,0,2,2,1,1,1
1,1,1,1,1,2,2,2,2,2,2,2,2,2,2,2,2,2,2,2,1,1,1,1,1
endlayer

layer
1,1,1,1,1,1,2,2,2,2,2,2,2,2,2,2,2,2,2,1,1,1,1,1,1
1,1,1,1,2,2,0,0,0,0,17,0,0,17,0,0,0,0,0,2,2,1,1,1,1
1,1,1,2,17,0,0,0,0,0,0,0,0,0,0,0,0,0,0,0,0,2,1,1,1
1,1,2,0,0,0,0,0,0,0,0,0,0,0,0,0,0,0,0,0,0,0,2,1,1
1,2,0,0,0,0,0,0,0,0,0,0,0,0,0,0,0,0,0,0,0,0,0,2,1
1,2,21,0,0,0,0,0,0,0,0,0,0,0,0,0,0,0,0,0,0,0,0,2,1
2,0,0,0,0,0,0,0,0,0,0,0,0,0,0,0,0,0,0,0,0,0,0,0,2
2,0,0,0,0,0,0,0,0,0,0,0,0,0,0,0,0,0,0,0,0,0,0,0,2
2,21,0,0,0,0,0,0,0,0,0,0,0,0,0,0,0,0,0,0,0,0,0,20,2
2,0,0,0,0,0,0,0,0,0,0,0,0,0,0,0,0,0,0,0,0,0,0,0,2
2,0,0,0,0,0,0,0,0,0,0,0,0,0,0,0,0,0,0,0,0,0,0,0,2
2,0,0,0,0,0,0,0,0,0,0,0,0,0,0,0,0,0,0,0,0,0,0,0,2
2,0,0,0,0,0,0,0,0,0,0,0,0,0,0,0,0,0,0,0,0,0,0,0,2
2,0,0,0,0,0,0,0,0,0,0,0,0,0,0,0,0,0,0,0,0,0,0,0,2
2,0,0,0,0,0,0,0,0,0,0,0,0,0,0,0,0,0,0,0,0,0,0,0,2
2,0,0,0,0,0,0,0,0,0,0,0,0,0,0,0,0,0,0,0,0,0,0,0,2
2,0,0,0,0,0,0,0,0,0,0,0,0,0,0,0,0,0,0,0,0,0,0,0,2
2,0,0,0,0,0,0,0,0,0,0,0,0,0,0,0,0,0,0,0,0,0,0,0,2
2,0,0,0,0,0,0,0,0,0,0,0,0,0,0,0,0,0,0,0,0,0,0,20,2
1,2,0,0,0,0,0,0,0,0,0,0,0,0,0,0,0,0,0,0,0,0,0,2,1
1,2,0,0,0,0,0,0,0,0,0,0,0,0,0,0,0,0,0,0,0,0,19,2,1
1,1,2,0,0,0,0,0,0,0,0,0,0,0,0,0,0,0,0,0,0,0,2,1,1
1,1,1,2,0,0,0,0,0,0,0,0,0,0,0,0,0,0,0,0,0,2,1,1,1
1,1,1,1,2,2,22,0,0,19,19,0,0,19,0,0,0,19,0,2,2,1,1,1,1
1,1,1,1,1,1,2,2,2,2,2,2,2,2,2,2,2,2,2,1,1,1,1,1,1
endlayer

layer
1,1,1,1,1,1,1,2,2,2,2,2,2,2,2,2,2,2,1,1,1,1,1,1,1
1,1,1,1,1,2,2,0,0,0,0,0,0,0,0,0,0,20,2,2,1,1,1,1,1
1,1,1,1,2,0,0,0,0,0,0,0,0,0,0,0,17,0,0,0,2,1,1,1,1
1,1,1,2,0,0,0,0,0,0,0,0,0,0,0,0,0,0,0,0,0,2,1,1,1
1,1,2,0,0,0,0,0,0,0,0,0,0,0,0,0,0,0,0,0,0,20,2,1,1
1,2,0,0,0,0,0,0,0,0,0,0,0,0,0,0,0,0,0,0,0,0,0,2,1
1,2,21,0,0,0,0,0,0,0,0,0,0,0,0,0,0,0,0,0,0,0,0,2,1
2,0,0,0,0,0,0,0,0,0,0,0,0,0,0,0,0,0,0,0,0,0,0,0,2
2,0,0,0,0,0,0,0,0,0,0,0,0,0,0,0,0,0,0,0,0,0,0,0,2
2,0,0,0,0,0,0,0,0,0,0,0,0,0,0,0,0,0,0,0,0,0,0,20,2
2,0,0,0,0,0,0,0,0,0,0,0,0,0,0,0,0,0,0,0,0,0,0,0,2
2,0,0,0,0,0,0,0,0,0,0,0,0,0,0,0,0,0,0,0,0,0,0,20,2
2,0,0,0,0,0,0,0,0,0,0,0,0,0,0,0,0,0,0,0,0,0,0,0,2
2,0,0,0,0,0,0,0,0,0,0,0,0,0,0,0,0,0,0,0,0,0,0,0,2
2,21,0,0,0,0,0,0,0,0,0,0,0,0,0,0,0,0,0,0,0,0,0,0,2
2,0,0,0,0,0,0,0,0,0,0,0,0,0,0,0,0,0,0,0,0,0,0,20,2
2,0,0,0,0,0,0,0,0,0,0,0,0,0,0,0,0,0,0,0,0,0,0,20,2
2,0,0,0,0,0,0,0,0,0,0,0,0,0,0,0,0,0,0,0,0,0,0,20,2
1,2,0,0,0,0,0,0,0,0,0,0,0,0,0,0,0,0,0,0,0,0,0,2,1
1,2,19,0,0,0,0,0,0,0,0,0,0,0,0,0,0,0,0,0,0,0,0,2,1
1,1,2,0,0,0,0,0,0,0,0,0,0,0,0,0,0,0,0,0,0,0,2,1,1
1,1,1,2,21,0,0,0,0,0,0,0,0,0,0,0,0,0,0,0,0,2,1,1,1
1,1,1,1,2,0,0,0,0,0,0,0,0,0,0,0,0,0,0,0,2,1,1,1,1
1,1,1,1,1,2,2,0,0,0,0,0,0,0,0,0,0,20,2,2,1,1,1,1,1
1,1,1,1,1,1,1,2,2,2,2,2,2,2,2,2,2,2,1,1,1,1,1,1,1
endlayer

layer
1,1,1,1,1,1,1,1,1,2,2,2,2,2,2,2,1,1,1,1,1,1,1,1,1
1,1,1,1,1,1,2,2,2,0,17,17,0,0,0,17,2,2,2,1,1,1,1,1,1
1,1,1,1,1,2,0,0,0,0,0,0,0,0,0,0,17,0,17,2,1,1,1,1,1
1,1,1,1,2,17,0,0,0,0,0,0,0,0,0,0,0,0,0,0,2,1,1,1,1
1,1,1,2,0,0,0,0,0,0,0,0,0,0,0,0,0,0,0,0,17,2,1,1,1
1,1,2,17,0,0,0,0,0,0,0,0,0,0,0,0,0,0,0,0,0,17,2,1,1
1,2,17,0,0,0,0,0,0,0,0,0,0,0,0,0,0,0,0,0,0,0,0,2,1
1,2,0,0,0,0,0,0,0,0,0,0,0,0,0,0,0,0,0,0,0,0,0,2,1
1,2,0,0,0,0,0,0,0,0,0,0,0,0,0,0,0,0,0,0,0,0,0,2,1
2,21,0,0,0,0,0,0,0,0,0,0,0,0,0,0,0,0,0,0,0,0,0,0,2
2,0,0,0,0,0,0,0,0,0,0,0,0,0,0,0,0,0,0,0,0,0,0,0,2
2,0,0,0,0,0,0,0,0,0,0,0,0,0,0,0,0,0,0,0,0,0,0,0,2
2,0,0,0,0,0,0,0,0,0,0,0,0,0,0,0,0,0,0,0,0,0,0,20,2
2,0,0,0,0,0,0,0,0,0,0,0,0,0,0,0,0,0,0,0,0,0,0,20,2
2,21,0,0,0,0,0,0,0,0,0,0,0,0,0,0,0,0,0,0,0,0,0,0,2
2,0,0,0,0,0,0,0,0,0,0,0,0,0,0,0,0,0,0,0,0,0,0,20,2
1,2,0,0,0,0,0,0,0,0,0,0,0,0,0,0,0,0,0,0,0,0,0,2,1
1,2,0,0,0,0,0,0,0,0,0,0,0,0,0,0,0,0,0,0,0,0,0,2,1
1,2,0,0,0,0,0,0,0,0,0,0,0,0,0,0,0,0,0,0,0,0,0,2,1
1,1,2,0,0,0,0,0,0,0,0,0,0,0,0,0,0,0,0,0,0,19,2,1,1
1,1,1,2,0,0,0,0,0,0,0,0,0,0,0,0,0,0,0,0,0,2,1,1,1
1,1,1,1,2,0,0,0,0,0,0,0,0,0,0,0,0,0,0,20,2,1,1,1,1
1,1,1,1,1,2,0,0,0,0,0,0,0,0,0,19,19,0,0,2,1,1,1,1,1
1,1,1,1,1,1,2,2,2,21,0,0,0,0,19,0,2,2,2,1,1,1,1,1,1
1,1,1,1,1,1,1,1,1,2,2,2,2,2,2,2,1,1,1,1,1,1,1,1,1
endlayer

layer
1,1,1,1,1,1,1,1,1,1,1,1,1,1,1,1,1,1,1,1,1,1,1,1,1
1,1,1,1,1,1,1,1,2,2,2,2,2,2,2,2,2,1,1,1,1,1,1,1,1
1,1,1,1,1,1,2,2,0,0,0,0,0,0,0,0,17,2,2,1,1,1,1,1,1
1,1,1,1,1,2,0,0,0,0,0,0,0,0,0,0,0,17,0,2,1,1,1,1,1
1,1,1,1,2,17,0,0,0,0,0,0,0,0,0,0,0,0,0,0,2,1,1,1,1
1,1,1,2,0,0,0,0,0,0,0,0,0,0,0,0,0,0,0,0,20,2,1,1,1
1,1,2,21,0,0,0,0,0,0,0,0,0,0,0,0,0,0,0,0,0,0,2,1,1
1,1,2,0,0,0,0,0,0,0,0,0,0,0,0,0,0,0,0,0,0,20,2,1,1
1,2,17,0,0,0,0,0,0,0,0,0,0,0,0,0,0,0,0,0,0,0,20,2,1
1,2,0,0,0,0,0,0,0,0,0,0,0,0,0,0,0,0,0,0,0,0,0,2,1
1,2,0,0,0,0,0,0,0,0,0,0,0,0,0,0,0,0,0,0,0,0,0,2,1
1,2,21,0,0,0,0,0,0,0,0,0,0,0,0,0,0,0,0,0,0,0,20,2,1
1,2,0,0,0,0,0,0,0,0,0,0,0,0,0,0,0,0,0,0,0,0,0,2,1
1,2,0,0,0,0,0,0,0,0,0,0,0,0,0,0,0,0,0,0,0,0,0,2,1
1,2,0,0,0,0,0,0,0,0,0,0,0,0,0,0,0,0,0,0,0,0,0,2,1
1,2,0,0,0,0,0,0,0,0,0,0,0,0,0,0,0,0,0,0,0,0,0,2,1
1,2,21,0,0,0,0,0,0,0,0,0,0,0,0,0,0,0,0,0,0,0,0,2,1
1,1,2,0,0,0,0,0,0,0,0,0,0,0,0,0,0,0,0,0,0,20,2,1,1
1,1,2,19,0,0,0,0,0,0,0,0,0,0,0,0,0,0,0,0,0,0,2,1,1
1,1,1,2,0,0,0,0,0,0,0,0,0,0,0,0,0,0,0,0,0,2,1,1,1
1,1,1,1,2,0,0,0,0,0,0,0,0,0,0,0,0,0,0,0,2,1,1,1,1
1,1,1,1,1,2,21,19,0,0,0,0,0,0,0,0,0,0,0,2,1,1,1,1,1
1,1,1,1,1,1,2,2,21,0,0,0,0,0,0,19,20,2,2,1,1,1,1,1,1
1,1,1,1,1,1,1,1,2,2,2,2,2,2,2,2,2,1,1,1,1,1,1,1,1
1,1,1,1,1,1,1,1,1,1,1,1,1,1,1,1,1,1,1,1,1,1,1,1,1
endlayer

layer
1,1,1,1,1,1,1,1,1,1,1,1,1,1,1,1,1,1,1,1,1,1,1,1,1
1,1,1,1,1,1,1,1,1,1,1,1,1,1,1,1,1,1,1,1,1,1,1,1,1
1,1,1,1,1,1,1,1,2,2,2,2,2,2,2,2,2,1,1,1,1,1,1,1,1
1,1,1,1,1,1,2,2,2,0,0,0,0,0,0,0,2,2,2,1,1,1,1,1,1
1,1,1,1,1,2,2,21,0,0,0,0,0,0,0,0,0,0,2,2,1,1,1,1,1
1,1,1,1,2,2,0,0,0,0,0,0,0,0,0,0,0,0,0,2,2,1,1,1,1
1,1,1,2,2,0,0,0,0,0,0,0,0,0,0,0,0,0,0,0,2,2,1,1,1
1,1,1,2,0,0,0,0,0,0,0,0,0,0,0,0,0,0,0,0,0,2,1,1,1
1,1,2,2,0,0,0,0,0,0,0,0,0,0,0,0,0,0,0,0,0,2,2,1,1
1,1,2,0,0,0,0,0,0,0,0,0,0,0,0,0,0,0,0,0,0,0,2,1,1
1,1,2,0,0,0,0,0,0,0,0,0,0,0,0,0,0,0,0,0,0,0,2,1,1
1,1,2,0,0,0,0,0,0,0,0,0,0,0,0,0,0,0,0,0,0,0,2,1,1
1,1,2,0,0,0,0,0,0,0,0,0,0,0,0,0,0,0,0,0,0,0,2,1,1
1,1,2,0,0,0,0,0,0,0,0,0,0,0,0,0,0,0,0,0,0,0,2,1,1
1,1,2,0,0,0,0,0,0,0,0,0,0,0,0,0,0,0,0,0,0,0,2,1,1
1,1,2,0,0,0,0,0,0,0,0,0,0,0,0,0,0,0,0,0,0,0,2,1,1
1,1,2,2,21,0,0,0,0,0,0,0,0,0,0,0,0,0,0,0,20,2,2,1,1
1,1,1,2,0,0,0,0,0,0,0,0,0,0,0,0,0,0,0,0,0,2,1,1,1
1,1,1,2,2,19,0,0,0,0,0,0,0,0,0,0,0,0,0,0,2,2,1,1,1
1,1,1,1,2,2,0,0,0,0,0,0,0,0,0,0,0,0,19,2,2,1,1,1,1
1,1,1,1,1,2,2,0,0,0,0,0,0,0,0,0,0,0,2,2,1,1,1,1,1
1,1,1,1,1,1,2,2,2,21,0,0,0,0,0,19,2,2,2,1,1,1,1,1,1
1,1,1,1,1,1,1,1,2,2,2,2,2,2,2,2,2,1,1,1,1,1,1,1,1
1,1,1,1,1,1,1,1,1,1,1,1,1,1,1,1,1,1,1,1,1,1,1,1,1
1,1,1,1,1,1,1,1,1,1,1,1,1,1,1,1,1,1,1,1,1,1,1,1,1
endlayer

layer
1,1,1,1,1,1,1,1,1,1,1,1,1,1,1,1,1,1,1,1,1,1,1,1,1
1,1,1,1,1,1,1,1,1,1,1,1,1,1,1,1,1,1,1,1,1,1,1,1,1
1,1,1,1,1,1,1,1,1,1,1,1,1,1,1,1,1,1,1,1,1,1,1,1,1
1,1,1,1,1,1,1,1,1,2,2,2,2,2,2,2,1,1,1,1,1,1,1,1,1
1,1,1,1,1,1,1,2,2,2,21,17,0,0,0,2,2,2,1,1,1,1,1,1,1
1,1,1,1,1,1,2,2,0,0,0,0,0,0,0,0,20,2,2,1,1,1,1,1,1
1,1,1,1,1,2,2,0,0,0,0,0,0,0,0,0,0,0,2,2,1,1,1,1,1
1,1,1,1,2,2,17,0,0,0,0,0,0,0,0,0,0,0,0,2,2,1,1,1,1
1,1,1,1,2,0,0,0,0,0,0,0,0,0,0,0,0,0,0,0,2,1,1,1,1
1,1,1,2,2,0,0,0,0,0,0,0,0,0,0,0,0,0,0,0,2,2,1,1,1
1,1,1,2,21,0,0,0,0,0,0,0,0,0,0,0,0,0,0,0,20,2,1,1,1
1,1,1,2,0,0,0,0,0,0,0,0,0,0,0,0,0,0,0,0,0,2,1,1,1
1,1,1,2,0,0,0,0,0,0,0,0,0,0,0,0,0,0,0,0,0,2,1,1,1
1,1,1,2,0,0,0,0,0,0,0,0,0,0,0,0,0,0,0,0,0,2,1,1,1
1,1,1,2,0,0,0,0,0,0,0,0,0,0,0,0,0,0,0,0,0,2,1,1,1
1,1,1,2,2,0,0,0,0,0,0,0,0,0,0,0,0,0,0,0,2,2,1,1,1
1,1,1,1,2,0,0,0,0,0,0,0,0,0,0,0,0,0,0,0,2,1,1,1,1
1,1,1,1,2,2,0,0,0,0,0,0,0,0,0,0,0,0,0,2,2,1,1,1,1
1,1,1,1,1,2,2,0,0,0,0,0,0,0,0,0,0,19,2,2,1,1,1,1,1
1,1,1,1,1,1,2,2,0,19,0,0,0,0,0,0,0,2,2,1,1,1,1,1,1
1,1,1,1,1,1,1,2,2,2,0,0,0,0,0,2,2,2,1,1,1,1,1,1,1
1,1,1,1,1,1,1,1,1,2,2,2,2,2,2,2,1,1,1,1,1,1,1,1,1
1,1,1,1,1,1,1,1,1,1,1,1,1,1,1,1,1,1,1,1,1,1,1,1,1
1,1,1,1,1,1,1,1,1,1,1,1,1,1,1,1,1,1,1,1,1,1,1,1,1
1,1,1,1,1,1,1,1,1,1,1,1,1,1,1,1,1,1,1,1,1,1,1,1,1
endlayer

layer
1,1,1,1,1,1,1,1,1,1,1,1,1,1,1,1,1,1,1,1,1,1,1,1,1
1,1,1,1,1,1,1,1,1,1,1,1,1,1,1,1,1,1,1,1,1,1,1,1,1
1,1,1,1,1,1,1,1,1,1,1,1,1,1,1,1,1,1,1,1,1,1,1,1,1
1,1,1,1,1,1,1,1,1,1,1,1,1,1,1,1,1,1,1,1,1,1,1,1,1
1,1,1,1,1,1,1,1,1,1,2,2,2,2,2,1,1,1,1,1,1,1,1,1,1
1,1,1,1,1,1,1,1,2,2,2,2,2,2,2,2,2,1,1,1,1,1,1,1,1
1,1,1,1,1,1,1,2,2,2,0,0,0,0,0,2,2,2,1,1,1,1,1,1,1
1,1,1,1,1,1,2,2,0,0,0,0,0,0,0,0,0,2,2,1,1,1,1,1,1
1,1,1,1,1,2,2,0,0,0,0,0,0,0,0,0,0,0,2,2,1,1,1,1,1
1,1,1,1,1,2,2,0,0,0,0,0,0,0,0,0,0,0,2,2,1,1,1,1,1
1,1,1,1,2,2,0,0,0,0,0,0,0,0,0,0,0,0,0,2,2,1,1,1,1
1,1,1,1,2,2,0,0,0,0,0,0,0,0,0,0,0,0,0,2,2,1,1,1,1
1,1,1,1,2,2,0,0,0,0,0,0,0,0,0,0,0,0,0,2,2,1,1,1,1
1,1,1,1,2,2,0,0,0,0,0,0,0,0,0,0,0,0,0,2,2,1,1,1,1
1,1,1,1,2,2,0,0,0,0,0,0,0,0,0,0,0,0,0,2,2,1,1,1,1
1,1,1,1,1,2,2,0,0,0,0,0,0,0,0,0,0,0,2,2,1,1,1,1,1
1,1,1,1,1,2,2,0,0,0,0,0,0,0,0,0,0,0,2,2,1,1,1,1,1
1,1,1,1,1,1,2,2,0,0,0,0,0,0,0,0,0,2,2,1,1,1,1,1,1
1,1,1,1,1,1,1,2,2,2,0,0,0,0,0,2,2,2,1,1,1,1,1,1,1
1,1,1,1,1,1,1,1,2,2,2,2,2,2,2,2,2,1,1,1,1,1,1,1,1
1,1,1,1,1,1,1,1,1,1,2,2,2,2,2,1,1,1,1,1,1,1,1,1,1
1,1,1,1,1,1,1,1,1,1,1,1,1,1,1,1,1,1,1,1,1,1,1,1,1
1,1,1,1,1,1,1,1,1,1,1,1,1,1,1,1,1,1,1,1,1,1,1,1,1
1,1,1,1,1,1,1,1,1,1,1,1,1,1,1,1,1,1,1,1,1,1,1,1,1
1,1,1,1,1,1,1,1,1,1,1,1,1,1,1,1,1,1,1,1,1,1,1,1,1
endlayer

layer
1,1,1,1,1,1,1,1,1,1,1,1,1,1,1,1,1,1,1,1,1,1,1,1,1
1,1,1,1,1,1,1,1,1,1,1,1,1,1,1,1,1,1,1,1,1,1,1,1,1
1,1,1,1,1,1,1,1,1,1,1,1,1,1,1,1,1,1,1,1,1,1,1,1,1
1,1,1,1,1,1,1,1,1,1,1,1,1,1,1,1,1,1,1,1,1,1,1,1,1
1,1,1,1,1,1,1,1,1,1,1,1,1,1,1,1,1,1,1,1,1,1,1,1,1
1,1,1,1,1,1,1,1,1,1,1,1,1,1,1,1,1,1,1,1,1,1,1,1,1
1,1,1,1,1,1,1,1,1,1,2,2,2,2,2,1,1,1,1,1,1,1,1,1,1
1,1,1,1,1,1,1,1,2,2,2,2,2,2,2,2,2,1,1,1,1,1,1,1,1
1,1,1,1,1,1,1,2,2,2,2,2,2,2,2,2,2,2,1,1,1,1,1,1,1
1,1,1,1,1,1,1,2,2,2,0,0,0,0,0,2,2,2,1,1,1,1,1,1,1
1,1,1,1,1,1,2,2,2,0,0,0,0,0,0,0,2,2,2,1,1,1,1,1,1
1,1,1,1,1,1,2,2,2,0,0,0,0,0,0,0,2,2,2,1,1,1,1,1,1
1,1,1,1,1,1,2,2,2,0,0,0,0,0,0,0,2,2,2,1,1,1,1,1,1
1,1,1,1,1,1,2,2,2,0,0,0,0,0,0,0,2,2,2,1,1,1,1,1,1
1,1,1,1,1,1,2,2,2,0,0,0,0,0,0,0,2,2,2,1,1,1,1,1,1
1,1,1,1,1,1,1,2,2,2,0,0,0,0,0,2,2,2,1,1,1,1,1,1,1
1,1,1,1,1,1,1,2,2,2,2,2,2,2,2,2,2,2,1,1,1,1,1,1,1
1,1,1,1,1,1,1,1,2,2,2,2,2,2,2,2,2,1,1,1,1,1,1,1,1
1,1,1,1,1,1,1,1,1,1,2,2,2,2,2,1,1,1,1,1,1,1,1,1,1
1,1,1,1,1,1,1,1,1,1,1,1,1,1,1,1,1,1,1,1,1,1,1,1,1
1,1,1,1,1,1,1,1,1,1,1,1,1,1,1,1,1,1,1,1,1,1,1,1,1
1,1,1,1,1,1,1,1,1,1,1,1,1,1,1,1,1,1,1,1,1,1,1,1,1
1,1,1,1,1,1,1,1,1,1,1,1,1,1,1,1,1,1,1,1,1,1,1,1,1
1,1,1,1,1,1,1,1,1,1,1,1,1,1,1,1,1,1,1,1,1,1,1,1,1
1,1,1,1,1,1,1,1,1,1,1,1,1,1,1,1,1,1,1,1,1,1,1,1,1
endlayer

layer
1,1,1,1,1,1,1,1,1,1,1,1,1,1,1,1,1,1,1,1,1,1,1,1,1
1,1,1,1,1,1,1,1,1,1,1,1,1,1,1,1,1,1,1,1,1,1,1,1,1
1,1,1,1,1,1,1,1,1,1,1,1,1,1,1,1,1,1,1,1,1,1,1,1,1
1,1,1,1,1,1,1,1,1,1,1,1,1,1,1,1,1,1,1,1,1,1,1,1,1
1,1,1,1,1,1,1,1,1,1,1,1,1,1,1,1,1,1,1,1,1,1,1,1,1
1,1,1,1,1,1,1,1,1,1,1,1,1,1,1,1,1,1,1,1,1,1,1,1,1
1,1,1,1,1,1,1,1,1,1,1,1,1,1,1,1,1,1,1,1,1,1,1,1,1
1,1,1,1,1,1,1,1,1,1,1,1,1,1,1,1,1,1,1,1,1,1,1,1,1
1,1,1,1,1,1,1,1,1,1,1,1,1,1,1,1,1,1,1,1,1,1,1,1,1
1,1,1,1,1,1,1,1,1,1,2,2,2,2,2,1,1,1,1,1,1,1,1,1,1
1,1,1,1,1,1,1,1,1,2,2,2,2,2,2,2,1,1,1,1,1,1,1,1,1
1,1,1,1,1,1,1,1,1,2,2,2,2,2,2,2,1,1,1,1,1,1,1,1,1
1,1,1,1,1,1,1,1,1,2,2,2,2,2,2,2,1,1,1,1,1,1,1,1,1
1,1,1,1,1,1,1,1,1,2,2,2,2,2,2,2,1,1,1,1,1,1,1,1,1
1,1,1,1,1,1,1,1,1,2,2,2,2,2,2,2,1,1,1,1,1,1,1,1,1
1,1,1,1,1,1,1,1,1,1,2,2,2,2,2,1,1,1,1,1,1,1,1,1,1
1,1,1,1,1,1,1,1,1,1,1,1,1,1,1,1,1,1,1,1,1,1,1,1,1
1,1,1,1,1,1,1,1,1,1,1,1,1,1,1,1,1,1,1,1,1,1,1,1,1
1,1,1,1,1,1,1,1,1,1,1,1,1,1,1,1,1,1,1,1,1,1,1,1,1
1,1,1,1,1,1,1,1,1,1,1,1,1,1,1,1,1,1,1,1,1,1,1,1,1
1,1,1,1,1,1,1,1,1,1,1,1,1,1,1,1,1,1,1,1,1,1,1,1,1
1,1,1,1,1,1,1,1,1,1,1,1,1,1,1,1,1,1,1,1,1,1,1,1,1
1,1,1,1,1,1,1,1,1,1,1,1,1,1,1,1,1,1,1,1,1,1,1,1,1
1,1,1,1,1,1,1,1,1,1,1,1,1,1,1,1,1,1,1,1,1,1,1,1,1
1,1,1,1,1,1,1,1,1,1,1,1,1,1,1,1,1,1,1,1,1,1,1,1,1
endlayer

