
# Created by Ruins mod version 17.0 Ingame Parser
# authoring Player: ST753M

weight=1
embed_into_distance=4
acceptable_target_blocks=
unacceptable_target_blocks=flowing_water,water,flowing_lava,lava
dimensions=17,15,15
allowable_overhang=0
max_leveling=0
leveling_buffer=-1
preserve_water=0
preserve_lava=0

=0,100,air
rule1=0,100,preserveBlock
rule2=0,100,minecraft:concrete-4
rule3=0,100,minecraft:yellow_glazed_terracotta-3
rule4=0,100,minecraft:yellow_glazed_terracotta-2
rule5=0,100,minecraft:yellow_glazed_terracotta-1
rule6=0,100,minecraft:yellow_glazed_terracotta-0
rule7=0,100,quark:crystal-3
rule8=0,100,IInventory;minecraft:yellow_shulker_box;minecraft:yellow_flower#7#0#2+minecraft:gold_ingot#6#0#6+minecraft:golden_shovel#{"Quark:RuneColor":4,ench:[{lvl:3s,id:35s},{lvl:1s,id:70s}],RepairCost:3,"Quark:ItemNameDye":11,display:{Name:"The Yellow Shovel"},"Quark:RuneAttached":1b}#0#13+minecraft:double_plant#4#0#25-0

layer
1,1,1,1,1,1,1,1,1,1,1,1,1,1,1
1,1,1,1,1,1,1,1,1,1,1,1,1,1,1
1,1,1,1,1,1,1,1,1,1,1,1,1,1,1
1,1,1,1,1,1,1,1,1,1,1,1,1,1,1
1,1,1,1,1,1,1,1,1,1,1,1,1,1,1
1,1,1,1,1,1,1,1,1,1,1,1,1,1,1
1,1,1,1,1,1,1,1,1,1,1,1,1,1,1
1,1,1,1,1,1,1,1,1,1,1,1,1,1,1
1,1,1,1,1,1,1,1,1,1,1,1,1,1,1
1,1,1,1,1,1,1,1,1,1,1,1,1,1,1
1,1,1,1,1,1,1,1,1,1,1,1,1,1,1
1,1,1,1,1,1,1,1,1,1,1,1,1,1,1
1,1,1,1,1,1,1,1,1,1,1,1,1,1,1
1,1,1,1,1,1,1,1,1,1,1,1,1,1,1
1,1,1,1,1,1,1,1,1,1,1,1,1,1,1
endlayer

layer
1,1,1,1,1,1,1,1,1,1,1,1,1,1,1
1,1,1,1,1,1,1,1,1,1,1,1,1,1,1
1,1,1,1,1,1,1,1,1,1,1,1,1,1,1
1,1,1,1,1,1,1,1,1,1,1,1,1,1,1
1,1,1,1,1,1,1,1,1,1,1,1,1,1,1
1,1,1,1,1,1,2,2,2,1,1,1,1,1,1
1,1,1,1,1,2,2,2,2,2,1,1,1,1,1
1,1,1,1,1,2,2,2,2,2,1,1,1,1,1
1,1,1,1,1,2,2,2,2,2,1,1,1,1,1
1,1,1,1,1,1,2,2,2,1,1,1,1,1,1
1,1,1,1,1,1,1,1,1,1,1,1,1,1,1
1,1,1,1,1,1,1,1,1,1,1,1,1,1,1
1,1,1,1,1,1,1,1,1,1,1,1,1,1,1
1,1,1,1,1,1,1,1,1,1,1,1,1,1,1
1,1,1,1,1,1,1,1,1,1,1,1,1,1,1
endlayer

layer
1,1,1,1,1,1,1,1,1,1,1,1,1,1,1
1,1,1,1,1,1,1,1,1,1,1,1,1,1,1
1,1,1,1,1,1,1,1,1,1,1,1,1,1,1
1,1,1,1,1,2,2,2,2,2,1,1,1,1,1
1,1,1,1,2,2,2,2,2,2,2,1,1,1,1
1,1,1,2,2,2,2,2,2,2,2,2,1,1,1
1,1,1,2,2,2,2,2,2,2,2,2,1,1,1
1,1,1,2,2,2,2,2,2,2,2,2,1,1,1
1,1,1,2,2,2,2,2,2,2,2,2,1,1,1
1,1,1,2,2,2,2,2,2,2,2,2,1,1,1
1,1,1,1,2,2,2,2,2,2,2,1,1,1,1
1,1,1,1,1,2,2,2,2,2,1,1,1,1,1
1,1,1,1,1,1,1,1,1,1,1,1,1,1,1
1,1,1,1,1,1,1,1,1,1,1,1,1,1,1
1,1,1,1,1,1,1,1,1,1,1,1,1,1,1
endlayer

layer
1,1,1,1,1,1,1,1,1,1,1,1,1,1,1
1,1,1,1,1,1,1,1,1,1,1,1,1,1,1
1,1,1,1,2,2,2,2,2,2,2,1,1,1,1
1,1,1,2,2,3,4,3,4,3,2,2,1,1,1
1,1,2,2,5,6,5,6,5,6,5,2,2,1,1
1,1,2,3,4,3,4,3,4,3,4,3,2,1,1
1,1,2,6,5,6,5,6,5,6,5,6,2,1,1
1,1,2,3,4,3,4,3,4,3,4,3,2,1,1
1,1,2,6,5,6,5,6,5,6,5,6,2,1,1
1,1,2,3,4,3,4,3,4,3,4,3,2,1,1
1,1,2,2,5,6,5,6,5,6,5,2,2,1,1
1,1,1,2,2,3,4,3,4,3,2,2,1,1,1
1,1,1,1,2,2,2,2,2,2,2,1,1,1,1
1,1,1,1,1,1,1,1,1,1,1,1,1,1,1
1,1,1,1,1,1,1,1,1,1,1,1,1,1,1
endlayer

layer
1,1,1,1,1,1,1,1,1,1,1,1,1,1,1
1,1,1,1,1,7,7,2,7,7,1,1,1,1,1
1,1,1,2,2,2,2,2,2,2,2,2,1,1,1
1,1,2,2,2,0,0,0,0,0,2,2,2,1,1
1,1,2,2,0,0,0,0,0,0,0,2,2,1,1
1,7,2,0,0,0,0,0,0,0,0,0,2,7,1
1,7,2,0,0,0,0,0,0,0,0,0,2,7,1
1,2,2,0,0,0,0,0,0,0,0,0,2,2,1
1,7,2,0,0,0,0,0,0,0,0,0,2,7,1
1,7,2,0,0,0,0,0,0,0,0,0,2,7,1
1,1,2,2,0,0,0,0,0,0,0,2,2,1,1
1,1,2,2,2,0,0,0,0,0,2,2,2,1,1
1,1,1,2,2,2,2,2,2,2,2,2,1,1,1
1,1,1,1,1,7,7,2,7,7,1,1,1,1,1
1,1,1,1,1,1,1,1,1,1,1,1,1,1,1
endlayer

layer
1,1,1,1,1,1,1,1,1,1,1,1,1,1,1
1,1,1,1,2,7,7,2,7,7,2,1,1,1,1
1,1,2,2,0,0,0,0,0,0,0,2,2,1,1
1,1,2,2,0,0,0,0,0,0,0,2,2,1,1
1,2,0,0,0,0,0,0,0,0,0,0,0,2,1
1,7,0,0,0,0,0,0,0,0,0,0,0,7,1
1,7,0,0,0,0,0,0,0,0,0,0,0,7,1
1,2,0,0,0,0,0,0,0,0,0,0,0,2,1
1,7,0,0,0,0,0,0,0,0,0,0,0,7,1
1,7,0,0,0,0,0,0,0,0,0,0,0,7,1
1,2,0,0,0,0,0,0,0,0,0,0,0,2,1
1,1,2,2,0,0,0,0,0,0,0,2,2,1,1
1,1,2,2,0,0,0,0,0,0,0,2,2,1,1
1,1,1,1,2,7,7,2,7,7,2,1,1,1,1
1,1,1,1,1,1,1,1,1,1,1,1,1,1,1
endlayer

layer
1,1,1,1,1,1,7,2,7,1,1,1,1,1,1
1,1,1,7,7,7,0,0,0,7,7,7,1,1,1
1,1,2,2,0,0,0,0,0,0,0,2,2,1,1
1,7,2,2,0,0,0,0,0,0,0,2,2,7,1
1,7,0,0,0,0,0,0,0,0,0,0,0,7,1
1,7,0,0,0,0,0,0,0,0,0,0,0,7,1
7,0,0,0,0,0,0,0,0,0,0,0,0,0,7
2,0,0,0,0,0,0,0,0,0,0,0,0,0,2
7,0,0,0,0,0,0,0,0,0,0,0,0,0,7
1,7,0,0,0,0,0,0,0,0,0,0,0,7,1
1,7,0,0,0,0,0,0,0,0,0,0,0,7,1
1,7,2,2,0,0,0,0,0,0,0,2,2,7,1
1,1,2,2,0,0,0,0,0,0,0,2,2,1,1
1,1,1,7,7,7,0,0,0,7,7,7,1,1,1
1,1,1,1,1,1,7,2,7,1,1,1,1,1,1
endlayer

layer
1,1,1,1,1,7,7,2,7,7,1,1,1,1,1
1,1,1,7,7,0,0,0,0,0,7,7,1,1,1
1,1,2,2,0,0,0,0,0,0,0,2,2,1,1
1,7,2,0,0,0,0,0,0,0,0,0,2,7,1
1,7,0,0,0,0,0,0,0,0,0,0,0,7,1
7,0,0,0,0,0,0,0,0,0,0,0,0,0,7
7,0,0,0,0,0,0,0,0,0,0,0,0,0,7
2,0,0,0,0,0,0,0,0,0,0,0,0,0,2
7,0,0,0,0,0,0,0,0,0,0,0,0,0,7
7,0,0,0,0,0,0,0,0,0,0,0,0,0,7
1,7,0,0,0,0,0,0,0,0,0,0,0,7,1
1,7,2,0,0,0,0,0,0,0,0,0,2,7,1
1,1,2,2,0,0,0,0,0,0,0,2,2,1,1
1,1,1,7,7,0,0,0,0,0,7,7,1,1,1
1,1,1,1,1,7,7,2,7,7,1,1,1,1,1
endlayer

layer
1,1,1,1,1,2,2,2,2,2,1,1,1,1,1
1,1,1,2,2,0,0,0,0,0,2,2,1,1,1
1,1,2,2,0,0,0,0,0,0,0,2,2,1,1
1,2,2,0,0,0,0,0,0,0,0,0,2,2,1
1,2,0,0,0,0,0,0,0,0,0,0,0,2,1
2,0,0,0,0,0,0,0,0,0,0,0,0,0,2
2,0,0,0,0,0,0,0,0,0,0,0,0,0,2
2,0,0,0,0,0,0,0,0,0,0,0,0,0,2
2,0,0,0,0,0,0,0,0,0,0,0,0,0,2
2,0,0,0,0,0,0,0,0,0,0,0,0,0,2
1,2,0,0,0,0,0,0,0,0,0,0,0,2,1
1,2,2,0,0,0,0,0,0,0,0,0,2,2,1
1,1,2,2,0,0,0,0,0,0,0,2,2,1,1
1,1,1,2,2,0,0,0,0,0,2,2,1,1,1
1,1,1,1,1,2,2,2,2,2,1,1,1,1,1
endlayer

layer
1,1,1,1,1,7,7,2,7,7,1,1,1,1,1
1,1,1,7,7,0,0,0,0,0,7,7,1,1,1
1,1,2,2,0,0,0,0,0,0,0,2,2,1,1
1,7,2,0,0,0,0,0,0,0,0,0,2,7,1
1,7,0,0,0,0,0,0,0,0,0,0,0,7,1
7,0,0,0,0,0,0,0,0,0,0,0,0,0,7
7,0,0,0,0,0,0,0,0,0,0,0,0,0,7
2,0,0,0,0,0,0,0,0,0,0,0,0,0,2
7,0,0,0,0,0,0,0,0,0,0,0,0,0,7
7,0,0,0,0,0,0,0,0,0,0,0,0,0,7
1,7,0,0,0,0,0,0,0,0,0,0,0,7,1
1,7,2,0,0,0,0,0,0,0,0,0,2,7,1
1,1,2,2,0,0,0,0,0,0,0,2,2,1,1
1,1,1,7,7,0,0,0,0,0,7,7,1,1,1
1,1,1,1,1,7,7,2,7,7,1,1,1,1,1
endlayer

layer
1,1,1,1,1,1,7,2,7,1,1,1,1,1,1
1,1,1,7,7,7,0,0,0,7,7,7,1,1,1
1,1,2,2,0,0,0,0,0,0,0,2,2,1,1
1,7,2,2,0,0,0,0,0,0,0,2,2,7,1
1,7,0,0,0,0,0,0,0,0,0,0,0,7,1
1,7,0,0,0,0,0,0,0,0,0,0,0,7,1
7,0,0,0,0,0,0,0,0,0,0,0,0,0,7
2,0,0,0,0,0,0,0,0,0,0,0,0,0,2
7,0,0,0,0,0,0,0,0,0,0,0,0,0,7
1,7,0,0,0,0,0,0,0,0,0,0,0,7,1
1,7,0,0,0,0,0,0,0,0,0,0,0,7,1
1,7,2,2,0,0,0,0,0,0,0,2,2,7,1
1,1,2,2,0,0,0,0,0,0,0,2,2,1,1
1,1,1,7,7,7,0,0,0,7,7,7,1,1,1
1,1,1,1,1,1,7,2,7,1,1,1,1,1,1
endlayer

layer
1,1,1,1,1,1,1,1,1,1,1,1,1,1,1
1,1,1,1,2,7,7,2,7,7,2,1,1,1,1
1,1,2,2,0,0,0,0,0,0,0,2,2,1,1
1,1,2,2,0,0,0,0,0,0,0,2,2,1,1
1,2,0,0,0,0,0,0,0,0,0,0,0,2,1
1,7,0,0,0,0,0,0,0,0,0,0,0,7,1
1,7,0,0,0,0,0,0,0,0,0,0,0,7,1
1,2,0,0,0,0,0,0,0,0,0,0,0,2,1
1,7,0,0,0,0,0,0,0,0,0,0,0,7,1
1,7,0,0,0,0,0,0,0,0,0,0,0,7,1
1,2,0,0,0,0,0,0,0,0,0,0,0,2,1
1,1,2,2,0,0,0,0,0,0,0,2,2,1,1
1,1,2,2,0,0,0,0,0,0,0,2,2,1,1
1,1,1,1,2,7,7,2,7,7,2,1,1,1,1
1,1,1,1,1,1,1,1,1,1,1,1,1,1,1
endlayer

layer
1,1,1,1,1,1,1,1,1,1,1,1,1,1,1
1,1,1,1,1,7,7,2,7,7,1,1,1,1,1
1,1,1,2,2,2,2,2,2,2,2,2,1,1,1
1,1,2,2,2,2,0,0,0,2,2,2,2,1,1
1,1,2,2,0,0,0,0,0,0,0,2,2,1,1
1,7,2,2,0,0,0,0,0,0,0,2,2,7,1
1,7,2,0,0,0,0,0,0,0,0,0,2,7,1
1,2,2,0,0,0,0,0,0,0,0,0,2,2,1
1,7,2,0,0,0,0,0,0,0,0,0,2,7,1
1,7,2,2,0,0,0,0,0,0,0,2,2,7,1
1,1,2,2,0,0,0,0,0,0,0,2,2,1,1
1,1,2,2,2,2,0,0,0,2,2,2,2,1,1
1,1,1,2,2,2,2,2,2,2,2,2,1,1,1
1,1,1,1,1,7,7,2,7,7,1,1,1,1,1
1,1,1,1,1,1,1,1,1,1,1,1,1,1,1
endlayer

layer
1,1,1,1,1,1,1,1,1,1,1,1,1,1,1
1,1,1,1,1,1,1,1,1,1,1,1,1,1,1
1,1,1,1,2,2,2,2,2,2,2,1,1,1,1
1,1,1,2,2,2,2,2,2,2,2,2,1,1,1
1,1,2,2,0,0,0,0,0,0,0,2,2,1,1
1,1,2,2,0,0,0,0,0,0,0,2,2,1,1
1,1,2,2,0,0,0,0,0,0,0,2,2,1,1
1,1,2,2,0,0,0,0,0,0,0,2,2,1,1
1,1,2,2,0,0,0,0,0,0,0,2,2,1,1
1,1,2,2,0,0,0,0,0,0,0,2,2,1,1
1,1,2,2,0,0,0,0,0,0,0,2,2,1,1
1,1,1,2,2,2,2,2,2,2,2,2,1,1,1
1,1,1,1,2,2,2,2,2,2,2,1,1,1,1
1,1,1,1,1,1,1,1,1,1,1,1,1,1,1
1,1,1,1,1,1,1,1,1,1,1,1,1,1,1
endlayer

layer
1,1,1,1,1,1,1,1,1,1,1,1,1,1,1
1,1,1,1,1,1,1,1,1,1,1,1,1,1,1
1,1,1,1,1,1,1,1,1,1,1,1,1,1,1
1,1,1,1,1,7,7,2,7,7,1,1,1,1,1
1,1,1,1,2,7,7,2,7,7,2,1,1,1,1
1,1,1,7,7,7,0,0,0,7,7,7,1,1,1
1,1,1,7,7,0,0,0,0,0,7,7,1,1,1
1,1,1,2,2,0,0,8,0,0,2,2,1,1,1
1,1,1,7,7,0,0,0,0,0,7,7,1,1,1
1,1,1,7,7,7,0,0,0,7,7,7,1,1,1
1,1,1,1,2,7,7,2,7,7,2,1,1,1,1
1,1,1,1,1,7,7,2,7,7,1,1,1,1,1
1,1,1,1,1,1,1,1,1,1,1,1,1,1,1
1,1,1,1,1,1,1,1,1,1,1,1,1,1,1
1,1,1,1,1,1,1,1,1,1,1,1,1,1,1
endlayer

layer
1,1,1,1,1,1,1,1,1,1,1,1,1,1,1
1,1,1,1,1,1,1,1,1,1,1,1,1,1,1
1,1,1,1,1,1,1,1,1,1,1,1,1,1,1
1,1,1,1,1,1,1,1,1,1,1,1,1,1,1
1,1,1,1,1,1,1,1,1,1,1,1,1,1,1
1,1,1,1,1,1,7,2,7,1,1,1,1,1,1
1,1,1,1,1,7,7,2,7,7,1,1,1,1,1
1,1,1,1,1,2,2,2,2,2,1,1,1,1,1
1,1,1,1,1,7,7,2,7,7,1,1,1,1,1
1,1,1,1,1,1,7,2,7,1,1,1,1,1,1
1,1,1,1,1,1,1,1,1,1,1,1,1,1,1
1,1,1,1,1,1,1,1,1,1,1,1,1,1,1
1,1,1,1,1,1,1,1,1,1,1,1,1,1,1
1,1,1,1,1,1,1,1,1,1,1,1,1,1,1
1,1,1,1,1,1,1,1,1,1,1,1,1,1,1
endlayer

layer
1,1,1,1,1,1,1,1,1,1,1,1,1,1,1
1,1,1,1,1,1,1,1,1,1,1,1,1,1,1
1,1,1,1,1,1,1,1,1,1,1,1,1,1,1
1,1,1,1,1,1,1,1,1,1,1,1,1,1,1
1,1,1,1,1,1,1,1,1,1,1,1,1,1,1
1,1,1,1,1,1,1,1,1,1,1,1,1,1,1
1,1,1,1,1,1,1,1,1,1,1,1,1,1,1
1,1,1,1,1,1,1,1,1,1,1,1,1,1,1
1,1,1,1,1,1,1,1,1,1,1,1,1,1,1
1,1,1,1,1,1,1,1,1,1,1,1,1,1,1
1,1,1,1,1,1,1,1,1,1,1,1,1,1,1
1,1,1,1,1,1,1,1,1,1,1,1,1,1,1
1,1,1,1,1,1,1,1,1,1,1,1,1,1,1
1,1,1,1,1,1,1,1,1,1,1,1,1,1,1
1,1,1,1,1,1,1,1,1,1,1,1,1,1,1
endlayer

