
# Created by Ruins mod version 17.0 Ingame Parser
# authoring Player: ST753M

weight=1
embed_into_distance=0
acceptable_target_blocks=
unacceptable_target_blocks=flowing_water,water,flowing_lava,lava
dimensions=10,25,17
allowable_overhang=0
max_leveling=0
leveling_buffer=-1
preserve_water=0
preserve_lava=0

=0,100,air
rule1=0,100,preserveBlock
rule2=2,100,minecraft:stone-0
rule3=0,100,minecraft:silver_glazed_terracotta-3
rule4=0,100,minecraft:silver_glazed_terracotta-0
rule5=0,100,minecraft:silver_glazed_terracotta-1
rule6=0,100,minecraft:silver_glazed_terracotta-2
rule7=0,100,minecraft:anvil-0
rule8=0,100,minecraft:stained_hardened_clay-9
rule9=0,100,minecraft:concrete-8
rule10=0,100,minecraft:concrete-9
rule11=0,100,minecraft:cobblestone_wall-0
rule12=0,100,IInventory;minecraft:silver_shulker_box;minecraft:web#4#0#1+minecraft:bucket#2#0#3+minecraft:iron_ingot#2#0#6+minecraft:arrow#5#0#8+minecraft:arrow#10#0#9+minecraft:iron_chestplate#{"Quark:RuneColor":8,ench:[{lvl:3s,id:8s},{lvl:4s,id:3s}],RepairCost:3,"Quark:ItemNameDye":7,display:{Name:"The Silver Chestplate"},"Quark:RuneAttached":1b}#0#13+minecraft:web#1#0#17+minecraft:skull#1#0#19+minecraft:iron_ingot#3#0#21+minecraft:arrow#4#0#23+minecraft:web#2#0#25-1
rule13=0,100,quark:crystal-0

layer
1,1,1,1,1,1,2,2,2,2,2,1,1,1,1,1,1
1,1,1,1,1,2,3,4,3,4,3,2,1,1,1,1,1
1,1,1,1,2,5,6,5,6,5,6,5,2,1,1,1,1
1,1,1,2,3,4,3,4,3,4,3,4,3,2,1,1,1
1,1,2,5,6,5,6,5,6,5,6,5,6,5,2,1,1
1,1,2,4,3,4,3,4,3,4,3,4,3,4,2,1,1
1,2,6,5,6,5,6,5,6,5,6,5,6,5,6,2,1
1,2,3,4,3,4,3,4,3,4,3,4,3,4,3,2,1
1,2,6,5,6,5,6,5,6,5,6,5,6,5,6,2,1
2,4,3,4,3,4,3,4,3,4,3,4,3,4,3,4,2
2,5,6,5,6,5,6,5,6,5,6,5,6,5,6,5,2
2,4,3,4,3,4,3,4,3,4,3,4,3,4,3,4,2
2,5,6,5,6,5,6,5,6,5,6,5,6,5,6,5,2
2,4,3,4,3,4,3,4,3,4,3,4,3,4,3,4,2
2,5,6,5,6,5,6,5,6,5,6,5,6,5,6,5,2
2,4,3,4,3,4,3,4,3,4,3,4,3,4,3,4,2
1,2,6,5,6,5,6,5,6,5,6,5,6,5,6,2,1
1,2,3,4,3,4,3,4,3,4,3,4,3,4,3,2,1
1,2,6,5,6,5,6,5,6,5,6,5,6,5,6,2,1
1,1,2,4,3,4,3,4,3,4,3,4,3,4,2,1,1
1,1,2,5,6,5,6,5,6,5,6,5,6,5,2,1,1
1,1,1,2,3,4,3,4,3,4,3,4,3,2,1,1,1
1,1,1,1,2,5,6,5,6,5,6,5,2,1,1,1,1
1,1,1,1,1,2,3,4,3,4,3,2,1,1,1,1,1
1,1,1,1,1,1,2,2,2,2,2,1,1,1,1,1,1
endlayer

layer
1,1,1,1,1,1,2,2,2,2,2,1,1,1,1,1,1
1,1,1,1,1,2,0,0,0,0,0,2,1,1,1,1,1
1,1,1,1,2,0,0,0,7,0,0,0,2,1,1,1,1
1,1,1,2,0,0,0,0,0,0,0,0,0,2,1,1,1
1,1,2,0,0,0,0,0,0,0,0,0,0,0,2,1,1
1,1,2,0,0,0,0,0,0,0,0,0,0,0,2,1,1
1,2,0,0,0,0,0,0,0,0,0,0,0,0,0,2,1
1,2,0,0,0,8,8,8,0,8,8,8,0,0,0,2,1
1,2,0,0,0,8,8,8,0,8,8,8,0,0,0,2,1
2,0,0,0,0,8,8,8,0,8,8,8,0,0,0,0,2
2,0,0,0,0,0,9,9,9,9,9,0,0,0,0,0,2
2,0,0,8,8,8,9,10,10,10,9,8,8,8,0,0,2
2,0,0,8,8,8,9,10,10,10,9,8,8,8,0,0,2
2,0,0,8,8,8,9,10,10,10,9,8,8,8,0,0,2
2,0,0,0,0,0,9,9,9,9,9,0,0,0,0,0,2
2,0,0,0,0,8,8,8,0,8,8,8,0,0,0,0,2
1,2,0,0,0,8,8,8,0,8,8,8,0,0,0,2,1
1,2,0,0,0,8,8,8,0,8,8,8,0,0,0,2,1
1,2,0,0,0,0,0,0,0,0,0,0,0,0,0,2,1
1,1,2,0,0,0,0,0,0,0,0,0,0,0,2,1,1
1,1,2,0,0,0,0,0,0,0,0,0,0,0,2,1,1
1,1,1,2,0,0,0,0,0,0,0,0,0,2,1,1,1
1,1,1,1,2,0,0,0,7,0,0,0,2,1,1,1,1
1,1,1,1,1,2,0,0,0,0,0,2,1,1,1,1,1
1,1,1,1,1,1,2,2,2,2,2,1,1,1,1,1,1
endlayer

layer
1,1,1,1,1,1,2,2,2,2,2,1,1,1,1,1,1
1,1,1,1,1,2,0,0,0,0,0,2,1,1,1,1,1
1,1,1,1,2,0,0,0,0,0,0,0,2,1,1,1,1
1,1,1,2,0,0,0,0,0,0,0,0,0,2,1,1,1
1,1,2,0,0,0,0,0,0,0,0,0,0,0,2,1,1
1,1,2,0,0,0,0,0,0,0,0,0,0,0,2,1,1
1,2,0,0,0,0,0,0,0,0,0,0,0,0,0,2,1
1,2,0,0,0,0,11,0,0,0,11,0,0,0,0,2,1
1,2,0,0,0,11,9,11,0,11,9,11,0,0,0,2,1
2,0,0,0,0,0,11,0,0,0,11,0,0,0,0,0,2
2,0,0,0,0,0,0,0,0,0,0,0,0,0,0,0,2
2,0,0,0,11,0,0,0,0,0,0,0,11,0,0,0,2
2,0,0,11,9,11,0,0,12,0,0,11,9,11,0,0,2
2,0,0,0,11,0,0,0,0,0,0,0,11,0,0,0,2
2,0,0,0,0,0,0,0,0,0,0,0,0,0,0,0,2
2,0,0,0,0,0,11,0,0,0,11,0,0,0,0,0,2
1,2,0,0,0,11,9,11,0,11,9,11,0,0,0,2,1
1,2,0,0,0,0,11,0,0,0,11,0,0,0,0,2,1
1,2,0,0,0,0,0,0,0,0,0,0,0,0,0,2,1
1,1,2,0,0,0,0,0,0,0,0,0,0,0,2,1,1
1,1,2,0,0,0,0,0,0,0,0,0,0,0,2,1,1
1,1,1,2,0,0,0,0,0,0,0,0,0,2,1,1,1
1,1,1,1,2,0,0,0,0,0,0,0,2,1,1,1,1
1,1,1,1,1,2,0,0,0,0,0,2,1,1,1,1,1
1,1,1,1,1,1,2,2,2,2,2,1,1,1,1,1,1
endlayer

layer
1,1,1,1,1,1,2,2,2,2,2,1,1,1,1,1,1
1,1,1,1,1,2,0,0,0,0,0,2,1,1,1,1,1
1,1,1,1,2,0,0,0,0,0,0,0,2,1,1,1,1
1,1,1,2,0,0,0,0,0,0,0,0,0,2,1,1,1
1,1,2,0,0,0,0,0,0,0,0,0,0,0,2,1,1
1,1,2,0,0,0,0,0,0,0,0,0,0,0,2,1,1
1,2,0,0,0,0,0,0,0,0,0,0,0,0,0,2,1
1,2,0,0,0,0,0,0,0,0,0,0,0,0,0,2,1
1,2,0,0,0,0,9,0,0,0,9,0,0,0,0,2,1
2,0,0,0,0,0,0,0,0,0,0,0,0,0,0,0,2
2,0,0,0,0,0,0,0,0,0,0,0,0,0,0,0,2
2,0,0,0,0,0,0,0,0,0,0,0,0,0,0,0,2
2,0,0,0,9,0,0,0,0,0,0,0,9,0,0,0,2
2,0,0,0,0,0,0,0,0,0,0,0,0,0,0,0,2
2,0,0,0,0,0,0,0,0,0,0,0,0,0,0,0,2
2,0,0,0,0,0,0,0,0,0,0,0,0,0,0,0,2
1,2,0,0,0,0,9,0,0,0,9,0,0,0,0,2,1
1,2,0,0,0,0,0,0,0,0,0,0,0,0,0,2,1
1,2,0,0,0,0,0,0,0,0,0,0,0,0,0,2,1
1,1,2,0,0,0,0,0,0,0,0,0,0,0,2,1,1
1,1,2,0,0,0,0,0,0,0,0,0,0,0,2,1,1
1,1,1,2,0,0,0,0,0,0,0,0,0,2,1,1,1
1,1,1,1,2,0,0,0,0,0,0,0,2,1,1,1,1
1,1,1,1,1,2,0,0,0,0,0,2,1,1,1,1,1
1,1,1,1,1,1,2,2,2,2,2,1,1,1,1,1,1
endlayer

layer
1,1,1,1,1,1,1,1,2,1,1,1,1,1,1,1,1
1,1,1,1,1,2,2,2,0,2,2,2,1,1,1,1,1
1,1,1,1,2,0,0,0,0,0,0,0,2,1,1,1,1
1,1,1,2,0,0,0,0,0,0,0,0,0,2,1,1,1
1,1,2,0,0,0,0,0,0,0,0,0,0,0,2,1,1
1,1,2,0,0,0,0,0,0,0,0,0,0,0,2,1,1
1,2,0,0,0,0,0,0,0,0,0,0,0,0,0,2,1
1,2,0,0,0,0,0,0,0,0,0,0,0,0,0,2,1
1,2,0,0,0,0,9,0,0,0,9,0,0,0,0,2,1
1,2,0,0,0,0,0,0,0,0,0,0,0,0,0,2,1
2,0,0,0,0,0,0,0,0,0,0,0,0,0,0,0,2
2,0,0,0,0,0,0,0,0,0,0,0,0,0,0,0,2
2,0,0,0,9,0,0,0,0,0,0,0,9,0,0,0,2
2,0,0,0,0,0,0,0,0,0,0,0,0,0,0,0,2
2,0,0,0,0,0,0,0,0,0,0,0,0,0,0,0,2
1,2,0,0,0,0,0,0,0,0,0,0,0,0,0,2,1
1,2,0,0,0,0,9,0,0,0,9,0,0,0,0,2,1
1,2,0,0,0,0,0,0,0,0,0,0,0,0,0,2,1
1,2,0,0,0,0,0,0,0,0,0,0,0,0,0,2,1
1,1,2,0,0,0,0,0,0,0,0,0,0,0,2,1,1
1,1,2,0,0,0,0,0,0,0,0,0,0,0,2,1,1
1,1,1,2,0,0,0,0,0,0,0,0,0,2,1,1,1
1,1,1,1,2,0,0,0,0,0,0,0,2,1,1,1,1
1,1,1,1,1,2,2,2,0,2,2,2,1,1,1,1,1
1,1,1,1,1,1,1,1,2,1,1,1,1,1,1,1,1
endlayer

layer
1,1,1,1,1,1,1,1,1,1,1,1,1,1,1,1,1
1,1,1,1,1,1,2,2,2,2,2,1,1,1,1,1,1
1,1,1,1,1,2,0,0,0,0,0,2,1,1,1,1,1
1,1,1,1,2,0,0,0,0,0,0,0,2,1,1,1,1
1,1,1,2,0,0,0,0,0,0,0,0,0,2,1,1,1
1,1,2,0,0,0,0,0,0,0,0,0,0,0,2,1,1
1,1,2,0,0,0,0,0,0,0,0,0,0,0,2,1,1
1,2,0,0,0,0,0,0,0,0,0,0,0,0,0,2,1
1,2,0,0,0,0,9,0,0,0,9,0,0,0,0,2,1
1,2,0,0,0,0,0,0,0,0,0,0,0,0,0,2,1
1,2,0,0,0,0,0,0,0,0,0,0,0,0,0,2,1
1,2,0,0,0,0,0,0,0,0,0,0,0,0,0,2,1
1,2,0,0,9,0,0,0,0,0,0,0,9,0,0,2,1
1,2,0,0,0,0,0,0,0,0,0,0,0,0,0,2,1
1,2,0,0,0,0,0,0,0,0,0,0,0,0,0,2,1
1,2,0,0,0,0,0,0,0,0,0,0,0,0,0,2,1
1,2,0,0,0,0,9,0,0,0,9,0,0,0,0,2,1
1,2,0,0,0,0,0,0,0,0,0,0,0,0,0,2,1
1,1,2,0,0,0,0,0,0,0,0,0,0,0,2,1,1
1,1,2,0,0,0,0,0,0,0,0,0,0,0,2,1,1
1,1,1,2,0,0,0,0,0,0,0,0,0,2,1,1,1
1,1,1,1,2,0,0,0,0,0,0,0,2,1,1,1,1
1,1,1,1,1,2,0,0,0,0,0,2,1,1,1,1,1
1,1,1,1,1,1,2,2,2,2,2,1,1,1,1,1,1
1,1,1,1,1,1,1,1,1,1,1,1,1,1,1,1,1
endlayer

layer
1,1,1,1,1,1,1,1,1,1,1,1,1,1,1,1,1
1,1,1,1,1,1,1,1,1,1,1,1,1,1,1,1,1
1,1,1,1,1,1,2,2,2,2,2,1,1,1,1,1,1
1,1,1,1,1,2,2,0,0,0,2,2,1,1,1,1,1
1,1,1,1,2,0,0,0,0,0,0,0,2,1,1,1,1
1,1,1,2,0,0,0,0,0,0,0,0,0,2,1,1,1
1,1,1,2,0,0,0,0,0,0,0,0,0,2,1,1,1
1,1,2,0,0,0,11,0,0,0,11,0,0,0,2,1,1
1,1,2,0,0,11,9,11,0,11,9,11,0,0,2,1,1
1,1,2,0,0,0,11,0,0,0,11,0,0,0,2,1,1
1,2,0,0,0,0,0,0,0,0,0,0,0,0,0,2,1
1,2,0,0,11,0,0,0,0,0,0,0,11,0,0,2,1
1,2,0,11,9,11,0,0,0,0,0,11,9,11,0,2,1
1,2,0,0,11,0,0,0,0,0,0,0,11,0,0,2,1
1,2,0,0,0,0,0,0,0,0,0,0,0,0,0,2,1
1,1,2,0,0,0,11,0,0,0,11,0,0,0,2,1,1
1,1,2,0,0,11,9,11,0,11,9,11,0,0,2,1,1
1,1,2,0,0,0,11,0,0,0,11,0,0,0,2,1,1
1,1,1,2,0,0,0,0,0,0,0,0,0,2,1,1,1
1,1,1,2,0,0,0,0,0,0,0,0,0,2,1,1,1
1,1,1,1,2,0,0,0,0,0,0,0,2,1,1,1,1
1,1,1,1,1,2,2,0,0,0,2,2,1,1,1,1,1
1,1,1,1,1,1,2,2,2,2,2,1,1,1,1,1,1
1,1,1,1,1,1,1,1,1,1,1,1,1,1,1,1,1
1,1,1,1,1,1,1,1,1,1,1,1,1,1,1,1,1
endlayer

layer
1,1,1,1,1,1,1,1,1,1,1,1,1,1,1,1,1
1,1,1,1,1,1,1,1,1,1,1,1,1,1,1,1,1
1,1,1,1,1,1,1,1,1,1,1,1,1,1,1,1,1
1,1,1,1,1,1,1,2,2,2,1,1,1,1,1,1,1
1,1,1,1,1,2,2,2,2,2,2,2,1,1,1,1,1
1,1,1,1,2,2,2,0,0,0,2,2,2,1,1,1,1
1,1,1,1,2,0,0,0,0,0,0,0,2,1,1,1,1
1,1,1,2,2,0,0,0,0,0,0,0,2,2,1,1,1
1,1,1,2,0,0,13,0,0,0,13,0,0,2,1,1,1
1,1,1,2,0,0,0,0,0,0,0,0,0,2,1,1,1
1,1,2,2,0,0,0,0,0,0,0,0,0,2,2,1,1
1,1,2,0,0,0,0,0,0,0,0,0,0,0,2,1,1
1,1,2,0,13,0,0,0,0,0,0,0,13,0,2,1,1
1,1,2,0,0,0,0,0,0,0,0,0,0,0,2,1,1
1,1,2,2,0,0,0,0,0,0,0,0,0,2,2,1,1
1,1,1,2,0,0,0,0,0,0,0,0,0,2,1,1,1
1,1,1,2,0,0,13,0,0,0,13,0,0,2,1,1,1
1,1,1,2,2,0,0,0,0,0,0,0,2,2,1,1,1
1,1,1,1,2,0,0,0,0,0,0,0,2,1,1,1,1
1,1,1,1,2,2,2,0,0,0,2,2,2,1,1,1,1
1,1,1,1,1,2,2,2,2,2,2,2,1,1,1,1,1
1,1,1,1,1,1,1,2,2,2,1,1,1,1,1,1,1
1,1,1,1,1,1,1,1,1,1,1,1,1,1,1,1,1
1,1,1,1,1,1,1,1,1,1,1,1,1,1,1,1,1
1,1,1,1,1,1,1,1,1,1,1,1,1,1,1,1,1
endlayer

layer
1,1,1,1,1,1,1,1,1,1,1,1,1,1,1,1,1
1,1,1,1,1,1,1,1,1,1,1,1,1,1,1,1,1
1,1,1,1,1,1,1,1,1,1,1,1,1,1,1,1,1
1,1,1,1,1,1,1,1,1,1,1,1,1,1,1,1,1
1,1,1,1,1,1,1,1,1,1,1,1,1,1,1,1,1
1,1,1,1,1,1,1,2,2,2,1,1,1,1,1,1,1
1,1,1,1,1,2,2,2,2,2,2,2,1,1,1,1,1
1,1,1,1,1,2,2,2,2,2,2,2,1,1,1,1,1
1,1,1,1,2,2,2,0,0,0,2,2,2,1,1,1,1
1,1,1,1,2,2,0,0,0,0,0,2,2,1,1,1,1
1,1,1,1,2,2,0,0,0,0,0,2,2,1,1,1,1
1,1,1,2,2,2,0,0,0,0,0,2,2,2,1,1,1
1,1,1,2,2,0,0,0,0,0,0,0,2,2,1,1,1
1,1,1,2,2,2,0,0,0,0,0,2,2,2,1,1,1
1,1,1,1,2,2,0,0,0,0,0,2,2,1,1,1,1
1,1,1,1,2,2,0,0,0,0,0,2,2,1,1,1,1
1,1,1,1,2,2,2,0,0,0,2,2,2,1,1,1,1
1,1,1,1,1,2,2,2,2,2,2,2,1,1,1,1,1
1,1,1,1,1,2,2,2,2,2,2,2,1,1,1,1,1
1,1,1,1,1,1,1,2,2,2,1,1,1,1,1,1,1
1,1,1,1,1,1,1,1,1,1,1,1,1,1,1,1,1
1,1,1,1,1,1,1,1,1,1,1,1,1,1,1,1,1
1,1,1,1,1,1,1,1,1,1,1,1,1,1,1,1,1
1,1,1,1,1,1,1,1,1,1,1,1,1,1,1,1,1
1,1,1,1,1,1,1,1,1,1,1,1,1,1,1,1,1
endlayer

layer
1,1,1,1,1,1,1,1,1,1,1,1,1,1,1,1,1
1,1,1,1,1,1,1,1,1,1,1,1,1,1,1,1,1
1,1,1,1,1,1,1,1,1,1,1,1,1,1,1,1,1
1,1,1,1,1,1,1,1,1,1,1,1,1,1,1,1,1
1,1,1,1,1,1,1,1,1,1,1,1,1,1,1,1,1
1,1,1,1,1,1,1,1,1,1,1,1,1,1,1,1,1
1,1,1,1,1,1,1,1,1,1,1,1,1,1,1,1,1
1,1,1,1,1,1,1,1,1,1,1,1,1,1,1,1,1
1,1,1,1,1,1,1,2,2,2,1,1,1,1,1,1,1
1,1,1,1,1,1,2,2,2,2,2,1,1,1,1,1,1
1,1,1,1,1,1,2,2,2,2,2,1,1,1,1,1,1
1,1,1,1,1,1,2,2,2,2,2,1,1,1,1,1,1
1,1,1,1,1,2,2,2,2,2,2,2,1,1,1,1,1
1,1,1,1,1,1,2,2,2,2,2,1,1,1,1,1,1
1,1,1,1,1,1,2,2,2,2,2,1,1,1,1,1,1
1,1,1,1,1,1,2,2,2,2,2,1,1,1,1,1,1
1,1,1,1,1,1,1,2,2,2,1,1,1,1,1,1,1
1,1,1,1,1,1,1,1,1,1,1,1,1,1,1,1,1
1,1,1,1,1,1,1,1,1,1,1,1,1,1,1,1,1
1,1,1,1,1,1,1,1,1,1,1,1,1,1,1,1,1
1,1,1,1,1,1,1,1,1,1,1,1,1,1,1,1,1
1,1,1,1,1,1,1,1,1,1,1,1,1,1,1,1,1
1,1,1,1,1,1,1,1,1,1,1,1,1,1,1,1,1
1,1,1,1,1,1,1,1,1,1,1,1,1,1,1,1,1
1,1,1,1,1,1,1,1,1,1,1,1,1,1,1,1,1
endlayer

