
# Created by Ruins mod version 16.7 Ingame Parser
# authoring Player: ST753M

weight=1
embed_into_distance=2
acceptable_target_blocks=mycelium,grass
unacceptable_target_blocks=flowing_water,water,flowing_lava,lava
dimensions=16,17,17
allowable_overhang=16
max_leveling=0
leveling_buffer=-1
preserve_water=0
preserve_lava=0

biomesToSpawnIn=mushroomisland,mushroomislandshore,mushroom_island,mushroom_island_shore,mushroom_forest,deep_mushroom_forest,mutated_swampland,mutated_roofed_forest

rule1=0,100,preserveBlock
rule2=0,100,minecraft:red_mushroom_block-15
rule3=0,100,minecraft:red_mushroom_block-14
rule4=0,100,minecraft:red_mushroom_block-0

layer
1,1,1,1,1,1,1,1,1,1,1,1,1,1,1,1,1
1,1,1,1,1,1,1,1,1,1,1,1,1,1,1,1,1
1,1,1,1,1,1,1,1,1,1,1,1,1,1,1,1,1
1,1,1,1,1,1,1,1,1,1,1,1,1,1,1,1,1
1,1,1,1,1,1,1,1,1,1,1,1,1,1,1,1,1
1,1,1,1,1,1,1,1,1,1,1,1,1,1,1,1,1
1,1,1,1,1,1,1,2,2,2,1,1,1,1,1,1,1
1,1,1,1,1,1,2,2,2,2,2,1,1,1,1,1,1
1,1,1,1,1,1,2,2,2,2,2,1,1,1,1,1,1
1,1,1,1,1,1,2,2,2,2,2,1,1,1,1,1,1
1,1,1,1,1,1,1,2,2,2,1,1,1,1,1,1,1
1,1,1,1,1,1,1,1,1,1,1,1,1,1,1,1,1
1,1,1,1,1,1,1,1,1,1,1,1,1,1,1,1,1
1,1,1,1,1,1,1,1,1,1,1,1,1,1,1,1,1
1,1,1,1,1,1,1,1,1,1,1,1,1,1,1,1,1
1,1,1,1,1,1,1,1,1,1,1,1,1,1,1,1,1
1,1,1,1,1,1,1,1,1,1,1,1,1,1,1,1,1
endlayer

layer
1,1,1,1,1,1,1,1,1,1,1,1,1,1,1,1,1
1,1,1,1,1,1,1,1,1,1,1,1,1,1,1,1,1
1,1,1,1,1,1,1,1,1,1,1,1,1,1,1,1,1
1,1,1,1,1,1,1,1,1,1,1,1,1,1,1,1,1
1,1,1,1,1,1,1,1,1,1,1,1,1,1,1,1,1
1,1,1,1,1,1,1,1,1,1,1,1,1,1,1,1,1
1,1,1,1,1,1,1,2,2,2,1,1,1,1,1,1,1
1,1,1,1,1,1,2,2,2,2,2,1,1,1,1,1,1
1,1,1,1,1,1,2,2,2,2,2,1,1,1,1,1,1
1,1,1,1,1,1,2,2,2,2,2,1,1,1,1,1,1
1,1,1,1,1,1,1,2,2,2,1,1,1,1,1,1,1
1,1,1,1,1,1,1,1,1,1,1,1,1,1,1,1,1
1,1,1,1,1,1,1,1,1,1,1,1,1,1,1,1,1
1,1,1,1,1,1,1,1,1,1,1,1,1,1,1,1,1
1,1,1,1,1,1,1,1,1,1,1,1,1,1,1,1,1
1,1,1,1,1,1,1,1,1,1,1,1,1,1,1,1,1
1,1,1,1,1,1,1,1,1,1,1,1,1,1,1,1,1
endlayer

layer
1,1,1,1,1,1,1,1,1,1,1,1,1,1,1,1,1
1,1,1,1,1,1,1,1,1,1,1,1,1,1,1,1,1
1,1,1,1,1,1,1,1,1,1,1,1,1,1,1,1,1
1,1,1,1,1,1,1,1,1,1,1,1,1,1,1,1,1
1,1,1,1,1,1,1,1,1,1,1,1,1,1,1,1,1
1,1,1,1,1,1,1,1,1,1,1,1,1,1,1,1,1
1,1,1,1,1,1,1,1,2,2,1,1,1,1,1,1,1
1,1,1,1,1,1,2,2,2,2,1,1,1,1,1,1,1
1,1,1,1,1,1,2,2,2,2,2,1,1,1,1,1,1
1,1,1,1,1,1,1,2,2,2,2,1,1,1,1,1,1
1,1,1,1,1,1,1,2,2,1,1,1,1,1,1,1,1
1,1,1,1,1,1,1,1,1,1,1,1,1,1,1,1,1
1,1,1,1,1,1,1,1,1,1,1,1,1,1,1,1,1
1,1,1,1,1,1,1,1,1,1,1,1,1,1,1,1,1
1,1,1,1,1,1,1,1,1,1,1,1,1,1,1,1,1
1,1,1,1,1,1,1,1,1,1,1,1,1,1,1,1,1
1,1,1,1,1,1,1,1,1,1,1,1,1,1,1,1,1
endlayer

layer
1,1,1,1,1,1,1,1,1,1,1,1,1,1,1,1,1
1,1,1,1,1,1,1,1,1,1,1,1,1,1,1,1,1
1,1,1,1,1,1,1,1,1,1,1,1,1,1,1,1,1
1,1,1,1,1,1,1,1,1,1,1,1,1,1,1,1,1
1,1,1,1,1,1,1,1,1,1,1,1,1,1,1,1,1
1,1,1,1,1,1,1,1,1,1,1,1,1,1,1,1,1
1,1,1,1,1,1,1,1,2,1,1,1,1,1,1,1,1
1,1,1,1,1,1,1,2,2,2,1,1,1,1,1,1,1
1,1,1,1,1,1,2,2,2,2,2,1,1,1,1,1,1
1,1,1,1,1,1,1,2,2,2,1,1,1,1,1,1,1
1,1,1,1,1,1,1,1,2,1,1,1,1,1,1,1,1
1,1,1,1,1,1,1,1,1,1,1,1,1,1,1,1,1
1,1,1,1,1,1,1,1,1,1,1,1,1,1,1,1,1
1,1,1,1,1,1,1,1,1,1,1,1,1,1,1,1,1
1,1,1,1,1,1,1,1,1,1,1,1,1,1,1,1,1
1,1,1,1,1,1,1,1,1,1,1,1,1,1,1,1,1
1,1,1,1,1,1,1,1,1,1,1,1,1,1,1,1,1
endlayer

layer
1,1,1,1,1,1,1,1,1,1,1,1,1,1,1,1,1
1,1,1,1,1,1,1,1,1,1,1,1,1,1,1,1,1
1,1,1,1,1,1,1,1,1,1,1,1,1,1,1,1,1
1,1,1,1,1,1,1,1,1,1,1,1,1,1,1,1,1
1,1,1,1,1,1,1,1,1,1,1,1,1,1,1,1,1
1,1,1,1,1,1,1,1,1,1,1,1,1,1,1,1,1
1,1,1,1,1,1,1,1,1,1,1,1,1,1,1,1,1
1,1,1,1,1,1,1,2,2,2,1,1,1,1,1,1,1
1,1,1,1,1,1,1,2,2,2,1,1,1,1,1,1,1
1,1,1,1,1,1,1,2,2,2,1,1,1,1,1,1,1
1,1,1,1,1,1,1,1,1,1,1,1,1,1,1,1,1
1,1,1,1,1,1,1,1,1,1,1,1,1,1,1,1,1
1,1,1,1,1,1,1,1,1,1,1,1,1,1,1,1,1
1,1,1,1,1,1,1,1,1,1,1,1,1,1,1,1,1
1,1,1,1,1,1,1,1,1,1,1,1,1,1,1,1,1
1,1,1,1,1,1,1,1,1,1,1,1,1,1,1,1,1
1,1,1,1,1,1,1,1,1,1,1,1,1,1,1,1,1
endlayer

layer
1,1,1,1,1,1,1,1,1,1,1,1,1,1,1,1,1
1,1,1,1,1,1,1,1,1,1,1,1,1,1,1,1,1
1,1,1,1,1,1,1,1,1,1,1,1,1,1,1,1,1
1,1,1,1,1,1,1,1,1,1,1,1,1,1,1,1,1
1,1,1,1,1,1,1,1,1,1,1,1,1,1,1,1,1
1,1,1,1,1,1,1,1,1,1,1,1,1,1,1,1,1
1,1,1,1,1,1,1,1,1,1,1,1,1,1,1,1,1
1,1,1,1,1,1,1,2,2,2,1,1,1,1,1,1,1
1,1,1,1,1,1,1,2,2,2,1,1,1,1,1,1,1
1,1,1,1,1,1,1,2,2,2,1,1,1,1,1,1,1
1,1,1,1,1,1,1,1,1,1,1,1,1,1,1,1,1
1,1,1,1,1,1,1,1,1,1,1,1,1,1,1,1,1
1,1,1,1,1,1,1,1,1,1,1,1,1,1,1,1,1
1,1,1,1,1,1,1,1,1,1,1,1,1,1,1,1,1
1,1,1,1,1,1,1,1,1,1,1,1,1,1,1,1,1
1,1,1,1,1,1,1,1,1,1,1,1,1,1,1,1,1
1,1,1,1,1,1,1,1,1,1,1,1,1,1,1,1,1
endlayer

layer
1,1,1,1,1,1,1,1,1,1,1,1,1,1,1,1,1
1,1,1,1,1,1,1,1,1,1,1,1,1,1,1,1,1
1,1,1,1,1,1,1,1,1,1,1,1,1,1,1,1,1
1,1,1,1,1,1,1,1,1,1,1,1,1,1,1,1,1
1,1,1,1,1,1,1,1,1,1,1,1,1,1,1,1,1
1,1,1,1,1,1,1,1,1,1,1,1,1,1,1,1,1
1,1,1,1,1,1,1,1,1,1,1,1,1,1,1,1,1
1,1,1,1,1,1,1,2,2,2,1,1,1,1,1,1,1
1,1,1,1,1,1,1,2,2,2,1,1,1,1,1,1,1
1,1,1,1,1,1,1,2,2,2,1,1,1,1,1,1,1
1,1,1,1,1,1,1,1,1,1,1,1,1,1,1,1,1
1,1,1,1,1,1,1,1,1,1,1,1,1,1,1,1,1
1,1,1,1,1,1,1,1,1,1,1,1,1,1,1,1,1
1,1,1,1,1,1,1,1,1,1,1,1,1,1,1,1,1
1,1,1,1,1,1,1,1,1,1,1,1,1,1,1,1,1
1,1,1,1,1,1,1,1,1,1,1,1,1,1,1,1,1
1,1,1,1,1,1,1,1,1,1,1,1,1,1,1,1,1
endlayer

layer
1,1,1,1,1,1,3,3,3,3,3,1,1,1,1,1,1
1,1,1,1,3,3,4,4,4,4,4,3,3,1,1,1,1
1,1,1,3,4,4,0,0,0,0,0,4,4,3,1,1,1
1,1,3,4,0,0,0,0,0,0,0,0,0,4,3,1,1
1,3,4,0,0,0,0,0,0,0,0,0,0,0,4,3,1
1,3,4,0,0,0,0,0,0,0,0,0,0,0,4,3,1
3,4,0,0,0,0,0,0,0,0,0,0,0,0,0,4,3
3,4,0,0,0,0,0,2,2,2,0,0,0,0,0,4,3
3,4,0,0,0,0,0,2,2,2,0,0,0,0,0,4,3
3,4,0,0,0,0,0,2,2,2,0,0,0,0,0,4,3
3,4,0,0,0,0,0,0,0,0,0,0,0,0,0,4,3
1,3,4,0,0,0,0,0,0,0,0,0,0,0,4,3,1
1,3,4,0,0,0,0,0,0,0,0,0,0,0,4,3,1
1,1,3,4,0,0,0,0,0,0,0,0,0,4,3,1,1
1,1,1,3,4,4,0,0,0,0,0,4,4,3,1,1,1
1,1,1,1,3,3,4,4,4,4,4,3,3,1,1,1,1
1,1,1,1,1,1,3,3,3,3,3,1,1,1,1,1,1
endlayer

layer
1,1,1,1,1,1,3,3,3,3,3,1,1,1,1,1,1
1,1,1,1,3,3,4,4,4,4,4,3,3,1,1,1,1
1,1,1,3,4,4,0,0,0,0,0,4,4,3,1,1,1
1,1,3,4,0,0,0,0,0,0,0,0,0,4,3,1,1
1,3,4,0,0,0,0,0,0,0,0,0,0,0,4,3,1
1,3,4,0,0,0,0,0,0,0,0,0,0,0,4,3,1
3,4,0,0,0,0,0,0,0,0,0,0,0,0,0,4,3
3,4,0,0,0,0,0,2,2,2,0,0,0,0,0,4,3
3,4,0,0,0,0,0,2,2,2,0,0,0,0,0,4,3
3,4,0,0,0,0,0,2,2,2,0,0,0,0,0,4,3
3,4,0,0,0,0,0,0,0,0,0,0,0,0,0,4,3
1,3,4,0,0,0,0,0,0,0,0,0,0,0,4,3,1
1,3,4,0,0,0,0,0,0,0,0,0,0,0,4,3,1
1,1,3,4,0,0,0,0,0,0,0,0,0,4,3,1,1
1,1,1,3,4,4,0,0,0,0,0,4,4,3,1,1,1
1,1,1,1,3,3,4,4,4,4,4,3,3,1,1,1,1
1,1,1,1,1,1,3,3,3,3,3,1,1,1,1,1,1
endlayer

layer
1,1,1,1,1,1,0,3,3,3,1,1,1,1,1,1,1
1,1,1,1,3,3,3,4,4,4,3,3,3,1,1,1,1
1,1,1,3,4,4,4,0,0,0,4,4,4,3,1,1,1
1,1,3,4,0,0,0,0,0,0,0,0,0,4,3,1,1
1,3,4,0,0,0,0,0,0,0,0,0,0,0,4,3,1
1,3,4,0,0,0,0,0,0,0,0,0,0,0,4,3,1
1,3,4,0,0,0,0,0,0,0,0,0,0,0,4,3,1
3,4,0,0,0,0,0,0,2,2,0,0,0,0,0,4,3
3,4,0,0,0,0,0,2,2,2,0,0,0,0,0,4,3
3,4,0,0,0,0,0,2,2,0,0,0,0,0,0,4,3
0,3,4,0,0,0,0,0,0,0,0,0,0,0,4,3,1
1,3,4,0,0,0,0,0,0,0,0,0,0,0,4,3,1
1,3,4,0,0,0,0,0,0,0,0,0,0,0,4,3,1
1,1,3,4,0,0,0,0,0,0,0,0,0,4,3,1,1
1,1,1,3,4,4,4,0,0,0,4,4,4,3,1,1,1
1,1,1,1,3,3,3,4,4,4,3,3,3,1,1,1,1
1,1,1,1,1,1,1,3,3,3,0,1,1,1,1,1,1
endlayer

layer
1,1,1,1,1,1,1,1,1,1,1,1,1,1,1,1,1
1,1,1,1,1,3,3,3,3,3,3,3,1,1,1,1,1
1,1,1,3,3,4,4,4,4,4,4,4,3,3,1,1,1
1,1,3,4,4,0,0,0,0,0,0,0,4,4,3,1,1
1,1,3,4,0,0,0,0,0,0,0,0,0,4,3,1,1
1,3,4,0,0,0,0,0,0,0,0,0,0,0,4,3,1
1,3,4,0,0,0,0,0,0,0,0,0,0,0,4,3,1
1,3,4,0,0,0,0,0,2,2,0,0,0,0,4,3,1
1,3,4,0,0,0,0,2,2,2,0,0,0,0,4,3,1
1,3,4,0,0,0,0,2,2,0,0,0,0,0,4,3,1
1,3,4,0,0,0,0,0,0,0,0,0,0,0,4,3,1
1,3,4,0,0,0,0,0,0,0,0,0,0,0,4,3,1
1,1,3,4,0,0,0,0,0,0,0,0,0,4,3,1,1
1,1,3,4,4,0,0,0,0,0,0,0,4,4,3,1,1
1,1,1,3,3,4,4,4,4,4,4,4,3,3,1,1,1
1,1,1,1,1,3,3,3,3,3,3,3,1,1,1,1,1
1,1,1,1,1,1,1,1,1,1,1,1,1,1,1,1,1
endlayer

layer
1,1,1,1,1,1,1,1,1,1,1,1,1,1,1,1,1
1,1,1,1,1,1,3,3,3,3,3,1,1,1,1,1,1
1,1,1,1,3,3,4,4,4,4,4,3,3,1,1,1,1
1,1,1,3,4,4,0,0,0,0,0,4,4,3,1,1,1
1,1,3,4,0,0,0,0,0,0,0,0,0,4,3,1,1
1,1,3,4,0,0,0,0,0,0,0,0,0,4,3,1,1
1,3,4,0,0,0,0,0,0,0,0,0,0,0,4,3,1
1,3,4,0,0,0,0,0,2,0,0,0,0,0,4,3,1
1,3,4,0,0,0,0,2,2,2,0,0,0,0,4,3,1
1,3,4,0,0,0,0,0,2,0,0,0,0,0,4,3,1
1,3,4,0,0,0,0,0,0,0,0,0,0,0,4,3,1
1,1,3,4,0,0,0,0,0,0,0,0,0,4,3,1,1
1,1,3,4,0,0,0,0,0,0,0,0,0,4,3,1,1
1,1,1,3,4,4,0,0,0,0,0,4,4,3,1,1,1
1,1,1,1,3,3,4,4,4,4,4,3,3,1,1,1,1
1,1,1,1,1,1,3,3,3,3,3,1,1,1,1,1,1
1,1,1,1,1,1,1,1,1,1,1,1,1,1,1,1,1
endlayer

layer
1,1,1,1,1,1,1,1,1,1,1,1,1,1,1,1,1
1,1,1,1,1,1,1,1,1,1,1,1,1,1,1,1,1
1,1,1,1,1,3,3,3,3,3,3,3,1,1,1,1,1
1,1,1,1,3,4,4,4,4,4,4,4,3,1,1,1,1
1,1,1,3,4,4,0,0,0,0,0,4,4,3,1,1,1
1,1,3,4,4,0,0,0,0,0,0,0,4,4,3,1,1
1,1,3,4,0,0,0,0,0,0,0,0,0,4,3,1,1
1,1,3,4,0,0,0,0,2,0,0,0,0,4,3,1,1
1,1,3,4,0,0,0,2,2,2,0,0,0,4,3,1,1
1,1,3,4,0,0,0,0,2,0,0,0,0,4,3,1,1
1,1,3,4,0,0,0,0,0,0,0,0,0,4,3,1,1
1,1,3,4,4,0,0,0,0,0,0,0,4,4,3,1,1
1,1,1,3,4,4,0,0,0,0,0,4,4,3,1,1,1
1,1,1,1,3,4,4,4,4,4,4,4,3,1,1,1,1
1,1,1,1,1,3,3,3,3,3,3,3,1,1,1,1,1
1,1,1,1,1,1,1,1,1,1,1,1,1,1,1,1,1
1,1,1,1,1,1,1,1,1,1,1,1,1,1,1,1,1
endlayer

layer
1,1,1,1,1,1,1,1,1,1,1,1,1,1,1,1,1
1,1,1,1,1,1,1,1,1,1,1,1,1,1,1,1,1
1,1,1,1,1,1,1,1,1,1,1,1,1,1,1,1,1
1,1,1,1,1,3,3,3,3,3,3,3,1,1,1,1,1
1,1,1,1,3,3,4,4,4,4,4,3,3,1,1,1,1
1,1,1,3,3,4,4,4,4,4,4,4,3,3,1,1,1
1,1,1,3,4,4,4,0,0,0,4,4,4,3,1,1,1
1,1,1,3,4,4,0,0,2,0,0,4,4,3,1,1,1
1,1,1,3,4,4,0,2,2,2,0,4,4,3,1,1,1
1,1,1,3,4,4,0,0,2,0,0,4,4,3,1,1,1
1,1,1,3,4,4,4,0,0,0,4,4,4,3,1,1,1
1,1,1,3,3,4,4,4,4,4,4,4,3,3,1,1,1
1,1,1,1,3,3,4,4,4,4,4,3,3,1,1,1,1
1,1,1,1,1,3,3,3,3,3,3,3,1,1,1,1,1
1,1,1,1,1,1,1,1,1,1,1,1,1,1,1,1,1
1,1,1,1,1,1,1,1,1,1,1,1,1,1,1,1,1
1,1,1,1,1,1,1,1,1,1,1,1,1,1,1,1,1
endlayer

layer
1,1,1,1,1,1,1,1,1,1,1,1,1,1,1,1,1
1,1,1,1,1,1,1,1,1,1,1,1,1,1,1,1,1
1,1,1,1,1,1,1,1,1,1,1,1,1,1,1,1,1
1,1,1,1,1,1,1,1,1,1,1,1,1,1,1,1,1
1,1,1,1,1,1,3,3,3,3,3,1,1,1,1,1,1
1,1,1,1,1,3,3,3,3,3,3,3,1,1,1,1,1
1,1,1,1,3,3,3,4,4,4,3,3,3,1,1,1,1
1,1,1,1,3,3,4,4,2,4,4,3,3,1,1,1,1
1,1,1,1,3,3,4,2,2,2,4,3,3,1,1,1,1
1,1,1,1,3,3,4,4,2,4,4,3,3,1,1,1,1
1,1,1,1,3,3,3,4,4,4,3,3,3,1,1,1,1
1,1,1,1,1,3,3,3,3,3,3,3,1,1,1,1,1
1,1,1,1,1,1,3,3,3,3,3,1,1,1,1,1,1
1,1,1,1,1,1,1,1,1,1,1,1,1,1,1,1,1
1,1,1,1,1,1,1,1,1,1,1,1,1,1,1,1,1
1,1,1,1,1,1,1,1,1,1,1,1,1,1,1,1,1
1,1,1,1,1,1,1,1,1,1,1,1,1,1,1,1,1
endlayer

layer
1,1,1,1,1,1,1,1,1,1,1,1,1,1,1,1,1
1,1,1,1,1,1,1,1,1,1,1,1,1,1,1,1,1
1,1,1,1,1,1,1,1,1,1,1,1,1,1,1,1,1
1,1,1,1,1,1,1,1,1,1,1,1,1,1,1,1,1
1,1,1,1,1,1,1,1,1,1,1,1,1,1,1,1,1
1,1,1,1,1,1,1,1,1,1,1,1,1,1,1,1,1
1,1,1,1,1,1,1,3,3,3,1,1,1,1,1,1,1
1,1,1,1,1,1,3,3,3,3,3,1,1,1,1,1,1
1,1,1,1,1,1,3,3,3,3,3,1,1,1,1,1,1
1,1,1,1,1,1,3,3,3,3,3,1,1,1,1,1,1
1,1,1,1,1,1,1,3,3,3,1,1,1,1,1,1,1
1,1,1,1,1,1,1,1,1,1,1,1,1,1,1,1,1
1,1,1,1,1,1,1,1,1,1,1,1,1,1,1,1,1
1,1,1,1,1,1,1,1,1,1,1,1,1,1,1,1,1
1,1,1,1,1,1,1,1,1,1,1,1,1,1,1,1,1
1,1,1,1,1,1,1,1,1,1,1,1,1,1,1,1,1
1,1,1,1,1,1,1,1,1,1,1,1,1,1,1,1,1
endlayer

