
# Created by Ruins mod version 16.7 Ingame Parser
# authoring Player: ST753M

weight=1
spawnMinDistance=500
embed_into_distance=1
acceptable_target_blocks=grass,dirt,stone
unacceptable_target_blocks=flowing_water,water,flowing_lava,lava
dimensions=13,13,13
allowable_overhang=1
max_leveling=2
leveling_buffer=0
preserve_water=0
preserve_lava=0

biomesToSpawnIn=roofed_forest,mutated_roofed_forest

=0,100,air
rule1=0,100,minecraft:cobblestone-0
rule2=0,100,minecraft:planks-1
rule3=0,100,minecraft:log-9
rule4=0,100,cookingforblockheads:kitchen_floor-0
rule5=0,100,minecraft:log-1
rule6=0,100,minecraft:planks-5
rule7=0,100,minecraft:bed-9
rule8=0,100,minecraft:fence-0
rule9=0,100,minecraft:spruce_stairs-0
rule10=0,100,minecraft:bed-1
rule11=0,100,minecraft:oak_stairs-1
rule12=0,100,minecraft:dark_oak_fence-0
rule13=0,100,minecraft:oak_stairs-0
rule14=0,100,cookingforblockheads:corner-3
rule15=0,100,cookingforblockheads:counter-3
rule16=0,100,minecraft:bookshelf-0
rule17=0,100,cookingforblockheads:oven-2
rule18=0,100,IInventory;minecraft:chest;harvestcraft:mixingbowlitem#1#0#0+harvestcraft:freshmilkitem#5#0#3+harvestcraft:potitem#1#0#7+harvestcraft:bakewareitem#1#0#11+harvestcraft:grapesodaitem#1#0#15+harvestcraft:cuttingboarditem#1#0#17+harvestcraft:peachesandcreamoatmealitem#1#0#19+harvestcraft:bellpepperitem#1#0#23-2
rule19=0,100,cookingforblockheads:sink-1
rule20=0,100,cookingforblockheads:cooking_table-4
rule21=0,100,cookingforblockheads:fridge-9
rule22=0,100,cookingforblockheads:corner-2
rule23=0,100,minecraft:cobblestone_wall-0
rule24=0,100,minecraft:stone_stairs-0
rule25=0,100,minecraft:log-5
rule26=0,100,minecraft:stone_stairs-2
rule27=0,100,minecraft:trapdoor-0
rule28=0,100,minecraft:stone_stairs-3
rule29=0,100,cookingforblockheads:toaster-3
rule30=0,100,cookingforblockheads:spice_rack-2
rule31=0,100,cookingforblockheads:tool_rack-4
rule32=0,100,minecraft:stone_stairs-1
rule33=0,100,minecraft:glass_pane-0
rule34=0,100,minecraft:wooden_slab-1
rule35=0,100,minecraft:wooden_slab-9
rule36=1,100,minecraft:torch-5
rule37=0,100,minecraft:stone_stairs-4
rule38=0,100,minecraft:stone_stairs-6
rule39=0,100,minecraft:stone_stairs-7
rule40=0,100,minecraft:stone_stairs-5
rule41=0,100,minecraft:spruce_stairs-2
rule42=0,100,minecraft:spruce_stairs-3
rule43=0,100,minecraft:spruce_stairs-1

layer
1,1,1,1,1,1,1,1,1,1,1,1,1
1,1,1,1,1,1,1,1,1,1,1,1,1
1,1,1,1,1,1,1,1,1,1,1,1,1
1,1,1,1,1,1,1,1,1,1,1,1,1
1,1,1,1,1,1,1,1,1,1,1,1,1
1,1,1,1,1,1,1,1,1,1,1,1,1
1,1,1,1,1,1,1,1,1,1,1,1,1
1,1,1,1,1,1,1,1,1,1,1,1,1
1,1,1,1,1,1,1,1,1,1,1,1,1
1,1,1,1,1,1,1,1,1,1,1,1,1
1,1,1,1,1,1,1,1,1,1,1,1,1
1,1,1,1,1,1,1,1,1,1,1,1,1
1,1,1,1,1,1,1,1,1,1,1,1,1
endlayer

layer
1,1,1,1,1,1,1,1,1,1,1,1,1
1,1,1,1,1,1,1,1,1,1,1,1,1
1,1,2,2,2,2,2,2,2,2,2,1,1
1,1,2,2,2,2,2,2,2,2,2,1,1
1,1,2,2,2,2,2,2,2,2,2,1,1
1,1,2,2,2,2,2,2,2,2,2,3,1
1,1,2,2,2,2,2,2,2,2,2,3,1
1,1,4,4,4,4,2,2,2,2,2,3,1
1,1,4,4,4,4,2,2,2,2,2,1,1
1,1,4,4,4,4,2,2,2,2,2,1,1
1,1,4,4,4,4,2,2,2,2,2,1,1
1,1,1,1,1,1,1,1,1,1,1,1,1
1,1,1,1,1,1,1,1,1,1,1,1,1
endlayer

layer
0,1,1,0,0,0,0,0,0,0,1,1,0
1,5,1,6,6,6,6,6,6,6,1,5,1
1,1,0,0,0,0,0,0,9,8,7,1,1
0,6,0,11,0,11,0,0,9,0,10,6,0
0,6,0,8,8,8,0,0,9,0,0,3,12
0,6,0,13,0,13,0,0,0,0,0,0,0
0,6,0,0,0,0,0,0,0,0,0,0,0
0,6,15,0,0,14,0,0,0,0,0,0,0
0,6,17,0,0,0,0,0,16,0,0,3,12
0,6,18,0,0,0,0,0,16,0,0,6,0
1,1,22,21,20,19,0,0,0,0,0,1,1
1,5,1,6,6,6,6,6,6,6,1,5,1
0,1,1,0,0,0,0,0,0,0,1,1,0
endlayer

layer
0,23,24,0,0,0,0,0,0,0,24,23,0
23,5,1,6,25,25,25,25,25,6,1,5,23
28,1,0,0,0,0,0,0,9,27,0,1,26
0,6,0,0,0,0,0,0,9,0,0,6,0
0,3,0,27,27,27,0,0,9,0,0,3,12
0,3,0,0,0,0,0,0,0,0,0,0,0
0,3,0,0,0,0,0,0,0,0,0,0,0
0,3,0,0,0,29,0,0,0,0,0,0,0
0,3,0,0,0,0,0,0,16,0,0,3,12
0,6,30,0,0,0,0,0,16,0,0,6,0
28,1,0,21,31,31,0,0,0,0,0,1,26
23,5,1,6,25,25,25,25,25,6,1,5,23
0,23,32,0,0,0,0,0,0,0,32,23,0
endlayer

layer
0,23,0,0,0,0,0,0,0,0,0,23,0
23,5,1,6,25,33,33,33,25,6,1,5,23
0,1,0,0,0,0,0,0,34,0,0,1,0
0,6,0,0,0,0,0,0,34,0,0,6,0
0,3,0,0,0,0,0,0,34,0,0,3,12
0,33,0,0,0,0,0,0,0,0,0,0,0
0,33,0,0,0,0,0,0,0,0,0,0,0
0,33,0,0,0,0,0,0,0,0,0,0,0
0,3,0,0,0,0,0,0,34,0,0,3,12
0,6,0,0,0,0,0,0,34,0,0,6,0
0,1,0,0,0,0,0,0,0,0,0,1,0
23,5,1,6,25,33,33,33,25,6,1,5,23
0,23,0,0,0,0,0,0,0,0,0,23,0
endlayer

layer
0,23,0,0,12,0,0,0,12,0,0,23,0
23,5,1,6,25,33,33,33,25,6,1,5,23
0,1,0,0,0,0,0,0,0,0,0,1,0
0,6,0,0,0,0,0,0,0,0,0,6,0
12,3,0,0,0,0,0,0,0,0,0,3,12
0,33,0,0,0,0,0,0,0,0,0,35,0
0,33,0,0,0,0,12,0,0,0,0,35,0
0,33,0,0,0,0,0,0,0,0,0,35,0
12,3,0,0,0,0,0,0,0,0,0,3,12
0,6,0,0,0,0,0,0,0,0,0,6,0
0,1,0,0,0,0,0,0,0,0,0,1,0
23,5,1,6,25,33,33,33,25,6,1,5,23
0,23,0,0,12,0,0,0,12,0,0,23,0
endlayer

layer
0,23,0,0,12,0,0,0,12,0,0,23,0
23,5,1,6,25,33,33,33,25,6,1,5,23
0,1,0,0,0,0,0,0,0,0,0,1,0
0,6,0,0,0,0,0,0,0,0,0,6,0
12,3,0,0,0,0,12,0,0,0,0,3,12
0,33,0,0,0,12,12,12,0,0,0,12,0
0,33,0,0,12,12,12,12,12,0,0,12,0
0,33,0,0,0,12,12,12,0,0,0,12,0
12,3,0,0,0,0,12,0,0,0,0,3,12
0,6,0,0,0,0,0,0,0,0,0,6,0
0,1,0,0,0,0,0,0,0,0,0,1,0
23,5,1,6,25,33,33,33,25,6,1,5,23
0,23,0,0,12,0,0,0,12,0,0,23,0
endlayer

layer
0,23,0,0,12,0,0,0,12,0,0,23,0
23,5,1,6,25,33,33,33,25,6,1,5,23
0,1,0,0,0,0,0,0,0,0,0,1,0
0,6,0,0,0,0,0,0,0,0,0,6,0
12,3,0,0,0,0,36,0,0,0,0,3,12
0,33,0,0,0,12,0,12,0,0,0,12,0
0,33,0,0,36,0,12,0,36,0,0,12,0
0,33,0,0,0,12,0,12,0,0,0,12,0
12,3,0,0,0,0,36,0,0,0,0,3,12
0,6,0,0,0,0,0,0,0,0,0,6,0
0,1,0,0,0,0,0,0,0,0,0,1,0
23,5,1,6,25,33,33,33,25,6,1,5,23
0,23,0,0,12,0,0,0,12,0,0,23,0
endlayer

layer
0,23,0,0,3,3,3,3,3,0,0,23,0
23,5,1,6,25,25,25,25,25,6,1,5,23
0,1,0,0,0,0,0,0,0,0,0,1,0
0,6,0,0,0,0,0,0,0,0,0,6,0
25,3,0,0,0,0,0,0,0,0,0,3,25
25,3,0,0,0,36,0,36,0,0,0,3,25
25,3,0,0,0,0,12,0,0,0,0,3,25
25,3,0,0,0,36,0,36,0,0,0,3,25
25,3,0,0,0,0,0,0,0,0,0,3,25
0,6,0,0,0,0,0,0,0,0,0,6,0
0,1,0,0,0,0,0,0,0,0,0,1,0
23,5,1,6,25,25,25,25,25,6,1,5,23
0,23,0,0,3,3,3,3,3,0,0,23,0
endlayer

layer
0,23,37,0,0,0,0,0,0,0,37,23,0
23,5,1,6,6,6,6,6,6,6,1,5,23
39,1,0,0,0,0,0,0,0,0,0,1,38
0,6,0,0,0,0,0,0,0,0,0,6,0
0,6,0,0,0,0,0,0,0,0,0,6,0
0,6,0,0,0,0,0,0,0,0,0,6,0
0,6,0,0,0,0,12,0,0,0,0,6,0
0,6,0,0,0,0,0,0,0,0,0,6,0
0,6,0,0,0,0,0,0,0,0,0,6,0
0,6,0,0,0,0,0,0,0,0,0,6,0
39,1,0,0,0,0,0,0,0,0,0,1,38
23,5,1,6,6,6,6,6,6,6,1,5,23
0,23,40,0,0,0,0,0,0,0,40,23,0
endlayer

layer
0,23,1,0,37,0,37,0,37,0,1,23,0
23,5,1,1,1,1,1,1,1,1,1,5,23
1,1,0,0,0,0,0,0,0,0,0,1,1
0,1,0,0,0,0,0,0,0,0,0,1,0
39,1,0,0,0,0,0,0,0,0,0,1,38
0,1,0,0,0,0,0,0,0,0,0,1,0
39,1,0,0,0,0,5,0,0,0,0,1,38
0,1,0,0,0,0,0,0,0,0,0,1,0
39,1,0,0,0,0,0,0,0,0,0,1,38
0,1,0,0,0,0,0,0,0,0,0,1,0
1,1,0,0,0,0,0,0,0,0,0,1,1
23,5,1,1,1,1,1,1,1,1,1,5,23
0,23,1,0,40,0,40,0,40,0,1,23,0
endlayer

layer
9,9,9,9,9,9,9,9,9,9,9,9,41
42,5,3,3,3,3,3,3,3,3,3,5,41
42,25,0,0,0,0,25,0,0,0,0,25,41
42,25,0,0,0,0,25,0,0,0,0,25,41
42,25,0,0,0,0,25,0,0,0,0,25,41
42,25,0,0,0,0,25,0,0,0,0,25,41
42,25,3,3,3,3,5,3,3,3,3,25,41
42,25,0,0,0,0,25,0,0,0,0,25,41
42,25,0,0,0,0,25,0,0,0,0,25,41
42,25,0,0,0,0,25,0,0,0,0,25,41
42,25,0,0,0,0,25,0,0,0,0,25,41
42,5,3,3,3,3,3,3,3,3,3,5,41
42,43,43,43,43,43,43,43,43,43,43,43,41
endlayer

layer
0,0,0,0,0,0,0,0,0,0,0,0,0
0,42,9,9,9,9,9,9,9,9,9,9,0
0,42,2,2,2,2,2,2,2,2,2,41,0
0,42,2,2,2,2,2,2,2,2,2,41,0
0,42,2,2,2,2,2,2,2,2,2,41,0
0,42,2,2,2,2,2,2,2,2,2,41,0
0,42,2,2,2,2,2,2,2,2,2,41,0
0,42,2,2,2,2,2,2,2,2,2,41,0
0,42,2,2,2,2,2,2,2,2,2,41,0
0,42,2,2,2,2,2,2,2,2,2,41,0
0,42,2,2,2,2,2,2,2,2,2,41,0
0,43,43,43,43,43,43,43,43,43,43,43,0
0,0,0,0,0,0,0,0,0,0,0,0,0
endlayer

